Workbook

Sheet scen2_ac15p
A1: turnId | B1: user_id | C1: assistant_id | D1: projectName | E1: sessionName | F1: seq | G1: anchorName | H1: weight | I1: promptSim | J1: responseSim | K1: activation delta | L1: prompt_to_response | N1: Average activation/turn | O1: average conversation activation | P1: count | Q1: correlation weights / activation delta | R1: p
A3: ce5c286d-cf7c-4f21-acca-96829addae4b | B3: cmj9wrb0d0011zcyqu1jsm0k1 | C3: cmj9wsedv001izcyqfmbz7fno | D3: ac15-plain | E3: Scenario_2_v3 | F3: 2 | G3: practicality_and_feasibility | H3: 0.2152 | I3: 0.31460323 | J3: 0.39451188 | K3: =J3-I3 -> 0.079908646 | L3: 0.84283713 | N3: =AVERAGE(K3:K8) -> 0.074473196 | O3: =K3:K144 -> 0.079908646 | P3: =COUNT(K3:K144) -> 142 | Q3: =CORREL(H3:H144,K3:K144) -> 0.088676395 | R3: 0.29
A4: ce5c286d-cf7c-4f21-acca-96829addae4b | B4: cmj9wrb0d0011zcyqu1jsm0k1 | C4: cmj9wsedv001izcyqfmbz7fno | D4: ac15-plain | E4: Scenario_2_v3 | F4: 2 | G4: temporal_dynamics | H4: 0.1928 | I4: 0.28186369 | J4: 0.33541395 | K4: =J4-I4 -> 0.053550256 | L4: 0.84283713
A5: ce5c286d-cf7c-4f21-acca-96829addae4b | B5: cmj9wrb0d0011zcyqu1jsm0k1 | C5: cmj9wsedv001izcyqfmbz7fno | D5: ac15-plain | E5: Scenario_2_v3 | F5: 2 | G5: mathematics_computer_science_engineering | H5: 0.1676 | I5: 0.2450536 | J5: 0.323708 | K5: =J5-I5 -> 0.078654401 | L5: 0.84283713
A6: ce5c286d-cf7c-4f21-acca-96829addae4b | B6: cmj9wrb0d0011zcyqu1jsm0k1 | C6: cmj9wsedv001izcyqfmbz7fno | D6: ac15-plain | E6: Scenario_2_v3 | F6: 2 | G6: affective_interface | H6: 0.1634 | I6: 0.23898851 | J6: 0.31067293 | K6: =J6-I6 -> 0.071684424 | L6: 0.84283713
A7: ce5c286d-cf7c-4f21-acca-96829addae4b | B7: cmj9wrb0d0011zcyqu1jsm0k1 | C7: cmj9wsedv001izcyqfmbz7fno | D7: ac15-plain | E7: Scenario_2_v3 | F7: 2 | G7: imagination_and_possibility | H7: 0.1611 | I7: 0.23549699 | J7: 0.28964819 | K7: =J7-I7 -> 0.054151199 | L7: 0.84283713
A8: ce5c286d-cf7c-4f21-acca-96829addae4b | B8: cmj9wrb0d0011zcyqu1jsm0k1 | C8: cmj9wsedv001izcyqfmbz7fno | D8: ac15-plain | E8: Scenario_2_v3 | F8: 2 | G8: truth_and_fact | H8: 0.1 | I8: 0.14406599 | J8: 0.25295624 | K8: =J8-I8 -> 0.10889025 | L8: 0.84283713
A9: ce3a83d5-84b1-4782-8a1b-9339c0ac7b3f | B9: cmj9wwl4b001mzcyql8irdgfa | C9: cmj9wxsc90023zcyq989zvie9 | D9: ac15-plain | E9: Scenario_2_v3 | F9: 4 | G9: practicality_and_feasibility | H9: 0.2137 | I9: 0.31014855 | J9: 0.38448096 | K9: =J9-I9 -> 0.074332402 | L9: 0.75574435 | N9: =AVERAGE(K9:K14) -> 0.068465937
A10: ce3a83d5-84b1-4782-8a1b-9339c0ac7b3f | B10: cmj9wwl4b001mzcyql8irdgfa | C10: cmj9wxsc90023zcyq989zvie9 | D10: ac15-plain | E10: Scenario_2_v3 | F10: 4 | G10: temporal_dynamics | H10: 0.1849 | I10: 0.26847894 | J10: 0.31643706 | K10: =J10-I10 -> 0.047958114 | L10: 0.75574435
A11: ce3a83d5-84b1-4782-8a1b-9339c0ac7b3f | B11: cmj9wwl4b001mzcyql8irdgfa | C11: cmj9wxsc90023zcyq989zvie9 | D11: ac15-plain | E11: Scenario_2_v3 | F11: 4 | G11: sovereignty | H11: 0.1779 | I11: 0.25822056 | J11: 0.30266537 | K11: =J11-I11 -> 0.044444806 | L11: 0.75574435
A12: ce3a83d5-84b1-4782-8a1b-9339c0ac7b3f | B12: cmj9wwl4b001mzcyql8irdgfa | C12: cmj9wxsc90023zcyq989zvie9 | D12: ac15-plain | E12: Scenario_2_v3 | F12: 4 | G12: mathematics_computer_science_engineering | H12: 0.163 | I12: 0.23660048 | J12: 0.31415716 | K12: =J12-I12 -> 0.077556679 | L12: 0.75574435
A13: ce3a83d5-84b1-4782-8a1b-9339c0ac7b3f | B13: cmj9wwl4b001mzcyql8irdgfa | C13: cmj9wxsc90023zcyq989zvie9 | D13: ac15-plain | E13: Scenario_2_v3 | F13: 4 | G13: affective_interface | H13: 0.1605 | I13: 0.23303867 | J13: 0.31824656 | K13: =J13-I13 -> 0.085207892 | L13: 0.75574435
A14: ce3a83d5-84b1-4782-8a1b-9339c0ac7b3f | B14: cmj9wwl4b001mzcyql8irdgfa | C14: cmj9wxsc90023zcyq989zvie9 | D14: ac15-plain | E14: Scenario_2_v3 | F14: 4 | G14: truth_and_fact | H14: 0.1 | I14: 0.17620724 | J14: 0.25750296 | K14: =J14-I14 -> 0.081295729 | L14: 0.75574435
A15: adbe0cc2-05ff-4dfa-98d0-16f472d301e3 | B15: cmj9wz6to0027zcyqe55009e3 | C15: cmj9wzv76002ozcyqo8tkuywo | D15: ac15-plain | E15: Scenario_2_v3 | F15: 6 | G15: practicality_and_feasibility | H15: 0.2125 | I15: 0.36853405 | J15: 0.42189643 | K15: =J15-I15 -> 0.053362378 | L15: 0.75246139 | N15: =AVERAGE(K15:K20) -> 0.059548965
A16: adbe0cc2-05ff-4dfa-98d0-16f472d301e3 | B16: cmj9wz6to0027zcyqe55009e3 | C16: cmj9wzv76002ozcyqo8tkuywo | D16: ac15-plain | E16: Scenario_2_v3 | F16: 6 | G16: temporal_dynamics | H16: 0.1871 | I16: 0.32447094 | J16: 0.38578238 | K16: =J16-I16 -> 0.061311444 | L16: 0.75246139
A17: adbe0cc2-05ff-4dfa-98d0-16f472d301e3 | B17: cmj9wz6to0027zcyqe55009e3 | C17: cmj9wzv76002ozcyqo8tkuywo | D17: ac15-plain | E17: Scenario_2_v3 | F17: 6 | G17: affective_interface | H17: 0.1772 | I17: 0.30735517 | J17: 0.36254235 | K17: =J17-I17 -> 0.05518718 | L17: 0.75246139
A18: adbe0cc2-05ff-4dfa-98d0-16f472d301e3 | B18: cmj9wz6to0027zcyqe55009e3 | C18: cmj9wzv76002ozcyqo8tkuywo | D18: ac15-plain | E18: Scenario_2_v3 | F18: 6 | G18: sovereignty | H18: 0.1658 | I18: 0.28763418 | J18: 0.33805047 | K18: =J18-I18 -> 0.050416285 | L18: 0.75246139
A19: adbe0cc2-05ff-4dfa-98d0-16f472d301e3 | B19: cmj9wz6to0027zcyqe55009e3 | C19: cmj9wzv76002ozcyqo8tkuywo | D19: ac15-plain | E19: Scenario_2_v3 | F19: 6 | G19: mathematics_computer_science_engineering | H19: 0.1575 | I19: 0.27311866 | J19: 0.35272261 | K19: =J19-I19 -> 0.079603952 | L19: 0.75246139
A20: adbe0cc2-05ff-4dfa-98d0-16f472d301e3 | B20: cmj9wz6to0027zcyqe55009e3 | C20: cmj9wzv76002ozcyqo8tkuywo | D20: ac15-plain | E20: Scenario_2_v3 | F20: 6 | G20: truth_and_fact | H20: 0.1 | I20: 0.20916898 | J20: 0.26658153 | K20: =J20-I20 -> 0.057412552 | L20: 0.75246139
A21: 6c024c7c-de30-4915-be0e-43cb40782ce7 | B21: cmj9x0yaw002szcyqatsdxe11 | C21: cmj9x1mkj0039zcyqy85cwm98 | D21: ac15-plain | E21: Scenario_2_v3 | F21: 8 | G21: practicality_and_feasibility | H21: 0.225 | I21: 0.35934998 | J21: 0.39880862 | K21: =J21-I21 -> 0.039458633 | L21: 0.75523994 | N21: =AVERAGE(K21:K26) -> 0.061501322
A22: 6c024c7c-de30-4915-be0e-43cb40782ce7 | B22: cmj9x0yaw002szcyqatsdxe11 | C22: cmj9x1mkj0039zcyqy85cwm98 | D22: ac15-plain | E22: Scenario_2_v3 | F22: 8 | G22: temporal_dynamics | H22: 0.1964 | I22: 0.31380202 | J22: 0.32879859 | K22: =J22-I22 -> 0.014996571 | L22: 0.75523994
A23: 6c024c7c-de30-4915-be0e-43cb40782ce7 | B23: cmj9x0yaw002szcyqatsdxe11 | C23: cmj9x1mkj0039zcyqy85cwm98 | D23: ac15-plain | E23: Scenario_2_v3 | F23: 8 | G23: mathematics_computer_science_engineering | H23: 0.1655 | I23: 0.26445423 | J23: 0.33940216 | K23: =J23-I23 -> 0.074947931 | L23: 0.75523994
A24: 6c024c7c-de30-4915-be0e-43cb40782ce7 | B24: cmj9x0yaw002szcyqatsdxe11 | C24: cmj9x1mkj0039zcyqy85cwm98 | D24: ac15-plain | E24: Scenario_2_v3 | F24: 8 | G24: sovereignty | H24: 0.1569 | I24: 0.25064936 | J24: 0.32903323 | K24: =J24-I24 -> 0.078383876 | L24: 0.75523994
A25: 6c024c7c-de30-4915-be0e-43cb40782ce7 | B25: cmj9x0yaw002szcyqatsdxe11 | C25: cmj9x1mkj0039zcyqy85cwm98 | D25: ac15-plain | E25: Scenario_2_v3 | F25: 8 | G25: affective_interface | H25: 0.1562 | I25: 0.24945621 | J25: 0.31170593 | K25: =J25-I25 -> 0.062249724 | L25: 0.75523994
A26: 6c024c7c-de30-4915-be0e-43cb40782ce7 | B26: cmj9x0yaw002szcyqatsdxe11 | C26: cmj9x1mkj0039zcyqy85cwm98 | D26: ac15-plain | E26: Scenario_2_v3 | F26: 8 | G26: truth_and_fact | H26: 0.1 | I26: 0.17844184 | J26: 0.27741304 | K26: =J26-I26 -> 0.098971199 | L26: 0.75523994
A27: 36815b24-8033-4152-bdde-9b210b90557a | B27: cmj9x3o06003dzcyqw1y82d0d | C27: cmj9x48fz003uzcyqwktot01w | D27: ac15-plain | E27: Scenario_2_v3 | F27: 10 | G27: practicality_and_feasibility | H27: 0.2138 | I27: 0.33803559 | J27: 0.39250541 | K27: =J27-I27 -> 0.054469814 | L27: 0.68196907 | N27: =AVERAGE(K27:K32) -> 0.044594508
A28: 36815b24-8033-4152-bdde-9b210b90557a | B28: cmj9x3o06003dzcyqw1y82d0d | C28: cmj9x48fz003uzcyqwktot01w | D28: ac15-plain | E28: Scenario_2_v3 | F28: 10 | G28: temporal_dynamics | H28: 0.1822 | I28: 0.28796534 | J28: 0.32065754 | K28: =J28-I28 -> 0.032692202 | L28: 0.68196907
A29: 36815b24-8033-4152-bdde-9b210b90557a | B29: cmj9x3o06003dzcyqw1y82d0d | C29: cmj9x48fz003uzcyqwktot01w | D29: ac15-plain | E29: Scenario_2_v3 | F29: 10 | G29: sovereignty | H29: 0.1812 | I29: 0.28646465 | J29: 0.3327644 | K29: =J29-I29 -> 0.046299749 | L29: 0.68196907
A30: 36815b24-8033-4152-bdde-9b210b90557a | B30: cmj9x3o06003dzcyqw1y82d0d | C30: cmj9x48fz003uzcyqwktot01w | D30: ac15-plain | E30: Scenario_2_v3 | F30: 10 | G30: mathematics_computer_science_engineering | H30: 0.1631 | I30: 0.25780428 | J30: 0.31451659 | K30: =J30-I30 -> 0.056712307 | L30: 0.68196907
A31: 36815b24-8033-4152-bdde-9b210b90557a | B31: cmj9x3o06003dzcyqw1y82d0d | C31: cmj9x48fz003uzcyqwktot01w | D31: ac15-plain | E31: Scenario_2_v3 | F31: 10 | G31: affective_interface | H31: 0.1597 | I31: 0.25242806 | J31: 0.31928442 | K31: =J31-I31 -> 0.066856367 | L31: 0.68196907
A32: 36815b24-8033-4152-bdde-9b210b90557a | B32: cmj9x3o06003dzcyqw1y82d0d | C32: cmj9x48fz003uzcyqwktot01w | D32: ac15-plain | E32: Scenario_2_v3 | F32: 10 | G32: truth_and_fact | H32: 0.1 | I32: 0.23122343 | J32: 0.24176004 | K32: =J32-I32 -> 0.01053661 | L32: 0.68196907
A33: 7fd71c82-50c3-43e6-9e8a-3e7b6c2bd89f | B33: cmj9x7oh4003yzcyqdwkswpug | C33: cmj9x8j4m004fzcyqa9lz7ko5 | D33: ac15-plain | E33: Scenario_2_v3 | F33: 12 | G33: practicality_and_feasibility | H33: 0.2215 | I33: 0.295812 | J33: 0.36395522 | K33: =J33-I33 -> 0.068143221 | L33: 0.80509458 | N33: =AVERAGE(K33:K38) -> 0.069508687
A34: 7fd71c82-50c3-43e6-9e8a-3e7b6c2bd89f | B34: cmj9x7oh4003yzcyqdwkswpug | C34: cmj9x8j4m004fzcyqa9lz7ko5 | D34: ac15-plain | E34: Scenario_2_v3 | F34: 12 | G34: temporal_dynamics | H34: 0.1978 | I34: 0.26424487 | J34: 0.31585339 | K34: =J34-I34 -> 0.051608518 | L34: 0.80509458
A35: 7fd71c82-50c3-43e6-9e8a-3e7b6c2bd89f | B35: cmj9x7oh4003yzcyqdwkswpug | C35: cmj9x8j4m004fzcyqa9lz7ko5 | D35: ac15-plain | E35: Scenario_2_v3 | F35: 12 | G35: mathematics_computer_science_engineering | H35: 0.1621 | I35: 0.21645564 | J35: 0.29265244 | K35: =J35-I35 -> 0.076196802 | L35: 0.80509458
A36: 7fd71c82-50c3-43e6-9e8a-3e7b6c2bd89f | B36: cmj9x7oh4003yzcyqdwkswpug | C36: cmj9x8j4m004fzcyqa9lz7ko5 | D36: ac15-plain | E36: Scenario_2_v3 | F36: 12 | G36: affective_interface | H36: 0.1602 | I36: 0.21391013 | J36: 0.2827649 | K36: =J36-I36 -> 0.068854765 | L36: 0.80509458
A37: 7fd71c82-50c3-43e6-9e8a-3e7b6c2bd89f | B37: cmj9x7oh4003yzcyqdwkswpug | C37: cmj9x8j4m004fzcyqa9lz7ko5 | D37: ac15-plain | E37: Scenario_2_v3 | F37: 12 | G37: sovereignty | H37: 0.1584 | I37: 0.21160476 | J37: 0.28042231 | K37: =J37-I37 -> 0.068817555 | L37: 0.80509458
A38: 7fd71c82-50c3-43e6-9e8a-3e7b6c2bd89f | B38: cmj9x7oh4003yzcyqdwkswpug | C38: cmj9x8j4m004fzcyqa9lz7ko5 | D38: ac15-plain | E38: Scenario_2_v3 | F38: 12 | G38: truth_and_fact | H38: 0.1 | I38: 0.14467323 | J38: 0.2281045 | K38: =J38-I38 -> 0.083431262 | L38: 0.80509458
A39: 34de177a-0699-47c2-a3a2-0eb9afd3b009 | B39: cmj9xaoqr004jzcyqlb2pq8bd | C39: cmj9xbcwf0050zcyqefvhe6e0 | D39: ac15-plain | E39: Scenario_2_v3 | F39: 14 | G39: practicality_and_feasibility | H39: 0.2263 | I39: 0.30036513 | J39: 0.39826587 | K39: =J39-I39 -> 0.097900747 | L39: 0.7314491 | N39: =AVERAGE(K39:K44) -> 0.1141924
A40: 34de177a-0699-47c2-a3a2-0eb9afd3b009 | B40: cmj9xaoqr004jzcyqlb2pq8bd | C40: cmj9xbcwf0050zcyqefvhe6e0 | D40: ac15-plain | E40: Scenario_2_v3 | F40: 14 | G40: temporal_dynamics | H40: 0.1786 | I40: 0.23707804 | J40: 0.33954256 | K40: =J40-I40 -> 0.10246452 | L40: 0.7314491
A41: 34de177a-0699-47c2-a3a2-0eb9afd3b009 | B41: cmj9xaoqr004jzcyqlb2pq8bd | C41: cmj9xbcwf0050zcyqefvhe6e0 | D41: ac15-plain | E41: Scenario_2_v3 | F41: 14 | G41: mathematics_computer_science_engineering | H41: 0.1752 | I41: 0.2325512 | J41: 0.33483936 | K41: =J41-I41 -> 0.10228816 | L41: 0.7314491
...

Sheet notes
A1: p calculation
A3: 1. count | B3: =A10 -> 142
A4: 2. t statistic | B4: =B10*SQRT((B3-2)/(1-B10^2)) -> 1.0533831
A5: 3. p | B5: =_xlfn.T.DIST.2T(ABS(B4),B3-2) -> 0.2939801
A9: count | B9: correlation weights / activation delta
A10: 142 | B10: 0.088676395

Sheet actdel_prompt_response
B1: prompt_to_response | C1: Average activation/turn | H1: Correlation | I1: count | J1: T-statistic | K1: p
A2: turn
A3: 1 | B3: 0.84283713 | C3: 0.074473196 | H3: =CORREL(B3:B27,C3:C27) -> 0.15921616 | I3: =COUNT(C3:C27) -> 25 | J3: =H3*SQRT((I3-2)/(1-H3^2)) -> 0.77344006 | K3: =_xlfn.T.DIST.2T(ABS(J3),I3-2) -> 0.44713898
A4: 2 | B4: 0.75574435 | C4: 0.068465937
A5: 3 | B5: 0.75246139 | C5: 0.059548965
A6: 4 | B6: 0.75523994 | C6: 0.061501322
A7: 5 | B7: 0.68196907 | C7: 0.044594508
A8: 6 | B8: 0.80509458 | C8: 0.069508687
A9: 7 | B9: 0.7314491 | C9: 0.1141924
A10: 8 | B10: 0.7986994 | C10: 0.100784
A11: 9 | B11: 0.75118107 | C11: 0.053061792
A12: 10 | B12: 0.78031701 | C12: 0.070225948
A13: 11 | B13: 0.78896492 | C13: 0.069101536
A14: 12 | B14: 0.74442966 | C14: 0.11209744
A15: 13 | B15: 0.76434794 | C15: 0.13157902
... A27: 25 | B27: 0.71511197 | C27: 0.060120661

Sheet inter_system_stats
B2: Prompt-response
B3: ac15p | C3: control | E3: std. Ac15p | F3: std. Control | G3: F. test | H3: T. Test equal variances | I3: T.Test unequal | J3: Mean difference
A4: 1 | B4: 0.84283713 | C4: 0.81423911 | E4: =_xlfn.STDEV.S(B4:B28) -> 0.044988984 | F4: =_xlfn.STDEV.S(C4:C28) -> 0.11577762 | G4: =_xlfn.F.TEST(B4:B28,C4:C28) -> 1.7096385e-05 | H4: =_xlfn.T.TEST(B4:B28, C4:C28, 2,2) -> 2.2389505e-11 | I4: =_xlfn.T.TEST(B4:B28,C4:C28, 2,3) -> 8.5891805e-10 | J4: =AVERAGE(B4:B28)-AVERAGE(C4:C28) -> 0.2151923
A5: 2 | B5: 0.75574435 | C5: 0.49037431
A6: 3 | B6: 0.75246139 | C6: 0.51102033 | E6: Paired t-test
A7: 4 | B7: 0.75523994 | C7: 0.73212747 | E7: Alpha | F7: 0.05
A8: 5 | B8: 0.68196907 | C8: 0.5045879 | E8: Hypothesized Mean Difference | F8: 0
A9: 6 | B9: 0.80509458 | C9: 0.62221695 | F9: Variable 1 | G9: Variable 2
A10: 7 | B10: 0.7314491 | C10: 0.5682134 | E10: Mean | F10: =AVERAGE(inter_system_stats!$B$3:$B$28) -> 0.75220636 | G10: =AVERAGE(inter_system_stats!$C$3:$C$28) -> 0.53701406
A11: 8 | B11: 0.7986994 | C11: 0.41336821 | E11: Variance | F11: =VAR(inter_system_stats!$B$3:$B$28) -> 0.0020240087 | G11: =VAR(inter_system_stats!$C$3:$C$28) -> 0.013404458
A12: 9 | B12: 0.75118107 | C12: 0.4696191 | E12: Observations | F12: =COUNT(inter_system_stats!$B$3:$B$28) -> 25 | G12: =COUNT(inter_system_stats!$C$3:$C$28) -> 25
A13: 10 | B13: 0.78031701 | C13: 0.70259754 | E13: Pearson Correlation | F13: =CORREL(inter_system_stats!$B$3:$B$28,inter_system_stats!$C$3:$C$28) -> 0.49891315
A14: 11 | B14: 0.78896492 | C14: 0.53574689 | E14: Observed Mean Difference | F14: {=AVERAGE(IF(ISODD(IF(ISNUMBER(inter_system_stats!$B$3:$B$28), 1, 0) * IF(ISNUMBER(inter_system_stats!$C$3:$C$28), 1, 0)), inter_system_stats!$B$3:$B$28 - inter_system_stats!$C$3:$C$28, "NA"))} -> 0.2151923
A15: 12 | B15: 0.74442966 | C15: 0.61680633 | E15: Variance of the Differences | F15: {=VAR(IF(ISODD(IF(ISNUMBER(inter_system_stats!$B$3:$B$28), 1, 0) * IF(ISNUMBER(inter_system_stats!$C$3:$C$28), 1, 0)), inter_system_stats!$B$3:$B$28 - inter_system_stats!$C$3:$C$28, "NA"))} -> 0.010231071
A16: 13 | B16: 0.76434794 | C16: 0.52630891 | E16: df | F16: {=SUM(IF(ISNUMBER(inter_system_stats!$B$3:$B$28), 1, 0) * IF(ISNUMBER(inter_system_stats!$C$3:$C$28), 1, 0)) - 1} -> 24
A17: 14 | B17: 0.71664792 | C17: 0.42768382 | E17: t Stat | F17: =(inter_system_stats!$F$14 - inter_system_stats!$F$8) / (inter_system_stats!$F$15 / ( inter_system_stats!$F$16 + 1)) ^ 0.5 -> 10.637417
A18: 15 | B18: 0.76192925 | C18: 0.57565816 | E18: P (T<=t) one-tail | F18: =TDIST(ABS(inter_system_stats!$F$17), inter_system_stats!$F$16, 1) -> 7.2540545e-11
A19: 16 | B19: 0.74274873 | C19: 0.57704588 | E19: t Critical one-tail | F19: =TINV(2*inter_system_stats!$F$7, inter_system_stats!$F$16) -> 1.7108821
A20: 17 | B20: 0.76420987 | C20: 0.65129577 | E20: P (T<=t) two-tail | F20: =TDIST(ABS(inter_system_stats!$F$17), inter_system_stats!$F$16, 2) -> 1.4508109e-10
A21: 18 | B21: 0.70079627 | C21: 0.59927589 | E21: t Critical two-tail | F21: =TINV(inter_system_stats!$F$7, inter_system_stats!$F$16) -> 2.0638986
A22: 19 | B22: 0.71628406 | C22: 0.50621472
A23: 20 | B23: 0.83902354 | C23: 0.47809959
A24: 21 | B24: 0.70402483 | C24: 0.38215194
A25: 22 | B25: 0.68499859 | C25: 0.42806876
A26: 23 | B26: 0.69681188 | C26: 0.34437109
A27: 24 | B27: 0.80983661 | C27: 0.58285066
A28: 25 | B28: 0.71511197 | C28: 0.36540877
