Workbook

Sheet Sheet1
A1: turnId | B1: user_id | C1: assistant_id | D1: projectName | E1: sessionName | F1: seq | G1: anchorName | H1: weight | I1: promptSim | J1: responseSim | K1: activation delta | L1: prompt_to_response | N1: Average activation/turn | O1: average conversation activation | P1: correlation weights / activation delta | Q1: P
A3: 8eff0223-8ddb-4ffe-88e8-5e3d73e5298a | B3: cmj8nqb0100y5zcr3f349l0p7 | C3: cmj8nr37x00ymzcr3y7zp7rvr | D3: ac15-plain | E3: scenario_1_v2 | F3: 1 | G3: temporal_dynamics | H3: 0.2038 | I3: 0.32301872 | J3: 0.35463903 | K3: =J3-I3 -> 0.031620313 | L3: 0.82032979 | N3: =AVERAGE(K3:K8) -> 0.063378966 | O3: =SUM(N3:N147)/SUMPRODUCT(ISNUMBER(N3:N147)) -> 0.040727738 | P3: =CORREL(H3:H152, K3:K152) -> -0.20986674 | Q3: 0.0099
A4: 8eff0223-8ddb-4ffe-88e8-5e3d73e5298a | B4: cmj8nqb0100y5zcr3f349l0p7 | C4: cmj8nr37x00ymzcr3y7zp7rvr | D4: ac15-plain | E4: scenario_1_v2 | F4: 1 | G4: mathematics_computer_science_engineering | H4: 0.1894 | I4: 0.30012803 | J4: 0.35759428 | K4: =J4-I4 -> 0.057466245 | L4: 0.82032979
A5: 8eff0223-8ddb-4ffe-88e8-5e3d73e5298a | B5: cmj8nqb0100y5zcr3f349l0p7 | C5: cmj8nr37x00ymzcr3y7zp7rvr | D5: ac15-plain | E5: scenario_1_v2 | F5: 1 | G5: practicality_and_feasibility | H5: 0.1882 | I5: 0.29832032 | J5: 0.38178199 | K5: =J5-I5 -> 0.08346168 | L5: 0.82032979
A6: 8eff0223-8ddb-4ffe-88e8-5e3d73e5298a | B6: cmj8nqb0100y5zcr3f349l0p7 | C6: cmj8nr37x00ymzcr3y7zp7rvr | D6: ac15-plain | E6: scenario_1_v2 | F6: 1 | G6: sovereignty | H6: 0.1638 | I6: 0.2595493 | J6: 0.33486624 | K6: =J6-I6 -> 0.075316945 | L6: 0.82032979
A7: 8eff0223-8ddb-4ffe-88e8-5e3d73e5298a | B7: cmj8nqb0100y5zcr3f349l0p7 | C7: cmj8nr37x00ymzcr3y7zp7rvr | D7: ac15-plain | E7: scenario_1_v2 | F7: 1 | G7: affective_interface | H7: 0.1549 | I7: 0.24547877 | J7: 0.29779768 | K7: =J7-I7 -> 0.052318917 | L7: 0.82032979
A8: 8eff0223-8ddb-4ffe-88e8-5e3d73e5298a | B8: cmj8nqb0100y5zcr3f349l0p7 | C8: cmj8nr37x00ymzcr3y7zp7rvr | D8: ac15-plain | E8: scenario_1_v2 | F8: 1 | G8: truth_and_fact | H8: 0.1 | I8: 0.19267929 | J8: 0.27276898 | K8: =J8-I8 -> 0.080089694 | L8: 0.82032979
A9: cc91fc78-a5d4-4819-8179-f29eabd305d2 | B9: cmj8ntn3r00yqzcr32p6ivowb | C9: cmj8nuio000z7zcr3jkdopne7 | D9: ac15-plain | E9: scenario_1_v2 | F9: 3 | G9: practicality_and_feasibility | H9: 0.1937 | I9: 0.31162497 | J9: 0.37807692 | K9: =J9-I9 -> 0.066451945 | L9: 0.76020895 | N9: =AVERAGE(K9:K14) -> 0.05504999
A10: cc91fc78-a5d4-4819-8179-f29eabd305d2 | B10: cmj8ntn3r00yqzcr32p6ivowb | C10: cmj8nuio000z7zcr3jkdopne7 | D10: ac15-plain | E10: scenario_1_v2 | F10: 3 | G10: sovereignty | H10: 0.1898 | I10: 0.30528763 | J10: 0.34066703 | K10: =J10-I10 -> 0.035379402 | L10: 0.76020895
A11: cc91fc78-a5d4-4819-8179-f29eabd305d2 | B11: cmj8ntn3r00yqzcr32p6ivowb | C11: cmj8nuio000z7zcr3jkdopne7 | D11: ac15-plain | E11: scenario_1_v2 | F11: 3 | G11: mathematics_computer_science_engineering | H11: 0.1825 | I11: 0.2935969 | J11: 0.34810482 | K11: =J11-I11 -> 0.054507923 | L11: 0.76020895
A12: cc91fc78-a5d4-4819-8179-f29eabd305d2 | B12: cmj8ntn3r00yqzcr32p6ivowb | C12: cmj8nuio000z7zcr3jkdopne7 | D12: ac15-plain | E12: scenario_1_v2 | F12: 3 | G12: temporal_dynamics | H12: 0.1793 | I12: 0.28849086 | J12: 0.3319783 | K12: =J12-I12 -> 0.043487441 | L12: 0.76020895
A13: cc91fc78-a5d4-4819-8179-f29eabd305d2 | B13: cmj8ntn3r00yqzcr32p6ivowb | C13: cmj8nuio000z7zcr3jkdopne7 | D13: ac15-plain | E13: scenario_1_v2 | F13: 3 | G13: affective_interface | H13: 0.1547 | I13: 0.24887051 | J13: 0.32417322 | K13: =J13-I13 -> 0.075302708 | L13: 0.76020895
A14: cc91fc78-a5d4-4819-8179-f29eabd305d2 | B14: cmj8ntn3r00yqzcr32p6ivowb | C14: cmj8nuio000z7zcr3jkdopne7 | D14: ac15-plain | E14: scenario_1_v2 | F14: 3 | G14: truth_and_fact | H14: 0.1 | I14: 0.2262226 | J14: 0.28139313 | K14: =J14-I14 -> 0.055170524 | L14: 0.76020895
A15: 02ee678e-e8a7-4721-b6f0-8416359f80e1 | B15: cmj8ny64700zbzcr3ovp6rpwj | C15: cmj8nym0p00zszcr3i1ctof1n | D15: ac15-plain | E15: scenario_1_v2 | F15: 5 | G15: practicality_and_feasibility | H15: 0.2003 | I15: 0.39561555 | J15: 0.40687902 | K15: =J15-I15 -> 0.011263465 | L15: 0.77935892 | N15: =AVERAGE(K15:K20) -> -0.0043915894
A16: 02ee678e-e8a7-4721-b6f0-8416359f80e1 | B16: cmj8ny64700zbzcr3ovp6rpwj | C16: cmj8nym0p00zszcr3i1ctof1n | D16: ac15-plain | E16: scenario_1_v2 | F16: 5 | G16: mathematics_computer_science_engineering | H16: 0.1848 | I16: 0.365034 | J16: 0.3579908 | K16: =J16-I16 -> -0.0070432067 | L16: 0.77935892
A17: 02ee678e-e8a7-4721-b6f0-8416359f80e1 | B17: cmj8ny64700zbzcr3ovp6rpwj | C17: cmj8nym0p00zszcr3i1ctof1n | D17: ac15-plain | E17: scenario_1_v2 | F17: 5 | G17: temporal_dynamics | H17: 0.1833 | I17: 0.3620211 | J17: 0.34425321 | K17: =J17-I17 -> -0.017767893 | L17: 0.77935892
A18: 02ee678e-e8a7-4721-b6f0-8416359f80e1 | B18: cmj8ny64700zbzcr3ovp6rpwj | C18: cmj8nym0p00zszcr3i1ctof1n | D18: ac15-plain | E18: scenario_1_v2 | F18: 5 | G18: sovereignty | H18: 0.1759 | I18: 0.3473134 | J18: 0.32782596 | K18: =J18-I18 -> -0.01948744 | L18: 0.77935892
A19: 02ee678e-e8a7-4721-b6f0-8416359f80e1 | B19: cmj8ny64700zbzcr3ovp6rpwj | C19: cmj8nym0p00zszcr3i1ctof1n | D19: ac15-plain | E19: scenario_1_v2 | F19: 5 | G19: metaphorical_scaffolding | H19: 0.1556 | I19: 0.30730608 | J19: 0.31402494 | K19: =J19-I19 -> 0.0067188578 | L19: 0.77935892
A20: 02ee678e-e8a7-4721-b6f0-8416359f80e1 | B20: cmj8ny64700zbzcr3ovp6rpwj | C20: cmj8nym0p00zszcr3i1ctof1n | D20: ac15-plain | E20: scenario_1_v2 | F20: 5 | G20: truth_and_fact | H20: 0.1 | I20: 0.2826347 | J20: 0.28260138 | K20: =J20-I20 -> -3.3319531e-05 | L20: 0.77935892
A21: ec480d08-08a8-4ed6-8b4c-c4c59ece4db0 | B21: cmj8o10s500zwzcr3p8xj5awp | C21: cmj8o1pem010dzcr301ek4qub | D21: ac15-plain | E21: scenario_1_v2 | F21: 7 | G21: practicality_and_feasibility | H21: 0.2264 | I21: 0.38018314 | J21: 0.40036345 | K21: =J21-I21 -> 0.020180307 | L21: 0.65547417 | N21: =AVERAGE(K21:K26) -> 0.050838449
A22: ec480d08-08a8-4ed6-8b4c-c4c59ece4db0 | B22: cmj8o10s500zwzcr3p8xj5awp | C22: cmj8o1pem010dzcr301ek4qub | D22: ac15-plain | E22: scenario_1_v2 | F22: 7 | G22: temporal_dynamics | H22: 0.1954 | I22: 0.32815211 | J22: 0.34443985 | K22: =J22-I22 -> 0.016287737 | L22: 0.65547417
A23: ec480d08-08a8-4ed6-8b4c-c4c59ece4db0 | B23: cmj8o10s500zwzcr3p8xj5awp | C23: cmj8o1pem010dzcr301ek4qub | D23: ac15-plain | E23: scenario_1_v2 | F23: 7 | G23: mathematics_computer_science_engineering | H23: 0.1749 | I23: 0.29379102 | J23: 0.38155146 | K23: =J23-I23 -> 0.087760442 | L23: 0.65547417
A24: ec480d08-08a8-4ed6-8b4c-c4c59ece4db0 | B24: cmj8o10s500zwzcr3p8xj5awp | C24: cmj8o1pem010dzcr301ek4qub | D24: ac15-plain | E24: scenario_1_v2 | F24: 7 | G24: sovereignty | H24: 0.1553 | I24: 0.26088718 | J24: 0.31898382 | K24: =J24-I24 -> 0.058096644 | L24: 0.65547417
A25: ec480d08-08a8-4ed6-8b4c-c4c59ece4db0 | B25: cmj8o10s500zwzcr3p8xj5awp | C25: cmj8o1pem010dzcr301ek4qub | D25: ac15-plain | E25: scenario_1_v2 | F25: 7 | G25: electricity | H25: 0.148 | I25: 0.24854197 | J25: 0.29530773 | K25: =J25-I25 -> 0.04676576 | L25: 0.65547417
A26: ec480d08-08a8-4ed6-8b4c-c4c59ece4db0 | B26: cmj8o10s500zwzcr3p8xj5awp | C26: cmj8o1pem010dzcr301ek4qub | D26: ac15-plain | E26: scenario_1_v2 | F26: 7 | G26: truth_and_fact | H26: 0.1 | I26: 0.22583022 | J26: 0.30177003 | K26: =J26-I26 -> 0.075939807 | L26: 0.65547417
A27: ad95b5ff-cbc3-4666-beb6-5a8ed7b039a9 | B27: cmj8o3xz2010hzcr3kwj2od2w | C27: cmj8o4ldz010yzcr3vhbg1k6c | D27: ac15-plain | E27: scenario_1_v2 | F27: 9 | G27: practicality_and_feasibility | H27: 0.2022 | I27: 0.3908278 | J27: 0.37630479 | K27: =J27-I27 -> -0.014523011 | L27: 0.60148827 | N27: =AVERAGE(K27:K32) -> 0.0023507645
A28: ad95b5ff-cbc3-4666-beb6-5a8ed7b039a9 | B28: cmj8o3xz2010hzcr3kwj2od2w | C28: cmj8o4ldz010yzcr3vhbg1k6c | D28: ac15-plain | E28: scenario_1_v2 | F28: 9 | G28: mathematics_computer_science_engineering | H28: 0.1809 | I28: 0.3497217 | J28: 0.33974964 | K28: =J28-I28 -> -0.0099720618 | L28: 0.60148827
A29: ad95b5ff-cbc3-4666-beb6-5a8ed7b039a9 | B29: cmj8o3xz2010hzcr3kwj2od2w | C29: cmj8o4ldz010yzcr3vhbg1k6c | D29: ac15-plain | E29: scenario_1_v2 | F29: 9 | G29: temporal_dynamics | H29: 0.1788 | I29: 0.34568565 | J29: 0.34804173 | K29: =J29-I29 -> 0.0023560862 | L29: 0.60148827
A30: ad95b5ff-cbc3-4666-beb6-5a8ed7b039a9 | B30: cmj8o3xz2010hzcr3kwj2od2w | C30: cmj8o4ldz010yzcr3vhbg1k6c | D30: ac15-plain | E30: scenario_1_v2 | F30: 9 | G30: electricity | H30: 0.1749 | I30: 0.33812443 | J30: 0.28613043 | K30: =J30-I30 -> -0.051994005 | L30: 0.60148827
A31: ad95b5ff-cbc3-4666-beb6-5a8ed7b039a9 | B31: cmj8o3xz2010hzcr3kwj2od2w | C31: cmj8o4ldz010yzcr3vhbg1k6c | D31: ac15-plain | E31: scenario_1_v2 | F31: 9 | G31: sovereignty | H31: 0.1633 | I31: 0.31565941 | J31: 0.36642542 | K31: =J31-I31 -> 0.050766014 | L31: 0.60148827
A32: ad95b5ff-cbc3-4666-beb6-5a8ed7b039a9 | B32: cmj8o3xz2010hzcr3kwj2od2w | C32: cmj8o4ldz010yzcr3vhbg1k6c | D32: ac15-plain | E32: scenario_1_v2 | F32: 9 | G32: truth_and_fact | H32: 0.1 | I32: 0.25725606 | J32: 0.29472762 | K32: =J32-I32 -> 0.037471565 | L32: 0.60148827
A33: 77b9c9c3-bc54-4c44-913f-5464e871f466 | B33: cmj8o7q000112zcr36bhvlmxx | C33: cmj8o8t6x011jzcr3src0dw8l | D33: ac15-plain | E33: scenario_1_v2 | F33: 11 | G33: practicality_and_feasibility | H33: 0.218 | I33: 0.34117038 | J33: 0.34055675 | K33: =J33-I33 -> -0.00061362947 | L33: 0.80260511 | N33: =AVERAGE(K33:K38) -> 0.026512963
A34: 77b9c9c3-bc54-4c44-913f-5464e871f466 | B34: cmj8o7q000112zcr36bhvlmxx | C34: cmj8o8t6x011jzcr3src0dw8l | D34: ac15-plain | E34: scenario_1_v2 | F34: 11 | G34: temporal_dynamics | H34: 0.1912 | I34: 0.2993105 | J34: 0.32211051 | K34: =J34-I34 -> 0.022800012 | L34: 0.80260511
A35: 77b9c9c3-bc54-4c44-913f-5464e871f466 | B35: cmj8o7q000112zcr36bhvlmxx | C35: cmj8o8t6x011jzcr3src0dw8l | D35: ac15-plain | E35: scenario_1_v2 | F35: 11 | G35: mathematics_computer_science_engineering | H35: 0.1749 | I35: 0.27379679 | J35: 0.32263524 | K35: =J35-I35 -> 0.048838448 | L35: 0.80260511
A36: 77b9c9c3-bc54-4c44-913f-5464e871f466 | B36: cmj8o7q000112zcr36bhvlmxx | C36: cmj8o8t6x011jzcr3src0dw8l | D36: ac15-plain | E36: scenario_1_v2 | F36: 11 | G36: sovereignty | H36: 0.1665 | I36: 0.26068281 | J36: 0.2685173 | K36: =J36-I36 -> 0.0078344912 | L36: 0.80260511
A37: 77b9c9c3-bc54-4c44-913f-5464e871f466 | B37: cmj8o7q000112zcr36bhvlmxx | C37: cmj8o8t6x011jzcr3src0dw8l | D37: ac15-plain | E37: scenario_1_v2 | F37: 11 | G37: electricity | H37: 0.1493 | I37: 0.23375761 | J37: 0.25949984 | K37: =J37-I37 -> 0.025742234 | L37: 0.80260511
A38: 77b9c9c3-bc54-4c44-913f-5464e871f466 | B38: cmj8o7q000112zcr36bhvlmxx | C38: cmj8o8t6x011jzcr3src0dw8l | D38: ac15-plain | E38: scenario_1_v2 | F38: 11 | G38: truth_and_fact | H38: 0.1 | I38: 0.18625881 | J38: 0.24073503 | K38: =J38-I38 -> 0.054476221 | L38: 0.80260511
A39: 862662a4-e02f-4634-a00c-d7d8b2e3339c | B39: cmj8ob3ib011nzcr3sob074uk | C39: cmj8obtpk0124zcr3fwee0ekm | D39: ac15-plain | E39: scenario_1_v2 | F39: 13 | G39: practicality_and_feasibility | H39: 0.1973 | I39: 0.26155764 | J39: 0.38990117 | K39: =J39-I39 -> 0.12834353 | L39: 0.64887842 | N39: =AVERAGE(K39:K44) -> 0.10564135
A40: 862662a4-e02f-4634-a00c-d7d8b2e3339c | B40: cmj8ob3ib011nzcr3sob074uk | C40: cmj8obtpk0124zcr3fwee0ekm | D40: ac15-plain | E40: scenario_1_v2 | F40: 13 | G40: temporal_dynamics | H40: 0.1945 | I40: 0.25773863 | J40: 0.35443002 | K40: =J40-I40 -> 0.09669139 | L40: 0.64887842
A41: 862662a4-e02f-4634-a00c-d7d8b2e3339c | B41: cmj8ob3ib011nzcr3sob074uk | C41: cmj8obtpk0124zcr3fwee0ekm | D41: ac15-plain | E41: scenario_1_v2 | F41: 13 | G41: mathematics_computer_science_engineering | H41: 0.1892 | I41: 0.25080024 | J41: 0.34829299 | K41: =J41-I41 -> 0.097492747 | L41: 0.64887842
...

Sheet Notes
A1: Calculation p
A3: 1. count | B3: =COUNT(Sheet1!K3:K152) -> 150 | C3: activation delta
A4: 2. t statistic | B4: =Sheet1!P3*SQRT((B3-2)/(1-Sheet1!P3^2)) -> -2.6112925
A5: 3. p | B5: =_xlfn.T.DIST.2T(ABS(B4),B3-2) -> 0.0099488618

Sheet activation-delta-vs. prompt-res
B1: prompt_to_response | C1: Average activation/turn | E1: Correlation | F1: count | G1: T-statistic | H1: p
A3: 1 | B3: 0.82032979 | C3: 0.063378966 | E3: =CORREL(B3:B27, C3:C27) -> 0.15881304 | F3: =COUNT(C3:C27) -> 25 | G3: =E3*SQRT((F3-2)/(1-E3^2)) -> 0.77143105 | H3: =_xlfn.T.DIST.2T(ABS(G3),F3-2) -> 0.44830508
A4: 2 | B4: 0.76020895 | C4: 0.05504999
A5: 3 | B5: 0.77935892 | C5: -0.0043915894
A6: 4 | B6: 0.65547417 | C6: 0.050838449
A7: 5 | B7: 0.60148827 | C7: 0.0023507645
A8: 6 | B8: 0.80260511 | C8: 0.026512963
A9: 7 | B9: 0.64887842 | C9: 0.10564135
A10: 8 | B10: 0.75255045 | C10: 0.056384955
A11: 9 | B11: 0.72599844 | C11: -0.006018787
A12: 10 | B12: 0.70681936 | C12: 0.035348457
A13: 11 | B13: 0.66388414 | C13: 0.068182279
A14: 12 | B14: 0.80868052 | C14: 0.087447435
A15: 13 | B15: 0.69778979 | C15: 0.096816082
... A27: 25 | B27: 0.69002391 | C27: 0.022345151

Sheet control vs. ac15p statistics
I1: Tests | O1: Paired t-test
C2: ac15p | D2: control | F2: std. Ac15p | G2: std. Control | H2: F. test | I2: T. Test equal variances | J2: T.Test unequal | K2: Mean difference | L2: Mean ac15p | M2: mean control | O2: Alpha | P2: 0.05
B3: 1 | C3: 0.82032979 | D3: 0.84316826 | F3: =_xlfn.STDEV.S(C3:C27) -> 0.067896899 | G3: =_xlfn.STDEV.S(D3:D27) -> 0.11788306 | H3: =_xlfn.F.TEST(C3:C27,D3:D27) -> 0.0090042231 | I3: =_xlfn.T.TEST(C3:C27, D3:D27, 2,2) -> 1.3447401e-07 | J3: =_xlfn.T.TEST(C3:C27,D3:D27, 2,3) -> 3.1421376e-07 | K3: =AVERAGE(C3:C27)-AVERAGE(D3:D27) -> 0.16806102 | L3: =AVERAGE(C3:C27) -> 0.73072651 | M3: =AVERAGE(D3:D27) -> 0.56266549 | O3: Hypothesized Mean Difference | P3: 0
B4: 2 | C4: 0.76020895 | D4: 0.41048157 | P4: Variable 1 | Q4: Variable 2
B5: 3 | C5: 0.77935892 | D5: 0.55797537 | O5: Mean | P5: =AVERAGE('control vs. ac15p statistics'!$C$3:$C$27) -> 0.73072651 | Q5: =AVERAGE('control vs. ac15p statistics'!$D$3:$D$27) -> 0.56266549
B6: 4 | C6: 0.65547417 | D6: 0.61915827 | O6: Variance | P6: =VAR('control vs. ac15p statistics'!$C$3:$C$27) -> 0.004609989 | Q6: =VAR('control vs. ac15p statistics'!$D$3:$D$27) -> 0.013896415
B7: 5 | C7: 0.60148827 | D7: 0.40396308 | O7: Observations | P7: =COUNT('control vs. ac15p statistics'!$C$3:$C$27) -> 25 | Q7: =COUNT('control vs. ac15p statistics'!$D$3:$D$27) -> 25
B8: 6 | C8: 0.80260511 | D8: 0.57074388 | O8: Pearson Correlation | P8: =CORREL('control vs. ac15p statistics'!$C$3:$C$27,'control vs. ac15p statistics'!$D$3:$D$27) -> 0.18479526
B9: 7 | C9: 0.64887842 | D9: 0.61160895 | O9: Observed Mean Difference | P9: {=AVERAGE(IF(ISODD(IF(ISNUMBER('control vs. ac15p statistics'!$C$3:$C$27), 1, 0) * IF(ISNUMBER('control vs. ac15p statistics'!$D$3:$D$27), 1, 0)), 'control vs. ac15p statistics'!$C$3:$C$27 - 'control vs. ac15p statistics'!$D$3:$D$27, "NA"))} -> 0.16806102
B10: 8 | C10: 0.75255045 | D10: 0.51665839 | O10: Variance of the Differences | P10: {=VAR(IF(ISODD(IF(ISNUMBER('control vs. ac15p statistics'!$C$3:$C$27), 1, 0) * IF(ISNUMBER('control vs. ac15p statistics'!$D$3:$D$27), 1, 0)), 'control vs. ac15p statistics'!$C$3:$C$27 - 'control vs. ac15p statistics'!$D$3:$D$27, "NA"))} -> 0.01554824
B11: 9 | C11: 0.72599844 | D11: 0.51910728 | O11: df | P11: {=SUM(IF(ISNUMBER('control vs. ac15p statistics'!$C$3:$C$27), 1, 0) * IF(ISNUMBER('control vs. ac15p statistics'!$D$3:$D$27), 1, 0)) - 1} -> 24
B12: 10 | C12: 0.70681936 | D12: 0.68124246 | O12: t Stat | P12: =('control vs. ac15p statistics'!$P$9 - 'control vs. ac15p statistics'!$P$3) / ('control vs. ac15p statistics'!$P$10 / ( 'control vs. ac15p statistics'!$P$11 + 1)) ^ 0.5 -> 6.7390143
B13: 11 | C13: 0.66388414 | D13: 0.66509925 | O13: P (T<=t) one-tail | P13: =TDIST(ABS('control vs. ac15p statistics'!$P$12), 'control vs. ac15p statistics'!$P$11, 1) -> 2.8517256e-07
B14: 12 | C14: 0.80868052 | D14: 0.68559512 | O14: t Critical one-tail | P14: =TINV(2*'control vs. ac15p statistics'!$P$2, 'control vs. ac15p statistics'!$P$11) -> 1.7108821
B15: 13 | C15: 0.69778979 | D15: 0.65114377 | O15: P (T<=t) two-tail | P15: =TDIST(ABS('control vs. ac15p statistics'!$P$12), 'control vs. ac15p statistics'!$P$11, 2) -> 5.7034512e-07
B16: 14 | C16: 0.74964989 | D16: 0.60348677 | O16: t Critical two-tail | P16: =TINV('control vs. ac15p statistics'!$P$2, 'control vs. ac15p statistics'!$P$11) -> 2.0638986
B17: 15 | C17: 0.73696733 | D17: 0.49806868
B18: 16 | C18: 0.76410474 | D18: 0.63037797
B19: 17 | C19: 0.72250109 | D19: 0.65792717
B20: 18 | C20: 0.68518215 | D20: 0.56086051
B21: 19 | C21: 0.57422987 | D21: 0.50207793
B22: 20 | C22: 0.86281466 | D22: 0.47716849
B23: 21 | C23: 0.7664436 | D23: 0.49071258
B24: 22 | C24: 0.75721945 | D24: 0.37364723
B25: 23 | C25: 0.75138095 | D25: 0.656355
B26: 24 | C26: 0.7835788 | D26: 0.57973183
B27: 25 | C27: 0.69002391 | D27: 0.30027741
