Workbook

Sheet scen1_hybrid
A1: turnId | B1: user_id | C1: assistant_id | D1: projectName | E1: sessionName | F1: seq | G1: anchorName | H1: weight | I1: promptSim | J1: responseSim | K1: activation delta | L1: prompt_to_response | N1: Average activation/turn | O1: average conversation activation | P1: count | Q1: correlation weights / activation delta | R1: p
A3: f4ede5b4-c038-4a40-b329-69cd73d7aab8 | B3: cmj8pszoe01dazcr39o3cdi6k | C3: cmj8pu37001drzcr35yt8d67v | D3: hybrid_v3_5 | E3: Scenario_1_v2 | F3: 1 | G3: temporal_dynamics | H3: 0.208 | I3: 0.29140293 | J3: 0.31430943 | K3: =J3-I3 -> 0.0229065 | L3: 0.83430834 | N3: =AVERAGE(K3:K8) -> 0.054866325 | O3: =SUM(N3:N143)/COUNT(N3:N143) -> 0.03949068 | P3: =COUNT(K3:K148) -> 146 | Q3: =CORREL(H3:H148, K3:K148) -> -0.04055391 | R3: =Notes!B5 -> 0.62696517
A4: f4ede5b4-c038-4a40-b329-69cd73d7aab8 | B4: cmj8pszoe01dazcr39o3cdi6k | C4: cmj8pu37001drzcr35yt8d67v | D4: hybrid_v3_5 | E4: Scenario_1_v2 | F4: 1 | G4: practicality_and_feasibility | H4: 0.1948 | I4: 0.2728694 | J4: 0.34707037 | K4: =J4-I4 -> 0.074200972 | L4: 0.83430834
A5: f4ede5b4-c038-4a40-b329-69cd73d7aab8 | B5: cmj8pszoe01dazcr39o3cdi6k | C5: cmj8pu37001drzcr35yt8d67v | D5: hybrid_v3_5 | E5: Scenario_1_v2 | F5: 1 | G5: mathematics_computer_science_engineering | H5: 0.1792 | I5: 0.25094679 | J5: 0.29306069 | K5: =J5-I5 -> 0.042113896 | L5: 0.83430834
A6: f4ede5b4-c038-4a40-b329-69cd73d7aab8 | B6: cmj8pszoe01dazcr39o3cdi6k | C6: cmj8pu37001drzcr35yt8d67v | D6: hybrid_v3_5 | E6: Scenario_1_v2 | F6: 1 | G6: sovereignty | H6: 0.1612 | I6: 0.22574719 | J6: 0.3048067 | K6: =J6-I6 -> 0.079059504 | L6: 0.83430834
A7: f4ede5b4-c038-4a40-b329-69cd73d7aab8 | B7: cmj8pszoe01dazcr39o3cdi6k | C7: cmj8pu37001drzcr35yt8d67v | D7: hybrid_v3_5 | E7: Scenario_1_v2 | F7: 1 | G7: imagination_and_possibility | H7: 0.1568 | I7: 0.21965936 | J7: 0.27405196 | K7: =J7-I7 -> 0.054392598 | L7: 0.83430834
A8: f4ede5b4-c038-4a40-b329-69cd73d7aab8 | B8: cmj8pszoe01dazcr39o3cdi6k | C8: cmj8pu37001drzcr35yt8d67v | D8: hybrid_v3_5 | E8: Scenario_1_v2 | F8: 1 | G8: truth_and_fact | H8: 0.1 | I8: 0.16806198 | J8: 0.22458646 | K8: =J8-I8 -> 0.056524479 | L8: 0.83430834
A9: c2e55b84-7dbd-4275-b6c7-323945afe399 | B9: cmj8pvqpw01dvzcr33bv3ng8n | C9: cmj8pwr4w01eczcr34zhtavni | D9: hybrid_v3_5 | E9: Scenario_1_v2 | F9: 3 | G9: temporal_dynamics | H9: 0.1956 | I9: 0.28235803 | J9: 0.30660803 | K9: =J9-I9 -> 0.024250006 | L9: 0.78737809 | N9: =AVERAGE(K9:K14) -> 0.049421284
A10: c2e55b84-7dbd-4275-b6c7-323945afe399 | B10: cmj8pvqpw01dvzcr33bv3ng8n | C10: cmj8pwr4w01eczcr34zhtavni | D10: hybrid_v3_5 | E10: Scenario_1_v2 | F10: 3 | G10: practicality_and_feasibility | H10: 0.1878 | I10: 0.27110351 | J10: 0.35341972 | K10: =J10-I10 -> 0.082316208 | L10: 0.78737809
A11: c2e55b84-7dbd-4275-b6c7-323945afe399 | B11: cmj8pvqpw01dvzcr33bv3ng8n | C11: cmj8pwr4w01eczcr34zhtavni | D11: hybrid_v3_5 | E11: Scenario_1_v2 | F11: 3 | G11: sovereignty | H11: 0.1832 | I11: 0.26447354 | J11: 0.31153494 | K11: =J11-I11 -> 0.0470614 | L11: 0.78737809
A12: c2e55b84-7dbd-4275-b6c7-323945afe399 | B12: cmj8pvqpw01dvzcr33bv3ng8n | C12: cmj8pwr4w01eczcr34zhtavni | D12: hybrid_v3_5 | E12: Scenario_1_v2 | F12: 3 | G12: mathematics_computer_science_engineering | H12: 0.17 | I12: 0.2453137 | J12: 0.30015547 | K12: =J12-I12 -> 0.054841768 | L12: 0.78737809
A13: c2e55b84-7dbd-4275-b6c7-323945afe399 | B13: cmj8pvqpw01dvzcr33bv3ng8n | C13: cmj8pwr4w01eczcr34zhtavni | D13: hybrid_v3_5 | E13: Scenario_1_v2 | F13: 3 | G13: electricity | H13: 0.1633 | I13: 0.23575898 | J13: 0.22699273 | K13: =J13-I13 -> -0.0087662471 | L13: 0.78737809
A14: c2e55b84-7dbd-4275-b6c7-323945afe399 | B14: cmj8pvqpw01dvzcr33bv3ng8n | C14: cmj8pwr4w01eczcr34zhtavni | D14: hybrid_v3_5 | E14: Scenario_1_v2 | F14: 3 | G14: truth_and_fact | H14: 0.1 | I14: 0.15286289 | J14: 0.24968746 | K14: =J14-I14 -> 0.09682457 | L14: 0.78737809
A15: 4e496481-26f9-4d1d-821e-c401645f132a | B15: cmj8pxz7m01egzcr328xztkoj | C15: cmj8pyitc01exzcr396h6boq8 | D15: hybrid_v3_5 | E15: Scenario_1_v2 | F15: 5 | G15: practicality_and_feasibility | H15: 0.2014 | I15: 0.34202352 | J15: 0.38747679 | K15: =J15-I15 -> 0.045453263 | L15: 0.82347011 | N15: =AVERAGE(K15:K20) -> 0.032563898
A16: 4e496481-26f9-4d1d-821e-c401645f132a | B16: cmj8pxz7m01egzcr328xztkoj | C16: cmj8pyitc01exzcr396h6boq8 | D16: hybrid_v3_5 | E16: Scenario_1_v2 | F16: 5 | G16: temporal_dynamics | H16: 0.1902 | I16: 0.32291789 | J16: 0.36241464 | K16: =J16-I16 -> 0.039496753 | L16: 0.82347011
A17: 4e496481-26f9-4d1d-821e-c401645f132a | B17: cmj8pxz7m01egzcr328xztkoj | C17: cmj8pyitc01exzcr396h6boq8 | D17: hybrid_v3_5 | E17: Scenario_1_v2 | F17: 5 | G17: mathematics_computer_science_engineering | H17: 0.1751 | I17: 0.29736601 | J17: 0.31071392 | K17: =J17-I17 -> 0.013347912 | L17: 0.82347011
A18: 4e496481-26f9-4d1d-821e-c401645f132a | B18: cmj8pxz7m01egzcr328xztkoj | C18: cmj8pyitc01exzcr396h6boq8 | D18: hybrid_v3_5 | E18: Scenario_1_v2 | F18: 5 | G18: sovereignty | H18: 0.1738 | I18: 0.29512909 | J18: 0.30613597 | K18: =J18-I18 -> 0.011006883 | L18: 0.82347011
A19: 4e496481-26f9-4d1d-821e-c401645f132a | B19: cmj8pxz7m01egzcr328xztkoj | C19: cmj8pyitc01exzcr396h6boq8 | D19: hybrid_v3_5 | E19: Scenario_1_v2 | F19: 5 | G19: imagination_and_possibility | H19: 0.1594 | I19: 0.27068982 | J19: 0.29864809 | K19: =J19-I19 -> 0.027958274 | L19: 0.82347011
A20: 4e496481-26f9-4d1d-821e-c401645f132a | B20: cmj8pxz7m01egzcr328xztkoj | C20: cmj8pyitc01exzcr396h6boq8 | D20: hybrid_v3_5 | E20: Scenario_1_v2 | F20: 5 | G20: truth_and_fact | H20: 0.1 | I20: 0.21031564 | J20: 0.26843595 | K20: =J20-I20 -> 0.058120305 | L20: 0.82347011
A21: ae7402a6-89a7-4c16-aa3f-c55eececa43f | B21: cmj8pzwqw01f1zcr3d51xaoso | C21: cmj8q0r3201fizcr3vb65kh1s | D21: hybrid_v3_5 | E21: Scenario_1_v2 | F21: 7 | G21: temporal_dynamics | H21: 0.2095 | I21: 0.31727299 | J21: 0.37371154 | K21: =J21-I21 -> 0.056438551 | L21: 0.64138219 | N21: =AVERAGE(K21:K26) -> 0.066348788
A22: ae7402a6-89a7-4c16-aa3f-c55eececa43f | B22: cmj8pzwqw01f1zcr3d51xaoso | C22: cmj8q0r3201fizcr3vb65kh1s | D22: hybrid_v3_5 | E22: Scenario_1_v2 | F22: 7 | G22: practicality_and_feasibility | H22: 0.2004 | I22: 0.30338267 | J22: 0.38471016 | K22: =J22-I22 -> 0.081327491 | L22: 0.64138219
A23: ae7402a6-89a7-4c16-aa3f-c55eececa43f | B23: cmj8pzwqw01f1zcr3d51xaoso | C23: cmj8q0r3201fizcr3vb65kh1s | D23: hybrid_v3_5 | E23: Scenario_1_v2 | F23: 7 | G23: sovereignty | H23: 0.1761 | I23: 0.26668321 | J23: 0.29668659 | K23: =J23-I23 -> 0.03000338 | L23: 0.64138219
A24: ae7402a6-89a7-4c16-aa3f-c55eececa43f | B24: cmj8pzwqw01f1zcr3d51xaoso | C24: cmj8q0r3201fizcr3vb65kh1s | D24: hybrid_v3_5 | E24: Scenario_1_v2 | F24: 7 | G24: mathematics_computer_science_engineering | H24: 0.1678 | I24: 0.25403023 | J24: 0.32496173 | K24: =J24-I24 -> 0.070931503 | L24: 0.64138219
A25: ae7402a6-89a7-4c16-aa3f-c55eececa43f | B25: cmj8pzwqw01f1zcr3d51xaoso | C25: cmj8q0r3201fizcr3vb65kh1s | D25: hybrid_v3_5 | E25: Scenario_1_v2 | F25: 7 | G25: electricity | H25: 0.1462 | I25: 0.22144897 | J25: 0.2815418 | K25: =J25-I25 -> 0.060092838 | L25: 0.64138219
A26: ae7402a6-89a7-4c16-aa3f-c55eececa43f | B26: cmj8pzwqw01f1zcr3d51xaoso | C26: cmj8q0r3201fizcr3vb65kh1s | D26: hybrid_v3_5 | E26: Scenario_1_v2 | F26: 7 | G26: truth_and_fact | H26: 0.1 | I26: 0.1847151 | J26: 0.28401407 | K26: =J26-I26 -> 0.099298964 | L26: 0.64138219
A27: a86f2c84-0509-49f0-be2b-be08ba78c870 | B27: cmj8q1y9d01fmzcr3lc8dw4wp | C27: cmj8q2jyw01g3zcr3i7dc7lvb | D27: hybrid_v3_5 | E27: Scenario_1_v2 | F27: 9 | G27: practicality_and_feasibility | H27: 0.2042 | I27: 0.33574716 | J27: 0.39326181 | K27: =J27-I27 -> 0.057514657 | L27: 0.64856074 | N27: =AVERAGE(K27:K32) -> 0.041698828
A28: a86f2c84-0509-49f0-be2b-be08ba78c870 | B28: cmj8q1y9d01fmzcr3lc8dw4wp | C28: cmj8q2jyw01g3zcr3i7dc7lvb | D28: hybrid_v3_5 | E28: Scenario_1_v2 | F28: 9 | G28: temporal_dynamics | H28: 0.1986 | I28: 0.32666017 | J28: 0.33498326 | K28: =J28-I28 -> 0.0083230907 | L28: 0.64856074
A29: a86f2c84-0509-49f0-be2b-be08ba78c870 | B29: cmj8q1y9d01fmzcr3lc8dw4wp | C29: cmj8q2jyw01g3zcr3i7dc7lvb | D29: hybrid_v3_5 | E29: Scenario_1_v2 | F29: 9 | G29: imagination_and_possibility | H29: 0.1683 | I29: 0.2768526 | J29: 0.32636437 | K29: =J29-I29 -> 0.049511768 | L29: 0.64856074
A30: a86f2c84-0509-49f0-be2b-be08ba78c870 | B30: cmj8q1y9d01fmzcr3lc8dw4wp | C30: cmj8q2jyw01g3zcr3i7dc7lvb | D30: hybrid_v3_5 | E30: Scenario_1_v2 | F30: 9 | G30: mathematics_computer_science_engineering | H30: 0.165 | I30: 0.27135265 | J30: 0.32862931 | K30: =J30-I30 -> 0.057276662 | L30: 0.64856074
A31: a86f2c84-0509-49f0-be2b-be08ba78c870 | B31: cmj8q1y9d01fmzcr3lc8dw4wp | C31: cmj8q2jyw01g3zcr3i7dc7lvb | D31: hybrid_v3_5 | E31: Scenario_1_v2 | F31: 9 | G31: electricity | H31: 0.1639 | I31: 0.26952501 | J31: 0.27100516 | K31: =J31-I31 -> 0.0014801459 | L31: 0.64856074
A32: a86f2c84-0509-49f0-be2b-be08ba78c870 | B32: cmj8q1y9d01fmzcr3lc8dw4wp | C32: cmj8q2jyw01g3zcr3i7dc7lvb | D32: hybrid_v3_5 | E32: Scenario_1_v2 | F32: 9 | G32: truth_and_fact | H32: 0.1 | I32: 0.20360686 | J32: 0.2796935 | K32: =J32-I32 -> 0.076086648 | L32: 0.64856074
A33: d348cd8c-23b1-446c-bd88-a3196505ce43 | B33: cmj8q3maf01g7zcr3isx1glnz | C33: cmj8q4i6y01gozcr3xcx9qt7n | D33: hybrid_v3_5 | E33: Scenario_1_v2 | F33: 11 | G33: practicality_and_feasibility | H33: 0.2161 | I33: 0.353769 | J33: 0.33234393 | K33: =J33-I33 -> -0.021425074 | L33: 0.73754073 | N33: =AVERAGE(K33:K38) -> -0.010193693
A34: d348cd8c-23b1-446c-bd88-a3196505ce43 | B34: cmj8q3maf01g7zcr3isx1glnz | C34: cmj8q4i6y01gozcr3xcx9qt7n | D34: hybrid_v3_5 | E34: Scenario_1_v2 | F34: 11 | G34: temporal_dynamics | H34: 0.185 | I34: 0.30296655 | J34: 0.31875392 | K34: =J34-I34 -> 0.015787369 | L34: 0.73754073
A35: d348cd8c-23b1-446c-bd88-a3196505ce43 | B35: cmj8q3maf01g7zcr3isx1glnz | C35: cmj8q4i6y01gozcr3xcx9qt7n | D35: hybrid_v3_5 | E35: Scenario_1_v2 | F35: 11 | G35: mathematics_computer_science_engineering | H35: 0.1704 | I35: 0.27906216 | J35: 0.27179829 | K35: =J35-I35 -> -0.0072638688 | L35: 0.73754073
A36: d348cd8c-23b1-446c-bd88-a3196505ce43 | B36: cmj8q3maf01g7zcr3isx1glnz | C36: cmj8q4i6y01gozcr3xcx9qt7n | D36: hybrid_v3_5 | E36: Scenario_1_v2 | F36: 11 | G36: imagination_and_possibility | H36: 0.1656 | I36: 0.27117446 | J36: 0.2572991 | K36: =J36-I36 -> -0.013875353 | L36: 0.73754073
A37: d348cd8c-23b1-446c-bd88-a3196505ce43 | B37: cmj8q3maf01g7zcr3isx1glnz | C37: cmj8q4i6y01gozcr3xcx9qt7n | D37: hybrid_v3_5 | E37: Scenario_1_v2 | F37: 11 | G37: sovereignty | H37: 0.1628 | I37: 0.26654193 | J37: 0.22949458 | K37: =J37-I37 -> -0.037047344 | L37: 0.73754073
A38: d348cd8c-23b1-446c-bd88-a3196505ce43 | B38: cmj8q3maf01g7zcr3isx1glnz | C38: cmj8q4i6y01gozcr3xcx9qt7n | D38: hybrid_v3_5 | E38: Scenario_1_v2 | F38: 11 | G38: truth_and_fact | H38: 0.1 | I38: 0.19843843 | J38: 0.20110055 | K38: =J38-I38 -> 0.0026621119 | L38: 0.73754073
A39: 9597a176-37f0-47a8-8c34-14f156e80ae4 | B39: cmj8q88wo01gszcr3blu9fyyw | C39: cmj8q9bpi01h9zcr3a6ksrax4 | D39: hybrid_v3_5 | E39: Scenario_1_v2 | F39: 13 | G39: practicality_and_feasibility | H39: 0.2161 | I39: 0.33231265 | J39: 0.37409771 | K39: =J39-I39 -> 0.041785068 | L39: 0.63496808 | N39: =AVERAGE(K39:K44) -> 0.044206235
A40: 9597a176-37f0-47a8-8c34-14f156e80ae4 | B40: cmj8q88wo01gszcr3blu9fyyw | C40: cmj8q9bpi01h9zcr3a6ksrax4 | D40: hybrid_v3_5 | E40: Scenario_1_v2 | F40: 13 | G40: temporal_dynamics | H40: 0.1946 | I40: 0.29927242 | J40: 0.33491009 | K40: =J40-I40 -> 0.035637671 | L40: 0.63496808
A41: 9597a176-37f0-47a8-8c34-14f156e80ae4 | B41: cmj8q88wo01gszcr3blu9fyyw | C41: cmj8q9bpi01h9zcr3a6ksrax4 | D41: hybrid_v3_5 | E41: Scenario_1_v2 | F41: 13 | G41: mathematics_computer_science_engineering | H41: 0.1932 | I41: 0.29707506 | J41: 0.30819125 | K41: =J41-I41 -> 0.011116194 | L41: 0.63496808
...

Sheet Notes
A1: p calculation | F1: prompt_to_response | G1: Average activation/turn
A3: 1. count | B3: =COUNT(scen1_hybrid!K3:K148) -> 146 | C3: activation delta
A4: 2. t statistic | B4: =scen1_hybrid!Q3*SQRT((B3-2)/(1-scen1_hybrid!Q3^2)) -> -0.48704759
A5: 3. p | B5: =_xlfn.T.DIST.2T(ABS(B4),B3-2) -> 0.62696517

Sheet activation delta to response_pr
B2: prompt_to_response | C2: Average activation/turn | H2: Correlation | I2: count | J2: T-statistic | K2: p
A3: 1 | B3: 0.83430834 | C3: 0.054866325 | H3: =CORREL(B3:B27,C3:C27) -> 0.22825949 | I3: =COUNT(C3:C27) -> 25 | J3: =H3*SQRT((I3-2)/(1-H3^2)) -> 1.1243772 | K3: =_xlfn.T.DIST.2T(ABS(J3),I3-2) -> 0.27245121
A4: 2 | B4: 0.78737809 | C4: 0.049421284
A5: 3 | B5: 0.82347011 | C5: 0.032563898
A6: 4 | B6: 0.64138219 | C6: 0.066348788
A7: 5 | B7: 0.64856074 | C7: 0.041698828
A8: 6 | B8: 0.73754073 | C8: -0.010193693
A9: 7 | B9: 0.63496808 | C9: 0.044206235
A10: 8 | B10: 0.74640085 | C10: 0.026024486
A11: 9 | B11: 0.68880534 | C11: -0.0050047294
A12: 10 | B12: 0.74363979 | C12: 0.047622962
A13: 11 | B13: 0.71319147 | C13: 0.065668477
A14: 12 | B14: 0.76713896 | C14: 0.054892293
A15: 13 | B15: 0.72568927 | C15: 0.10723274
... A27: 25 | B27: 0.70629147 | C27: 0.042409837

Sheet control_hybrid stats
H2: Tests | L2: Paired t-test
B3: hybrid | C3: control | E3: std. Hybrid | F3: std. Control | G3: F. test | H3: T. Test equal variances | I3: T.Test unequal | J3: Mean difference | L3: Alpha | M3: 0.05
A4: 1 | B4: 0.83430834 | C4: 0.84316826 | E4: =_xlfn.STDEV.S(B4:B28) -> 0.056581542 | F4: =_xlfn.STDEV.S(C4:C28) -> 0.11788306 | G4: =_xlfn.F.TEST(B4:B28,C4:C28) -> 0.00063255311 | H4: =_xlfn.T.TEST(B4:B28, C4:C28, 2,2) -> 5.7118842e-08 | I4: =_xlfn.T.TEST(B4:B28,C4:C28, 2,3) -> 2.3132071e-07 | J4: =AVERAGE(B4:B28)-AVERAGE(C4:C28) -> 0.16788549 | L4: Hypothesized Mean Difference | M4: 0
A5: 2 | B5: 0.78737809 | C5: 0.41048157 | M5: Variable 1 | N5: Variable 2
A6: 3 | B6: 0.82347011 | C6: 0.55797537 | L6: Mean | M6: =AVERAGE('control_hybrid stats'!$B$4:$B$28) -> 0.73055098 | N6: =AVERAGE('control_hybrid stats'!$C$4:$C$28) -> 0.56266549
A7: 4 | B7: 0.64138219 | C7: 0.61915827 | L7: Variance | M7: =VAR('control_hybrid stats'!$B$4:$B$28) -> 0.0032014709 | N7: =VAR('control_hybrid stats'!$C$4:$C$28) -> 0.013896415
A8: 5 | B8: 0.64856074 | C8: 0.40396308 | L8: Observations | M8: =COUNT('control_hybrid stats'!$B$4:$B$28) -> 25 | N8: =COUNT('control_hybrid stats'!$C$4:$C$28) -> 25
A9: 6 | B9: 0.73754073 | C9: 0.57074388 | L9: Pearson Correlation | M9: =CORREL('control_hybrid stats'!$B$4:$B$28,'control_hybrid stats'!$C$4:$C$28) -> 0.22924188
A10: 7 | B10: 0.63496808 | C10: 0.61160895 | L10: Observed Mean Difference | M10: {=AVERAGE(IF(ISODD(IF(ISNUMBER('control_hybrid stats'!$B$4:$B$28), 1, 0) * IF(ISNUMBER('control_hybrid stats'!$C$4:$C$28), 1, 0)), 'control_hybrid stats'!$B$4:$B$28 - 'control_hybrid stats'!$C$4:$C$28, "NA"))} -> 0.16788549
A11: 8 | B11: 0.74640085 | C11: 0.51665839 | L11: Variance of the Differences | M11: {=VAR(IF(ISODD(IF(ISNUMBER('control_hybrid stats'!$B$4:$B$28), 1, 0) * IF(ISNUMBER('control_hybrid stats'!$C$4:$C$28), 1, 0)), 'control_hybrid stats'!$B$4:$B$28 - 'control_hybrid stats'!$C$4:$C$28, "NA"))} -> 0.014039797
A12: 9 | B12: 0.68880534 | C12: 0.51910728 | L12: df | M12: {=SUM(IF(ISNUMBER('control_hybrid stats'!$B$4:$B$28), 1, 0) * IF(ISNUMBER('control_hybrid stats'!$C$4:$C$28), 1, 0)) - 1} -> 24
A13: 10 | B13: 0.74363979 | C13: 0.68124246 | L13: t Stat | M13: =('control_hybrid stats'!$M$10 - 'control_hybrid stats'!$M$4) / ('control_hybrid stats'!$M$11 / ( 'control_hybrid stats'!$M$12 + 1)) ^ 0.5 -> 7.0843949
A14: 11 | B14: 0.71319147 | C14: 0.66509925 | L14: P (T<=t) one-tail | M14: =TDIST(ABS('control_hybrid stats'!$M$13), 'control_hybrid stats'!$M$12, 1) -> 1.2646132e-07
A15: 12 | B15: 0.76713896 | C15: 0.68559512 | L15: t Critical one-tail | M15: =TINV(2*'control_hybrid stats'!$M$3, 'control_hybrid stats'!$M$12) -> 1.7108821
A16: 13 | B16: 0.72568927 | C16: 0.65114377 | L16: P (T<=t) two-tail | M16: =TDIST(ABS('control_hybrid stats'!$M$13), 'control_hybrid stats'!$M$12, 2) -> 2.5292263e-07
A17: 14 | B17: 0.68375138 | C17: 0.60348677 | L17: t Critical two-tail | M17: =TINV('control_hybrid stats'!$M$3, 'control_hybrid stats'!$M$12) -> 2.0638986
A18: 15 | B18: 0.77881066 | C18: 0.49806868
A19: 16 | B19: 0.72071281 | C19: 0.63037797
A20: 17 | B20: 0.77253676 | C20: 0.65792717
A21: 18 | B21: 0.70540047 | C21: 0.56086051
A22: 19 | B22: 0.6540305 | C22: 0.50207793
A23: 20 | B23: 0.81993506 | C23: 0.47716849
A24: 21 | B24: 0.77593529 | C24: 0.49071258
A25: 22 | B25: 0.68930606 | C25: 0.37364723
A26: 23 | B26: 0.75786237 | C26: 0.656355
A27: 24 | B27: 0.70672767 | C27: 0.57973183
A28: 25 | B28: 0.70629147 | C28: 0.30027741
H32: Tests | L32: Paired t-test
B33: hybrid | C33: ac15p | E33: std. Hybrid | F33: ac15p | G33: F. test | H33: T. Test equal variances | I33: T.Test unequal | J33: Mean difference | L33: Alpha | M33: 0.05
A34: 1 | B34: 0.83430834 | C34: 0.82032979 | E34: =_xlfn.STDEV.S(B34:B58) -> 0.056581542 | F34: =_xlfn.STDEV.S(C34:C58) -> 0.067896899 | G34: =_xlfn.F.TEST(B34:B58,C34:C58) -> 0.37806646 | H34: =_xlfn.T.TEST(B34:B58, C34:C58, 2,2) -> 0.99211813 | I34: =_xlfn.T.TEST(B34:B58,C34:C58, 2,3) -> 0.99211947 | J34: =AVERAGE(B34:B58)-AVERAGE(C34:C58) -> -0.00017553112 | L34: Hypothesized Mean Difference | M34: 0
A35: 2 | B35: 0.78737809 | C35: 0.76020895 | M35: Variable 1 | N35: Variable 2
A36: 3 | B36: 0.82347011 | C36: 0.77935892 | L36: Mean | M36: =AVERAGE('control_hybrid stats'!$B$34:$B$58) -> 0.73055098 | N36: =AVERAGE('control_hybrid stats'!$C$34:$C$58) -> 0.73072651
A37: 4 | B37: 0.64138219 | C37: 0.65547417 | L37: Variance | M37: =VAR('control_hybrid stats'!$B$34:$B$58) -> 0.0032014709 | N37: =VAR('control_hybrid stats'!$C$34:$C$58) -> 0.004609989
A38: 5 | B38: 0.64856074 | C38: 0.60148827 | L38: Observations | M38: =COUNT('control_hybrid stats'!$B$34:$B$58) -> 25 | N38: =COUNT('control_hybrid stats'!$C$34:$C$58) -> 25
A39: 6 | B39: 0.73754073 | C39: 0.80260511 | L39: Pearson Correlation | M39: =CORREL('control_hybrid stats'!$B$34:$B$58,'control_hybrid stats'!$C$34:$C$58) -> 0.75938621
A40: 7 | B40: 0.63496808 | C40: 0.64887842 | L40: Observed Mean Difference | M40: {=AVERAGE(IF(ISODD(IF(ISNUMBER('control_hybrid stats'!$B$34:$B$58), 1, 0) * IF(ISNUMBER('control_hybrid stats'!$C$34:$C$58), 1, 0)), 'control_hybrid stats'!$B$34:$B$58 - 'control_hybrid stats'!$C$34:$C$58, "NA"))} -> -0.00017553112
A41: 8 | B41: 0.74640085 | C41: 0.75255045 | L41: Variance of the Differences | M41: {=VAR(IF(ISODD(IF(ISNUMBER('control_hybrid stats'!$B$34:$B$58), 1, 0) * IF(ISNUMBER('control_hybrid stats'!$C$34:$C$58), 1, 0)), 'control_hybrid stats'!$B$34:$B$58 - 'control_hybrid stats'!$C$34:$C$58, "NA"))} -> 0.0019767747
A42: 9 | B42: 0.68880534 | C42: 0.72599844 | L42: df | M42: {=SUM(IF(ISNUMBER('control_hybrid stats'!$B$34:$B$58), 1, 0) * IF(ISNUMBER('control_hybrid stats'!$C$34:$C$58), 1, 0)) - 1} -> 24
A43: 10 | B43: 0.74363979 | C43: 0.70681936 | L43: t Stat | M43: =('control_hybrid stats'!$M$40 - 'control_hybrid stats'!$M$34) / ('control_hybrid stats'!$M$41 / ( 'control_hybrid stats'!$M$42 + 1)) ^ 0.5 -> -0.019739927
A44: 11 | B44: 0.71319147 | C44: 0.66388414 | L44: P (T<=t) one-tail | M44: =TDIST(ABS('control_hybrid stats'!$M$43), 'control_hybrid stats'!$M$42, 1) -> 0.49220702
...
