Workbook

Sheet scen5_hybrid
A1: turnId | B1: user_id | C1: assistant_id | D1: projectName | E1: sessionName | F1: seq | G1: anchorName | H1: weight | I1: promptSim | J1: responseSim | K1: activation delta | L1: prompt_to_response | P1: count | Q1: activation delta average | R1: correlation weights / activation delta | S1: p
P2: =COUNT(K3:K152) -> 150 | Q2: =AVERAGE(K3:K152) -> 0.037631878 | R2: =CORREL(H3:H152,K3:K152) -> -0.20998728 | S2: =notes!B5 -> 0.00990535
A3: 71edbd34-23c9-4b6e-81bf-6d7a15aa4c99 | B3: cmjcpymd300u0zc7e4niyf78c | C3: cmjcpzt7300uhzc7ehx6l6qwo | D3: hybrid_v3_5 | E3: Scenario_5 | F3: 0 | G3: identity | H3: 0.199 | I3: 0.38326795 | J3: 0.42904917 | K3: =J3-I3 -> 0.045781222 | L3: 0.74885829
A4: 71edbd34-23c9-4b6e-81bf-6d7a15aa4c99 | B4: cmjcpymd300u0zc7e4niyf78c | C4: cmjcpzt7300uhzc7ehx6l6qwo | D4: hybrid_v3_5 | E4: Scenario_5 | F4: 0 | G4: temporal_dynamics | H4: 0.1803 | I4: 0.34713741 | J4: 0.44033307 | K4: =J4-I4 -> 0.09319566 | L4: 0.74885829
A5: 71edbd34-23c9-4b6e-81bf-6d7a15aa4c99 | B5: cmjcpymd300u0zc7e4niyf78c | C5: cmjcpzt7300uhzc7ehx6l6qwo | D5: hybrid_v3_5 | E5: Scenario_5 | F5: 0 | G5: practicality_and_feasibility | H5: 0.1754 | I5: 0.337839 | J5: 0.42613371 | K5: =J5-I5 -> 0.088294706 | L5: 0.74885829
A6: 71edbd34-23c9-4b6e-81bf-6d7a15aa4c99 | B6: cmjcpymd300u0zc7e4niyf78c | C6: cmjcpzt7300uhzc7ehx6l6qwo | D6: hybrid_v3_5 | E6: Scenario_5 | F6: 0 | G6: imagination_and_possibility | H6: 0.1732 | I6: 0.33346458 | J6: 0.42629363 | K6: =J6-I6 -> 0.092829046 | L6: 0.74885829
A7: 71edbd34-23c9-4b6e-81bf-6d7a15aa4c99 | B7: cmjcpymd300u0zc7e4niyf78c | C7: cmjcpzt7300uhzc7ehx6l6qwo | D7: hybrid_v3_5 | E7: Scenario_5 | F7: 0 | G7: affective_interface | H7: 0.1721 | I7: 0.33142638 | J7: 0.40823314 | K7: =J7-I7 -> 0.076806763 | L7: 0.74885829
A8: 71edbd34-23c9-4b6e-81bf-6d7a15aa4c99 | B8: cmjcpymd300u0zc7e4niyf78c | C8: cmjcpzt7300uhzc7ehx6l6qwo | D8: hybrid_v3_5 | E8: Scenario_5 | F8: 0 | G8: truth_and_fact | H8: 0.1 | I8: 0.24044726 | J8: 0.36917237 | K8: =J8-I8 -> 0.12872511 | L8: 0.74885829
A9: 8bbb6f15-4dc1-4cda-9328-42f22ce733e3 | B9: cmjcq0iv100ulzc7eb4e2fdrr | C9: cmjcq0xps00v2zc7eeznbsu0r | D9: hybrid_v3_5 | E9: Scenario_5 | F9: 2 | G9: temporal_dynamics | H9: 0.1954 | I9: 0.37597131 | J9: 0.39053041 | K9: =J9-I9 -> 0.014559094 | L9: 0.75950632
A10: 8bbb6f15-4dc1-4cda-9328-42f22ce733e3 | B10: cmjcq0iv100ulzc7eb4e2fdrr | C10: cmjcq0xps00v2zc7eeznbsu0r | D10: hybrid_v3_5 | E10: Scenario_5 | F10: 2 | G10: identity | H10: 0.1855 | I10: 0.35687958 | J10: 0.39890888 | K10: =J10-I10 -> 0.042029295 | L10: 0.75950632
A11: 8bbb6f15-4dc1-4cda-9328-42f22ce733e3 | B11: cmjcq0iv100ulzc7eb4e2fdrr | C11: cmjcq0xps00v2zc7eeznbsu0r | D11: hybrid_v3_5 | E11: Scenario_5 | F11: 2 | G11: mathematics_computer_science_engineering | H11: 0.174 | I11: 0.33484729 | J11: 0.38216939 | K11: =J11-I11 -> 0.047322099 | L11: 0.75950632
A12: 8bbb6f15-4dc1-4cda-9328-42f22ce733e3 | B12: cmjcq0iv100ulzc7eb4e2fdrr | C12: cmjcq0xps00v2zc7eeznbsu0r | D12: hybrid_v3_5 | E12: Scenario_5 | F12: 2 | G12: practicality_and_feasibility | H12: 0.1735 | I12: 0.33379293 | J12: 0.40052793 | K12: =J12-I12 -> 0.066735001 | L12: 0.75950632
A13: 8bbb6f15-4dc1-4cda-9328-42f22ce733e3 | B13: cmjcq0iv100ulzc7eb4e2fdrr | C13: cmjcq0xps00v2zc7eeznbsu0r | D13: hybrid_v3_5 | E13: Scenario_5 | F13: 2 | G13: imagination_and_possibility | H13: 0.1716 | I13: 0.33022599 | J13: 0.38082301 | K13: =J13-I13 -> 0.050597023 | L13: 0.75950632
A14: 8bbb6f15-4dc1-4cda-9328-42f22ce733e3 | B14: cmjcq0iv100ulzc7eb4e2fdrr | C14: cmjcq0xps00v2zc7eeznbsu0r | D14: hybrid_v3_5 | E14: Scenario_5 | F14: 2 | G14: truth_and_fact | H14: 0.1 | I14: 0.28992938 | J14: 0.33675124 | K14: =J14-I14 -> 0.046821863 | L14: 0.75950632
... A152: 5bc5bec0-edaa-4c93-a592-9f4cc69a6b65 | B152: cmjcqki5z0180zc7e6p7r0bxw | C152: cmjcqkx0p018hzc7eg5kpxwy3 | D152: hybrid_v3_5 | E152: Scenario_5 | F152: 48 | G152: freedom_and_limitations | H152: 0.1502 | I152: 0.32342478 | J152: 0.38101298 | K152: =J152-I152 -> 0.057588194 | L152: 0.68787927

Sheet notes
A1: p calculation
A3: 1. count | B3: =scen5_hybrid!P2 -> 150
A4: 2. t statistic | B4: =B10*SQRT((B3-2)/(1-B10^2)) -> -2.6128615
A5: 3. p | B5: =_xlfn.T.DIST.2T(ABS(B4),B3-2) -> 0.00990535
A9: count | B9: correlation weights / activation delta
A10: =B3 -> 150 | B10: =scen5_hybrid!R2 -> -0.20998728

Sheet actdel_prompt_response
A2: Prompt-response
A3: Turn | B3: hybrid
A4: 1 | B4: 0.74885829
A5: 2 | B5: 0.75950632
A6: 3 | B6: 0.71541388
A7: 4 | B7: 0.75834839
A8: 5 | B8: 0.81056506
A9: 6 | B9: 0.74228911
A10: 7 | B10: 0.76425064
A11: 8 | B11: 0.69857772
A12: 9 | B12: 0.76611524
A13: 10 | B13: 0.7779242
A14: 11 | B14: 0.73133786
A15: 12 | B15: 0.76164459
... A28: 25 | B28: 0.68787927

Sheet inter_sysem_stats
B2: prompt_to_response
A3: Turn | B3: hybrid | C3: control | E3: std.hybrid | F3: std. Control | G3: F. test | H3: T. Test equal variances | I3: T.Test unequal | J3: Mean difference | K3: Average scen | L3: Average cont
A4: 1 | B4: 0.74885829 | C4: 0.75451957 | E4: =_xlfn.STDEV.S(B4:B28) -> 0.039676048 | F4: =_xlfn.STDEV.S(C4:C28) -> 0.070588432 | G4: =_xlfn.F.TEST(B4:B28,C4:C28) -> 0.0064899184 | H4: =_xlfn.T.TEST(B4:B28, C4:C28, 2,2) -> 2.4259587e-07 | I4: =_xlfn.T.TEST(B4:B28,C4:C28, 2,3) -> 5.6411108e-07 | J4: =AVERAGE(B4:B28)-AVERAGE(C4:C28) -> 0.097321697 | K4: =AVERAGE(B4:B28) -> 0.73237725 | L4: =AVERAGE(C4:C28) -> 0.63505555
A5: 2 | B5: 0.75950632 | C5: 0.58315782
A6: 3 | B6: 0.71541388 | C6: 0.61890492
A7: 4 | B7: 0.75834839 | C7: 0.74737712
A8: 5 | B8: 0.81056506 | C8: 0.54898023
A9: 6 | B9: 0.74228911 | C9: 0.63269023
A10: 7 | B10: 0.76425064 | C10: 0.70178677
A11: 8 | B11: 0.69857772 | C11: 0.58456232
A12: 9 | B12: 0.76611524 | C12: 0.63553024
A13: 10 | B13: 0.7779242 | C13: 0.69186078
A14: 11 | B14: 0.73133786 | C14: 0.74687441
A15: 12 | B15: 0.76164459 | C15: 0.64610334
A16: 13 | B16: 0.71942937 | C16: 0.71426745
... A28: 25 | B28: 0.68787927 | C28: 0.51286959
A32: General
A34: Turn | B34: ac15p | C34: hybrid | E34: Paired t-test
A35: 1 | B35: 0.77595367 | C35: 0.74885829 | E35: Alpha | F35: 0.05
A36: 2 | B36: 0.74238116 | C36: 0.75950632 | E36: Hypothesized Mean Difference | F36: 0
A37: 3 | B37: 0.71959451 | C37: 0.71541388 | F37: Variable 1 | G37: Variable 2
A38: 4 | B38: 0.74468578 | C38: 0.75834839 | E38: Mean | F38: =AVERAGE(inter_sysem_stats!$B$34:$B$59) -> 0.73237105 | G38: =AVERAGE(inter_sysem_stats!$C$34:$C$59) -> 0.73237725
A39: 5 | B39: 0.81047209 | C39: 0.81056506 | E39: Variance | F39: =VAR(inter_sysem_stats!$B$34:$B$59) -> 0.0021075812 | G39: =VAR(inter_sysem_stats!$C$34:$C$59) -> 0.0015741888
A40: 6 | B40: 0.72631626 | C40: 0.74228911 | E40: Observations | F40: =COUNT(inter_sysem_stats!$B$34:$B$59) -> 25 | G40: =COUNT(inter_sysem_stats!$C$34:$C$59) -> 25
A41: 7 | B41: 0.79321544 | C41: 0.76425064 | E41: Pearson Correlation | F41: =CORREL(inter_sysem_stats!$B$34:$B$59,inter_sysem_stats!$C$34:$C$59) -> 0.61372287
A42: 8 | B42: 0.70459928 | C42: 0.69857772 | E42: Observed Mean Difference | F42: {=AVERAGE(IF(ISODD(IF(ISNUMBER(inter_sysem_stats!$B$34:$B$59), 1, 0) * IF(ISNUMBER(inter_sysem_stats!$C$34:$C$59), 1, 0)), inter_sysem_stats!$B$34:$B$59 - inter_sysem_stats!$C$34:$C$59, "NA"))} -> -6.2002322e-06
A43: 9 | B43: 0.75323189 | C43: 0.76611524 | E43: Variance of the Differences | F43: {=VAR(IF(ISODD(IF(ISNUMBER(inter_sysem_stats!$B$34:$B$59), 1, 0) * IF(ISNUMBER(inter_sysem_stats!$C$34:$C$59), 1, 0)), inter_sysem_stats!$B$34:$B$59 - inter_sysem_stats!$C$34:$C$59, "NA"))} -> 0.0014460219
A44: 10 | B44: 0.78691806 | C44: 0.7779242 | E44: df | F44: {=SUM(IF(ISNUMBER(inter_sysem_stats!$B$34:$B$59), 1, 0) * IF(ISNUMBER(inter_sysem_stats!$C$34:$C$59), 1, 0)) - 1} -> 24
A45: 11 | B45: 0.75773765 | C45: 0.73133786 | E45: t Stat | F45: =(inter_sysem_stats!$F$42 - inter_sysem_stats!$F$36) / (inter_sysem_stats!$F$43 / ( inter_sysem_stats!$F$44 + 1)) ^ 0.5 -> -0.00081524948
A46: 12 | B46: 0.79048878 | C46: 0.76164459 | E46: P (T<=t) one-tail | F46: =TDIST(ABS(inter_sysem_stats!$F$45), inter_sysem_stats!$F$44, 1) -> 0.49967813
A47: 13 | B47: 0.69218774 | C47: 0.71942937 | E47: t Critical one-tail | F47: =TINV(2*inter_sysem_stats!$F$35, inter_sysem_stats!$F$44) -> 1.7108821
A48: 14 | B48: 0.68937987 | C48: 0.67864551 | E48: P (T<=t) two-tail | F48: =TDIST(ABS(inter_sysem_stats!$F$45), inter_sysem_stats!$F$44, 2) -> 0.99935626
A49: 15 | B49: 0.76978674 | C49: 0.70496101 | E49: t Critical two-tail | F49: =TINV(inter_sysem_stats!$F$35, inter_sysem_stats!$F$44) -> 2.0638986
A50: 16 | B50: 0.78421202 | C50: 0.70120829
A51: 17 | B51: 0.74172531 | C51: 0.79001392
A52: 18 | B52: 0.71842175 | C52: 0.717786
A53: 19 | B53: 0.67659873 | C53: 0.70476772
A54: 20 | B54: 0.62907881 | C54: 0.73180489
A55: 21 | B55: 0.71642667 | C55: 0.76689669
A56: 22 | B56: 0.67103092 | C56: 0.62802587
...
