Workbook

Sheet scen2_hybrid
A1: turnId | B1: user_id | C1: assistant_id | D1: projectName | E1: sessionName | F1: seq | G1: anchorName | H1: weight | I1: promptSim | J1: responseSim | K1: activation delta | L1: prompt_to_response | N1: Average activation/turn | O1: average conversation activation | P1: count | Q1: correlation weights / activation delta | R1: p
A3: d7199d7d-6a47-4d63-91a7-1d642985b639 | B3: cmj9sphq4000kzc31ucmlve74 | C3: cmj9sql6b0011zc31zau5r6ne | D3: hybrid_v3_5 | E3: Scenario_2_v3 | F3: 1 | G3: practicality_and_feasibility | H3: 0.2123 | I3: 0.31726229 | J3: 0.3599769 | K3: =J3-I3 -> 0.042714609 | L3: 0.82558738 | N3: =AVERAGE(K3:K8) -> 0.03790127 | O3: =AVERAGE(K3:K133) -> 0.061242462 | P3: =COUNT(K3:K133) -> 131 | Q3: =CORREL(H3:H133,K3:K133) -> 0.19163293 | R3: 0.02833034
A4: d7199d7d-6a47-4d63-91a7-1d642985b639 | B4: cmj9sphq4000kzc31ucmlve74 | C4: cmj9sql6b0011zc31zau5r6ne | D4: hybrid_v3_5 | E4: Scenario_2_v3 | F4: 1 | G4: temporal_dynamics | H4: 0.1805 | I4: 0.26964543 | J4: 0.3193594 | K4: =J4-I4 -> 0.04971397 | L4: 0.82558738
A5: d7199d7d-6a47-4d63-91a7-1d642985b639 | B5: cmj9sphq4000kzc31ucmlve74 | C5: cmj9sql6b0011zc31zau5r6ne | D5: hybrid_v3_5 | E5: Scenario_2_v3 | F5: 1 | G5: affective_interface | H5: 0.1704 | I5: 0.25464037 | J5: 0.29404759 | K5: =J5-I5 -> 0.039407221 | L5: 0.82558738
A6: d7199d7d-6a47-4d63-91a7-1d642985b639 | B6: cmj9sphq4000kzc31ucmlve74 | C6: cmj9sql6b0011zc31zau5r6ne | D6: hybrid_v3_5 | E6: Scenario_2_v3 | F6: 1 | G6: imagination_and_possibility | H6: 0.1692 | I6: 0.252859 | J6: 0.27328846 | K6: =J6-I6 -> 0.020429456 | L6: 0.82558738
A7: d7199d7d-6a47-4d63-91a7-1d642985b639 | B7: cmj9sphq4000kzc31ucmlve74 | C7: cmj9sql6b0011zc31zau5r6ne | D7: hybrid_v3_5 | E7: Scenario_2_v3 | F7: 1 | G7: mathematics_computer_science_engineering | H7: 0.1675 | I7: 0.25025636 | J7: 0.2648271 | K7: =J7-I7 -> 0.014570738 | L7: 0.82558738
A8: d7199d7d-6a47-4d63-91a7-1d642985b639 | B8: cmj9sphq4000kzc31ucmlve74 | C8: cmj9sql6b0011zc31zau5r6ne | D8: hybrid_v3_5 | E8: Scenario_2_v3 | F8: 1 | G8: truth_and_fact | H8: 0.1 | I8: 0.13985696 | J8: 0.20042858 | K8: =J8-I8 -> 0.060571627 | L8: 0.82558738
A9: d01f6534-66fb-4c96-96cb-6e5a528be504 | B9: cmj9swzgr001mzc31ym4n4haq | C9: cmj9sxqo20023zc31e8tb02xf | D9: hybrid_v3_5 | E9: Scenario_2_v3 | F9: 4 | G9: practicality_and_feasibility | H9: 0.2243 | I9: 0.29889489 | J9: 0.38842158 | K9: =J9-I9 -> 0.089526685 | L9: 0.7843254 | N9: =AVERAGE(K9:K14) -> 0.10135166
A10: d01f6534-66fb-4c96-96cb-6e5a528be504 | B10: cmj9swzgr001mzc31ym4n4haq | C10: cmj9sxqo20023zc31e8tb02xf | D10: hybrid_v3_5 | E10: Scenario_2_v3 | F10: 4 | G10: temporal_dynamics | H10: 0.1897 | I10: 0.25272424 | J10: 0.3365534 | K10: =J10-I10 -> 0.083829161 | L10: 0.7843254
A11: d01f6534-66fb-4c96-96cb-6e5a528be504 | B11: cmj9swzgr001mzc31ym4n4haq | C11: cmj9sxqo20023zc31e8tb02xf | D11: hybrid_v3_5 | E11: Scenario_2_v3 | F11: 4 | G11: affective_interface | H11: 0.1724 | I11: 0.22965034 | J11: 0.35722594 | K11: =J11-I11 -> 0.1275756 | L11: 0.7843254
A12: d01f6534-66fb-4c96-96cb-6e5a528be504 | B12: cmj9swzgr001mzc31ym4n4haq | C12: cmj9sxqo20023zc31e8tb02xf | D12: hybrid_v3_5 | E12: Scenario_2_v3 | F12: 4 | G12: mathematics_computer_science_engineering | H12: 0.1572 | I12: 0.20945698 | J12: 0.2990598 | K12: =J12-I12 -> 0.089602821 | L12: 0.7843254
A13: d01f6534-66fb-4c96-96cb-6e5a528be504 | B13: cmj9swzgr001mzc31ym4n4haq | C13: cmj9sxqo20023zc31e8tb02xf | D13: hybrid_v3_5 | E13: Scenario_2_v3 | F13: 4 | G13: imagination_and_possibility | H13: 0.1564 | I13: 0.20833547 | J13: 0.29999495 | K13: =J13-I13 -> 0.091659483 | L13: 0.7843254
A14: d01f6534-66fb-4c96-96cb-6e5a528be504 | B14: cmj9swzgr001mzc31ym4n4haq | C14: cmj9sxqo20023zc31e8tb02xf | D14: hybrid_v3_5 | E14: Scenario_2_v3 | F14: 4 | G14: truth_and_fact | H14: 0.1 | I14: 0.13896738 | J14: 0.26488361 | K14: =J14-I14 -> 0.12591623 | L14: 0.7843254
A15: 0fc922b6-44bd-43d3-a2d9-e96baaed72f5 | B15: cmj9t0aru0027zc312n57vva0 | C15: cmj9t0wcs002ozc31p2zwtkxn | D15: hybrid_v3_5 | E15: Scenario_2_v3 | F15: 6 | G15: practicality_and_feasibility | H15: 0.2133 | I15: 0.34629168 | J15: 0.38360294 | K15: =J15-I15 -> 0.03731126 | L15: 0.74701543 | N15: =AVERAGE(K15:K20) -> 0.048569019
A16: 0fc922b6-44bd-43d3-a2d9-e96baaed72f5 | B16: cmj9t0aru0027zc312n57vva0 | C16: cmj9t0wcs002ozc31p2zwtkxn | D16: hybrid_v3_5 | E16: Scenario_2_v3 | F16: 6 | G16: temporal_dynamics | H16: 0.1959 | I16: 0.31797887 | J16: 0.38090109 | K16: =J16-I16 -> 0.062922223 | L16: 0.74701543
A17: 0fc922b6-44bd-43d3-a2d9-e96baaed72f5 | B17: cmj9t0aru0027zc312n57vva0 | C17: cmj9t0wcs002ozc31p2zwtkxn | D17: hybrid_v3_5 | E17: Scenario_2_v3 | F17: 6 | G17: affective_interface | H17: 0.1737 | I17: 0.28198129 | J17: 0.32209441 | K17: =J17-I17 -> 0.040113126 | L17: 0.74701543
A18: 0fc922b6-44bd-43d3-a2d9-e96baaed72f5 | B18: cmj9t0aru0027zc312n57vva0 | C18: cmj9t0wcs002ozc31p2zwtkxn | D18: hybrid_v3_5 | E18: Scenario_2_v3 | F18: 6 | G18: imagination_and_possibility | H18: 0.1637 | I18: 0.26577626 | J18: 0.32356187 | K18: =J18-I18 -> 0.05778561 | L18: 0.74701543
A19: 0fc922b6-44bd-43d3-a2d9-e96baaed72f5 | B19: cmj9t0aru0027zc312n57vva0 | C19: cmj9t0wcs002ozc31p2zwtkxn | D19: hybrid_v3_5 | E19: Scenario_2_v3 | F19: 6 | G19: mathematics_computer_science_engineering | H19: 0.1534 | I19: 0.24911286 | J19: 0.28062141 | K19: =J19-I19 -> 0.031508557 | L19: 0.74701543
A20: 0fc922b6-44bd-43d3-a2d9-e96baaed72f5 | B20: cmj9t0aru0027zc312n57vva0 | C20: cmj9t0wcs002ozc31p2zwtkxn | D20: hybrid_v3_5 | E20: Scenario_2_v3 | F20: 6 | G20: truth_and_fact | H20: 0.1 | I20: 0.16948795 | J20: 0.23126129 | K20: =J20-I20 -> 0.061773337 | L20: 0.74701543
A21: 96ccf57e-b7a0-408c-8a96-58a208ea0005 | B21: cmj9t1ovx002szc31u7y416eg | C21: cmj9t2ba70039zc31nps62our | D21: hybrid_v3_5 | E21: Scenario_2_v3 | F21: 8 | G21: practicality_and_feasibility | H21: 0.2212 | I21: 0.34035508 | J21: 0.36326452 | K21: =J21-I21 -> 0.022909448 | L21: 0.74257299 | N21: =AVERAGE(K21:K26) -> 0.055058713
A22: 96ccf57e-b7a0-408c-8a96-58a208ea0005 | B22: cmj9t1ovx002szc31u7y416eg | C22: cmj9t2ba70039zc31nps62our | D22: hybrid_v3_5 | E22: Scenario_2_v3 | F22: 8 | G22: temporal_dynamics | H22: 0.2036 | I22: 0.31325547 | J22: 0.33601336 | K22: =J22-I22 -> 0.022757891 | L22: 0.74257299
A23: 96ccf57e-b7a0-408c-8a96-58a208ea0005 | B23: cmj9t1ovx002szc31u7y416eg | C23: cmj9t2ba70039zc31nps62our | D23: hybrid_v3_5 | E23: Scenario_2_v3 | F23: 8 | G23: imagination_and_possibility | H23: 0.1644 | I23: 0.25302301 | J23: 0.27759204 | K23: =J23-I23 -> 0.024569028 | L23: 0.74257299
A24: 96ccf57e-b7a0-408c-8a96-58a208ea0005 | B24: cmj9t1ovx002szc31u7y416eg | C24: cmj9t2ba70039zc31nps62our | D24: hybrid_v3_5 | E24: Scenario_2_v3 | F24: 8 | G24: affective_interface | H24: 0.1562 | I24: 0.24042283 | J24: 0.3471171 | K24: =J24-I24 -> 0.10669428 | L24: 0.74257299
A25: 96ccf57e-b7a0-408c-8a96-58a208ea0005 | B25: cmj9t1ovx002szc31u7y416eg | C25: cmj9t2ba70039zc31nps62our | D25: hybrid_v3_5 | E25: Scenario_2_v3 | F25: 8 | G25: mathematics_computer_science_engineering | H25: 0.1546 | I25: 0.23792166 | J25: 0.2971031 | K25: =J25-I25 -> 0.059181434 | L25: 0.74257299
A26: 96ccf57e-b7a0-408c-8a96-58a208ea0005 | B26: cmj9t1ovx002szc31u7y416eg | C26: cmj9t2ba70039zc31nps62our | D26: hybrid_v3_5 | E26: Scenario_2_v3 | F26: 8 | G26: truth_and_fact | H26: 0.1 | I26: 0.18171493 | J26: 0.27595513 | K26: =J26-I26 -> 0.094240202 | L26: 0.74257299
A27: be699ceb-2e68-43a1-8ae8-ccaaec0a4d85 | B27: cmj9t33lg003dzc31m2926qrd | C27: cmj9t3o78003uzc317yc0atb5 | D27: hybrid_v3_5 | E27: Scenario_2_v3 | F27: 10 | G27: practicality_and_feasibility | H27: 0.2187 | I27: 0.34649718 | J27: 0.41005799 | K27: =J27-I27 -> 0.063560809 | L27: 0.6382916 | N27: =AVERAGE(K27:K32) -> 0.054060902
A28: be699ceb-2e68-43a1-8ae8-ccaaec0a4d85 | B28: cmj9t33lg003dzc31m2926qrd | C28: cmj9t3o78003uzc317yc0atb5 | D28: hybrid_v3_5 | E28: Scenario_2_v3 | F28: 10 | G28: temporal_dynamics | H28: 0.1899 | I28: 0.30091958 | J28: 0.34890603 | K28: =J28-I28 -> 0.047986455 | L28: 0.6382916
A29: be699ceb-2e68-43a1-8ae8-ccaaec0a4d85 | B29: cmj9t33lg003dzc31m2926qrd | C29: cmj9t3o78003uzc317yc0atb5 | D29: hybrid_v3_5 | E29: Scenario_2_v3 | F29: 10 | G29: affective_interface | H29: 0.1719 | I29: 0.27245447 | J29: 0.33486267 | K29: =J29-I29 -> 0.062408204 | L29: 0.6382916
A30: be699ceb-2e68-43a1-8ae8-ccaaec0a4d85 | B30: cmj9t33lg003dzc31m2926qrd | C30: cmj9t3o78003uzc317yc0atb5 | D30: hybrid_v3_5 | E30: Scenario_2_v3 | F30: 10 | G30: mathematics_computer_science_engineering | H30: 0.1627 | I30: 0.257774 | J30: 0.30740442 | K30: =J30-I30 -> 0.049630426 | L30: 0.6382916
A31: be699ceb-2e68-43a1-8ae8-ccaaec0a4d85 | B31: cmj9t33lg003dzc31m2926qrd | C31: cmj9t3o78003uzc317yc0atb5 | D31: hybrid_v3_5 | E31: Scenario_2_v3 | F31: 10 | G31: imagination_and_possibility | H31: 0.1569 | I31: 0.24855886 | J31: 0.31500133 | K31: =J31-I31 -> 0.066442469 | L31: 0.6382916
A32: be699ceb-2e68-43a1-8ae8-ccaaec0a4d85 | B32: cmj9t33lg003dzc31m2926qrd | C32: cmj9t3o78003uzc317yc0atb5 | D32: hybrid_v3_5 | E32: Scenario_2_v3 | F32: 10 | G32: truth_and_fact | H32: 0.1 | I32: 0.21552891 | J32: 0.24986595 | K32: =J32-I32 -> 0.034337049 | L32: 0.6382916
A33: f9d05408-2fa1-4752-a27b-b4ebdcf98095 | B33: cmj9t4ycr003yzc31z80o9oao | C33: cmj9t648s004fzc316o71tcvj | D33: hybrid_v3_5 | E33: Scenario_2_v3 | F33: 12 | G33: practicality_and_feasibility | H33: 0.2198 | I33: 0.29650627 | J33: 0.37274755 | K33: =J33-I33 -> 0.076241278 | L33: 0.77002186 | N33: =AVERAGE(K33:K38) -> 0.066861225
A34: f9d05408-2fa1-4752-a27b-b4ebdcf98095 | B34: cmj9t4ycr003yzc31z80o9oao | C34: cmj9t648s004fzc316o71tcvj | D34: hybrid_v3_5 | E34: Scenario_2_v3 | F34: 12 | G34: temporal_dynamics | H34: 0.1988 | I34: 0.26816135 | J34: 0.31432131 | K34: =J34-I34 -> 0.046159962 | L34: 0.77002186
A35: f9d05408-2fa1-4752-a27b-b4ebdcf98095 | B35: cmj9t4ycr003yzc31z80o9oao | C35: cmj9t648s004fzc316o71tcvj | D35: hybrid_v3_5 | E35: Scenario_2_v3 | F35: 12 | G35: mathematics_computer_science_engineering | H35: 0.1665 | I35: 0.22455424 | J35: 0.28093945 | K35: =J35-I35 -> 0.056385208 | L35: 0.77002186
A36: f9d05408-2fa1-4752-a27b-b4ebdcf98095 | B36: cmj9t4ycr003yzc31z80o9oao | C36: cmj9t648s004fzc316o71tcvj | D36: hybrid_v3_5 | E36: Scenario_2_v3 | F36: 12 | G36: imagination_and_possibility | H36: 0.1599 | I36: 0.21575579 | J36: 0.29323948 | K36: =J36-I36 -> 0.077483688 | L36: 0.77002186
A37: f9d05408-2fa1-4752-a27b-b4ebdcf98095 | B37: cmj9t4ycr003yzc31z80o9oao | C37: cmj9t648s004fzc316o71tcvj | D37: hybrid_v3_5 | E37: Scenario_2_v3 | F37: 12 | G37: affective_interface | H37: 0.155 | I37: 0.20913174 | J37: 0.28998854 | K37: =J37-I37 -> 0.080856805 | L37: 0.77002186
A38: f9d05408-2fa1-4752-a27b-b4ebdcf98095 | B38: cmj9t4ycr003yzc31z80o9oao | C38: cmj9t648s004fzc316o71tcvj | D38: hybrid_v3_5 | E38: Scenario_2_v3 | F38: 12 | G38: truth_and_fact | H38: 0.1 | I38: 0.15518972 | J38: 0.21923012 | K38: =J38-I38 -> 0.064040407 | L38: 0.77002186
A39: a0d1772a-53f9-4df4-884a-3af84a607054 | B39: cmj9t7lil004jzc31ri26w9sc | C39: cmj9t89650050zc31qnqyba0m | D39: hybrid_v3_5 | E39: Scenario_2_v3 | F39: 14 | G39: practicality_and_feasibility | H39: 0.2761 | I39: 0.27199082 | J39: 0.37473108 | K39: =J39-I39 -> 0.10274026 | L39: 0.77670818 | N39: =AVERAGE(K39:K43) -> 0.093461242
A40: a0d1772a-53f9-4df4-884a-3af84a607054 | B40: cmj9t7lil004jzc31ri26w9sc | C40: cmj9t89650050zc31qnqyba0m | D40: hybrid_v3_5 | E40: Scenario_2_v3 | F40: 14 | G40: mathematics_computer_science_engineering | H40: 0.2092 | I40: 0.20614687 | J40: 0.28086491 | K40: =J40-I40 -> 0.074718047 | L40: 0.77670818
A41: a0d1772a-53f9-4df4-884a-3af84a607054 | B41: cmj9t7lil004jzc31ri26w9sc | C41: cmj9t89650050zc31qnqyba0m | D41: hybrid_v3_5 | E41: Scenario_2_v3 | F41: 14 | G41: temporal_dynamics | H41: 0.2077 | I41: 0.20467843 | J41: 0.31714151 | K41: =J41-I41 -> 0.11246308 | L41: 0.77670818
...

Sheet notes
A1: p calculation
A3: 1. count | B3: =scen2_hybrid!P3 -> 131
A4: 2. t statistic | B4: =B10*SQRT((B3-2)/(1-B10^2)) -> 2.2176318
A5: 3. p | B5: =_xlfn.T.DIST.2T(ABS(B4),B3-2) -> 0.02833034
A9: count | B9: correlation weights / activation delta
A10: =B3 -> 131 | B10: 0.19163293

Sheet actdel_prompt_response
B1: prompt_to_response | C1: Average activation/turn | H1: Correlation | I1: count | J1: T-statistic | K1: p
A2: turn
A3: 1 | B3: 0.82558738 | C3: 0.03790127 | H3: =CORREL(B3:B27,C3:C27) -> 0.020988639 | I3: =COUNT(C3:C27) -> 25 | J3: =H3*SQRT((I3-2)/(1-H3^2)) -> 0.10068016 | K3: =_xlfn.T.DIST.2T(ABS(J3),I3-2) -> 0.92067686
A4: 2 | B4: 0.7843254 | C4: 0.10135166
A5: 3 | B5: 0.74701543 | C5: 0.048569019
A6: 4 | B6: 0.74257299 | C6: 0.055058713
A7: 5 | B7: 0.6382916 | C7: 0.054060902
A8: 6 | B8: 0.77002186 | C8: 0.066861225
A9: 7 | B9: 0.77670818 | C9: 0.093461242
A10: 8 | B10: 0.76689514 | C10: 0.065037241
A11: 9 | B11: 0.72686528 | C11: 0.031519636
A12: 10 | B12: 0.76670386 | C12: 0.061360611
A13: 11 | B13: 0.82651214 | C13: 0.062703826
A14: 12 | B14: 0.76273614 | C14: 0.12582337
A15: 13 | B15: 0.7101601 | C15: 0.11847326
... A27: 25 | B27: 0.72723041 | C27: 0.03093229

Sheet inter_system_stats
B2: Prompt-response
B3: hybrid | C3: control | E3: std. Hybrid | F3: std. Control | G3: F. test | H3: T. Test equal variances | I3: T.Test unequal | J3: Mean difference
A4: 1 | B4: 0.82558738 | C4: 0.81423911 | E4: =_xlfn.STDEV.S(B4:B28) -> 0.048146689 | F4: =_xlfn.STDEV.S(C4:C28) -> 0.11577762 | G4: =_xlfn.F.TEST(B4:B28,C4:C28) -> 5.7570479e-05 | H4: =_xlfn.T.TEST(B4:B28, C4:C28, 2,2) -> 2.8643042e-11 | I4: =_xlfn.T.TEST(B4:B28,C4:C28, 2,3) -> 7.9981665e-10 | J4: =AVERAGE(B4:B28)-AVERAGE(C4:C28) -> 0.21543012
A5: 2 | B5: 0.7843254 | C5: 0.49037431
A6: 3 | B6: 0.74701543 | C6: 0.51102033
A7: 4 | B7: 0.74257299 | C7: 0.73212747
A8: 5 | B8: 0.6382916 | C8: 0.5045879 | E8: Paired t-test
A9: 6 | B9: 0.77002186 | C9: 0.62221695 | E9: Alpha | F9: 0.05
A10: 7 | B10: 0.77670818 | C10: 0.5682134 | E10: Hypothesized Mean Difference | F10: 0
A11: 8 | B11: 0.76689514 | C11: 0.41336821 | F11: Variable 1 | G11: Variable 2
A12: 9 | B12: 0.72686528 | C12: 0.4696191 | E12: Mean | F12: =AVERAGE(inter_system_stats!$B$3:$B$28) -> 0.75244418 | G12: =AVERAGE(inter_system_stats!$C$3:$C$28) -> 0.53701406
A13: 10 | B13: 0.76670386 | C13: 0.70259754 | E13: Variance | F13: =VAR(inter_system_stats!$B$3:$B$28) -> 0.0023181036 | G13: =VAR(inter_system_stats!$C$3:$C$28) -> 0.013404458
A14: 11 | B14: 0.82651214 | C14: 0.53574689 | E14: Observations | F14: =COUNT(inter_system_stats!$B$3:$B$28) -> 25 | G14: =COUNT(inter_system_stats!$C$3:$C$28) -> 25
A15: 12 | B15: 0.76273614 | C15: 0.61680633 | E15: Pearson Correlation | F15: =CORREL(inter_system_stats!$B$3:$B$28,inter_system_stats!$C$3:$C$28) -> 0.47316063
A16: 13 | B16: 0.7101601 | C16: 0.52630891 | E16: Observed Mean Difference | F16: {=AVERAGE(IF(ISODD(IF(ISNUMBER(inter_system_stats!$B$3:$B$28), 1, 0) * IF(ISNUMBER(inter_system_stats!$C$3:$C$28), 1, 0)), inter_system_stats!$B$3:$B$28 - inter_system_stats!$C$3:$C$28, "NA"))} -> 0.21543012
A17: 14 | B17: 0.73437638 | C17: 0.42768382 | E17: Variance of the Differences | F17: {=VAR(IF(ISODD(IF(ISNUMBER(inter_system_stats!$B$3:$B$28), 1, 0) * IF(ISNUMBER(inter_system_stats!$C$3:$C$28), 1, 0)), inter_system_stats!$B$3:$B$28 - inter_system_stats!$C$3:$C$28, "NA"))} -> 0.010447474
A18: 15 | B18: 0.75654224 | C18: 0.57565816 | E18: df | F18: {=SUM(IF(ISNUMBER(inter_system_stats!$B$3:$B$28), 1, 0) * IF(ISNUMBER(inter_system_stats!$C$3:$C$28), 1, 0)) - 1} -> 24
A19: 16 | B19: 0.77373202 | C19: 0.57704588 | E19: t Stat | F19: =(inter_system_stats!$F$16 - inter_system_stats!$F$10) / (inter_system_stats!$F$17 / ( inter_system_stats!$F$18 + 1)) ^ 0.5 -> 10.538305
A20: 17 | B20: 0.81269061 | C20: 0.65129577 | E20: P (T<=t) one-tail | F20: =TDIST(ABS(inter_system_stats!$F$19), inter_system_stats!$F$18, 1) -> 8.7417318e-11
A21: 18 | B21: 0.72648885 | C21: 0.59927589 | E21: t Critical one-tail | F21: =TINV(2*inter_system_stats!$F$9, inter_system_stats!$F$18) -> 1.7108821
A22: 19 | B22: 0.76330056 | C22: 0.50621472 | E22: P (T<=t) two-tail | F22: =TDIST(ABS(inter_system_stats!$F$19), inter_system_stats!$F$18, 2) -> 1.7483464e-10
A23: 20 | B23: 0.81653813 | C23: 0.47809959 | E23: t Critical two-tail | F23: =TINV(inter_system_stats!$F$9, inter_system_stats!$F$18) -> 2.0638986
A24: 21 | B24: 0.64339143 | C24: 0.38215194
A25: 22 | B25: 0.76925587 | C25: 0.42806876
A26: 23 | B26: 0.68467054 | C26: 0.34437109
A27: 24 | B27: 0.75849189 | C27: 0.58285066
A28: 25 | B28: 0.72723041 | C28: 0.36540877
B34: Prompt-response
B35: hybrid | C35: ac15p | E35: std. Hybrid | F35: std. Ac15p | G35: F. test | H35: T. Test equal variances | I35: T.Test unequal | J35: Mean difference
B36: 0.82558738 | C36: 0.84283713 | E36: =_xlfn.STDEV.S(B36:B60) -> 0.048146689 | F36: =_xlfn.STDEV.S(C36:C60) -> 0.044988984 | G36: =_xlfn.F.TEST(B36:B60,C36:C60) -> 0.742342 | H36: =_xlfn.T.TEST(B36:B60, C36:C60, 2,2) -> 0.98567765 | I36: =_xlfn.T.TEST(B36:B60,C36:C60, 2,3) -> 0.985678 | J36: =AVERAGE(B36:B60)-AVERAGE(C36:C60) -> 0.00023781566
B37: 0.7843254 | C37: 0.75574435
B38: 0.74701543 | C38: 0.75246139
B39: 0.74257299 | C39: 0.75523994
B40: 0.6382916 | C40: 0.68196907
B41: 0.77002186 | C41: 0.80509458
B42: 0.77670818 | C42: 0.7314491
B43: 0.76689514 | C43: 0.7986994
B44: 0.72686528 | C44: 0.75118107
B45: 0.76670386 | C45: 0.78031701
B46: 0.82651214 | C46: 0.78896492
...
