Workbook

Sheet scen8_hybrid
A1: turnId | B1: user_id | C1: assistant_id | D1: projectName | E1: sessionName | F1: seq | G1: anchorName | H1: weight | I1: promptSim | J1: responseSim | K1: activation delta | L1: prompt_to_response | P1: count | Q1: Activation delta average | R1: correlation weights / activation delta | S1: p
P2: =COUNT(K3:K127) -> 125 | Q2: =AVERAGE(K3:K127) -> 0.070469109 | R2: =CORREL(H3:H127,K3:K127) -> 0.35334384 | S2: =Notes!B5 -> 5.2998013e-05
A3: d1cc98f7-b3cc-4239-b14d-e012eba739d3 | B3: cmjl3dae300fdzccmq5ckmxim | C3: cmjl3e3zt00fuzccmt2w9lt7y | D3: hybrid_v3_5 | E3: Scenario_8 | F3: 0 | G3: affective_interface | H3: 0.9 | I3: 0.23595319 | J3: 0.41566697 | K3: =J3-I3 -> 0.17971378 | L3: 0.7534273
A4: d1cc98f7-b3cc-4239-b14d-e012eba739d3 | B4: cmjl3dae300fdzccmq5ckmxim | C4: cmjl3e3zt00fuzccmt2w9lt7y | D4: hybrid_v3_5 | E4: Scenario_8 | F4: 0 | G4: truth_and_fact | H4: 0.1 | I4: 0.16162794 | J4: 0.32573467 | K4: =J4-I4 -> 0.16410673 | L4: 0.7534273
A5: 2206d5b9-9914-41ec-9d11-238d592440cd | B5: cmjl3f41c00fyzccmyd3hu4ni | C5: cmjl3fm5000gfzccmkzkl43ls | D5: hybrid_v3_5 | E5: Scenario_8 | F5: 2 | G5: affective_interface | H5: 0.5514 | I5: 0.24986252 | J5: 0.42355563 | K5: =J5-I5 -> 0.17369311 | L5: 0.76537158
A6: 2206d5b9-9914-41ec-9d11-238d592440cd | B6: cmjl3f41c00fyzccmyd3hu4ni | C6: cmjl3fm5000gfzccmkzkl43ls | D6: hybrid_v3_5 | E6: Scenario_8 | F6: 2 | G6: truth_and_fact | H6: 0.4486 | I6: 0.20323906 | J6: 0.29520231 | K6: =J6-I6 -> 0.091963243 | L6: 0.76537158
A7: 96b100d8-f37c-4cf2-9bc7-041054000240 | B7: cmjl3g40s00gjzccm55q2kzcr | C7: cmjl3ggvs00h0zccmdnxpl4oi | D7: hybrid_v3_5 | E7: Scenario_8 | F7: 4 | G7: affective_interface | H7: 0.5699 | I7: 0.27046963 | J7: 0.44962515 | K7: =J7-I7 -> 0.17915552 | L7: 0.75306867
A8: 96b100d8-f37c-4cf2-9bc7-041054000240 | B8: cmjl3g40s00gjzccm55q2kzcr | C8: cmjl3ggvs00h0zccmdnxpl4oi | D8: hybrid_v3_5 | E8: Scenario_8 | F8: 4 | G8: truth_and_fact | H8: 0.4301 | I8: 0.20410814 | J8: 0.34690563 | K8: =J8-I8 -> 0.14279748 | L8: 0.75306867
A9: 6e88d09a-e2b5-42a8-906f-ba239840c492 | B9: cmjl3h1zo00h4zccm6w94dudf | C9: cmjl3hhs800hlzccmy2qnn47x | D9: hybrid_v3_5 | E9: Scenario_8 | F9: 6 | G9: affective_interface | H9: 0.2513 | I9: 0.30046001 | J9: 0.44576437 | K9: =J9-I9 -> 0.14530436 | L9: 0.73318408
A10: 6e88d09a-e2b5-42a8-906f-ba239840c492 | B10: cmjl3h1zo00h4zccm6w94dudf | C10: cmjl3hhs800hlzccmy2qnn47x | D10: hybrid_v3_5 | E10: Scenario_8 | F10: 6 | G10: truth_and_fact | H10: 0.22 | I10: 0.26303281 | J10: 0.37609415 | K10: =J10-I10 -> 0.11306134 | L10: 0.73318408
A11: 6e88d09a-e2b5-42a8-906f-ba239840c492 | B11: cmjl3h1zo00h4zccm6w94dudf | C11: cmjl3hhs800hlzccmy2qnn47x | D11: hybrid_v3_5 | E11: Scenario_8 | F11: 6 | G11: science | H11: 0.1832 | I11: 0.21902533 | J11: 0.31358473 | K11: =J11-I11 -> 0.0945594 | L11: 0.73318408
A12: 6e88d09a-e2b5-42a8-906f-ba239840c492 | B12: cmjl3h1zo00h4zccm6w94dudf | C12: cmjl3hhs800hlzccmy2qnn47x | D12: hybrid_v3_5 | E12: Scenario_8 | F12: 6 | G12: practicality_and_feasibility | H12: 0.1751 | I12: 0.20935258 | J12: 0.32516184 | K12: =J12-I12 -> 0.11580926 | L12: 0.73318408
A13: 6e88d09a-e2b5-42a8-906f-ba239840c492 | B13: cmjl3h1zo00h4zccm6w94dudf | C13: cmjl3hhs800hlzccmy2qnn47x | D13: hybrid_v3_5 | E13: Scenario_8 | F13: 6 | G13: imagination_and_possibility | H13: 0.1703 | I13: 0.20355944 | J13: 0.31069065 | K13: =J13-I13 -> 0.10713121 | L13: 0.73318408
A14: c100e627-9fa3-4710-a78d-29b10f70f163 | B14: cmjl3hr3500hpzccm6x4qlbsa | C14: cmjl3hz5c00i6zccm22dv44p5 | D14: hybrid_v3_5 | E14: Scenario_8 | F14: 8 | G14: affective_interface | H14: 0.211 | I14: 0.31454828 | J14: 0.42970154 | K14: =J14-I14 -> 0.11515326 | L14: 0.83979766
... A127: 14ff667e-8673-4f06-8a9b-b5a501c7bff2 | B127: cmjl3y3m500tdzccmb2fckjdx | C127: cmjl3yff700tuzccm7x0vg9s4 | D127: hybrid_v3_5 | E127: Scenario_8 | F127: 48 | G127: imagination_and_possibility | H127: 0.1452 | I127: 0.28252186 | J127: 0.30561268 | K127: =J127-I127 -> 0.023090823 | L127: 0.71750131

Sheet Notes
A1: p calculation
A3: 1. count | B3: =scen8_hybrid!P2 -> 125
A4: 2. t statistic | B4: =B10*SQRT((B3-2)/(1-B10^2)) -> 4.1889897
A5: 3. p | B5: =_xlfn.T.DIST.2T(ABS(B4),B3-2) -> 5.2998013e-05
A9: count | B9: correlation weights / activation delta
A10: =B3 -> 125 | B10: =scen8_hybrid!R2 -> 0.35334384

Sheet actdel_prompt_response
A1: Prompt-response
A2: Turn | B2: hybrid
A3: 1 | B3: 0.7534273
A4: 2 | B4: 0.76537158
A5: 3 | B5: 0.75306867
A6: 4 | B6: 0.73318408
A7: 5 | B7: 0.83979766
A8: 6 | B8: 0.62076408
A9: 7 | B9: 0.70824915
A10: 8 | B10: 0.81183171
A11: 9 | B11: 0.71788979
A12: 10 | B12: 0.82670674
A13: 11 | B13: 0.7515872
A14: 12 | B14: 0.76757629
... A27: 25 | B27: 0.71750131

Sheet inter_system_stats
A2: Prompt-response
A3: Turn | B3: hybrid | C3: control | E3: std. Hybrid | F3: std. Control | G3: F. test | H3: T. Test equal variances | I3: T.Test unequal | J3: Mean difference | K3: Mean hybrid | L3: Mean control
A4: 1 | B4: 0.7534273 | C4: 0.77181473 | E4: =_xlfn.STDEV.S(B4:B28) -> 0.04983038 | F4: =_xlfn.STDEV.S(C4:C28) -> 0.077480319 | G4: =_xlfn.F.TEST(B4:B28,C4:C28) -> 0.03511274 | H4: =_xlfn.T.TEST(B4:B28, C4:C28, 2,2) -> 1.2042768e-06 | I4: =_xlfn.T.TEST(B4:B28,C4:C28, 2,3) -> 1.8810965e-06 | J4: =AVERAGE(B4:B28)-AVERAGE(C4:C28) -> 0.10228458 | K4: =AVERAGE(B4:B28) -> 0.7440653 | L4: =AVERAGE(C4:C28) -> 0.64178072
A5: 2 | B5: 0.76537158 | C5: 0.58574872
A6: 3 | B6: 0.75306867 | C6: 0.59442253
A7: 4 | B7: 0.73318408 | C7: 0.60678637
A8: 5 | B8: 0.83979766 | C8: 0.69941561
A9: 6 | B9: 0.62076408 | C9: 0.58498361
A10: 7 | B10: 0.70824915 | C10: 0.5234345
A11: 8 | B11: 0.81183171 | C11: 0.73317738
A12: 9 | B12: 0.71788979 | C12: 0.62302935
A13: 10 | B13: 0.82670674 | C13: 0.56912644
A14: 11 | B14: 0.7515872 | C14: 0.71261685
A15: 12 | B15: 0.76757629 | C15: 0.62399467
A16: 13 | B16: 0.7747223 | C16: 0.70817517
... A28: 25 | B28: 0.71750131 | C28: 0.63735102
A32: Turn | B32: ac15p | C32: hybrid | E32: Paired t-test
A33: 1 | B33: 0.74689963 | C33: 0.7534273 | E33: Alpha | F33: 0.05
A34: 2 | B34: 0.76044077 | C34: 0.76537158 | E34: Hypothesized Mean Difference | F34: 0
A35: 3 | B35: 0.7454261 | C35: 0.75306867 | F35: Variable 1 | G35: Variable 2
A36: 4 | B36: 0.75451829 | C36: 0.73318408 | E36: Mean | F36: =AVERAGE(inter_system_stats!$B$32:$B$57) -> 0.74206089 | G36: =AVERAGE(inter_system_stats!$C$32:$C$57) -> 0.7440653
A37: 5 | B37: 0.81871695 | C37: 0.83979766 | E37: Variance | F37: =VAR(inter_system_stats!$B$32:$B$57) -> 0.0023570201 | G37: =VAR(inter_system_stats!$C$32:$C$57) -> 0.0024830668
A38: 6 | B38: 0.66147537 | C38: 0.62076408 | E38: Observations | F38: =COUNT(inter_system_stats!$B$32:$B$57) -> 25 | G38: =COUNT(inter_system_stats!$C$32:$C$57) -> 25
A39: 7 | B39: 0.70483109 | C39: 0.70824915 | E39: Pearson Correlation | F39: =CORREL(inter_system_stats!$B$32:$B$57,inter_system_stats!$C$32:$C$57) -> 0.88746591
A40: 8 | B40: 0.77544567 | C40: 0.81183171 | E40: Observed Mean Difference | F40: {=AVERAGE(IF(ISODD(IF(ISNUMBER(inter_system_stats!$B$32:$B$57), 1, 0) * IF(ISNUMBER(inter_system_stats!$C$32:$C$57), 1, 0)), inter_system_stats!$B$32:$B$57 - inter_system_stats!$C$32:$C$57, "NA"))} -> -0.0020044116
A41: 9 | B41: 0.73492259 | C41: 0.71788979 | E41: Variance of the Differences | F41: {=VAR(IF(ISODD(IF(ISNUMBER(inter_system_stats!$B$32:$B$57), 1, 0) * IF(ISNUMBER(inter_system_stats!$C$32:$C$57), 1, 0)), inter_system_stats!$B$32:$B$57 - inter_system_stats!$C$32:$C$57, "NA"))} -> 0.00054613161
A42: 10 | B42: 0.80955347 | C42: 0.82670674 | E42: df | F42: {=SUM(IF(ISNUMBER(inter_system_stats!$B$32:$B$57), 1, 0) * IF(ISNUMBER(inter_system_stats!$C$32:$C$57), 1, 0)) - 1} -> 24
A43: 11 | B43: 0.73619363 | C43: 0.7515872 | E43: t Stat | F43: =(inter_system_stats!$F$40 - inter_system_stats!$F$34) / (inter_system_stats!$F$41 / ( inter_system_stats!$F$42 + 1)) ^ 0.5 -> -0.4288528
A44: 12 | B44: 0.76045069 | C44: 0.76757629 | E44: P (T<=t) one-tail | F44: =TDIST(ABS(inter_system_stats!$F$43), inter_system_stats!$F$42, 1) -> 0.33592762
A45: 13 | B45: 0.78341715 | C45: 0.7747223 | E45: t Critical one-tail | F45: =TINV(2*inter_system_stats!$F$33, inter_system_stats!$F$42) -> 1.7108821
A46: 14 | B46: 0.73635141 | C46: 0.714364 | E46: P (T<=t) two-tail | F46: =TDIST(ABS(inter_system_stats!$F$43), inter_system_stats!$F$42, 2) -> 0.67185523
A47: 15 | B47: 0.69516465 | C47: 0.71442988 | E47: t Critical two-tail | F47: =TINV(inter_system_stats!$F$33, inter_system_stats!$F$42) -> 2.0638986
A48: 16 | B48: 0.75366371 | C48: 0.73057533
A49: 17 | B49: 0.75925493 | C49: 0.73176737
A50: 18 | B50: 0.74400179 | C50: 0.71592458
A51: 19 | B51: 0.77774572 | C51: 0.78193272
A52: 20 | B52: 0.78440488 | C52: 0.77021152
A53: 21 | B53: 0.6465587 | C53: 0.6564293
A54: 22 | B54: 0.64627244 | C54: 0.69967526
A55: 23 | B55: 0.72738344 | C55: 0.73634039
...
