Workbook

Sheet scen6_hybrid
A1: turnId | B1: user_id | C1: assistant_id | D1: projectName | E1: sessionName | F1: seq | G1: anchorName | H1: weight | I1: promptSim | J1: responseSim | K1: activation delta | L1: prompt_to_response | P1: count | Q1: activation delta average | R1: correlation weights / activation delta | S1: p
P2: =COUNT(K3:K115) -> 113 | Q2: =AVERAGE(K3:K115) -> 0.044551994 | R2: =CORREL(H3:H115,K3:K115) -> 0.035675108 | S2: 0.708
A3: c93f4cd5-d999-4d7a-920b-d2aa1cf301ea | B3: cmjfktnnh01dbzca6ahpd34ma | C3: cmjfkumue01dszca6xjud42dj | D3: hybrid_v3_5 | E3: Scenario_6 | F3: 0 | G3: truth_and_fact | H3: 0.1 | I3: 0.15280972 | J3: 0.21734596 | K3: =J3-I3 -> 0.064536246 | L3: 0.8189473
A4: 05bd537b-4d55-4f59-b39c-d8c9bcc18fc0 | B4: cmjfkvn5h01dwzca6ybvm0d0r | C4: cmjfkw59301edzca6oozo3xof | D4: hybrid_v3_5 | E4: Scenario_6 | F4: 2 | G4: truth_and_fact | H4: 0.1 | I4: 0.12310281 | J4: 0.21813422 | K4: =J4-I4 -> 0.09503141 | L4: 0.72667505
A5: 7549d458-2ac4-430d-af68-d71123c6d3c6 | B5: cmjfkww8701ehzca69xpisk8l | C5: cmjfkxrhr01eyzca6vjc9m6by | D5: hybrid_v3_5 | E5: Scenario_6 | F5: 4 | G5: practicality_and_feasibility | H5: 0.197 | I5: 0.234369 | J5: 0.25420051 | K5: =J5-I5 -> 0.019831515 | L5: 0.75382376
A6: 7549d458-2ac4-430d-af68-d71123c6d3c6 | B6: cmjfkww8701ehzca69xpisk8l | C6: cmjfkxrhr01eyzca6vjc9m6by | D6: hybrid_v3_5 | E6: Scenario_6 | F6: 4 | G6: imagination_and_possibility | H6: 0.1785 | I6: 0.21236651 | J6: 0.21958067 | K6: =J6-I6 -> 0.0072141689 | L6: 0.75382376
A7: 7549d458-2ac4-430d-af68-d71123c6d3c6 | B7: cmjfkww8701ehzca69xpisk8l | C7: cmjfkxrhr01eyzca6vjc9m6by | D7: hybrid_v3_5 | E7: Scenario_6 | F7: 4 | G7: context_dependent_expression | H7: 0.1761 | I7: 0.20959299 | J7: 0.23253901 | K7: =J7-I7 -> 0.022946019 | L7: 0.75382376
A8: 7549d458-2ac4-430d-af68-d71123c6d3c6 | B8: cmjfkww8701ehzca69xpisk8l | C8: cmjfkxrhr01eyzca6vjc9m6by | D8: hybrid_v3_5 | E8: Scenario_6 | F8: 4 | G8: mathematics_computer_science_engineering | H8: 0.1751 | I8: 0.20832708 | J8: 0.2137602 | K8: =J8-I8 -> 0.0054331177 | L8: 0.75382376
A9: 7549d458-2ac4-430d-af68-d71123c6d3c6 | B9: cmjfkww8701ehzca69xpisk8l | C9: cmjfkxrhr01eyzca6vjc9m6by | D9: hybrid_v3_5 | E9: Scenario_6 | F9: 4 | G9: freedom_and_limitations | H9: 0.1733 | I9: 0.20623599 | J9: 0.23774806 | K9: =J9-I9 -> 0.031512069 | L9: 0.75382376
A10: 7549d458-2ac4-430d-af68-d71123c6d3c6 | B10: cmjfkww8701ehzca69xpisk8l | C10: cmjfkxrhr01eyzca6vjc9m6by | D10: hybrid_v3_5 | E10: Scenario_6 | F10: 4 | G10: truth_and_fact | H10: 0.1 | I10: 0.18091732 | J10: 0.23300886 | K10: =J10-I10 -> 0.052091539 | L10: 0.75382376
A11: 9f26c07b-d653-4599-9876-edd9bdc0ef5c | B11: cmjfkyakl01f2zca6ye0d370k | C11: cmjfkysvf01fjzca6bxxktl1u | D11: hybrid_v3_5 | E11: Scenario_6 | F11: 6 | G11: truth_and_fact | H11: 0.1 | I11: 0.17992466 | J11: 0.28193229 | K11: =J11-I11 -> 0.10200763 | L11: 0.69468916
A12: 3fe8d050-d84d-4148-82f7-00c1e0b1ba03 | B12: cmjfkzs6q01fnzca6yjq6za3v | C12: cmjfl0zw001g4zca6lojot2aw | D12: hybrid_v3_5 | E12: Scenario_6 | F12: 8 | G12: practicality_and_feasibility | H12: 0.2044 | I12: 0.33402501 | J12: 0.30630939 | K12: =J12-I12 -> -0.027715612 | L12: 0.75031898
A13: 3fe8d050-d84d-4148-82f7-00c1e0b1ba03 | B13: cmjfkzs6q01fnzca6yjq6za3v | C13: cmjfl0zw001g4zca6lojot2aw | D13: hybrid_v3_5 | E13: Scenario_6 | F13: 8 | G13: freedom_and_limitations | H13: 0.1639 | I13: 0.26781425 | J13: 0.24833229 | K13: =J13-I13 -> -0.019481954 | L13: 0.75031898
A14: 3fe8d050-d84d-4148-82f7-00c1e0b1ba03 | B14: cmjfkzs6q01fnzca6yjq6za3v | C14: cmjfl0zw001g4zca6lojot2aw | D14: hybrid_v3_5 | E14: Scenario_6 | F14: 8 | G14: imagination_and_possibility | H14: 0.163 | I14: 0.26637517 | J14: 0.24880633 | K14: =J14-I14 -> -0.017568837 | L14: 0.75031898
... A115: 52d73fb7-f967-47ca-9a97-f974925f9019 | B115: cmjfllj8901rbzca6oqsn6lva | C115: cmjfllzsq01rszca660rp5q47 | D115: hybrid_v3_5 | E115: Scenario_6 | F115: 48 | G115: truth_and_fact | H115: 0.1 | I115: 0.20275582 | J115: 0.31077254 | K115: =J115-I115 -> 0.10801672 | L115: 0.7362928

Sheet Notes
A1: p calculation
A3: 1. count | B3: =scen6_hybrid!P2 -> 113
A4: 2. t statistic | B4: =B10*SQRT((B3-2)/(1-B10^2)) -> 0.3761
A5: 3. p | B5: =_xlfn.T.DIST.2T(ABS(B4),B3-2) -> 0.70756043
A9: count | B9: correlation weights / activation delta
A10: =B3 -> 113 | B10: =scen6_hybrid!R2 -> 0.035675108

Sheet actdel_prompt_response
A2: Prompt-response
A3: Turn | B3: hybrid
A4: 1 | B4: 0.8189473
A5: 2 | B5: 0.72667505
A6: 3 | B6: 0.75382376
A7: 4 | B7: 0.69468916
A8: 5 | B8: 0.75031898
A9: 6 | B9: 0.79289751
A10: 7 | B10: 0.74071706
A11: 8 | B11: 0.70151887
A12: 9 | B12: 0.67940884
A13: 10 | B13: 0.69382834
A14: 11 | B14: 0.71401509
A15: 12 | B15: 0.82935334
... A28: 25 | B28: 0.7362928

Sheet Inter_system_stats
A1: Prompt-response
A2: Turn | B2: hybrid | C2: control | E2: std. Hybrid | F2: std. Control | G2: F. test | H2: T. Test equal variances | I2: T.Test unequal | J2: Mean difference | K2: Mean scen | L2: Mean control
A3: 1 | B3: 0.8189473 | C3: 0.8205306 | E3: =_xlfn.STDEV.S(B3:B27) -> 0.054678553 | F3: =_xlfn.STDEV.S(C3:C27) -> 0.1102969 | G3: =_xlfn.F.TEST(B3:B27,C3:C27) -> 0.0010477438 | H3: =_xlfn.T.TEST(B3:B27, C3:C27, 2,2) -> 8.0884894e-09 | I3: =_xlfn.T.TEST(B3:B27,C3:C27, 2,3) -> 4.0618641e-08 | J3: =AVERAGE(B3:B27)-AVERAGE(C3:C27) -> 0.17168388 | K3: =AVERAGE(B3:B27) -> 0.73603082 | L3: =AVERAGE(C3:C27) -> 0.56434695
A4: 2 | B4: 0.72667505 | C4: 0.4077777
A5: 3 | B5: 0.75382376 | C5: 0.64741534
A6: 4 | B6: 0.69468916 | C6: 0.4921473
A7: 5 | B7: 0.75031898 | C7: 0.53686287
A8: 6 | B8: 0.79289751 | C8: 0.63772449
A9: 7 | B9: 0.74071706 | C9: 0.61665661
A10: 8 | B10: 0.70151887 | C10: 0.62659257
A11: 9 | B11: 0.67940884 | C11: 0.64803425
A12: 10 | B12: 0.69382834 | C12: 0.50632365
A13: 11 | B13: 0.71401509 | C13: 0.58561227
A14: 12 | B14: 0.82935334 | C14: 0.52267553
A15: 13 | B15: 0.74133511 | C15: 0.59336895
... A27: 25 | B27: 0.7362928 | C27: 0.46942826
A32: General
A34: Turn | B34: ac15p | C34: hybrid | E34: Paired t-test
A35: 1 | B35: 0.79000575 | C35: 0.8189473 | E35: Alpha | F35: 0.05
A36: 2 | B36: 0.6817351 | C36: 0.72667505 | E36: Hypothesized Mean Difference | F36: 0
A37: 3 | B37: 0.73659154 | C37: 0.75382376 | F37: Variable 1 | G37: Variable 2
A38: 4 | B38: 0.65821229 | C38: 0.69468916 | E38: Mean | F38: =AVERAGE(Inter_system_stats!$B$34:$B$59) -> 0.72805647 | G38: =AVERAGE(Inter_system_stats!$C$34:$C$59) -> 0.73603082
A39: 5 | B39: 0.74318489 | C39: 0.75031898 | E39: Variance | F39: =VAR(Inter_system_stats!$B$34:$B$59) -> 0.0037347451 | G39: =VAR(Inter_system_stats!$C$34:$C$59) -> 0.0029897442
A40: 6 | B40: 0.7383633 | C40: 0.79289751 | E40: Observations | F40: =COUNT(Inter_system_stats!$B$34:$B$59) -> 25 | G40: =COUNT(Inter_system_stats!$C$34:$C$59) -> 25
A41: 7 | B41: 0.80270938 | C41: 0.74071706 | E41: Pearson Correlation | F41: =CORREL(Inter_system_stats!$B$34:$B$59,Inter_system_stats!$C$34:$C$59) -> 0.81110148
A42: 8 | B42: 0.76713782 | C42: 0.70151887 | E42: Observed Mean Difference | F42: {=AVERAGE(IF(ISODD(IF(ISNUMBER(Inter_system_stats!$B$34:$B$59), 1, 0) * IF(ISNUMBER(Inter_system_stats!$C$34:$C$59), 1, 0)), Inter_system_stats!$B$34:$B$59 - Inter_system_stats!$C$34:$C$59, "NA"))} -> -0.0079743531
A43: 9 | B43: 0.65520384 | C43: 0.67940884 | E43: Variance of the Differences | F43: {=VAR(IF(ISODD(IF(ISNUMBER(Inter_system_stats!$B$34:$B$59), 1, 0) * IF(ISNUMBER(Inter_system_stats!$C$34:$C$59), 1, 0)), Inter_system_stats!$B$34:$B$59 - Inter_system_stats!$C$34:$C$59, "NA"))} -> 0.0013038228
A44: 10 | B44: 0.70090518 | C44: 0.69382834 | E44: df | F44: {=SUM(IF(ISNUMBER(Inter_system_stats!$B$34:$B$59), 1, 0) * IF(ISNUMBER(Inter_system_stats!$C$34:$C$59), 1, 0)) - 1} -> 24
A45: 11 | B45: 0.71962924 | C45: 0.71401509 | E45: t Stat | F45: =(Inter_system_stats!$F$42 - Inter_system_stats!$F$36) / (Inter_system_stats!$F$43 / ( Inter_system_stats!$F$44 + 1)) ^ 0.5 -> -1.1042214
A46: 12 | B46: 0.83162141 | C46: 0.82935334 | E46: P (T<=t) one-tail | F46: =TDIST(ABS(Inter_system_stats!$F$45), Inter_system_stats!$F$44, 1) -> 0.1402227
A47: 13 | B47: 0.7095195 | C47: 0.74133511 | E47: t Critical one-tail | F47: =TINV(2*Inter_system_stats!$F$35, Inter_system_stats!$F$44) -> 1.7108821
A48: 14 | B48: 0.75258804 | C48: 0.77755869 | E48: P (T<=t) two-tail | F48: =TDIST(ABS(Inter_system_stats!$F$45), Inter_system_stats!$F$44, 2) -> 0.2804454
A49: 15 | B49: 0.74255587 | C49: 0.76965524 | E49: t Critical two-tail | F49: =TINV(Inter_system_stats!$F$35, Inter_system_stats!$F$44) -> 2.0638986
A50: 16 | B50: 0.62660019 | C50: 0.69268523
A51: 17 | B51: 0.81814248 | C51: 0.80578727
A52: 18 | B52: 0.64796342 | C52: 0.63109379
A53: 19 | B53: 0.64384174 | C53: 0.69026916
A54: 20 | B54: 0.65454773 | C54: 0.69704907
A55: 21 | B55: 0.73727979 | C55: 0.69517695
A56: 22 | B56: 0.741791 | C56: 0.7579538
...
