Workbook

Sheet scen7_hybrid
A1: turnId | B1: user_id | C1: assistant_id | D1: projectName | E1: sessionName | F1: seq | G1: anchorName | H1: weight | I1: promptSim | J1: responseSim | K1: activation delta | L1: prompt_to_response | P1: count | Q1: activation delta average | R1: correlation weights / activation delta | S1: p
P2: =COUNT(K3:K129) -> 127 | Q2: =AVERAGE(K3:K129) -> 0.045117016 | R2: =CORREL(H3:H129,K3:K129) -> 0.14440781 | S2: 0.1053
A3: 937b6ccc-6f0d-4a63-b80a-779859c628c5 | B3: cmjjugzdk00g0zceeze9t0p2j | C3: cmjjui33y00ghzceeowd1wpeh | D3: hybrid_v3_5 | E3: Scenario_7 | F3: 0 | G3: temporal_dynamics | H3: 0.3218 | I3: 0.23236596 | J3: 0.32079421 | K3: =J3-I3 -> 0.088428244 | L3: 0.74561822
A4: 937b6ccc-6f0d-4a63-b80a-779859c628c5 | B4: cmjjugzdk00g0zceeze9t0p2j | C4: cmjjui33y00ghzceeowd1wpeh | D4: hybrid_v3_5 | E4: Scenario_7 | F4: 0 | G4: imagination_and_possibility | H4: 0.2954 | I4: 0.2132818 | J4: 0.30014987 | K4: =J4-I4 -> 0.086868072 | L4: 0.74561822
A5: 937b6ccc-6f0d-4a63-b80a-779859c628c5 | B5: cmjjugzdk00g0zceeze9t0p2j | C5: cmjjui33y00ghzceeowd1wpeh | D5: hybrid_v3_5 | E5: Scenario_7 | F5: 0 | G5: affective_interface | H5: 0.2828 | I5: 0.20419119 | J5: 0.33789956 | K5: =J5-I5 -> 0.13370837 | L5: 0.74561822
A6: 937b6ccc-6f0d-4a63-b80a-779859c628c5 | B6: cmjjugzdk00g0zceeze9t0p2j | C6: cmjjui33y00ghzceeowd1wpeh | D6: hybrid_v3_5 | E6: Scenario_7 | F6: 0 | G6: truth_and_fact | H6: 0.1 | I6: 0.14138829 | J6: 0.27890963 | K6: =J6-I6 -> 0.13752134 | L6: 0.74561822
A7: d2817632-926f-4904-aa49-3bda712ab08c | B7: cmjjuivvf00glzceea066cb7b | C7: cmjjujcq500h2zcee45ucikpe | D7: hybrid_v3_5 | E7: Scenario_7 | F7: 2 | G7: imagination_and_possibility | H7: 0.9 | I7: 0.20799375 | J7: 0.3204156 | K7: =J7-I7 -> 0.11242185 | L7: 0.73196562
A8: d2817632-926f-4904-aa49-3bda712ab08c | B8: cmjjuivvf00glzceea066cb7b | C8: cmjjujcq500h2zcee45ucikpe | D8: hybrid_v3_5 | E8: Scenario_7 | F8: 2 | G8: truth_and_fact | H8: 0.1 | I8: 0.14605259 | J8: 0.26708672 | K8: =J8-I8 -> 0.12103413 | L8: 0.73196562
A9: 36d4d1a5-59e4-41b1-b6c2-61c5d080cd6b | B9: cmjjujwln00h6zceelx4ss03s | C9: cmjjuki0w00hnzcee9n49ep9n | D9: hybrid_v3_5 | E9: Scenario_7 | F9: 4 | G9: affective_interface | H9: 0.303 | I9: 0.22458166 | J9: 0.30638893 | K9: =J9-I9 -> 0.081807267 | L9: 0.55634941
A10: 36d4d1a5-59e4-41b1-b6c2-61c5d080cd6b | B10: cmjjujwln00h6zceelx4ss03s | C10: cmjjuki0w00hnzcee9n49ep9n | D10: hybrid_v3_5 | E10: Scenario_7 | F10: 4 | G10: identity | H10: 0.3003 | I10: 0.22256591 | J10: 0.25383132 | K10: =J10-I10 -> 0.031265412 | L10: 0.55634941
A11: 36d4d1a5-59e4-41b1-b6c2-61c5d080cd6b | B11: cmjjujwln00h6zceelx4ss03s | C11: cmjjuki0w00hnzcee9n49ep9n | D11: hybrid_v3_5 | E11: Scenario_7 | F11: 4 | G11: electricity | H11: 0.2967 | I11: 0.21986327 | J11: 0.17657975 | K11: =J11-I11 -> -0.043283524 | L11: 0.55634941
A12: 36d4d1a5-59e4-41b1-b6c2-61c5d080cd6b | B12: cmjjujwln00h6zceelx4ss03s | C12: cmjjuki0w00hnzcee9n49ep9n | D12: hybrid_v3_5 | E12: Scenario_7 | F12: 4 | G12: truth_and_fact | H12: 0.1 | I12: 0.15244167 | J12: 0.25974759 | K12: =J12-I12 -> 0.10730591 | L12: 0.55634941
A13: fa3ff29c-6efe-46bb-b339-b3218ac47ff5 | B13: cmjjulpgw00hrzcee4oabclrw | C13: cmjjumc5z00i8zceem4dlf59z | D13: hybrid_v3_5 | E13: Scenario_7 | F13: 6 | G13: affective_interface | H13: 0.1881 | I13: 0.30686585 | J13: 0.35512841 | K13: =J13-I13 -> 0.048262561 | L13: 0.74696128
A14: fa3ff29c-6efe-46bb-b339-b3218ac47ff5 | B14: cmjjulpgw00hrzcee4oabclrw | C14: cmjjumc5z00i8zceem4dlf59z | D14: hybrid_v3_5 | E14: Scenario_7 | F14: 6 | G14: imagination_and_possibility | H14: 0.1665 | I14: 0.27172127 | J14: 0.33457117 | K14: =J14-I14 -> 0.062849894 | L14: 0.74696128
... A129: 50c6e73f-43d3-46aa-a4e1-479ffd87dee3 | B129: cmjjv9ojb00u0zceey9sq4gmd | C129: cmjjva7z800uhzceedv2cegl5 | D129: hybrid_v3_5 | E129: Scenario_7 | F129: 48 | G129: mathematics_computer_science_engineering | H129: 0.1501 | I129: 0.27280971 | J129: 0.24043149 | K129: =J129-I129 -> -0.032378218 | L129: 0.727724

Sheet Notes
A1: p calculation
A3: 1. count | B3: =scen7_hybrid!P2 -> 127
A4: 2. t statistic | B4: =B10*SQRT((B3-2)/(1-B10^2)) -> 1.6316307
A5: 3. p | B5: =_xlfn.T.DIST.2T(ABS(B4),B3-2) -> 0.10527419
A9: count | B9: correlation weights / activation delta
A10: =B3 -> 127 | B10: =scen7_hybrid!R2 -> 0.14440781

Sheet actdel_prompt_response
A1: Prompt-response
A2: Turn | B2: Hybrid
A3: 1 | B3: 0.74561822
A4: 2 | B4: 0.73196562
A5: 3 | B5: 0.55634941
A6: 4 | B6: 0.74696128
A7: 5 | B7: 0.73630313
A8: 6 | B8: 0.69306052
A9: 7 | B9: 0.74859756
A10: 8 | B10: 0.70516594
A11: 9 | B11: 0.75036872
A12: 10 | B12: 0.682433
A13: 11 | B13: 0.72387381
A14: 12 | B14: 0.66770176
... A27: 25 | B27: 0.727724

Sheet inter_system_stats
A2: Prompt-response
A3: Turn | B3: Hybrid | C3: control | E3: std. Hybrid | F3: std. Control | G3: F. test | H3: T. Test equal variances | I3: T.Test unequal | J3: Mean difference | K3: Mean hybrid | L3: Mean control
A4: 1 | B4: 0.74561822 | C4: 0.78035784 | E4: =_xlfn.STDEV.S(B4:B28) -> 0.050384152 | F4: =_xlfn.STDEV.S(C4:C28) -> 0.10899113 | G4: =_xlfn.F.TEST(B4:B28,C4:C28) -> 0.00034575751 | H4: =_xlfn.T.TEST(B4:B28, C4:C28, 2,2) -> 5.8179761e-08 | I4: =_xlfn.T.TEST(B4:B28,C4:C28, 2,3) -> 2.5702888e-07 | J4: =AVERAGE(B4:B28)-AVERAGE(C4:C28) -> 0.15404094 | K4: =AVERAGE(B4:B28) -> 0.72229125 | L4: =AVERAGE(C4:C28) -> 0.56825031
A5: 2 | B5: 0.73196562 | C5: 0.41620709
A6: 3 | B6: 0.55634941 | C6: 0.44069473
A7: 4 | B7: 0.74696128 | C7: 0.50298343
A8: 5 | B8: 0.73630313 | C8: 0.64837824
A9: 6 | B9: 0.69306052 | C9: 0.55690541
A10: 7 | B10: 0.74859756 | C10: 0.67658778
A11: 8 | B11: 0.70516594 | C11: 0.53755699
A12: 9 | B12: 0.75036872 | C12: 0.54745066
A13: 10 | B13: 0.682433 | C13: 0.40447571
A14: 11 | B14: 0.72387381 | C14: 0.57351245
A15: 12 | B15: 0.66770176 | C15: 0.68842639
A16: 13 | B16: 0.72995268 | C16: 0.53673254
... A28: 25 | B28: 0.727724 | C28: 0.4547081
A30: General
A32: Turn | B32: ac15p | C32: Hybrid | E32: Paired t-test
A33: 1 | B33: 0.72660445 | C33: 0.74561822 | E33: Alpha | F33: 0.05
A34: 2 | B34: 0.70895983 | C34: 0.73196562 | E34: Hypothesized Mean Difference | F34: 0
A35: 3 | B35: 0.65625079 | C35: 0.55634941 | F35: Variable 1 | G35: Variable 2
A36: 4 | B36: 0.68248006 | C36: 0.74696128 | E36: Mean | F36: =AVERAGE(inter_system_stats!$B$32:$B$57) -> 0.71141589 | G36: =AVERAGE(inter_system_stats!$C$32:$C$57) -> 0.72229125
A37: 5 | B37: 0.75066609 | C37: 0.73630313 | E37: Variance | F37: =VAR(inter_system_stats!$B$32:$B$57) -> 0.0022639834 | G37: =VAR(inter_system_stats!$C$32:$C$57) -> 0.0025385628
A38: 6 | B38: 0.69003761 | C38: 0.69306052 | E38: Observations | F38: =COUNT(inter_system_stats!$B$32:$B$57) -> 25 | G38: =COUNT(inter_system_stats!$C$32:$C$57) -> 25
A39: 7 | B39: 0.70889799 | C39: 0.74859756 | E39: Pearson Correlation | F39: =CORREL(inter_system_stats!$B$32:$B$57,inter_system_stats!$C$32:$C$57) -> 0.63924681
A40: 8 | B40: 0.68554662 | C40: 0.70516594 | E40: Observed Mean Difference | F40: {=AVERAGE(IF(ISODD(IF(ISNUMBER(inter_system_stats!$B$32:$B$57), 1, 0) * IF(ISNUMBER(inter_system_stats!$C$32:$C$57), 1, 0)), inter_system_stats!$B$32:$B$57 - inter_system_stats!$C$32:$C$57, "NA"))} -> -0.01087536
A41: 9 | B41: 0.72762952 | C41: 0.75036872 | E41: Variance of the Differences | F41: {=VAR(IF(ISODD(IF(ISNUMBER(inter_system_stats!$B$32:$B$57), 1, 0) * IF(ISNUMBER(inter_system_stats!$C$32:$C$57), 1, 0)), inter_system_stats!$B$32:$B$57 - inter_system_stats!$C$32:$C$57, "NA"))} -> 0.0017375556
A42: 10 | B42: 0.63748551 | C42: 0.682433 | E42: df | F42: {=SUM(IF(ISNUMBER(inter_system_stats!$B$32:$B$57), 1, 0) * IF(ISNUMBER(inter_system_stats!$C$32:$C$57), 1, 0)) - 1} -> 24
A43: 11 | B43: 0.71798946 | C43: 0.72387381 | E43: t Stat | F43: =(inter_system_stats!$F$40 - inter_system_stats!$F$34) / (inter_system_stats!$F$41 / ( inter_system_stats!$F$42 + 1)) ^ 0.5 -> -1.3045006
A44: 12 | B44: 0.77090629 | C44: 0.66770176 | E44: P (T<=t) one-tail | F44: =TDIST(ABS(inter_system_stats!$F$43), inter_system_stats!$F$42, 1) -> 0.1022173
A45: 13 | B45: 0.7098279 | C45: 0.72995268 | E45: t Critical one-tail | F45: =TINV(2*inter_system_stats!$F$33, inter_system_stats!$F$42) -> 1.7108821
A46: 14 | B46: 0.824776 | C46: 0.79516956 | E46: P (T<=t) two-tail | F46: =TDIST(ABS(inter_system_stats!$F$43), inter_system_stats!$F$42, 2) -> 0.20443461
A47: 15 | B47: 0.6113315 | C47: 0.64136105 | E47: t Critical two-tail | F47: =TINV(inter_system_stats!$F$33, inter_system_stats!$F$42) -> 2.0638986
A48: 16 | B48: 0.74347337 | C48: 0.75855012
A49: 17 | B49: 0.6577691 | C49: 0.69417603
A50: 18 | B50: 0.73366789 | C50: 0.75354741
A51: 19 | B51: 0.66476983 | C51: 0.71847314
A52: 20 | B52: 0.73551176 | C52: 0.75453899
A53: 21 | B53: 0.71546661 | C53: 0.71601755
A54: 22 | B54: 0.7090201 | C54: 0.75187651
...
