Workbook

Sheet scen4_hybrid
A1: turnId | B1: user_id | C1: assistant_id | D1: projectName | E1: sessionName | F1: seq | G1: anchorName | H1: weight | I1: promptSim | J1: responseSim | K1: activation delta | L1: prompt_to_response | P1: count | Q1: average activation delta | R1: correlation weights / activation delta | S1: p
P2: =COUNT(K3:K147) -> 145 | Q2: =AVERAGE(K3:K147) -> 0.054236474 | R2: =CORREL(H3:H147,K3:K147) -> 0.041393677 | S2: 0.621
A3: 3c6e77ea-5a26-47dd-a507-b33f85e398c8 | B3: cmjbk6y9p00glzc8goa91nwq4 | C3: cmjbk820j00h2zc8g73iiwdu8 | D3: hybrid_v3_5 | E3: Scenario_4 | F3: 0 | G3: practicality_and_feasibility | H3: 0.2025 | I3: 0.32767827 | J3: 0.41576891 | K3: =J3-I3 -> 0.088090641 | L3: 0.79629877
A4: 3c6e77ea-5a26-47dd-a507-b33f85e398c8 | B4: cmjbk6y9p00glzc8goa91nwq4 | C4: cmjbk820j00h2zc8g73iiwdu8 | D4: hybrid_v3_5 | E4: Scenario_4 | F4: 0 | G4: identity | H4: 0.192 | I4: 0.31064045 | J4: 0.33468279 | K4: =J4-I4 -> 0.024042345 | L4: 0.79629877
A5: 3c6e77ea-5a26-47dd-a507-b33f85e398c8 | B5: cmjbk6y9p00glzc8goa91nwq4 | C5: cmjbk820j00h2zc8g73iiwdu8 | D5: hybrid_v3_5 | E5: Scenario_4 | F5: 0 | G5: mathematics_computer_science_engineering | H5: 0.176 | I5: 0.28487454 | J5: 0.32218754 | K5: =J5-I5 -> 0.037312999 | L5: 0.79629877
A6: 3c6e77ea-5a26-47dd-a507-b33f85e398c8 | B6: cmjbk6y9p00glzc8goa91nwq4 | C6: cmjbk820j00h2zc8g73iiwdu8 | D6: hybrid_v3_5 | E6: Scenario_4 | F6: 0 | G6: imagination_and_possibility | H6: 0.1713 | I6: 0.27720482 | J6: 0.31821718 | K6: =J6-I6 -> 0.041012357 | L6: 0.79629877
A7: 3c6e77ea-5a26-47dd-a507-b33f85e398c8 | B7: cmjbk6y9p00glzc8goa91nwq4 | C7: cmjbk820j00h2zc8g73iiwdu8 | D7: hybrid_v3_5 | E7: Scenario_4 | F7: 0 | G7: metaphorical_scaffolding | H7: 0.1582 | I7: 0.25598444 | J7: 0.32716453 | K7: =J7-I7 -> 0.071180089 | L7: 0.79629877
A8: 3c6e77ea-5a26-47dd-a507-b33f85e398c8 | B8: cmjbk6y9p00glzc8goa91nwq4 | C8: cmjbk820j00h2zc8g73iiwdu8 | D8: hybrid_v3_5 | E8: Scenario_4 | F8: 0 | G8: truth_and_fact | H8: 0.1 | I8: 0.20878812 | J8: 0.25701856 | K8: =J8-I8 -> 0.048230442 | L8: 0.79629877
A9: 38e658f8-e0d6-4dbb-a8bf-cfd590ba56e8 | B9: cmjbk8zt100h6zc8gouesc057 | C9: cmjbk9st500hnzc8gzhdq6c5b | D9: hybrid_v3_5 | E9: Scenario_4 | F9: 2 | G9: practicality_and_feasibility | H9: 0.2144 | I9: 0.36457019 | J9: 0.36668258 | K9: =J9-I9 -> 0.0021123867 | L9: 0.73955855
A10: 38e658f8-e0d6-4dbb-a8bf-cfd590ba56e8 | B10: cmjbk8zt100h6zc8gouesc057 | C10: cmjbk9st500hnzc8gzhdq6c5b | D10: hybrid_v3_5 | E10: Scenario_4 | F10: 2 | G10: identity | H10: 0.1822 | I10: 0.30968205 | J10: 0.36258004 | K10: =J10-I10 -> 0.052897985 | L10: 0.73955855
A11: 38e658f8-e0d6-4dbb-a8bf-cfd590ba56e8 | B11: cmjbk8zt100h6zc8gouesc057 | C11: cmjbk9st500hnzc8gzhdq6c5b | D11: hybrid_v3_5 | E11: Scenario_4 | F11: 2 | G11: metaphorical_scaffolding | H11: 0.1713 | I11: 0.29119751 | J11: 0.31069013 | K11: =J11-I11 -> 0.019492618 | L11: 0.73955855
A12: 38e658f8-e0d6-4dbb-a8bf-cfd590ba56e8 | B12: cmjbk8zt100h6zc8gouesc057 | C12: cmjbk9st500hnzc8gzhdq6c5b | D12: hybrid_v3_5 | E12: Scenario_4 | F12: 2 | G12: imagination_and_possibility | H12: 0.1663 | I12: 0.28280169 | J12: 0.31424288 | K12: =J12-I12 -> 0.03144119 | L12: 0.73955855
A13: 38e658f8-e0d6-4dbb-a8bf-cfd590ba56e8 | B13: cmjbk8zt100h6zc8gouesc057 | C13: cmjbk9st500hnzc8gzhdq6c5b | D13: hybrid_v3_5 | E13: Scenario_4 | F13: 2 | G13: affective_interface | H13: 0.1658 | I13: 0.28179301 | J13: 0.35222548 | K13: =J13-I13 -> 0.070432472 | L13: 0.73955855
A14: 38e658f8-e0d6-4dbb-a8bf-cfd590ba56e8 | B14: cmjbk8zt100h6zc8gouesc057 | C14: cmjbk9st500hnzc8gzhdq6c5b | D14: hybrid_v3_5 | E14: Scenario_4 | F14: 2 | G14: truth_and_fact | H14: 0.1 | I14: 0.26187478 | J14: 0.29990409 | K14: =J14-I14 -> 0.038029302 | L14: 0.73955855
... A147: 2fdfa08d-753c-4370-9365-b2befef3c73e | B147: cmjblcc8400ulzc8gdbvejap6 | C147: cmjblcsde00v2zc8gglyjcggd | D147: hybrid_v3_5 | E147: Scenario_4 | F147: 48 | G147: truth_and_fact | H147: 0.1433 | I147: 0.24582913 | J147: 0.2885993 | K147: =J147-I147 -> 0.042770175 | L147: 0.69566442

Sheet Notes
A1: p calculation
A3: 1. count | B3: =scen4_hybrid!P2 -> 145
A4: 2. t statistic | B4: =B10*SQRT((B3-2)/(1-B10^2)) -> 0.495421
A5: 3. p | B5: =_xlfn.T.DIST.2T(ABS(B4),B3-2) -> 0.62106343
A9: count | B9: correlation weights / activation delta
A10: =B3 -> 145 | B10: =scen4_hybrid!R2 -> 0.041393677

Sheet actdel_prompt_response
B2: Prompt-response
A3: Turn | B3: hybrid
A4: 1 | B4: 0.79629877
A5: 2 | B5: 0.73955855
A6: 3 | B6: 0.7395449
A7: 4 | B7: 0.74302939
A8: 5 | B8: 0.72550205
A9: 6 | B9: 0.74855685
A10: 7 | B10: 0.73413847
A11: 8 | B11: 0.66870134
A12: 9 | B12: 0.78688004
A13: 10 | B13: 0.80994866
A14: 11 | B14: 0.69017189
A15: 12 | B15: 0.74912535
... A28: 25 | B28: 0.69566442

Sheet inter_system_stats
B2: prompt_to_response
A3: Turn | B3: hybrid | C3: control | E3: std.ac15 | F3: std. Control | G3: F. test | H3: T. Test equal variances | I3: T.Test unequal | J3: Mean difference | K3: Average Scenario | L3: Average control
A4: 1 | B4: 0.79629877 | C4: 0.82062035 | E4: =_xlfn.STDEV.S(B4:B28) -> 0.064494717 | F4: =_xlfn.STDEV.S(C4:C28) -> 0.083848556 | G4: =_xlfn.F.TEST(B4:B28,C4:C28) -> 0.20579936 | H4: =_xlfn.T.TEST(B4:B28, C4:C28, 2,2) -> 0.00018662898 | I4: =_xlfn.T.TEST(B4:B28,C4:C28, 2,3) -> 0.00020003225 | J4: =AVERAGE(B4:B28)-AVERAGE(C4:C28) -> 0.085663653 | K4: =AVERAGE(B4:B28) -> 0.72773559 | L4: =AVERAGE(C4:C28) -> 0.64207194
A5: 2 | B5: 0.73955855 | C5: 0.67785078
A6: 3 | B6: 0.7395449 | C6: 0.67795229
A7: 4 | B7: 0.74302939 | C7: 0.66135317
A8: 5 | B8: 0.72550205 | C8: 0.59399104
A9: 6 | B9: 0.74855685 | C9: 0.6086453
A10: 7 | B10: 0.73413847 | C10: 0.57481882
A11: 8 | B11: 0.66870134 | C11: 0.52225005
A12: 9 | B12: 0.78688004 | C12: 0.76343563
A13: 10 | B13: 0.80994866 | C13: 0.6903629
A14: 11 | B14: 0.69017189 | C14: 0.66961631
A15: 12 | B15: 0.74912535 | C15: 0.75051558
A16: 13 | B16: 0.67748078 | C16: 0.70922297
... A28: 25 | B28: 0.69566442 | C28: 0.62965658
A32: General
A34: Turn | B34: ac15p | C34: hybrid | E34: Paired t-test
A35: 1 | B35: 0.78294334 | C35: 0.79629877 | E35: Alpha | F35: 0.05
A36: 2 | B36: 0.72616788 | C36: 0.73955855 | E36: Hypothesized Mean Difference | F36: 0
A37: 3 | B37: 0.76238484 | C37: 0.7395449 | F37: Variable 1 | G37: Variable 2
A38: 4 | B38: 0.70329396 | C38: 0.74302939 | E38: Mean | F38: =AVERAGE(inter_system_stats!$B$34:$B$59) -> 0.73449037 | G38: =AVERAGE(inter_system_stats!$C$34:$C$59) -> 0.72773559
A39: 5 | B39: 0.7296907 | C39: 0.72550205 | E39: Variance | F39: =VAR(inter_system_stats!$B$34:$B$59) -> 0.0034118332 | G39: =VAR(inter_system_stats!$C$34:$C$59) -> 0.0041595685
A40: 6 | B40: 0.75207613 | C40: 0.74855685 | E40: Observations | F40: =COUNT(inter_system_stats!$B$34:$B$59) -> 25 | G40: =COUNT(inter_system_stats!$C$34:$C$59) -> 25
A41: 7 | B41: 0.81177256 | C41: 0.73413847 | E41: Pearson Correlation | F41: =CORREL(inter_system_stats!$B$34:$B$59,inter_system_stats!$C$34:$C$59) -> 0.74079291
A42: 8 | B42: 0.71832924 | C42: 0.66870134 | E42: Observed Mean Difference | F42: {=AVERAGE(IF(ISODD(IF(ISNUMBER(inter_system_stats!$B$34:$B$59), 1, 0) * IF(ISNUMBER(inter_system_stats!$C$34:$C$59), 1, 0)), inter_system_stats!$B$34:$B$59 - inter_system_stats!$C$34:$C$59, "NA"))} -> 0.0067547795
A43: 9 | B43: 0.75089851 | C43: 0.78688004 | E43: Variance of the Differences | F43: {=VAR(IF(ISODD(IF(ISNUMBER(inter_system_stats!$B$34:$B$59), 1, 0) * IF(ISNUMBER(inter_system_stats!$C$34:$C$59), 1, 0)), inter_system_stats!$B$34:$B$59 - inter_system_stats!$C$34:$C$59, "NA"))} -> 0.0019899799
A44: 10 | B44: 0.71233537 | C44: 0.80994866 | E44: df | F44: {=SUM(IF(ISNUMBER(inter_system_stats!$B$34:$B$59), 1, 0) * IF(ISNUMBER(inter_system_stats!$C$34:$C$59), 1, 0)) - 1} -> 24
A45: 11 | B45: 0.77617003 | C45: 0.69017189 | E45: t Stat | F45: =(inter_system_stats!$F$42 - inter_system_stats!$F$36) / (inter_system_stats!$F$43 / ( inter_system_stats!$F$44 + 1)) ^ 0.5 -> 0.75710626
A46: 12 | B46: 0.77041801 | C46: 0.74912535 | E46: P (T<=t) one-tail | F46: =TDIST(ABS(inter_system_stats!$F$45), inter_system_stats!$F$44, 1) -> 0.22817768
A47: 13 | B47: 0.68718184 | C47: 0.67748078 | E47: t Critical one-tail | F47: =TINV(2*inter_system_stats!$F$35, inter_system_stats!$F$44) -> 1.7108821
A48: 14 | B48: 0.81381365 | C48: 0.79291905 | E48: P (T<=t) two-tail | F48: =TDIST(ABS(inter_system_stats!$F$45), inter_system_stats!$F$44, 2) -> 0.45635536
A49: 15 | B49: 0.78154173 | C49: 0.80088441 | E49: t Critical two-tail | F49: =TINV(inter_system_stats!$F$35, inter_system_stats!$F$44) -> 2.0638986
A50: 16 | B50: 0.67997326 | C50: 0.64539917
A51: 17 | B51: 0.80453974 | C51: 0.77301622
A52: 18 | B52: 0.57578838 | C52: 0.58304544
A53: 19 | B53: 0.80829344 | C53: 0.7954812
A54: 20 | B54: 0.6310987 | C54: 0.65250777
A55: 21 | B55: 0.72352146 | C55: 0.6134279
A56: 22 | B56: 0.66763609 | C56: 0.65699942
...
