Workbook

Sheet sims_per_turn
B1: General
A2: turns | B2: ac15 | C2: hybrid | D2: ac15p | E2: hybsem
A3: 1 | B3: 0.82022841 | C3: 0.82558738 | D3: 0.84283713 | E3: 0.82646574
A4: 2 | B4: 0.76459215 | C4: 0.7843254 | D4: 0.75574435 | E4: 0.76029579
A5: 3 | B5: 0.72301136 | C5: 0.74701543 | D5: 0.75246139 | E5: 0.7455131
A6: 4 | B6: 0.75642044 | C6: 0.74257299 | D6: 0.75523994 | E6: 0.74023798
A7: 5 | B7: 0.62046218 | C7: 0.6382916 | D7: 0.68196907 | E7: 0.70141781
A8: 6 | B8: 0.798549 | C8: 0.77002186 | D8: 0.80509458 | E8: 0.76441227
A9: 7 | B9: 0.75460376 | C9: 0.77670818 | D9: 0.7314491 | E9: 0.70462919
A10: 8 | B10: 0.78612837 | C10: 0.76689514 | D10: 0.7986994 | E10: 0.77201186
A11: 9 | B11: 0.75325744 | C11: 0.72686528 | D11: 0.75118107 | E11: 0.72188408
A12: 10 | B12: 0.80784383 | C12: 0.76670386 | D12: 0.78031701 | E12: 0.80179909
A13: 11 | B13: 0.77810084 | C13: 0.82651214 | D13: 0.78896492 | E13: 0.82639187
A14: 12 | B14: 0.76245246 | C14: 0.76273614 | D14: 0.74442966 | E14: 0.74557662
... A27: 25 | B27: 0.73057748 | C27: 0.72723041 | D27: 0.71511197 | E27: 0.72503242
B30: per turn, prompt-response deltas
A32: turns | B32: hybsem | C32: hybrid | D32: Delta=hybrid-hybsem | E32: ABS delta | F32: Mean difference | G32: std delta | I32: Paired t-test | M32: turns | N32: ABS delta
A33: 1 | B33: 0.82646574 | C33: 0.82558738 | D33: =C33-B33 -> -0.0008783599 | E33: =ABS(D33) -> 0.0008783599 | F33: =AVERAGE(D33:D57) -> 0.0033778274 | G33: =_xlfn.STDEV.S(D33:D57) -> 0.042557033 | I33: Alpha | J33: 0.05 | M33: 22 | N33: 0.10403392
A34: 2 | B34: 0.76029579 | C34: 0.7843254 | D34: =C34-B34 -> 0.02402961 | E34: =ABS(D34) -> 0.02402961 | I34: Hypothesized Mean Difference | J34: 0 | M34: 21 | N34: 0.08360635
A35: 3 | B35: 0.7455131 | C35: 0.74701543 | D35: =C35-B35 -> 0.0015023292 | E35: =ABS(D35) -> 0.0015023292 | J35: Variable 1 | K35: Variable 2 | M35: 23 | N35: 0.077076384
A36: 4 | B36: 0.74023798 | C36: 0.74257299 | D36: =C36-B36 -> 0.0023350099 | E36: =ABS(D36) -> 0.0023350099 | I36: Mean | J36: =AVERAGE(sims_per_turn!$B$32:$B$57) -> 0.74906635 | K36: =AVERAGE(sims_per_turn!$C$32:$C$57) -> 0.75244418 | M36: 7 | N36: 0.072078989
A37: 5 | B37: 0.70141781 | C37: 0.6382916 | D37: =C37-B37 -> -0.063126203 | E37: =ABS(D37) -> 0.063126203 | I37: Variance | J37: =VAR(sims_per_turn!$B$32:$B$57) -> 0.0020364168 | K37: =VAR(sims_per_turn!$C$32:$C$57) -> 0.0023181036 | M37: 5 | N37: 0.063126203
A38: 6 | B38: 0.76441227 | C38: 0.77002186 | D38: =C38-B38 -> 0.0056095917 | E38: =ABS(D38) -> 0.0056095917 | I38: Observations | J38: =COUNT(sims_per_turn!$B$32:$B$57) -> 25 | K38: =COUNT(sims_per_turn!$C$32:$C$57) -> 25 | M38: 20 | N38: 0.044752891
A39: 7 | B39: 0.70462919 | C39: 0.77670818 | D39: =C39-B39 -> 0.072078989 | E39: =ABS(D39) -> 0.072078989 | I39: Pearson Correlation | J39: =CORREL(sims_per_turn!$B$32:$B$57,sims_per_turn!$C$32:$C$57) -> 0.58531308 | M39: 18 | N39: 0.042564127
A40: 8 | B40: 0.77201186 | C40: 0.76689514 | D40: =C40-B40 -> -0.0051167269 | E40: =ABS(D40) -> 0.0051167269 | I40: Observed Mean Difference | J40: {=AVERAGE(IF(ISODD(IF(ISNUMBER(sims_per_turn!$B$32:$B$57), 1, 0) * IF(ISNUMBER(sims_per_turn!$C$32:$C$57), 1, 0)), sims_per_turn!$B$32:$B$57 - sims_per_turn!$C$32:$C$57, "NA"))} -> -0.0033778274 | M40: 10 | N40: 0.035095234
A41: 9 | B41: 0.72188408 | C41: 0.72686528 | D41: =C41-B41 -> 0.0049812049 | E41: =ABS(D41) -> 0.0049812049 | I41: Variance of the Differences | J41: {=VAR(IF(ISODD(IF(ISNUMBER(sims_per_turn!$B$32:$B$57), 1, 0) * IF(ISNUMBER(sims_per_turn!$C$32:$C$57), 1, 0)), sims_per_turn!$B$32:$B$57 - sims_per_turn!$C$32:$C$57, "NA"))} -> 0.001811101 | M41: 15 | N41: 0.033187541
A42: 10 | B42: 0.80179909 | C42: 0.76670386 | D42: =C42-B42 -> -0.035095234 | E42: =ABS(D42) -> 0.035095234 | I42: df | J42: {=SUM(IF(ISNUMBER(sims_per_turn!$B$32:$B$57), 1, 0) * IF(ISNUMBER(sims_per_turn!$C$32:$C$57), 1, 0)) - 1} -> 24 | M42: 16 | N42: 0.032250515
A43: 11 | B43: 0.82639187 | C43: 0.82651214 | D43: =C43-B43 -> 0.00012027252 | E43: =ABS(D43) -> 0.00012027252 | I43: t Stat | J43: =(sims_per_turn!$J$40 - sims_per_turn!$J$34) / (sims_per_turn!$J$41 / ( sims_per_turn!$J$42 + 1)) ^ 0.5 -> -0.3968589 | M43: 17 | N43: 0.029877386
A44: 12 | B44: 0.74557662 | C44: 0.76273614 | D44: =C44-B44 -> 0.017159517 | E44: =ABS(D44) -> 0.017159517 | I44: P (T<=t) one-tail | J44: =TDIST(ABS(sims_per_turn!$J$43), sims_per_turn!$J$42, 1) -> 0.34748928 | M44: 13 | N44: 0.029144688
A45: 13 | B45: 0.73930479 | C45: 0.7101601 | D45: =C45-B45 -> -0.029144688 | E45: =ABS(D45) -> 0.029144688 | I45: t Critical one-tail | J45: =TINV(2*sims_per_turn!$J$33, sims_per_turn!$J$42) -> 1.7108821 | M45: 2 | N45: 0.02402961
A46: 14 | B46: 0.71677589 | C46: 0.73437638 | D46: =C46-B46 -> 0.017600494 | E46: =ABS(D46) -> 0.017600494 | I46: P (T<=t) two-tail | J46: =TDIST(ABS(sims_per_turn!$J$43), sims_per_turn!$J$42, 2) -> 0.69497856 | M46: 19 | N46: 0.021438931
A47: 15 | B47: 0.7233547 | C47: 0.75654224 | D47: =C47-B47 -> 0.033187541 | E47: =ABS(D47) -> 0.033187541 | I47: t Critical two-tail | J47: =TINV(sims_per_turn!$J$33, sims_per_turn!$J$42) -> 2.0638986 | M47: 14 | N47: 0.017600494
A48: 16 | B48: 0.7414815 | C48: 0.77373202 | D48: =C48-B48 -> 0.032250515 | E48: =ABS(D48) -> 0.032250515 | M48: 12 | N48: 0.017159517
A49: 17 | B49: 0.78281323 | C49: 0.81269061 | D49: =C49-B49 -> 0.029877386 | E49: =ABS(D49) -> 0.029877386 | M49: 24 | N49: 0.012275094
A50: 18 | B50: 0.68392473 | C50: 0.72648885 | D50: =C50-B50 -> 0.042564127 | E50: =ABS(D50) -> 0.042564127 | M50: 6 | N50: 0.0056095917
A51: 19 | B51: 0.74186163 | C51: 0.76330056 | D51: =C51-B51 -> 0.021438931 | E51: =ABS(D51) -> 0.021438931 | M51: 8 | N51: 0.0051167269
A52: 20 | B52: 0.86129103 | C52: 0.81653813 | D52: =C52-B52 -> -0.044752891 | E52: =ABS(D52) -> 0.044752891 | M52: 9 | N52: 0.0049812049
A53: 21 | B53: 0.72699778 | C53: 0.64339143 | D53: =C53-B53 -> -0.08360635 | E53: =ABS(D53) -> 0.08360635 | M53: 4 | N53: 0.0023350099
A54: 22 | B54: 0.66522196 | C54: 0.76925587 | D54: =C54-B54 -> 0.10403392 | E54: =ABS(D54) -> 0.10403392 | M54: 25 | N54: 0.0021979944
A55: 23 | B55: 0.76174693 | C55: 0.68467054 | D55: =C55-B55 -> -0.077076384 | E55: =ABS(D55) -> 0.077076384 | M55: 3 | N55: 0.0015023292
...

Sheet pivot-table sims per turn
A3: turns | B3: comparison | C3: abs delta | E3: Count - abs delta | F3: comparison
A4: 22 | B4: Hybesm-hybrid | C4: 0.10403392 | E4: turns | F4: ac15-ac15p | G4: Hybesm-hybrid | H4: Hybrid-ac15 | I4: Hybrid-ac15p | J4: Hybsem-ac15 | K4: Hybsem-ac15p | L4: Total Result
A5: 21 | B5: Hybrid-ac15 | C5: 0.091267052 | E5: 5 | F5: 1 | G5: 1 | J5: 1 | L5: 3
A6: 22 | B6: Hybrid-ac15p | C6: 0.084257278 | E6: 7 | G6: 1 | L6: 1
A7: 21 | B7: Hybesm-hybrid | C7: 0.08360635 | E7: 13 | I7: 1 | L7: 1
A8: 5 | B8: Hybsem-ac15 | C8: 0.080955631 | E8: 17 | H8: 1 | L8: 1
A9: 23 | B9: Hybesm-hybrid | C9: 0.077076384 | E9: 21 | G9: 1 | H9: 1 | I9: 1 | L9: 3
A10: 7 | B10: Hybesm-hybrid | C10: 0.072078989 | E10: 22 | G10: 1 | H10: 1 | I10: 1 | L10: 3
A11: 17 | B11: Hybrid-ac15 | C11: 0.068022618 | E11: 23 | G11: 1 | K11: 1 | L11: 2
A12: 22 | B12: Hybrid-ac15 | C12: 0.067050276 | E12: 24 | I12: 1 | K12: 1 | L12: 2
A13: 23 | B13: Hybsem-ac15p | C13: 0.064935049 | E13: Total Result | F13: 1 | G13: 5 | H13: 3 | I13: 4 | J13: 1 | K13: 2 | L13: 16
A14: 24 | B14: Hybsem-ac15p | C14: 0.063619817
A15: 5 | B15: Hybesm-hybrid | C15: 0.063126203
A16: 5 | B16: ac15-ac15p | C16: 0.061506891
A17: 21 | B17: Hybrid-ac15p | C17: 0.060633403
A18: 13 | B18: Hybrid-ac15p | C18: 0.054187836
A19: 24 | B19: Hybrid-ac15p | C19: 0.051344723

Sheet anchors_raw_information
B1: seq | C1: anchorName | D1: weight | E1: projectName
B2: 1 | C2: practicality_and_feasibility | D2: 0.2058 | E2: test_ac15 | G2: Count - anchorName | H2: projectName
B3: 1 | C3: temporal_dynamics | D3: 0.1919 | E3: test_ac15 | G3: seq | H3: ac15-plain | I3: hybrid_v3_5 | J3: test_ac15 | K3: hysem | L3: Total Result | M3: Total Result
B4: 1 | C4: mathematics_computer_science_engineering | D4: 0.182 | E4: test_ac15 | G4: 1 | H4: 6 | I4: 6 | J4: 6 | K4: 6 | L4: 24 | M4: 24
B5: 1 | C5: affective_interface | D5: 0.1602 | E5: test_ac15 | G5: 3 | H5: 6 | I5: 6 | J5: 6 | K5: 6 | L5: 24 | M5: 24
B6: 1 | C6: imagination_and_possibility | D6: 0.1601 | E6: test_ac15 | G6: 5 | H6: 6 | I6: 6 | J6: 6 | K6: 6 | L6: 24 | M6: 24
B7: 1 | C7: truth_and_fact | D7: 0.1 | E7: test_ac15 | G7: 7 | H7: 6 | I7: 6 | J7: 6 | K7: 6 | L7: 24 | M7: 24
B8: 3 | C8: practicality_and_feasibility | D8: 0.1939 | E8: test_ac15 | G8: 9 | H8: 6 | I8: 6 | J8: 6 | K8: 6 | L8: 24 | M8: 24
B9: 3 | C9: temporal_dynamics | D9: 0.1889 | E9: test_ac15 | G9: 11 | H9: 6 | I9: 6 | J9: 4 | K9: 6 | L9: 22 | M9: 22
B10: 3 | C10: mathematics_computer_science_engineering | D10: 0.1848 | E10: test_ac15 | G10: 13 | H10: 6 | I10: 5 | J10: 6 | K10: 6 | L10: 23 | M10: 23
B11: 3 | C11: sovereignty | D11: 0.1733 | E11: test_ac15 | G11: 15 | H11: 6 | I11: 6 | J11: 6 | K11: 6 | L11: 24 | M11: 24
B12: 3 | C12: affective_interface | D12: 0.1591 | E12: test_ac15 | G12: 17 | H12: 6 | I12: 6 | J12: 6 | K12: 6 | L12: 24 | M12: 24
B13: 3 | C13: truth_and_fact | D13: 0.1 | E13: test_ac15 | G13: 19 | H13: 6 | I13: 6 | J13: 6 | K13: 6 | L13: 24 | M13: 24
B14: 5 | C14: practicality_and_feasibility | D14: 0.1939 | E14: test_ac15 | G14: 21 | H14: 6 | I14: 5 | J14: 6 | K14: 4 | L14: 21 | M14: 21
B15: 5 | C15: temporal_dynamics | D15: 0.1901 | E15: test_ac15 | G15: 23 | H15: 5 | I15: 4 | J15: 5 | K15: 4 | L15: 18 | M15: 18
... B28: 9 | C28: sovereignty | D28: 0.1757 | E28: test_ac15 | G28: 49 | H28: 6 | I28: 6 | J28: 6 | K28: 6 | L28: 24 | M28: 24
B29: 9 | C29: affective_interface | D29: 0.1723 | E29: test_ac15 | G29: Total Result | H29: 142 | I29: 131 | J29: 139 | K29: 139 | L29: 551 | M29: 551
B30: 9 | C30: mathematics_computer_science_engineering | D30: 0.1634 | E30: test_ac15
B31: 9 | C31: truth_and_fact | D31: 0.1 | E31: test_ac15
B32: 11 | C32: practicality_and_feasibility | D32: 0.3091 | E32: test_ac15
B33: 11 | C33: temporal_dynamics | D33: 0.3023 | E33: test_ac15 | I33: projectName
B34: 11 | C34: mathematics_computer_science_engineering | D34: 0.2886 | E34: test_ac15 | G34: anchorName | H34: Data | I34: ac15-plain | J34: hybrid_v3_5 | K34: hysem | L34: test_ac15 | M34: Total Result
B35: 11 | C35: truth_and_fact | D35: 0.1 | E35: test_ac15 | G35: affective_interface | H35: Count - weight | I35: 20 | J35: 18 | K35: 24 | L35: 17 | M35: 79
B36: 13 | C36: practicality_and_feasibility | D36: 0.2042 | E36: test_ac15 | H36: Average - weight* | I36: 0.175175 | J36: 0.18772222 | K36: 0.2031875 | L36: 0.17807059 | M36: 0.18716709
B37: 13 | C37: mathematics_computer_science_engineering | D37: 0.1944 | E37: test_ac15 | G37: context_dependent_expression | H37: Count - weight | I37: 1 | J37: 1 | L37: 2 | M37: 4
B38: 13 | C38: temporal_dynamics | D38: 0.1911 | E38: test_ac15 | H38: Average - weight* | I38: 0.1711 | J38: 0.2002 | L38: 0.16385 | M38: 0.17475
B39: 13 | C39: affective_interface | D39: 0.1553 | E39: test_ac15 | G39: freedom_and_limitations | H39: Count - weight | J39: 1 | K39: 2 | M39: 3
B40: 13 | C40: sovereignty | D40: 0.1549 | E40: test_ac15 | H40: Average - weight* | J40: 0.1772 | K40: 0.15575 | M40: 0.1629
B41: 13 | C41: truth_and_fact | D41: 0.1 | E41: test_ac15 | G41: imagination_and_possibility | H41: Count - weight | I41: 6 | J41: 18 | K41: 19 | L41: 10 | M41: 53
B42: 15 | C42: affective_interface | D42: 0.186 | E42: test_ac15 | H42: Average - weight* | I42: 0.15935 | J42: 0.17331667 | K42: 0.16609474 | L42: 0.16556 | M42: 0.16768302
B43: 15 | C43: practicality_and_feasibility | D43: 0.184 | E43: test_ac15 | G43: mathematics_computer_science_engineering | H43: Count - weight | I43: 21 | J43: 16 | K43: 16 | L43: 24 | M43: 77
B44: 15 | C44: temporal_dynamics | D44: 0.1797 | E44: test_ac15 | H44: Average - weight* | I44: 0.17064762 | J44: 0.16456875 | K44: 0.1561375 | L44: 0.197875 | M44: 0.17485584
B45: 15 | C45: mathematics_computer_science_engineering | D45: 0.1787 | E45: test_ac15 | G45: metaphorical_scaffolding | H45: Count - weight | I45: 1 | J45: 1 | K45: 1 | L45: 2 | M45: 5
B46: 15 | C46: sovereignty | D46: 0.1716 | E46: test_ac15 | H46: Average - weight* | I46: 0.1616 | J46: 0.1628 | K46: 0.1625 | L46: 0.1531 | M46: 0.15862
B47: 15 | C47: truth_and_fact | D47: 0.1 | E47: test_ac15 | G47: practicality_and_feasibility | H47: Count - weight | I47: 25 | J47: 25 | K47: 25 | L47: 25 | M47: 100
B48: 17 | C48: temporal_dynamics | D48: 0.2097 | E48: test_ac15 | H48: Average - weight* | I48: 0.23228 | J48: 0.264 | K48: 0.24388 | L48: 0.219052 | M48: 0.239803
B49: 17 | C49: practicality_and_feasibility | D49: 0.1892 | E49: test_ac15 | G49: science | H49: Count - weight | I49: 1 | K49: 1 | L49: 3 | M49: 5
B50: 17 | C50: mathematics_computer_science_engineering | D50: 0.1689 | E50: test_ac15 | H50: Average - weight* | I50: 0.1614 | K50: 0.1484 | L50: 0.16423333 | M50: 0.1605
B51: 17 | C51: affective_interface | D51: 0.1672 | E51: test_ac15 | G51: sovereignty | H51: Count - weight | I51: 18 | J51: 1 | K51: 2 | L51: 6 | M51: 27
B52: 17 | C52: imagination_and_possibility | D52: 0.1649 | E52: test_ac15 | H52: Average - weight* | I52: 0.1731 | J52: 0.1529 | K52: 0.1544 | L52: 0.16506667 | M52: 0.16918148
...
