Workbook

Sheet sims_per_turn_scen6
A2: Turn | B2: ac15p | C2: hybrid | D2: hybsem | E2: ac15 | F2: control | I2: ANOVA - Single Factor
A3: 1 | B3: 0.79000575 | C3: 0.8189473 | D3: 0.78516876 | E3: 0.82327274 | F3: 0.75451957 | I3: Alpha | J3: 0.05
A4: 2 | B4: 0.6817351 | C4: 0.72667505 | D4: 0.70344439 | E4: 0.64219932 | F4: 0.58315782
A5: 3 | B5: 0.73659154 | C5: 0.75382376 | D5: 0.73539986 | E5: 0.72456003 | F5: 0.61890492 | I5: Groups | J5: Count | K5: Sum | L5: Mean | M5: Variance
A6: 4 | B6: 0.65821229 | C6: 0.69468916 | D6: 0.69729745 | E6: 0.70833619 | F6: 0.74737712 | I6: Column 1 | J6: =COUNT(sims_per_turn_scen6!$B$2:$B$27) -> 25 | K6: =SUM(sims_per_turn_scen6!$B$2:$B$27) -> 18.201412 | L6: =AVERAGE(sims_per_turn_scen6!$B$2:$B$27) -> 0.72805647 | M6: =VAR(sims_per_turn_scen6!$B$2:$B$27) -> 0.0037347451
A7: 5 | B7: 0.74318489 | C7: 0.75031898 | D7: 0.71322313 | E7: 0.69762049 | F7: 0.54898023 | I7: Column 2 | J7: =COUNT(sims_per_turn_scen6!$C$2:$C$27) -> 25 | K7: =SUM(sims_per_turn_scen6!$C$2:$C$27) -> 18.400771 | L7: =AVERAGE(sims_per_turn_scen6!$C$2:$C$27) -> 0.73603082 | M7: =VAR(sims_per_turn_scen6!$C$2:$C$27) -> 0.0029897442
A8: 6 | B8: 0.7383633 | C8: 0.79289751 | D8: 0.76734743 | E8: 0.75727629 | F8: 0.63269023 | I8: Column 3 | J8: =COUNT(sims_per_turn_scen6!$D$2:$D$27) -> 25 | K8: =SUM(sims_per_turn_scen6!$D$2:$D$27) -> 18.007959 | L8: =AVERAGE(sims_per_turn_scen6!$D$2:$D$27) -> 0.72031836 | M8: =VAR(sims_per_turn_scen6!$D$2:$D$27) -> 0.0032534829
A9: 7 | B9: 0.80270938 | C9: 0.74071706 | D9: 0.74121447 | E9: 0.7584497 | F9: 0.70178677 | I9: Column 4 | J9: =COUNT(sims_per_turn_scen6!$E$2:$E$27) -> 25 | K9: =SUM(sims_per_turn_scen6!$E$2:$E$27) -> 18.12056 | L9: =AVERAGE(sims_per_turn_scen6!$E$2:$E$27) -> 0.72482238 | M9: =VAR(sims_per_turn_scen6!$E$2:$E$27) -> 0.0027128713
A10: 8 | B10: 0.76713782 | C10: 0.70151887 | D10: 0.7026918 | E10: 0.70527533 | F10: 0.58456232 | I10: Column 5 | J10: =COUNT(sims_per_turn_scen6!$F$2:$F$27) -> 25 | K10: =SUM(sims_per_turn_scen6!$F$2:$F$27) -> 15.876389 | L10: =AVERAGE(sims_per_turn_scen6!$F$2:$F$27) -> 0.63505555 | M10: =VAR(sims_per_turn_scen6!$F$2:$F$27) -> 0.0049827267
A11: 9 | B11: 0.65520384 | C11: 0.67940884 | D11: 0.67641093 | E11: 0.63811046 | F11: 0.63553024
A12: 10 | B12: 0.70090518 | C12: 0.69382834 | D12: 0.71515554 | E12: 0.71891692 | F12: 0.69186078 | I12: Source of Variation | J12: SS | K12: df | L12: MS | M12: F | N12: P-value | O12: F critical
A13: 11 | B13: 0.71962924 | C13: 0.71401509 | D13: 0.72491699 | E13: 0.76091064 | F13: 0.74687441 | I13: Between Groups | J13: =SUMPRODUCT(sims_per_turn_scen6!$K$6:$K$10,sims_per_turn_scen6!$L$6:$L$10)-SUM(sims_per_turn_scen6!$K$6:$K$10)^2/SUM(sims_per_turn_scen6!$J$6:$J$10) -> 0.17349867 | K13: =COUNT(sims_per_turn_scen6!$K$6:$K$10)-1 -> 4 | L13: =sims_per_turn_scen6!$J$13 / sims_per_turn_scen6!$K$13 -> 0.043374668 | M13: =sims_per_turn_scen6!$L$13 / sims_per_turn_scen6!$L$14 -> 12.271054 | N13: =FDIST(sims_per_turn_scen6!$M$13, sims_per_turn_scen6!$K$13, sims_per_turn_scen6!$K$14) -> 2.1375935e-08 | O13: =FINV(sims_per_turn_scen6!$J$3, sims_per_turn_scen6!$K$13, sims_per_turn_scen6!$K$14) -> 2.4472365
A14: 12 | B14: 0.83162141 | C14: 0.82935334 | D14: 0.84477335 | E14: 0.8127806 | F14: 0.64610334 | I14: Within Groups | J14: =SUM(DEVSQ(sims_per_turn_scen6!$B$2:$B$27),DEVSQ(sims_per_turn_scen6!$C$2:$C$27),DEVSQ(sims_per_turn_scen6!$D$2:$D$27),DEVSQ(sims_per_turn_scen6!$E$2:$E$27),DEVSQ(sims_per_turn_scen6!$F$2:$F$27)) -> 0.42416568 | K14: =SUM(sims_per_turn_scen6!$J$6:$J$10)-COUNT(sims_per_turn_scen6!$J$6:$J$10) -> 120 | L14: =sims_per_turn_scen6!$J$14 / sims_per_turn_scen6!$K$14 -> 0.003534714
A15: 13 | B15: 0.7095195 | C15: 0.74133511 | D15: 0.67077129 | E15: 0.72140757 | F15: 0.71426745 | I15: Total | J15: =DEVSQ(sims_per_turn_scen6!$B$2:$B$27,sims_per_turn_scen6!$C$2:$C$27,sims_per_turn_scen6!$D$2:$D$27,sims_per_turn_scen6!$E$2:$E$27,sims_per_turn_scen6!$F$2:$F$27) -> 0.59766436 | K15: =SUM(sims_per_turn_scen6!$J$6:$J$10) - 1 -> 124
A16: 14 | B16: 0.75258804 | C16: 0.77755869 | D16: 0.74919935 | E16: 0.76471606 | F16: 0.64598849
A17: 15 | B17: 0.74255587 | C17: 0.76965524 | D17: 0.7103344 | E17: 0.71175796 | F17: 0.55912558
A18: 16 | B18: 0.62660019 | C18: 0.69268523 | D18: 0.65823366 | E18: 0.63640913 | F18: 0.66444414
A19: 17 | B19: 0.81814248 | C19: 0.80578727 | D19: 0.82153301 | E19: 0.76068461 | F19: 0.68292872
A20: 18 | B20: 0.64796342 | C20: 0.63109379 | D20: 0.65400156 | E20: 0.68944451 | F20: 0.60902978
A21: 19 | B21: 0.64384174 | C21: 0.69026916 | D21: 0.59076887 | E21: 0.69990755 | F21: 0.62513635
A22: 20 | B22: 0.65454773 | C22: 0.69704907 | D22: 0.71658496 | E22: 0.72147067 | F22: 0.62889699
A23: 21 | B23: 0.73727979 | C23: 0.69517695 | D23: 0.66973956 | E23: 0.69401911 | F23: 0.49049501
A24: 22 | B24: 0.741791 | C24: 0.7579538 | D24: 0.73555551 | E24: 0.75579758 | F24: 0.55121839
A25: 23 | B25: 0.72032451 | C25: 0.66315081 | D25: 0.70593758 | E25: 0.65088531 | F25: 0.64465959
A26: 24 | B26: 0.85301227 | C26: 0.84656935 | D26: 0.82105372 | E26: 0.81031859 | F26: 0.65498089
A27: 25 | B27: 0.72794547 | C27: 0.7362928 | D27: 0.69720151 | E27: 0.75603222 | F27: 0.51286959
B44: per turn, prompt-response deltas
A46: Turn | B46: hybsem | C46: hybrid | D46: Delta=hybrid-hybsem | E46: ABS delta | F46: Mean difference | G46: std delta | I46: Paired t-test
A47: 1 | B47: 0.78516876 | C47: 0.8189473 | D47: =C47-B47 -> 0.033778537 | E47: =ABS(D47) -> 0.033778537 | F47: =AVERAGE(D47:D71) -> 0.01571246 | G47: =_xlfn.STDEV.S(D47:D71) -> 0.032537491 | I47: Alpha | J47: 0.05
A48: 2 | B48: 0.70344439 | C48: 0.72667505 | D48: =C48-B48 -> 0.023230667 | E48: =ABS(D48) -> 0.023230667 | I48: Hypothesized Mean Difference | J48: 0
A49: 3 | B49: 0.73539986 | C49: 0.75382376 | D49: =C49-B49 -> 0.018423907 | E49: =ABS(D49) -> 0.018423907 | J49: Variable 1 | K49: Variable 2
A50: 4 | B50: 0.69729745 | C50: 0.69468916 | D50: =C50-B50 -> -0.0026082933 | E50: =ABS(D50) -> 0.0026082933 | I50: Mean | J50: =AVERAGE(sims_per_turn_scen6!$B$46:$B$71) -> 0.72031836 | K50: =AVERAGE(sims_per_turn_scen6!$C$46:$C$71) -> 0.73603082
A51: 5 | B51: 0.71322313 | C51: 0.75031898 | D51: =C51-B51 -> 0.037095847 | E51: =ABS(D51) -> 0.037095847 | I51: Variance | J51: =VAR(sims_per_turn_scen6!$B$46:$B$71) -> 0.0032534829 | K51: =VAR(sims_per_turn_scen6!$C$46:$C$71) -> 0.0029897442
A52: 6 | B52: 0.76734743 | C52: 0.79289751 | D52: =C52-B52 -> 0.025550077 | E52: =ABS(D52) -> 0.025550077 | I52: Observations | J52: =COUNT(sims_per_turn_scen6!$B$46:$B$71) -> 25 | K52: =COUNT(sims_per_turn_scen6!$C$46:$C$71) -> 25
A53: 7 | B53: 0.74121447 | C53: 0.74071706 | D53: =C53-B53 -> -0.00049741077 | E53: =ABS(D53) -> 0.00049741077 | I53: Pearson Correlation | J53: =CORREL(sims_per_turn_scen6!$B$46:$B$71,sims_per_turn_scen6!$C$46:$C$71) -> 0.83116807
A54: 8 | B54: 0.7026918 | C54: 0.70151887 | D54: =C54-B54 -> -0.0011729386 | E54: =ABS(D54) -> 0.0011729386 | I54: Observed Mean Difference | J54: {=AVERAGE(IF(ISODD(IF(ISNUMBER(sims_per_turn_scen6!$B$46:$B$71), 1, 0) * IF(ISNUMBER(sims_per_turn_scen6!$C$46:$C$71), 1, 0)), sims_per_turn_scen6!$B$46:$B$71 - sims_per_turn_scen6!$C$46:$C$71, "NA"))} -> -0.01571246
A55: 9 | B55: 0.67641093 | C55: 0.67940884 | D55: =C55-B55 -> 0.0029979126 | E55: =ABS(D55) -> 0.0029979126 | I55: Variance of the Differences | J55: {=VAR(IF(ISODD(IF(ISNUMBER(sims_per_turn_scen6!$B$46:$B$71), 1, 0) * IF(ISNUMBER(sims_per_turn_scen6!$C$46:$C$71), 1, 0)), sims_per_turn_scen6!$B$46:$B$71 - sims_per_turn_scen6!$C$46:$C$71, "NA"))} -> 0.0010586883
A56: 10 | B56: 0.71515554 | C56: 0.69382834 | D56: =C56-B56 -> -0.021327201 | E56: =ABS(D56) -> 0.021327201 | I56: df | J56: {=SUM(IF(ISNUMBER(sims_per_turn_scen6!$B$46:$B$71), 1, 0) * IF(ISNUMBER(sims_per_turn_scen6!$C$46:$C$71), 1, 0)) - 1} -> 24
A57: 11 | B57: 0.72491699 | C57: 0.71401509 | D57: =C57-B57 -> -0.010901901 | E57: =ABS(D57) -> 0.010901901 | I57: t Stat | J57: =(sims_per_turn_scen6!$J$54 - sims_per_turn_scen6!$J$48) / (sims_per_turn_scen6!$J$55 / ( sims_per_turn_scen6!$J$56 + 1)) ^ 0.5 -> -2.4145162
A58: 12 | B58: 0.84477335 | C58: 0.82935334 | D58: =C58-B58 -> -0.015420017 | E58: =ABS(D58) -> 0.015420017 | I58: P (T<=t) one-tail | J58: =TDIST(ABS(sims_per_turn_scen6!$J$57), sims_per_turn_scen6!$J$56, 1) -> 0.011871129
...

Sheet pivot_sim_per_turn
A3: Turns | B3: abs delta | C3: comparison | E3: Count - abs delta | F3: comparison
A4: 19 | B4: 0.10913869 | C4: Hybsem-ac15 | E4: Turns | F4: ac15-ac15p | G4: Hybrid-ac15 | H4: Hybrid-ac15p | I4: Hybrid-hybsem | J4: Hybsem-ac15 | K4: Hybsem-ac15p | L4: Total Result
A5: 19 | B5: 0.099500295 | C5: Hybrid-hybsem | E5: 2 | G5: 1 | J5: 1 | L5: 2
A6: 2 | B6: 0.084475737 | C6: Hybrid-ac15 | E6: 4 | F6: 1 | L6: 1
A7: 13 | B7: 0.070563828 | C7: Hybrid-hybsem | E7: 5 | G7: 1 | L7: 1
A8: 23 | B8: 0.069439197 | C8: ac15-ac15p | E8: 6 | H8: 1 | L8: 1
A9: 21 | B9: 0.067540238 | C9: Hybsem-ac15p | E9: 7 | H9: 1 | K9: 1 | L9: 2
A10: 20 | B10: 0.066922936 | C10: ac15-ac15p | E10: 8 | F10: 1 | H10: 1 | K10: 1 | L10: 3
A11: 16 | B11: 0.066085045 | C11: Hybrid-ac15p | E11: 13 | I11: 1 | J11: 1 | L11: 2
A12: 8 | B12: 0.065618954 | C12: Hybrid-ac15p | E12: 15 | G12: 1 | I12: 1 | L12: 2
A13: 8 | B13: 0.064446016 | C13: Hybsem-ac15p | E13: 16 | G13: 1 | H13: 1 | L13: 2
A14: 20 | B14: 0.062037233 | C14: Hybsem-ac15p | E14: 17 | F14: 1 | J14: 1 | L14: 2
A15: 7 | B15: 0.061992317 | C15: Hybrid-ac15p | E15: 18 | G15: 1 | L15: 1
A16: 8 | B16: 0.061862495 | C16: ac15-ac15p | E16: 19 | F16: 1 | I16: 1 | J16: 1 | K16: 1 | L16: 4
A17: 7 | B17: 0.061494906 | C17: Hybsem-ac15p | E17: 20 | F17: 1 | K17: 1 | L17: 2
A18: 2 | B18: 0.06124507 | C18: Hybsem-ac15 | E18: 21 | K18: 1 | L18: 1
A19: 17 | B19: 0.0608484 | C19: Hybsem-ac15 | E19: 23 | F19: 1 | H19: 1 | J19: 1 | L19: 3
A20: 15 | B20: 0.059320833 | C20: Hybrid-hybsem | E20: 25 | J20: 1 | L20: 1
A21: 25 | B21: 0.058830709 | C21: Hybsem-ac15 | E21: Total Result | F21: 6 | G21: 5 | H21: 5 | I21: 3 | J21: 6 | K21: 5 | L21: 30
A22: 18 | B22: 0.058350715 | C22: Hybrid-ac15
A23: 15 | B23: 0.057897275 | C23: Hybrid-ac15
A24: 17 | B24: 0.057457866 | C24: ac15-ac15p
A25: 23 | B25: 0.057173693 | C25: Hybrid-ac15p
A26: 16 | B26: 0.056276103 | C26: Hybrid-ac15
A27: 19 | B27: 0.056065812 | C27: ac15-ac15p
A28: 23 | B28: 0.055052267 | C28: Hybsem-ac15
A29: 6 | B29: 0.054534206 | C29: Hybrid-ac15p
A30: 19 | B30: 0.053072874 | C30: Hybsem-ac15p
A31: 5 | B31: 0.052698488 | C31: Hybrid-ac15
A32: 13 | B32: 0.050636284 | C32: Hybsem-ac15
A33: 4 | B33: 0.050123894 | C33: ac15-ac15p

Sheet anchor_raw_information
A1: seq | B1: anchorName | C1: weight | D1: projectName
A2: 0 | B2: truth_and_fact | C2: 0.1 | D2: ac15-plain | F2: Count - anchorName | G2: projectName
A3: 2 | B3: context_dependent_expression | C3: 0.3097 | D3: ac15-plain | F3: seq | G3: ac15-plain | H3: hybrid_v3_5 | I3: hybrid_v3_5_semantic | J3: test_ac15 | K3: Total Result
A4: 2 | B4: practicality_and_feasibility | C4: 0.3021 | D4: ac15-plain | F4: 0 | G4: 1 | H4: 1 | I4: 1 | J4: 1 | K4: 4
A5: 2 | B5: temporal_dynamics | C5: 0.2882 | D5: ac15-plain | F5: 2 | G5: 4 | H5: 1 | I5: 4 | J5: 1 | K5: 10
A6: 2 | B6: truth_and_fact | C6: 0.1 | D6: ac15-plain | F6: 4 | G6: 6 | H6: 6 | I6: 5 | J6: 6 | K6: 23
A7: 4 | B7: practicality_and_feasibility | C7: 0.2081 | D7: ac15-plain | F7: 6 | G7: 2 | H7: 1 | I7: 1 | J7: 3 | K7: 7
A8: 4 | B8: sovereignty | C8: 0.1881 | D8: ac15-plain | F8: 8 | G8: 6 | H8: 6 | I8: 6 | J8: 6 | K8: 24
A9: 4 | B9: temporal_dynamics | C9: 0.1785 | D9: ac15-plain | F9: 10 | G9: 2 | H9: 2 | I9: 1 | J9: 3 | K9: 8
A10: 4 | B10: context_dependent_expression | C10: 0.164 | D10: ac15-plain | F10: 12 | G10: 6 | H10: 4 | I10: 5 | J10: 6 | K10: 21
A11: 4 | B11: freedom_and_limitations | C11: 0.1613 | D11: ac15-plain | F11: 14 | G11: 6 | H11: 5 | I11: 2 | J11: 6 | K11: 19
A12: 4 | B12: truth_and_fact | C12: 0.1 | D12: ac15-plain | F12: 16 | G12: 1 | H12: 1 | I12: 1 | J12: 1 | K12: 4
A13: 6 | B13: practicality_and_feasibility | C13: 0.9 | D13: ac15-plain | F13: 18 | G13: 6 | H13: 6 | I13: 6 | J13: 6 | K13: 24
A14: 6 | B14: truth_and_fact | C14: 0.1 | D14: ac15-plain | F14: 20 | G14: 6 | H14: 5 | I14: 6 | J14: 6 | K14: 23
A15: 8 | B15: practicality_and_feasibility | C15: 0.2263 | D15: ac15-plain | F15: 22 | G15: 6 | H15: 5 | I15: 6 | J15: 6 | K15: 23
... A28: 12 | B28: truth_and_fact | C28: 0.1 | D28: ac15-plain | F28: 48 | G28: 6 | H28: 6 | I28: 6 | J28: 6 | K28: 24
A29: 14 | B29: practicality_and_feasibility | C29: 0.1843 | D29: ac15-plain | F29: Total Result | G29: 124 | H29: 113 | I29: 115 | J29: 126 | K29: 478
A30: 14 | B30: sovereignty | C30: 0.1781 | D30: ac15-plain
A31: 14 | B31: freedom_and_limitations | C31: 0.1674 | D31: ac15-plain
A32: 14 | B32: affective_interface | C32: 0.1663 | D32: ac15-plain | F32: Sum - weight | H32: projectName
A33: 14 | B33: truth_and_fact | C33: 0.1559 | D33: ac15-plain | F33: seq | G33: anchorName | H33: ac15-plain | I33: hybrid_v3_5 | J33: hybrid_v3_5_semantic | K33: test_ac15 | L33: Total Result
A34: 14 | B34: imagination_and_possibility | C34: 0.148 | D34: ac15-plain | F34: 0 | G34: truth_and_fact | H34: 0.1 | I34: 0.1 | J34: 0.1 | K34: 0.1 | L34: 0.4
A35: 16 | B35: truth_and_fact | C35: 0.1 | D35: ac15-plain | F35: 2 | G35: affective_interface | J35: 0.2849 | L35: 0.2849
A36: 18 | B36: practicality_and_feasibility | C36: 0.196 | D36: ac15-plain | G36: context_dependent_expression | H36: 0.3097 | L36: 0.3097
A37: 18 | B37: sovereignty | C37: 0.1806 | D37: ac15-plain | G37: practicality_and_feasibility | H37: 0.3021 | J37: 0.3369 | L37: 0.639
A38: 18 | B38: mathematics_computer_science_engineering | C38: 0.1579 | D38: ac15-plain | G38: temporal_dynamics | H38: 0.2882 | J38: 0.2782 | L38: 0.5664
A39: 18 | B39: affective_interface | C39: 0.1573 | D39: ac15-plain | G39: truth_and_fact | H39: 0.1 | I39: 0.1 | J39: 0.1 | K39: 0.1 | L39: 0.4
A40: 18 | B40: truth_and_fact | C40: 0.1555 | D40: ac15-plain | F40: 4 | G40: affective_interface | J40: 0.2208 | L40: 0.2208
A41: 18 | B41: context_dependent_expression | C41: 0.1526 | D41: ac15-plain | G41: context_dependent_expression | H41: 0.164 | I41: 0.1761 | J41: 0.2119 | L41: 0.552
A42: 20 | B42: practicality_and_feasibility | C42: 0.1925 | D42: ac15-plain | G42: freedom_and_limitations | H42: 0.1613 | I42: 0.1733 | K42: 0.1751 | L42: 0.5097
A43: 20 | B43: sovereignty | C43: 0.1921 | D43: ac15-plain | G43: identity | K43: 0.1694 | L43: 0.1694
A44: 20 | B44: affective_interface | C44: 0.1811 | D44: ac15-plain | G44: imagination_and_possibility | I44: 0.1785 | L44: 0.1785
A45: 20 | B45: freedom_and_limitations | C45: 0.1739 | D45: ac15-plain | G45: mathematics_computer_science_engineering | I45: 0.1751 | L45: 0.1751
A46: 20 | B46: temporal_dynamics | C46: 0.1605 | D46: ac15-plain | G46: practicality_and_feasibility | H46: 0.2081 | I46: 0.197 | J46: 0.2505 | K46: 0.1903 | L46: 0.8459
A47: 20 | B47: truth_and_fact | C47: 0.1 | D47: ac15-plain | G47: sovereignty | H47: 0.1881 | J47: 0.2168 | K47: 0.1741 | L47: 0.579
A48: 22 | B48: affective_interface | C48: 0.1967 | D48: ac15-plain | G48: temporal_dynamics | H48: 0.1785 | K48: 0.1911 | L48: 0.3696
A49: 22 | B49: sovereignty | C49: 0.1713 | D49: ac15-plain | G49: truth_and_fact | H49: 0.1 | I49: 0.1 | J49: 0.1 | K49: 0.1 | L49: 0.4
A50: 22 | B50: truth_and_fact | C50: 0.1657 | D50: ac15-plain | F50: 6 | G50: practicality_and_feasibility | H50: 0.9 | K50: 0.444 | L50: 1.344
A51: 22 | B51: practicality_and_feasibility | C51: 0.1567 | D51: ac15-plain | G51: sovereignty | K51: 0.456 | L51: 0.456
A52: 22 | B52: freedom_and_limitations | C52: 0.1556 | D52: ac15-plain | G52: truth_and_fact | H52: 0.1 | I52: 0.1 | J52: 0.1 | K52: 0.1 | L52: 0.4
...
