Workbook

Sheet sims_per_turn_scen4
A1: Sum - abs delta | B1: comparison
A2: turns | B2: ac15-ac15p | C2: hybrid-ac15 | D2: hybrid-ac15p | E2: hybrid-hybsem | F2: hybsem-ac15 | G2: hybsem-ac15p | H2: Total Result
A3: 1 | B3: 0.010366376 | C3: 0.023721804 | D3: 0.013355428 | E3: 0.0065593368 | F3: 0.030281141 | G3: 0.019914765 | H3: 0.10419885
A4: 2 | B4: 0.045209191 | C4: 0.058599866 | D4: 0.013390675 | E4: 0.015727828 | F4: 0.042872039 | G4: 0.0023371527 | H4: 0.17813675
A5: 3 | B5: 0.0090818561 | C5: 0.031921802 | D5: 0.022839946 | E5: 0.019447974 | F5: 0.051369776 | G5: 0.04228792 | H5: 0.17694927
A6: 4 | B6: 0.043509697 | C6: 0.0037742689 | D6: 0.039735428 | E6: 0.0015342534 | F6: 0.0022400155 | G6: 0.041269682 | H6: 0.13206335
A7: 5 | B7: 0.0082900588 | C7: 0.012478715 | D7: 0.0041886564 | E7: 0.054355375 | F7: 0.06683409 | G7: 0.058544031 | H7: 0.20469093
A8: 6 | B8: 0.052816941 | C8: 0.049297665 | D8: 0.0035192764 | E8: 0.0078581442 | F8: 0.041439521 | G8: 0.011377421 | H8: 0.16630897
A9: 7 | B9: 0.07663348 | C9: 0.0010006125 | D9: 0.077634092 | E9: 0.039633969 | F9: 0.038633357 | G9: 0.038000123 | H9: 0.27153563
A10: 8 | B10: 0.024003865 | C10: 0.025624037 | D10: 0.049627903 | E10: 0.00042994844 | F10: 0.025194089 | G10: 0.049197954 | H10: 0.1740778
A11: 9 | B11: 0.004055477 | C11: 0.031926052 | D11: 0.035981529 | E11: 0.017516459 | F11: 0.014409593 | G11: 0.01846507 | H11: 0.12235418
A12: 10 | B12: 0.067796257 | C12: 0.029817035 | D12: 0.097613292 | E12: 0.014555058 | F12: 0.015261977 | G12: 0.083058233 | H12: 0.30810185
A13: 11 | B13: 0.03479862 | C13: 0.051199519 | D13: 0.085998138 | E13: 0.060108118 | F13: 0.0089085994 | G13: 0.02589002 | H13: 0.26690301
A14: 12 | B14: 0.017987462 | C14: 0.0033051977 | D14: 0.02129266 | E14: 0.041986704 | F14: 0.038681506 | G14: 0.020694043 | H14: 0.14394757
... A27: 25 | B27: 0.021870797 | C27: 0.020542141 | D27: 0.0013286564 | E27: 0.053068307 | F27: 0.032526166 | G27: 0.054396963 | H27: 0.18373303
A28: Total Result | B28: 0.7080422 | C28: 0.61674533 | D28: 0.8218033 | E28: 0.68480488 | F28: 0.81459571 | G28: 0.67393097 | H28: 4.3199224
B31: per turn, prompt-response deltas
A33: Turn | B33: hybsem | C33: hybrid | D33: Delta=hybrid-hybsem | E33: ABS delta | F33: Mean difference | G33: std delta | I33: Paired t-test | M33: Turn | N33: ABS delta
A34: 1 | B34: 0.80285811 | C34: 0.79629877 | D34: =C34-B34 -> -0.0065593368 | E34: =ABS(D34) -> 0.0065593368 | F34: =AVERAGE(D34:D58) -> -0.01085548 | G34: =_xlfn.STDEV.S(D34:D58) -> 0.038278776 | I34: Alpha | J34: 0.05 | M34: 21 | N34: 0.13469783
A35: 2 | B35: 0.72383072 | C35: 0.73955855 | D35: =C35-B35 -> 0.015727828 | E35: =ABS(D35) -> 0.015727828 | I35: Hypothesized Mean Difference | J35: 0 | M35: 11 | N35: 0.060108118
A36: 3 | B36: 0.72009692 | C36: 0.7395449 | D36: =C36-B36 -> 0.019447974 | E36: =ABS(D36) -> 0.019447974 | J36: Variable 1 | K36: Variable 2 | M36: 5 | N36: 0.054355375
A37: 4 | B37: 0.74456365 | C37: 0.74302939 | D37: =C37-B37 -> -0.0015342534 | E37: =ABS(D37) -> 0.0015342534 | I37: Mean | J37: =AVERAGE(sims_per_turn_scen4!$B$33:$B$58) -> 0.73859107 | K37: =AVERAGE(sims_per_turn_scen4!$C$33:$C$58) -> 0.72773559 | M37: 25 | N37: 0.053068307
A38: 5 | B38: 0.67114667 | C38: 0.72550205 | D38: =C38-B38 -> 0.054355375 | E38: =ABS(D38) -> 0.054355375 | I38: Variance | J38: =VAR(sims_per_turn_scen4!$B$33:$B$58) -> 0.0029744307 | K38: =VAR(sims_per_turn_scen4!$C$33:$C$58) -> 0.0041595685 | M38: 24 | N38: 0.047454776
A39: 6 | B39: 0.74069871 | C39: 0.74855685 | D39: =C39-B39 -> 0.0078581442 | E39: =ABS(D39) -> 0.0078581442 | I39: Observations | J39: =COUNT(sims_per_turn_scen4!$B$33:$B$58) -> 25 | K39: =COUNT(sims_per_turn_scen4!$C$33:$C$58) -> 25 | M39: 12 | N39: 0.041986704
A40: 7 | B40: 0.77377244 | C40: 0.73413847 | D40: =C40-B40 -> -0.039633969 | E40: =ABS(D40) -> 0.039633969 | I40: Pearson Correlation | J40: =CORREL(sims_per_turn_scen4!$B$33:$B$58,sims_per_turn_scen4!$C$33:$C$58) -> 0.80580518 | M40: 7 | N40: 0.039633969
A41: 8 | B41: 0.66913129 | C41: 0.66870134 | D41: =C41-B41 -> -0.00042994844 | E41: =ABS(D41) -> 0.00042994844 | I41: Observed Mean Difference | J41: {=AVERAGE(IF(ISODD(IF(ISNUMBER(sims_per_turn_scen4!$B$33:$B$58), 1, 0) * IF(ISNUMBER(sims_per_turn_scen4!$C$33:$C$58), 1, 0)), sims_per_turn_scen4!$B$33:$B$58 - sims_per_turn_scen4!$C$33:$C$58, "NA"))} -> 0.01085548 | M41: 16 | N41: 0.032223574
A42: 9 | B42: 0.76936358 | C42: 0.78688004 | D42: =C42-B42 -> 0.017516459 | E42: =ABS(D42) -> 0.017516459 | I42: Variance of the Differences | J42: {=VAR(IF(ISODD(IF(ISNUMBER(sims_per_turn_scen4!$B$33:$B$58), 1, 0) * IF(ISNUMBER(sims_per_turn_scen4!$C$33:$C$58), 1, 0)), sims_per_turn_scen4!$B$33:$B$58 - sims_per_turn_scen4!$C$33:$C$58, "NA"))} -> 0.0014652647 | M42: 18 | N42: 0.025864755
A43: 10 | B43: 0.7953936 | C43: 0.80994866 | D43: =C43-B43 -> 0.014555058 | E43: =ABS(D43) -> 0.014555058 | I43: df | J43: {=SUM(IF(ISNUMBER(sims_per_turn_scen4!$B$33:$B$58), 1, 0) * IF(ISNUMBER(sims_per_turn_scen4!$C$33:$C$58), 1, 0)) - 1} -> 24 | M43: 20 | N43: 0.023405154
A44: 11 | B44: 0.75028001 | C44: 0.69017189 | D44: =C44-B44 -> -0.060108118 | E44: =ABS(D44) -> 0.060108118 | I44: t Stat | J44: =(sims_per_turn_scen4!$J$41 - sims_per_turn_scen4!$J$35) / (sims_per_turn_scen4!$J$42 / ( sims_per_turn_scen4!$J$43 + 1)) ^ 0.5 -> 1.4179503 | M44: 23 | N44: 0.022224364
A45: 12 | B45: 0.79111205 | C45: 0.74912535 | D45: =C45-B45 -> -0.041986704 | E45: =ABS(D45) -> 0.041986704 | I45: P (T<=t) one-tail | J45: =TDIST(ABS(sims_per_turn_scen4!$J$44), sims_per_turn_scen4!$J$43, 1) -> 0.084529718 | M45: 19 | N45: 0.020857805
A46: 13 | B46: 0.68490072 | C46: 0.67748078 | D46: =C46-B46 -> -0.0074199365 | E46: =ABS(D46) -> 0.0074199365 | I46: t Critical one-tail | J46: =TINV(2*sims_per_turn_scen4!$J$34, sims_per_turn_scen4!$J$43) -> 1.7108821 | M46: 3 | N46: 0.019447974
A47: 14 | B47: 0.81196411 | C47: 0.79291905 | D47: =C47-B47 -> -0.01904506 | E47: =ABS(D47) -> 0.01904506 | I47: P (T<=t) two-tail | J47: =TDIST(ABS(sims_per_turn_scen4!$J$44), sims_per_turn_scen4!$J$43, 2) -> 0.16905944 | M47: 14 | N47: 0.01904506
A48: 15 | B48: 0.79331545 | C48: 0.80088441 | D48: =C48-B48 -> 0.0075689632 | E48: =ABS(D48) -> 0.0075689632 | I48: t Critical two-tail | J48: =TINV(sims_per_turn_scen4!$J$34, sims_per_turn_scen4!$J$43) -> 2.0638986 | M48: 9 | N48: 0.017516459
A49: 16 | B49: 0.67762274 | C49: 0.64539917 | D49: =C49-B49 -> -0.032223574 | E49: =ABS(D49) -> 0.032223574 | M49: 2 | N49: 0.015727828
A50: 17 | B50: 0.77509055 | C50: 0.77301622 | D50: =C50-B50 -> -0.0020743228 | E50: =ABS(D50) -> 0.0020743228 | M50: 10 | N50: 0.014555058
A51: 18 | B51: 0.6089102 | C51: 0.58304544 | D51: =C51-B51 -> -0.025864755 | E51: =ABS(D51) -> 0.025864755 | M51: 22 | N51: 0.0091868639
A52: 19 | B52: 0.81633901 | C52: 0.7954812 | D52: =C52-B52 -> -0.020857805 | E52: =ABS(D52) -> 0.020857805 | M52: 6 | N52: 0.0078581442
A53: 20 | B53: 0.67591292 | C53: 0.65250777 | D53: =C53-B53 -> -0.023405154 | E53: =ABS(D53) -> 0.023405154 | M53: 15 | N53: 0.0075689632
A54: 21 | B54: 0.74812573 | C54: 0.6134279 | D54: =C54-B54 -> -0.13469783 | E54: =ABS(D54) -> 0.13469783 | M54: 13 | N54: 0.0074199365
A55: 22 | B55: 0.66618629 | C55: 0.65699942 | D55: =C55-B55 -> -0.0091868639 | E55: =ABS(D55) -> 0.0091868639 | M55: 1 | N55: 0.0065593368
...

Sheet pivot_sim_per_turn
A3: turns | B3: comparison | C3: abs delta
A4: 1 | B4: hybrid-hybsem | C4: 0.0065593368
A5: 2 | B5: hybrid-hybsem | C5: 0.015727828
A6: 3 | B6: hybrid-hybsem | C6: 0.019447974
A7: 4 | B7: hybrid-hybsem | C7: 0.0015342534
A8: 5 | B8: hybrid-hybsem | C8: 0.054355375 | E8: Count - abs delta | F8: comparison
A9: 6 | B9: hybrid-hybsem | C9: 0.0078581442 | E9: turns | F9: ac15-ac15p | G9: hybrid-ac15 | H9: hybrid-ac15p | I9: hybrid-hybsem | J9: hybsem-ac15 | K9: hybsem-ac15p | L9: Total Result
A10: 7 | B10: hybrid-hybsem | C10: 0.039633969 | E10: 1 | F10: 1 | G10: 1 | H10: 1 | I10: 1 | J10: 1 | K10: 1 | L10: 6
A11: 8 | B11: hybrid-hybsem | C11: 0.00042994844 | E11: 2 | F11: 1 | G11: 1 | H11: 1 | I11: 1 | J11: 1 | K11: 1 | L11: 6
A12: 9 | B12: hybrid-hybsem | C12: 0.017516459 | E12: 3 | F12: 1 | G12: 1 | H12: 1 | I12: 1 | J12: 1 | K12: 1 | L12: 6
A13: 10 | B13: hybrid-hybsem | C13: 0.014555058 | E13: 4 | F13: 1 | G13: 1 | H13: 1 | I13: 1 | J13: 1 | K13: 1 | L13: 6
A14: 11 | B14: hybrid-hybsem | C14: 0.060108118 | E14: 5 | F14: 1 | G14: 1 | H14: 1 | I14: 1 | J14: 1 | K14: 1 | L14: 6
A15: 12 | B15: hybrid-hybsem | C15: 0.041986704 | E15: 6 | F15: 1 | G15: 1 | H15: 1 | I15: 1 | J15: 1 | K15: 1 | L15: 6
A16: 13 | B16: hybrid-hybsem | C16: 0.0074199365 | E16: 7 | F16: 1 | G16: 1 | H16: 1 | I16: 1 | J16: 1 | K16: 1 | L16: 6
A17: 14 | B17: hybrid-hybsem | C17: 0.01904506 | E17: 8 | F17: 1 | G17: 1 | H17: 1 | I17: 1 | J17: 1 | K17: 1 | L17: 6
A18: 15 | B18: hybrid-hybsem | C18: 0.0075689632 | E18: 9 | F18: 1 | G18: 1 | H18: 1 | I18: 1 | J18: 1 | K18: 1 | L18: 6
A19: 16 | B19: hybrid-hybsem | C19: 0.032223574 | E19: 10 | F19: 1 | G19: 1 | H19: 1 | I19: 1 | J19: 1 | K19: 1 | L19: 6
A20: 17 | B20: hybrid-hybsem | C20: 0.0020743228 | E20: 11 | F20: 1 | G20: 1 | H20: 1 | I20: 1 | J20: 1 | K20: 1 | L20: 6
A21: 18 | B21: hybrid-hybsem | C21: 0.025864755 | E21: 12 | F21: 1 | H21: 1 | I21: 1 | J21: 1 | K21: 1 | L21: 5
A22: 19 | B22: hybrid-hybsem | C22: 0.020857805 | E22: 13 | F22: 1 | H22: 1 | I22: 1 | J22: 1 | K22: 1 | L22: 5
A23: 20 | B23: hybrid-hybsem | C23: 0.023405154 | E23: 14 | F23: 1 | H23: 1 | I23: 1 | J23: 1 | K23: 1 | L23: 5
A24: 21 | B24: hybrid-hybsem | C24: 0.13469783 | E24: 15 | F24: 1 | H24: 1 | I24: 1 | J24: 1 | K24: 1 | L24: 5
A25: 22 | B25: hybrid-hybsem | C25: 0.0091868639 | E25: 16 | F25: 1 | H25: 1 | I25: 1 | J25: 1 | K25: 1 | L25: 5
A26: 23 | B26: hybrid-hybsem | C26: 0.022224364 | E26: 17 | F26: 1 | H26: 1 | I26: 1 | J26: 1 | K26: 1 | L26: 5
A27: 24 | B27: hybrid-hybsem | C27: 0.047454776 | E27: 18 | F27: 1 | H27: 1 | I27: 1 | J27: 1 | K27: 1 | L27: 5
A28: 25 | B28: hybrid-hybsem | C28: 0.053068307 | E28: 19 | F28: 1 | H28: 1 | I28: 1 | J28: 1 | K28: 1 | L28: 5
A29: 1 | B29: ac15-ac15p | C29: 0.010366376 | E29: 20 | F29: 1 | H29: 1 | I29: 1 | J29: 1 | K29: 1 | L29: 5
A30: 2 | B30: ac15-ac15p | C30: 0.045209191 | E30: 21 | F30: 1 | H30: 1 | I30: 1 | J30: 1 | K30: 1 | L30: 5
A31: 3 | B31: ac15-ac15p | C31: 0.0090818561 | E31: 22 | F31: 1 | H31: 1 | I31: 1 | J31: 1 | K31: 1 | L31: 5
A32: 4 | B32: ac15-ac15p | C32: 0.043509697 | E32: 23 | F32: 1 | H32: 1 | I32: 1 | J32: 1 | K32: 1 | L32: 5
... A34: 6 | B34: ac15-ac15p | C34: 0.052816941 | E34: 25 | F34: 1 | H34: 1 | I34: 1 | J34: 1 | K34: 1 | L34: 5
A35: 7 | B35: ac15-ac15p | C35: 0.07663348 | E35: Total Result | F35: 25 | G35: 11 | H35: 25 | I35: 25 | J35: 25 | K35: 25 | L35: 136
A36: 8 | B36: ac15-ac15p | C36: 0.024003865
A37: 9 | B37: ac15-ac15p | C37: 0.004055477
A38: 10 | B38: ac15-ac15p | C38: 0.067796257
A39: 11 | B39: ac15-ac15p | C39: 0.03479862
A40: 12 | B40: ac15-ac15p | C40: 0.017987462
A41: 13 | B41: ac15-ac15p | C41: 0.028484422
A42: 14 | B42: ac15-ac15p | C42: 0.00022046947
A43: 15 | B43: ac15-ac15p | C43: 0.022701839
...

Sheet anchors_raw_information
B1: seq | C1: anchorName | D1: weight | E1: projectName
B2: 0 | C2: practicality_and_feasibility | D2: 0.2051 | E2: ac15-plain | H2: Count - anchorName | I2: projectName
B3: 0 | C3: identity | D3: 0.1784 | E3: ac15-plain | H3: seq | I3: ac15-plain | J3: hybrid_v3_5 | K3: hybrid_v3_5_semantic | L3: test_ac15 | M3: Total Result
B4: 0 | C4: sovereignty | D4: 0.1734 | E4: ac15-plain | H4: 0 | I4: 6 | J4: 6 | K4: 6 | L4: 6 | M4: 24
B5: 0 | C5: mathematics_computer_science_engineering | D5: 0.1731 | E5: ac15-plain | H5: 2 | I5: 6 | J5: 6 | K5: 6 | L5: 6 | M5: 24
B6: 0 | C6: imagination_and_possibility | D6: 0.17 | E6: ac15-plain | H6: 4 | I6: 6 | J6: 6 | K6: 6 | L6: 6 | M6: 24
B7: 0 | C7: truth_and_fact | D7: 0.1 | E7: ac15-plain | H7: 6 | I7: 6 | J7: 6 | K7: 6 | L7: 6 | M7: 24
B8: 2 | C8: practicality_and_feasibility | D8: 0.2205 | E8: ac15-plain | H8: 8 | I8: 6 | J8: 6 | K8: 6 | L8: 6 | M8: 24
B9: 2 | C9: affective_interface | D9: 0.1768 | E9: ac15-plain | H9: 10 | I9: 6 | J9: 6 | K9: 6 | L9: 6 | M9: 24
B10: 2 | C10: sovereignty | D10: 0.1714 | E10: ac15-plain | H10: 12 | I10: 6 | J10: 6 | K10: 6 | L10: 6 | M10: 24
B11: 2 | C11: mathematics_computer_science_engineering | D11: 0.1692 | E11: ac15-plain | H11: 14 | I11: 6 | J11: 6 | K11: 6 | L11: 6 | M11: 24
B12: 2 | C12: imagination_and_possibility | D12: 0.1621 | E12: ac15-plain | H12: 16 | I12: 6 | J12: 6 | K12: 6 | L12: 6 | M12: 24
B13: 2 | C13: truth_and_fact | D13: 0.1 | E13: ac15-plain | H13: 18 | I13: 6 | J13: 6 | K13: 6 | L13: 6 | M13: 24
B14: 4 | C14: practicality_and_feasibility | D14: 0.1959 | E14: ac15-plain | H14: 20 | I14: 6 | J14: 6 | K14: 6 | L14: 6 | M14: 24
B15: 4 | C15: identity | D15: 0.1859 | E15: ac15-plain | H15: 22 | I15: 6 | J15: 6 | K15: 6 | L15: 6 | M15: 24
... B28: 8 | C28: mathematics_computer_science_engineering | D28: 0.1666 | E28: ac15-plain | H28: 48 | I28: 6 | J28: 6 | K28: 6 | L28: 6 | M28: 24
B29: 8 | C29: sovereignty | D29: 0.1646 | E29: ac15-plain | H29: Total Result | I29: 150 | J29: 145 | K29: 147 | L29: 150 | M29: 592
B30: 8 | C30: freedom_and_limitations | D30: 0.1626 | E30: ac15-plain
B31: 8 | C31: truth_and_fact | D31: 0.1 | E31: ac15-plain
B32: 10 | C32: practicality_and_feasibility | D32: 0.2116 | E32: ac15-plain | H32: Sum - weight | J32: projectName
B33: 10 | C33: sovereignty | D33: 0.1821 | E33: ac15-plain | H33: seq | I33: anchorName | J33: ac15-plain | K33: hybrid_v3_5 | L33: hybrid_v3_5_semantic | M33: test_ac15 | N33: Total Result
B34: 10 | C34: mathematics_computer_science_engineering | D34: 0.1751 | E34: ac15-plain | H34: 0 | I34: affective_interface | L34: 0.1596 | N34: 0.1596
B35: 10 | C35: affective_interface | D35: 0.1661 | E35: ac15-plain | I35: identity | J35: 0.1784 | K35: 0.192 | L35: 0.1924 | M35: 0.1622 | N35: 0.725
B36: 10 | C36: metaphorical_scaffolding | D36: 0.1651 | E36: ac15-plain | I36: imagination_and_possibility | J36: 0.17 | K36: 0.1713 | L36: 0.1764 | M36: 0.1783 | N36: 0.696
B37: 10 | C37: truth_and_fact | D37: 0.1 | E37: ac15-plain | I37: mathematics_computer_science_engineering | J37: 0.1731 | K37: 0.176 | L37: 0.172 | M37: 0.191 | N37: 0.7121
B38: 12 | C38: practicality_and_feasibility | D38: 0.2297 | E38: ac15-plain | I38: metaphorical_scaffolding | K38: 0.1582 | M38: 0.1553 | N38: 0.3135
B39: 12 | C39: sovereignty | D39: 0.1882 | E39: ac15-plain | I39: practicality_and_feasibility | J39: 0.2051 | K39: 0.2025 | L39: 0.1996 | M39: 0.2132 | N39: 0.8204
B40: 12 | C40: freedom_and_limitations | D40: 0.164 | E40: ac15-plain | I40: sovereignty | J40: 0.1734 | N40: 0.1734
B41: 12 | C41: mathematics_computer_science_engineering | D41: 0.1602 | E41: ac15-plain | I41: truth_and_fact | J41: 0.1 | K41: 0.1 | L41: 0.1 | M41: 0.1 | N41: 0.4
B42: 12 | C42: imagination_and_possibility | D42: 0.1579 | E42: ac15-plain | H42: 2 | I42: affective_interface | J42: 0.1768 | K42: 0.1658 | L42: 0.1775 | M42: 0.165 | N42: 0.6851
B43: 12 | C43: truth_and_fact | D43: 0.1 | E43: ac15-plain | I43: identity | K43: 0.1822 | L43: 0.1824 | N43: 0.3646
B44: 14 | C44: practicality_and_feasibility | D44: 0.2059 | E44: ac15-plain | I44: imagination_and_possibility | J44: 0.1621 | K44: 0.1663 | L44: 0.1678 | M44: 0.1767 | N44: 0.6729
B45: 14 | C45: sovereignty | D45: 0.1897 | E45: ac15-plain | I45: mathematics_computer_science_engineering | J45: 0.1692 | L45: 0.1632 | M45: 0.1772 | N45: 0.5096
B46: 14 | C46: metaphorical_scaffolding | D46: 0.1709 | E46: ac15-plain | I46: metaphorical_scaffolding | K46: 0.1713 | M46: 0.1647 | N46: 0.336
B47: 14 | C47: imagination_and_possibility | D47: 0.1688 | E47: ac15-plain | I47: practicality_and_feasibility | J47: 0.2205 | K47: 0.2144 | L47: 0.2092 | M47: 0.2164 | N47: 0.8605
B48: 14 | C48: freedom_and_limitations | D48: 0.1647 | E48: ac15-plain | I48: sovereignty | J48: 0.1714 | N48: 0.1714
B49: 14 | C49: truth_and_fact | D49: 0.1 | E49: ac15-plain | I49: truth_and_fact | J49: 0.1 | K49: 0.1 | L49: 0.1 | M49: 0.1 | N49: 0.4
B50: 16 | C50: practicality_and_feasibility | D50: 0.1926 | E50: ac15-plain | H50: 4 | I50: affective_interface | J50: 0.1794 | K50: 0.1693 | L50: 0.1774 | M50: 0.1705 | N50: 0.6966
B51: 16 | C51: sovereignty | D51: 0.188 | E51: ac15-plain | I51: identity | J51: 0.1859 | K51: 0.2066 | L51: 0.1706 | N51: 0.5631
B52: 16 | C52: affective_interface | D52: 0.1788 | E52: ac15-plain | I52: imagination_and_possibility | J52: 0.1603 | K52: 0.1594 | L52: 0.1743 | M52: 0.1736 | N52: 0.6676
...
