Workbook

Sheet sims_per_turn_scen7
A2: Turn | B2: ac15p | C2: Hybrid | D2: Hybsem | E2: ac15 | F2: control
A3: 1 | B3: 0.72660445 | C3: 0.74561822 | D3: 0.72409953 | E3: 0.72607266 | F3: 0.78035784
A4: 2 | B4: 0.70895983 | C4: 0.73196562 | D4: 0.69040579 | E4: 0.6826637 | F4: 0.41620709
A5: 3 | B5: 0.65625079 | C5: 0.55634941 | D5: 0.66442409 | E5: 0.61522445 | F5: 0.44069473
A6: 4 | B6: 0.68248006 | C6: 0.74696128 | D6: 0.73787209 | E6: 0.72861828 | F6: 0.50298343
A7: 5 | B7: 0.75066609 | C7: 0.73630313 | D7: 0.73166495 | E7: 0.68860406 | F7: 0.64837824
A8: 6 | B8: 0.69003761 | C8: 0.69306052 | D8: 0.72767432 | E8: 0.66907489 | F8: 0.55690541
A9: 7 | B9: 0.70889799 | C9: 0.74859756 | D9: 0.78515917 | E9: 0.7593725 | F9: 0.67658778
A10: 8 | B10: 0.68554662 | C10: 0.70516594 | D10: 0.69936593 | E10: 0.6958285 | F10: 0.53755699
A11: 9 | B11: 0.72762952 | C11: 0.75036872 | D11: 0.74686473 | E11: 0.77989957 | F11: 0.54745066
A12: 10 | B12: 0.63748551 | C12: 0.682433 | D12: 0.68571667 | E12: 0.6325723 | F12: 0.40447571
A13: 11 | B13: 0.71798946 | C13: 0.72387381 | D13: 0.76511491 | E13: 0.73306421 | F13: 0.57351245
A14: 12 | B14: 0.77090629 | C14: 0.66770176 | D14: 0.73664424 | E14: 0.69302754 | F14: 0.68842639
... A27: 25 | B27: 0.76958641 | C27: 0.727724 | D27: 0.76225457 | E27: 0.74520686 | F27: 0.4547081
B33: per turn, prompt-response deltas
A35: Turn | B35: Hybsem | C35: Hybrid | D35: Delta=hybrid-hybsem | E35: ABS delta | F35: Mean difference | G35: std delta | I35: Paired t-test
A36: 1 | B36: 0.72409953 | C36: 0.74561822 | D36: =C36-B36 -> 0.021518688 | E36: =ABS(D36) -> 0.021518688 | F36: =AVERAGE(D36:D60) -> 0.0016729357 | G36: =_xlfn.STDEV.S(D36:D60) -> 0.043070731 | I36: Alpha | J36: 0.05
A37: 2 | B37: 0.69040579 | C37: 0.73196562 | D37: =C37-B37 -> 0.041559836 | E37: =ABS(D37) -> 0.041559836 | I37: Hypothesized Mean Difference | J37: 0
A38: 3 | B38: 0.66442409 | C38: 0.55634941 | D38: =C38-B38 -> -0.10807468 | E38: =ABS(D38) -> 0.10807468 | J38: Variable 1 | K38: Variable 2
A39: 4 | B39: 0.73787209 | C39: 0.74696128 | D39: =C39-B39 -> 0.0090891899 | E39: =ABS(D39) -> 0.0090891899 | I39: Mean | J39: =AVERAGE(sims_per_turn_scen7!$B$35:$B$60) -> 0.72061831 | K39: =AVERAGE(sims_per_turn_scen7!$C$35:$C$60) -> 0.72229125
A40: 5 | B40: 0.73166495 | C40: 0.73630313 | D40: =C40-B40 -> 0.004638178 | E40: =ABS(D40) -> 0.004638178 | I40: Variance | J40: =VAR(sims_per_turn_scen7!$B$35:$B$60) -> 0.0024899574 | K40: =VAR(sims_per_turn_scen7!$C$35:$C$60) -> 0.0025385628
A41: 6 | B41: 0.72767432 | C41: 0.69306052 | D41: =C41-B41 -> -0.034613796 | E41: =ABS(D41) -> 0.034613796 | I41: Observations | J41: =COUNT(sims_per_turn_scen7!$B$35:$B$60) -> 25 | K41: =COUNT(sims_per_turn_scen7!$C$35:$C$60) -> 25
A42: 7 | B42: 0.78515917 | C42: 0.74859756 | D42: =C42-B42 -> -0.036561609 | E42: =ABS(D42) -> 0.036561609 | I42: Pearson Correlation | J42: =CORREL(sims_per_turn_scen7!$B$35:$B$60,sims_per_turn_scen7!$C$35:$C$60) -> 0.6311162
A43: 8 | B43: 0.69936593 | C43: 0.70516594 | D43: =C43-B43 -> 0.0058000054 | E43: =ABS(D43) -> 0.0058000054 | I43: Observed Mean Difference | J43: {=AVERAGE(IF(ISODD(IF(ISNUMBER(sims_per_turn_scen7!$B$35:$B$60), 1, 0) * IF(ISNUMBER(sims_per_turn_scen7!$C$35:$C$60), 1, 0)), sims_per_turn_scen7!$B$35:$B$60 - sims_per_turn_scen7!$C$35:$C$60, "NA"))} -> -0.0016729357
A44: 9 | B44: 0.74686473 | C44: 0.75036872 | D44: =C44-B44 -> 0.0035039841 | E44: =ABS(D44) -> 0.0035039841 | I44: Variance of the Differences | J44: {=VAR(IF(ISODD(IF(ISNUMBER(sims_per_turn_scen7!$B$35:$B$60), 1, 0) * IF(ISNUMBER(sims_per_turn_scen7!$C$35:$C$60), 1, 0)), sims_per_turn_scen7!$B$35:$B$60 - sims_per_turn_scen7!$C$35:$C$60, "NA"))} -> 0.0018550879
A45: 10 | B45: 0.68571667 | C45: 0.682433 | D45: =C45-B45 -> -0.0032836738 | E45: =ABS(D45) -> 0.0032836738 | I45: df | J45: {=SUM(IF(ISNUMBER(sims_per_turn_scen7!$B$35:$B$60), 1, 0) * IF(ISNUMBER(sims_per_turn_scen7!$C$35:$C$60), 1, 0)) - 1} -> 24
A46: 11 | B46: 0.76511491 | C46: 0.72387381 | D46: =C46-B46 -> -0.041241095 | E46: =ABS(D46) -> 0.041241095 | I46: t Stat | J46: =(sims_per_turn_scen7!$J$43 - sims_per_turn_scen7!$J$37) / (sims_per_turn_scen7!$J$44 / ( sims_per_turn_scen7!$J$45 + 1)) ^ 0.5 -> -0.19420795
A47: 12 | B47: 0.73664424 | C47: 0.66770176 | D47: =C47-B47 -> -0.068942473 | E47: =ABS(D47) -> 0.068942473 | I47: P (T<=t) one-tail | J47: =TDIST(ABS(sims_per_turn_scen7!$J$46), sims_per_turn_scen7!$J$45, 1) -> 0.42382377
A48: 13 | B48: 0.67866651 | C48: 0.72995268 | D48: =C48-B48 -> 0.051286169 | E48: =ABS(D48) -> 0.051286169 | I48: t Critical one-tail | J48: =TINV(2*sims_per_turn_scen7!$J$36, sims_per_turn_scen7!$J$45) -> 1.7108821
A49: 14 | B49: 0.80014865 | C49: 0.79516956 | D49: =C49-B49 -> -0.004979093 | E49: =ABS(D49) -> 0.004979093 | I49: P (T<=t) two-tail | J49: =TDIST(ABS(sims_per_turn_scen7!$J$46), sims_per_turn_scen7!$J$45, 2) -> 0.84764754
A50: 15 | B50: 0.61365644 | C50: 0.64136105 | D50: =C50-B50 -> 0.027704615 | E50: =ABS(D50) -> 0.027704615 | I50: t Critical two-tail | J50: =TINV(sims_per_turn_scen7!$J$36, sims_per_turn_scen7!$J$45) -> 2.0638986
A51: 16 | B51: 0.70191453 | C51: 0.75855012 | D51: =C51-B51 -> 0.056635589 | E51: =ABS(D51) -> 0.056635589
A52: 17 | B52: 0.69604098 | C52: 0.69417603 | D52: =C52-B52 -> -0.0018649528 | E52: =ABS(D52) -> 0.0018649528
A53: 18 | B53: 0.76411137 | C53: 0.75354741 | D53: =C53-B53 -> -0.010563961 | E53: =ABS(D53) -> 0.010563961
A54: 19 | B54: 0.61294959 | C54: 0.71847314 | D54: =C54-B54 -> 0.10552355 | E54: =ABS(D54) -> 0.10552355
A55: 20 | B55: 0.76123446 | C55: 0.75453899 | D55: =C55-B55 -> -0.0066954637 | E55: =ABS(D55) -> 0.0066954637
A56: 21 | B56: 0.70854575 | C56: 0.71601755 | D56: =C56-B56 -> 0.0074718001 | E56: =ABS(D56) -> 0.0074718001
A57: 22 | B57: 0.75606945 | C57: 0.75187651 | D57: =C57-B57 -> -0.0041929363 | E57: =ABS(D57) -> 0.0041929363
A58: 23 | B58: 0.67153187 | C58: 0.71733009 | D58: =C58-B58 -> 0.045798221 | E58: =ABS(D58) -> 0.045798221
A59: 24 | B59: 0.79332729 | C59: 0.81016516 | D59: =C59-B59 -> 0.016837868 | E59: =ABS(D59) -> 0.016837868
...

Sheet pivot_sim_per_turn
A3: Turns | B3: ABS Delta | C3: Comparison | E3: Count - ABS Delta | F3: Comparison
A4: 3 | B4: 0.10807468 | C4: Hybrid-hybsem | E4: Turns | F4: ac15-ac15p | G4: Hybrid-ac15 | H4: Hybrid-ac15p | I4: Hybrid-hybsem | J4: Hybsem-ac15 | K4: Hybsem-ac15p | L4: Total Result
A5: 19 | B5: 0.10552355 | C5: Hybrid-hybsem | E5: 3 | G5: 1 | H5: 1 | I5: 1 | L5: 3
A6: 12 | B6: 0.10320453 | C6: Hybrid-ac15p | E6: 4 | H6: 1 | K6: 1 | L6: 2
A7: 3 | B7: 0.099901379 | C7: Hybrid-ac15p | E7: 5 | F7: 1 | L7: 1
A8: 12 | B8: 0.077878751 | C8: ac15-ac15p | E8: 6 | J8: 1 | L8: 1
A9: 7 | B9: 0.076261182 | C9: Hybsem-ac15p | E9: 7 | F9: 1 | K9: 1 | L9: 2
A10: 12 | B10: 0.068942473 | C10: Hybrid-hybsem | E10: 9 | F10: 1 | L10: 1
A11: 17 | B11: 0.068627941 | C11: Hybsem-ac15 | E11: 10 | J11: 1 | L11: 1
A12: 17 | B12: 0.066762988 | C12: Hybrid-ac15 | E12: 12 | F12: 1 | H12: 1 | I12: 1 | L12: 3
A13: 4 | B13: 0.064481214 | C13: Hybrid-ac15p | E13: 13 | I13: 1 | L13: 1
A14: 5 | B14: 0.062062032 | C14: ac15-ac15p | E14: 16 | I14: 1 | L14: 1
A15: 23 | B15: 0.061016202 | C15: Hybsem-ac15 | E15: 17 | G15: 1 | J15: 1 | L15: 2
A16: 3 | B16: 0.058875043 | C16: Hybrid-ac15 | E16: 19 | G16: 1 | H16: 1 | I16: 1 | J16: 1 | K16: 1 | L16: 5
A17: 6 | B17: 0.058599423 | C17: Hybsem-ac15 | E17: 23 | F17: 1 | J17: 1 | L17: 2
A18: 23 | B18: 0.05669162 | C18: ac15-ac15p | E18: Total Result | F18: 5 | G18: 3 | H18: 4 | I18: 5 | J18: 5 | K18: 3 | L18: 25
A19: 16 | B19: 0.056635589 | C19: Hybrid-hybsem
A20: 4 | B20: 0.055392024 | C20: Hybsem-ac15p
A21: 19 | B21: 0.053703308 | C21: Hybrid-ac15p
A22: 10 | B22: 0.053144372 | C22: Hybsem-ac15
A23: 19 | B23: 0.053030422 | C23: Hybrid-ac15
A24: 19 | B24: 0.05249313 | C24: Hybsem-ac15
A25: 9 | B25: 0.052270058 | C25: ac15-ac15p
A26: 19 | B26: 0.051820244 | C26: Hybsem-ac15p
A27: 13 | B27: 0.051286169 | C27: Hybrid-hybsem
A28: 7 | B28: 0.050474514 | C28: ac15-ac15p

Sheet anchor_raw_information
A1: seq | B1: anchorName | C1: weight | D1: projectName
A2: 0 | B2: temporal_dynamics | C2: 0.3195 | D2: ac15-plain | F2: Count - weight | G2: projectName
A3: 0 | B3: imagination_and_possibility | C3: 0.2925 | D3: ac15-plain | F3: seq | G3: ac15-plain | H3: hybrid_v3_5 | I3: hybrid_v3_5_semantic | J3: test_ac15 | K3: Total Result
A4: 0 | B4: practicality_and_feasibility | C4: 0.288 | D4: ac15-plain | F4: 0 | G4: 4 | H4: 4 | I4: 4 | J4: 4 | K4: 16
A5: 0 | B5: truth_and_fact | C5: 0.1 | D5: ac15-plain | F5: 2 | G5: 2 | H5: 2 | I5: 6 | J5: 6 | K5: 16
A6: 2 | B6: practicality_and_feasibility | C6: 0.9 | D6: ac15-plain | F6: 4 | G6: 5 | H6: 4 | I6: 6 | J6: 2 | K6: 17
A7: 2 | B7: truth_and_fact | C7: 0.1 | D7: ac15-plain | F7: 6 | G7: 6 | H7: 6 | I7: 6 | J7: 6 | K7: 24
A8: 4 | B8: affective_interface | C8: 0.241 | D8: ac15-plain | F8: 8 | G8: 6 | H8: 6 | I8: 6 | J8: 6 | K8: 24
A9: 4 | B9: practicality_and_feasibility | C9: 0.2312 | D9: ac15-plain | F9: 10 | G9: 6 | H9: 6 | I9: 6 | J9: 6 | K9: 24
A10: 4 | B10: electricity | C10: 0.2187 | D10: ac15-plain | F10: 12 | G10: 4 | H10: 2 | I10: 4 | J10: 3 | K10: 13
A11: 4 | B11: context_dependent_expression | C11: 0.2091 | D11: ac15-plain | F11: 14 | G11: 3 | H11: 4 | I11: 5 | J11: 3 | K11: 15
A12: 4 | B12: truth_and_fact | C12: 0.1 | D12: ac15-plain | F12: 16 | G12: 2 | H12: 2 | I12: 2 | J12: 3 | K12: 9
A13: 6 | B13: affective_interface | C13: 0.1788 | D13: ac15-plain | F13: 18 | G13: 6 | H13: 6 | I13: 6 | J13: 6 | K13: 24
A14: 6 | B14: context_dependent_expression | C14: 0.1718 | D14: ac15-plain | F14: 20 | G14: 6 | H14: 6 | I14: 6 | J14: 6 | K14: 24
A15: 6 | B15: sovereignty | C15: 0.1648 | D15: ac15-plain | F15: 22 | G15: 6 | H15: 4 | I15: 6 | J15: 6 | K15: 22
... A28: 10 | B28: affective_interface | C28: 0.1641 | D28: ac15-plain | F28: 48 | G28: 6 | H28: 6 | I28: 6 | J28: 6 | K28: 24
A29: 10 | B29: science | C29: 0.1622 | D29: ac15-plain | F29: Total Result | G29: 133 | H29: 127 | I29: 141 | J29: 135 | K29: 536
A30: 10 | B30: truth_and_fact | C30: 0.1 | D30: ac15-plain
A31: 12 | B31: temporal_dynamics | C31: 0.3348 | D31: ac15-plain
A32: 12 | B32: practicality_and_feasibility | C32: 0.3045 | D32: ac15-plain | F32: Sum - weight | H32: projectName
A33: 12 | B33: imagination_and_possibility | C33: 0.2607 | D33: ac15-plain | F33: seq | G33: anchorName | H33: ac15-plain | I33: hybrid_v3_5 | J33: hybrid_v3_5_semantic | K33: test_ac15 | L33: Total Result
A34: 12 | B34: truth_and_fact | C34: 0.1 | D34: ac15-plain | F34: 0 | G34: affective_interface | I34: 0.2828 | J34: 0.2876 | L34: 0.5704
A35: 14 | B35: sovereignty | C35: 0.4851 | D35: ac15-plain | G35: imagination_and_possibility | H35: 0.2925 | I35: 0.2954 | J35: 0.3145 | K35: 0.2993 | L35: 1.2017
A36: 14 | B36: practicality_and_feasibility | C36: 0.4149 | D36: ac15-plain | G36: practicality_and_feasibility | H36: 0.288 | K36: 0.2763 | L36: 0.5643
A37: 14 | B37: truth_and_fact | C37: 0.1 | D37: ac15-plain | G37: temporal_dynamics | H37: 0.3195 | I37: 0.3218 | J37: 0.298 | K37: 0.3244 | L37: 1.2637
A38: 16 | B38: practicality_and_feasibility | C38: 0.9 | D38: ac15-plain | G38: truth_and_fact | H38: 0.1 | I38: 0.1 | J38: 0.1 | K38: 0.1 | L38: 0.4
A39: 16 | B39: truth_and_fact | C39: 0.1 | D39: ac15-plain | F39: 2 | G39: affective_interface | J39: 0.1796 | L39: 0.1796
A40: 18 | B40: practicality_and_feasibility | C40: 0.2268 | D40: ac15-plain | G40: context_dependent_expression | J40: 0.1712 | L40: 0.1712
A41: 18 | B41: imagination_and_possibility | C41: 0.1921 | D41: ac15-plain | G41: electricity | K41: 0.1699 | L41: 0.1699
A42: 18 | B42: temporal_dynamics | C42: 0.1712 | D42: ac15-plain | G42: freedom_and_limitations | K42: 0.163 | L42: 0.163
A43: 18 | B43: freedom_and_limitations | C43: 0.1666 | D43: ac15-plain | G43: imagination_and_possibility | I43: 0.9 | J43: 0.1879 | K43: 0.2074 | L43: 1.2953
A44: 18 | B44: context_dependent_expression | C44: 0.1433 | D44: ac15-plain | G44: practicality_and_feasibility | H44: 0.9 | J44: 0.1866 | K44: 0.1653 | L44: 1.2519
A45: 18 | B45: truth_and_fact | C45: 0.1 | D45: ac15-plain | G45: temporal_dynamics | J45: 0.1746 | K45: 0.1944 | L45: 0.369
A46: 20 | B46: practicality_and_feasibility | C46: 0.1765 | D46: ac15-plain | G46: truth_and_fact | H46: 0.1 | I46: 0.1 | J46: 0.1 | K46: 0.1 | L46: 0.4
A47: 20 | B47: imagination_and_possibility | C47: 0.1737 | D47: ac15-plain | F47: 4 | G47: affective_interface | H47: 0.241 | I47: 0.303 | J47: 0.1933 | L47: 0.7373
A48: 20 | B48: sovereignty | C48: 0.166 | D48: ac15-plain | G48: context_dependent_expression | H48: 0.2091 | J48: 0.1674 | L48: 0.3765
A49: 20 | B49: truth_and_fact | C49: 0.1652 | D49: ac15-plain | G49: electricity | H49: 0.2187 | I49: 0.2967 | J49: 0.1809 | L49: 0.6963
A50: 20 | B50: science | C50: 0.1647 | D50: ac15-plain | G50: identity | I50: 0.3003 | J50: 0.1957 | L50: 0.496
A51: 20 | B51: temporal_dynamics | C51: 0.154 | D51: ac15-plain | G51: imagination_and_possibility | J51: 0.1626 | K51: 0.9 | L51: 1.0626
A52: 22 | B52: affective_interface | C52: 0.1804 | D52: ac15-plain | G52: practicality_and_feasibility | H52: 0.2312 | L52: 0.2312
...
