Workbook

Sheet sims_per_turn
B1: General
B3: Hybsem | C3: Hybrid | D3: ac15p | E3: ac15
B4: 0.82908352 | C4: 0.83430834 | D4: 0.82032979 | E4: 0.82952135
B5: 0.7664449 | C5: 0.78737809 | D5: 0.76020895 | E5: 0.73519371
B6: 0.82081493 | C6: 0.82347011 | D6: 0.77935892 | E6: 0.73805452
B7: 0.58934068 | C7: 0.64138219 | D7: 0.65547417 | E7: 0.63946145
B8: 0.54993991 | C8: 0.64856074 | D8: 0.60148827 | E8: 0.6011484
B9: 0.8063013 | C9: 0.73754073 | D9: 0.80260511 | E9: 0.77349923
B10: 0.65442075 | C10: 0.63496808 | D10: 0.64887842 | E10: 0.65742523
B11: 0.74745701 | C11: 0.74640085 | D11: 0.75255045 | E11: 0.71261314
B12: 0.76315444 | C12: 0.68880534 | D12: 0.72599844 | E12: 0.69508286
B13: 0.74529883 | C13: 0.74363979 | D13: 0.70681936 | E13: 0.70158644
B14: 0.70359943 | C14: 0.71319147 | D14: 0.66388414 | E14: 0.69702804
B15: 0.79229112 | C15: 0.76713896 | D15: 0.80868052 | E15: 0.78055884
... B28: 0.71866241 | C28: 0.70629147 | D28: 0.69002391 | E28: 0.68313654
B31: per turn, prompt-response deltas
A33: turns | B33: Hybsem | C33: Hybrid | D33: Delta=hybrid-hybsem | E33: ABS delta | F33: Mean difference | G33: std delta | I33: Paired t-test | M33: Turn | N33: Delta=hybrid-hybsem
A34: 1 | B34: 0.82908352 | C34: 0.83430834 | D34: =C34-B34 -> 0.0052248206 | E34: =ABS(D34) -> 0.0052248206 | F34: =AVERAGE(D34:D58) -> -0.0024904092 | G34: =_xlfn.STDEV.S(D34:D58) -> 0.040066552 | I34: Alpha | J34: 0.05 | M34: 5 | N34: 0.098620831
A35: 2 | B35: 0.7664449 | C35: 0.78737809 | D35: =C35-B35 -> 0.020933186 | E35: =ABS(D35) -> 0.020933186 | I35: Hypothesized Mean Difference | J35: 0 | M35: 9 | N35: 0.074349093
A36: 3 | B36: 0.82081493 | C36: 0.82347011 | D36: =C36-B36 -> 0.0026551817 | E36: =ABS(D36) -> 0.0026551817 | J36: Variable 1 | K36: Variable 2 | M36: 6 | N36: 0.068760577
A37: 4 | B37: 0.58934068 | C37: 0.64138219 | D37: =C37-B37 -> 0.052041506 | E37: =ABS(D37) -> 0.052041506 | I37: Mean | J37: =AVERAGE(sims_per_turn!$B$33:$B$58) -> 0.73304139 | K37: =AVERAGE(sims_per_turn!$C$33:$C$58) -> 0.73055098 | M37: 17 | N37: 0.052987223
A38: 5 | B38: 0.54993991 | C38: 0.64856074 | D38: =C38-B38 -> 0.098620831 | E38: =ABS(D38) -> 0.098620831 | I38: Variance | J38: =VAR(sims_per_turn!$B$33:$B$58) -> 0.0042880587 | K38: =VAR(sims_per_turn!$C$33:$C$58) -> 0.0032014709 | M38: 19 | N38: 0.052745357
A39: 6 | B39: 0.8063013 | C39: 0.73754073 | D39: =C39-B39 -> -0.068760577 | E39: =ABS(D39) -> 0.068760577 | I39: Observations | J39: =COUNT(sims_per_turn!$B$33:$B$58) -> 25 | K39: =COUNT(sims_per_turn!$C$33:$C$58) -> 25 | M39: 4 | N39: 0.052041506
A40: 7 | B40: 0.65442075 | C40: 0.63496808 | D40: =C40-B40 -> -0.019452665 | E40: =ABS(D40) -> 0.019452665 | I40: Pearson Correlation | J40: =CORREL(sims_per_turn!$B$33:$B$58,sims_per_turn!$C$33:$C$58) -> 0.79405825 | M40: 15 | N40: 0.051309121
A41: 8 | B41: 0.74745701 | C41: 0.74640085 | D41: =C41-B41 -> -0.0010561521 | E41: =ABS(D41) -> 0.0010561521 | I41: Observed Mean Difference | J41: {=AVERAGE(IF(ISODD(IF(ISNUMBER(sims_per_turn!$B$33:$B$58), 1, 0) * IF(ISNUMBER(sims_per_turn!$C$33:$C$58), 1, 0)), sims_per_turn!$B$33:$B$58 - sims_per_turn!$C$33:$C$58, "NA"))} -> 0.0024904092 | M41: 24 | N41: 0.047894516
A42: 9 | B42: 0.76315444 | C42: 0.68880534 | D42: =C42-B42 -> -0.074349093 | E42: =ABS(D42) -> 0.074349093 | I42: Variance of the Differences | J42: {=VAR(IF(ISODD(IF(ISNUMBER(sims_per_turn!$B$33:$B$58), 1, 0) * IF(ISNUMBER(sims_per_turn!$C$33:$C$58), 1, 0)), sims_per_turn!$B$33:$B$58 - sims_per_turn!$C$33:$C$58, "NA"))} -> 0.0016053286 | M42: 14 | N42: 0.046987649
A43: 10 | B43: 0.74529883 | C43: 0.74363979 | D43: =C43-B43 -> -0.0016590318 | E43: =ABS(D43) -> 0.0016590318 | I43: df | J43: {=SUM(IF(ISNUMBER(sims_per_turn!$B$33:$B$58), 1, 0) * IF(ISNUMBER(sims_per_turn!$C$33:$C$58), 1, 0)) - 1} -> 24 | M43: 16 | N43: 0.028592564
A44: 11 | B44: 0.70359943 | C44: 0.71319147 | D44: =C44-B44 -> 0.0095920385 | E44: =ABS(D44) -> 0.0095920385 | I44: t Stat | J44: =(sims_per_turn!$J$41 - sims_per_turn!$J$35) / (sims_per_turn!$J$42 / ( sims_per_turn!$J$43 + 1)) ^ 0.5 -> 0.31078407 | M44: 12 | N44: 0.025152163
A45: 12 | B45: 0.79229112 | C45: 0.76713896 | D45: =C45-B45 -> -0.025152163 | E45: =ABS(D45) -> 0.025152163 | I45: P (T<=t) one-tail | J45: =TDIST(ABS(sims_per_turn!$J$44), sims_per_turn!$J$43, 1) -> 0.37932396 | M45: 2 | N45: 0.020933186
A46: 13 | B46: 0.74274884 | C46: 0.72568927 | D46: =C46-B46 -> -0.017059576 | E46: =ABS(D46) -> 0.017059576 | I46: t Critical one-tail | J46: =TINV(2*sims_per_turn!$J$34, sims_per_turn!$J$43) -> 1.7108821 | M46: 7 | N46: 0.019452665
A47: 14 | B47: 0.73073903 | C47: 0.68375138 | D47: =C47-B47 -> -0.046987649 | E47: =ABS(D47) -> 0.046987649 | I47: P (T<=t) two-tail | J47: =TDIST(ABS(sims_per_turn!$J$44), sims_per_turn!$J$43, 2) -> 0.75864793 | M47: 22 | N47: 0.017706595
A48: 15 | B48: 0.72750153 | C48: 0.77881066 | D48: =C48-B48 -> 0.051309121 | E48: =ABS(D48) -> 0.051309121 | I48: t Critical two-tail | J48: =TINV(sims_per_turn!$J$34, sims_per_turn!$J$43) -> 2.0638986 | M48: 13 | N48: 0.017059576
A49: 16 | B49: 0.69212024 | C49: 0.72071281 | D49: =C49-B49 -> 0.028592564 | E49: =ABS(D49) -> 0.028592564 | M49: 25 | N49: 0.01237094
A50: 17 | B50: 0.71954954 | C50: 0.77253676 | D50: =C50-B50 -> 0.052987223 | E50: =ABS(D50) -> 0.052987223 | M50: 11 | N50: 0.0095920385
A51: 18 | B51: 0.70854009 | C51: 0.70540047 | D51: =C51-B51 -> -0.0031396161 | E51: =ABS(D51) -> 0.0031396161 | M51: 20 | N51: 0.009382288
A52: 19 | B52: 0.70677586 | C52: 0.6540305 | D52: =C52-B52 -> -0.052745357 | E52: =ABS(D52) -> 0.052745357 | M52: 1 | N52: 0.0052248206
A53: 20 | B53: 0.81055278 | C53: 0.81993506 | D53: =C53-B53 -> 0.009382288 | E53: =ABS(D53) -> 0.009382288 | M53: 21 | N53: 0.0037162216
A54: 21 | B54: 0.77965151 | C54: 0.77593529 | D54: =C54-B54 -> -0.0037162216 | E54: =ABS(D54) -> 0.0037162216 | M54: 18 | N54: 0.0031396161
A55: 22 | B55: 0.70701265 | C55: 0.68930606 | D55: =C55-B55 -> -0.017706595 | E55: =ABS(D55) -> 0.017706595 | M55: 3 | N55: 0.0026551817
A56: 23 | B56: 0.7594112 | C56: 0.75786237 | D56: =C56-B56 -> -0.0015488383 | E56: =ABS(D56) -> 0.0015488383 | M56: 10 | N56: 0.0016590318
...

Sheet Pivot Table_sims_per_turn_1
A3: Turn | B3: comparison | C3: delta | F3: Count - delta | G3: comparison
A4: 5 | B4: hybrid-hybsem | C4: 0.098620831 | F4: Turn | G4: ac15 hybrid | H4: ac15 hybsem | I4: ac15-ac15p | J4: hybrid-ac15p | K4: hybrid-hybsem | L4: hybsem ac15p | M4: Total Result
A5: 9 | B5: hybrid-hybsem | C5: 0.074349093 | F5: 2 | G5: 1 | M5: 1
A6: 6 | B6: hybrid-hybsem | C6: 0.068760577 | F6: 3 | G6: 1 | H6: 1 | M6: 2
A7: 17 | B7: hybrid-hybsem | C7: 0.052987223 | F7: 4 | H7: 1 | K7: 1 | L7: 1 | M7: 3
A8: 19 | B8: hybrid-hybsem | C8: 0.052745357 | F8: 5 | H8: 1 | K8: 1 | L8: 1 | M8: 3
A9: 4 | B9: hybrid-hybsem | C9: 0.052041506 | F9: 6 | J9: 1 | K9: 1 | M9: 2
A10: 15 | B10: hybrid-hybsem | C10: 0.051309121 | F10: 9 | H10: 1 | K10: 1 | M10: 2
A11: 22 | B11: ac15-ac15p | C11: 0.079287974 | F11: 14 | G11: 1 | J11: 1 | M11: 2
A12: 24 | B12: ac15-ac15p | C12: 0.055768384 | F12: 15 | G12: 1 | K12: 1 | M12: 2
A13: 19 | B13: hybrid-ac15p | C13: 0.079800639 | F13: 16 | L13: 1 | M13: 1
A14: 24 | B14: hybrid-ac15p | C14: 0.076851129 | F14: 17 | G14: 1 | J14: 1 | K14: 1 | M14: 3
A15: 22 | B15: hybrid-ac15p | C15: 0.067913393 | F15: 19 | G15: 1 | H15: 1 | J15: 1 | K15: 1 | L15: 1 | M15: 5
A16: 14 | B16: hybrid-ac15p | C16: 0.06589851 | F16: 20 | L16: 1 | M16: 1
A17: 6 | B17: hybrid-ac15p | C17: 0.065064386 | F17: 22 | I17: 1 | J17: 1 | L17: 1 | M17: 3
A18: 17 | B18: hybrid-ac15p | C18: 0.050035675 | F18: 24 | I18: 1 | J18: 1 | M18: 2
A19: 19 | B19: hybsem ac15p | C19: 0.132546 | F19: Total Result | G19: 6 | H19: 5 | I19: 2 | J19: 6 | K19: 7 | L19: 6 | M19: 32
A20: 16 | B20: hybsem ac15p | C20: 0.071984492
A21: 4 | B21: hybsem ac15p | C21: 0.066133487
A22: 20 | B22: hybsem ac15p | C22: 0.052261883
A23: 5 | B23: hybsem ac15p | C23: 0.051548359
A24: 22 | B24: hybsem ac15p | C24: 0.050206798
A25: 3 | B25: ac15 hybrid | C25: 0.085415588
A26: 19 | B26: ac15 hybrid | C26: 0.072330129
A27: 15 | B27: ac15 hybrid | C27: 0.071369072
A28: 14 | B28: ac15 hybrid | C28: 0.056547607
A29: 17 | B29: ac15 hybrid | C29: 0.053647376
A30: 2 | B30: ac15 hybrid | C30: 0.052184378
A31: 19 | B31: ac15 hybsem | C31: 0.12507549
... A35: 4 | B35: ac15 hybsem | C35: 0.05012077

Sheet anchors_raw_information
A3: seq | B3: Anchors | C3: weights | D3: Project | F3: Count - Anchors | G3: Project
A4: 1 | B4: temporal_dynamics | C4: 0.2038 | D4: ac15-plain | F4: seq | G4: ac15-plain | H4: hybrid_v3_5 | I4: hybrid_v3_5_semantic | J4: test_ac15 | K4: Total Result
A5: 1 | B5: mathematics_computer_science_engineering | C5: 0.1894 | D5: ac15-plain | E5: 1 | F5: 1 | G5: 6 | H5: 6 | I5: 6 | J5: 6 | K5: 24
A6: 1 | B6: practicality_and_feasibility | C6: 0.1882 | D6: ac15-plain | E6: 2 | F6: 3 | G6: 6 | H6: 6 | I6: 6 | J6: 6 | K6: 24
A7: 1 | B7: sovereignty | C7: 0.1638 | D7: ac15-plain | E7: 3 | F7: 5 | G7: 6 | H7: 6 | I7: 6 | J7: 6 | K7: 24
A8: 1 | B8: affective_interface | C8: 0.1549 | D8: ac15-plain | E8: 4 | F8: 7 | G8: 6 | H8: 6 | I8: 6 | J8: 6 | K8: 24
A9: 1 | B9: truth_and_fact | C9: 0.1 | D9: ac15-plain | E9: 5 | F9: 9 | G9: 6 | H9: 6 | I9: 6 | J9: 6 | K9: 24
A10: 3 | B10: practicality_and_feasibility | C10: 0.1937 | D10: ac15-plain | E10: 6 | F10: 11 | G10: 6 | H10: 6 | I10: 6 | J10: 6 | K10: 24
A11: 3 | B11: sovereignty | C11: 0.1898 | D11: ac15-plain | E11: 7 | F11: 13 | G11: 6 | H11: 6 | I11: 5 | J11: 6 | K11: 23
A12: 3 | B12: mathematics_computer_science_engineering | C12: 0.1825 | D12: ac15-plain | E12: 8 | F12: 15 | G12: 6 | H12: 6 | I12: 6 | J12: 6 | K12: 24
A13: 3 | B13: temporal_dynamics | C13: 0.1793 | D13: ac15-plain | E13: 9 | F13: 17 | G13: 6 | H13: 6 | I13: 6 | J13: 6 | K13: 24
A14: 3 | B14: affective_interface | C14: 0.1547 | D14: ac15-plain | E14: 10 | F14: 19 | G14: 6 | H14: 6 | I14: 6 | J14: 6 | K14: 24
A15: 3 | B15: truth_and_fact | C15: 0.1 | D15: ac15-plain | E15: 11 | F15: 21 | G15: 6 | H15: 6 | I15: 6 | J15: 6 | K15: 24
A16: 5 | B16: practicality_and_feasibility | C16: 0.2003 | D16: ac15-plain | E16: 12 | F16: 23 | G16: 6 | H16: 6 | I16: 6 | J16: 6 | K16: 24
... A29: 9 | B29: mathematics_computer_science_engineering | C29: 0.1809 | D29: ac15-plain | E29: 25 | F29: 49 | G29: 6 | H29: 6 | I29: 6 | J29: 6 | K29: 24
A30: 9 | B30: temporal_dynamics | C30: 0.1788 | D30: ac15-plain | F30: Total Result | G30: 150 | H30: 146 | I30: 146 | J30: 150 | K30: 592
A31: 9 | B31: electricity | C31: 0.1749 | D31: ac15-plain
A32: 9 | B32: sovereignty | C32: 0.1633 | D32: ac15-plain | F32: Sum - weights | H32: Project
A33: 9 | B33: truth_and_fact | C33: 0.1 | D33: ac15-plain | F33: seq | G33: Anchors | H33: ac15-plain | I33: hybrid_v3_5 | J33: hybrid_v3_5_semantic | K33: test_ac15 | L33: Total Result
A34: 11 | B34: practicality_and_feasibility | C34: 0.218 | D34: ac15-plain | E34: 1 | F34: 1 | G34: affective_interface | H34: 0.1549 | J34: 0.1636 | K34: 0.1578 | L34: 0.4763
A35: 11 | B35: temporal_dynamics | C35: 0.1912 | D35: ac15-plain | G35: imagination_and_possibility | I35: 0.1568 | L35: 0.1568
A36: 11 | B36: mathematics_computer_science_engineering | C36: 0.1749 | D36: ac15-plain | G36: mathematics_computer_science_engineering | H36: 0.1894 | I36: 0.1792 | J36: 0.1723 | K36: 0.1901 | L36: 0.731
A37: 11 | B37: sovereignty | C37: 0.1665 | D37: ac15-plain | G37: practicality_and_feasibility | H37: 0.1882 | I37: 0.1948 | J37: 0.2068 | K37: 0.1952 | L37: 0.785
A38: 11 | B38: electricity | C38: 0.1493 | D38: ac15-plain | G38: sovereignty | H38: 0.1638 | I38: 0.1612 | J38: 0.1606 | K38: 0.1611 | L38: 0.6467
A39: 11 | B39: truth_and_fact | C39: 0.1 | D39: ac15-plain | G39: temporal_dynamics | H39: 0.2038 | I39: 0.208 | J39: 0.1966 | K39: 0.1958 | L39: 0.8042
A40: 13 | B40: practicality_and_feasibility | C40: 0.1973 | D40: ac15-plain | G40: truth_and_fact | H40: 0.1 | I40: 0.1 | J40: 0.1 | K40: 0.1 | L40: 0.4
A41: 13 | B41: temporal_dynamics | C41: 0.1945 | D41: ac15-plain | E41: =ROUNDDOWN(F41/2,0)+1 -> 2 | F41: 3 | G41: affective_interface | H41: 0.1547 | L41: 0.1547
A42: 13 | B42: mathematics_computer_science_engineering | C42: 0.1892 | D42: ac15-plain | G42: electricity | I42: 0.1633 | J42: 0.1509 | K42: 0.1493 | L42: 0.4635
A43: 13 | B43: electricity | C43: 0.168 | D43: ac15-plain | G43: imagination_and_possibility | J43: 0.1584 | L43: 0.1584
A44: 13 | B44: sovereignty | C44: 0.151 | D44: ac15-plain | G44: mathematics_computer_science_engineering | H44: 0.1825 | I44: 0.17 | K44: 0.1832 | L44: 0.5357
A45: 13 | B45: truth_and_fact | C45: 0.1 | D45: ac15-plain | G45: practicality_and_feasibility | H45: 0.1937 | I45: 0.1878 | J45: 0.2204 | K45: 0.2047 | L45: 0.8066
A46: 15 | B46: practicality_and_feasibility | C46: 0.1877 | D46: ac15-plain | G46: sovereignty | H46: 0.1898 | I46: 0.1832 | J46: 0.1964 | K46: 0.1775 | L46: 0.7469
A47: 15 | B47: sovereignty | C47: 0.1748 | D47: ac15-plain | G47: temporal_dynamics | H47: 0.1793 | I47: 0.1956 | J47: 0.1738 | K47: 0.1852 | L47: 0.7339
A48: 15 | B48: mathematics_computer_science_engineering | C48: 0.1702 | D48: ac15-plain | G48: truth_and_fact | H48: 0.1 | I48: 0.1 | J48: 0.1 | K48: 0.1 | L48: 0.4
A49: 15 | B49: affective_interface | C49: 0.1666 | D49: ac15-plain | E49: =ROUNDDOWN(F49/2,0)+1 -> 3 | F49: 5 | G49: imagination_and_possibility | I49: 0.1594 | J49: 0.1684 | L49: 0.3278
A50: 15 | B50: temporal_dynamics | C50: 0.1633 | D50: ac15-plain | G50: mathematics_computer_science_engineering | H50: 0.1848 | I50: 0.1751 | J50: 0.1681 | K50: 0.1805 | L50: 0.7085
A51: 15 | B51: truth_and_fact | C51: 0.1373 | D51: ac15-plain | G51: metaphorical_scaffolding | H51: 0.1556 | K51: 0.1558 | L51: 0.3114
A52: 17 | B52: practicality_and_feasibility | C52: 0.1981 | D52: ac15-plain | G52: practicality_and_feasibility | H52: 0.2003 | I52: 0.2014 | J52: 0.2176 | K52: 0.2014 | L52: 0.8207
A53: 17 | B53: temporal_dynamics | C53: 0.175 | D53: ac15-plain | G53: sovereignty | H53: 0.1759 | I53: 0.1738 | J53: 0.1699 | K53: 0.1599 | L53: 0.6795
A54: 17 | B54: mathematics_computer_science_engineering | C54: 0.1638 | D54: ac15-plain | G54: temporal_dynamics | H54: 0.1833 | I54: 0.1902 | J54: 0.1759 | K54: 0.2024 | L54: 0.7518
...

Sheet Delta(t)=sim(t)-sim(t-1)
A2: std(delta(t)=sim(t)-sim(t-1))
A4: Scenario 1
A5: Hybsem | B5: Hybrid | C5: ac15p | D5: ac15
A6: 0.092058482 | B6: 0.079958501 | C6: 0.10509626 | D6: 0.091544494
A9: Scenario 2
