Workbook

Sheet scen4_ac15
A1: turnId | B1: user_id | C1: assistant_id | D1: projectName | E1: sessionName | F1: seq | G1: anchorName | H1: weight | I1: promptSim | J1: responseSim | K1: activation delta | L1: prompt_to_response | P1: count | Q1: Activation average | R1: correlation weights / activation delta | S1: p
P2: =COUNT(K3:K152) -> 150 | Q2: =AVERAGE(K3:K152) -> 0.055958911 | R2: =CORREL(H3:H152,K3:K152) -> 0.034070544 | S2: 0.68
A3: 1dd2a4d9-93a4-4e86-b9aa-29d39510a6b4 | B3: cmjcmn5de000qzc7e7yayzu6e | C3: cmjcmo69c0017zc7er2t20j86 | D3: test_ac15 | E3: scenario_4 | F3: 0 | G3: practicality_and_feasibility | H3: 0.2132 | I3: 0.38187386 | J3: 0.4642862 | K3: =J3-I3 -> 0.08241234 | L3: 0.77257697
A4: 1dd2a4d9-93a4-4e86-b9aa-29d39510a6b4 | B4: cmjcmn5de000qzc7e7yayzu6e | C4: cmjcmo69c0017zc7er2t20j86 | D4: test_ac15 | E4: scenario_4 | F4: 0 | G4: mathematics_computer_science_engineering | H4: 0.191 | I4: 0.34212205 | J4: 0.40751778 | K4: =J4-I4 -> 0.06539573 | L4: 0.77257697
A5: 1dd2a4d9-93a4-4e86-b9aa-29d39510a6b4 | B5: cmjcmn5de000qzc7e7yayzu6e | C5: cmjcmo69c0017zc7er2t20j86 | D5: test_ac15 | E5: scenario_4 | F5: 0 | G5: imagination_and_possibility | H5: 0.1783 | I5: 0.3194655 | J5: 0.39401536 | K5: =J5-I5 -> 0.074549855 | L5: 0.77257697
A6: 1dd2a4d9-93a4-4e86-b9aa-29d39510a6b4 | B6: cmjcmn5de000qzc7e7yayzu6e | C6: cmjcmo69c0017zc7er2t20j86 | D6: test_ac15 | E6: scenario_4 | F6: 0 | G6: identity | H6: 0.1622 | I6: 0.29052408 | J6: 0.33272908 | K6: =J6-I6 -> 0.042204991 | L6: 0.77257697
A7: 1dd2a4d9-93a4-4e86-b9aa-29d39510a6b4 | B7: cmjcmn5de000qzc7e7yayzu6e | C7: cmjcmo69c0017zc7er2t20j86 | D7: test_ac15 | E7: scenario_4 | F7: 0 | G7: metaphorical_scaffolding | H7: 0.1553 | I7: 0.27826115 | J7: 0.36086825 | K7: =J7-I7 -> 0.082607096 | L7: 0.77257697
A8: 1dd2a4d9-93a4-4e86-b9aa-29d39510a6b4 | B8: cmjcmn5de000qzc7e7yayzu6e | C8: cmjcmo69c0017zc7er2t20j86 | D8: test_ac15 | E8: scenario_4 | F8: 0 | G8: truth_and_fact | H8: 0.1 | I8: 0.23297008 | J8: 0.30667192 | K8: =J8-I8 -> 0.073701836 | L8: 0.77257697
A9: add942e5-787b-4707-823f-28c69c101556 | B9: cmjcmoqhn001bzc7e8gce6ia4 | C9: cmjcmpecp001szc7ehemr30k1 | D9: test_ac15 | E9: scenario_4 | F9: 2 | G9: practicality_and_feasibility | H9: 0.2164 | I9: 0.42789092 | J9: 0.4096234 | K9: =J9-I9 -> -0.018267522 | L9: 0.68095868
A10: add942e5-787b-4707-823f-28c69c101556 | B10: cmjcmoqhn001bzc7e8gce6ia4 | C10: cmjcmpecp001szc7ehemr30k1 | D10: test_ac15 | E10: scenario_4 | F10: 2 | G10: mathematics_computer_science_engineering | H10: 0.1772 | I10: 0.35025611 | J10: 0.36961835 | K10: =J10-I10 -> 0.019362239 | L10: 0.68095868
A11: add942e5-787b-4707-823f-28c69c101556 | B11: cmjcmoqhn001bzc7e8gce6ia4 | C11: cmjcmpecp001szc7ehemr30k1 | D11: test_ac15 | E11: scenario_4 | F11: 2 | G11: imagination_and_possibility | H11: 0.1767 | I11: 0.34928031 | J11: 0.33783698 | K11: =J11-I11 -> -0.011443324 | L11: 0.68095868
A12: add942e5-787b-4707-823f-28c69c101556 | B12: cmjcmoqhn001bzc7e8gce6ia4 | C12: cmjcmpecp001szc7ehemr30k1 | D12: test_ac15 | E12: scenario_4 | F12: 2 | G12: affective_interface | H12: 0.165 | I12: 0.32618695 | J12: 0.376154 | K12: =J12-I12 -> 0.049967045 | L12: 0.68095868
A13: add942e5-787b-4707-823f-28c69c101556 | B13: cmjcmoqhn001bzc7e8gce6ia4 | C13: cmjcmpecp001szc7ehemr30k1 | D13: test_ac15 | E13: scenario_4 | F13: 2 | G13: metaphorical_scaffolding | H13: 0.1647 | I13: 0.32568828 | J13: 0.32433554 | K13: =J13-I13 -> -0.0013527394 | L13: 0.68095868
A14: add942e5-787b-4707-823f-28c69c101556 | B14: cmjcmoqhn001bzc7e8gce6ia4 | C14: cmjcmpecp001szc7ehemr30k1 | D14: test_ac15 | E14: scenario_4 | F14: 2 | G14: truth_and_fact | H14: 0.1 | I14: 0.31289025 | J14: 0.28633425 | K14: =J14-I14 -> -0.026556005 | L14: 0.68095868
... A152: 9fcca688-86ed-4128-8f1b-feee7d030f5b | B152: cmjcncs8z00eqzc7e4e8bgseh | C152: cmjcnd3oi00f7zc7exonh7e43 | D152: test_ac15 | E152: scenario_4 | F152: 48 | G152: truth_and_fact | H152: 0.1 | I152: 0.26148268 | J152: 0.26755172 | K152: =J152-I152 -> 0.0060690476 | L152: 0.71620656

Sheet notes
A1: p calculation
A3: 1. count | B3: =scen4_ac15!P2 -> 150
A4: 2. t statistic | B4: =B10*SQRT((B3-2)/(1-B10^2)) -> 0.41472683
A5: 3. p | B5: =_xlfn.T.DIST.2T(ABS(B4),B3-2) -> 0.67894242
A9: count | B9: correlation weights / activation delta
A10: =B3 -> 150 | B10: =scen4_ac15!R2 -> 0.034070544

Sheet actdel_prompt_response
B2: Prompt-response
A3: Turn | B3: ac15
A4: 1 | B4: 0.77257697
A5: 2 | B5: 0.68095868
A6: 3 | B6: 0.7714667
A7: 4 | B7: 0.74680366
A8: 5 | B8: 0.73798076
A9: 6 | B9: 0.69925919
A10: 7 | B10: 0.73513908
A11: 8 | B11: 0.69432538
A12: 9 | B12: 0.75495398
A13: 10 | B13: 0.78013162
A14: 11 | B14: 0.74137141
A15: 12 | B15: 0.75243055
... A28: 25 | B28: 0.71620656

Sheet inter_system_stats
B2: prompt_to_response
A3: Turn | B3: ac15 | C3: control | E3: std.ac15 | F3: std. Control | G3: F. test | H3: T. Test equal variances | I3: T.Test unequal | J3: Mean difference | K3: Average Scenario | L3: Average Control
A4: 1 | B4: 0.77257697 | C4: 0.82062035 | E4: =_xlfn.STDEV.S(B4:B28) -> 0.058444652 | F4: =_xlfn.STDEV.S(C4:C28) -> 0.083848556 | G4: =_xlfn.F.TEST(B4:B28,C4:C28) -> 0.083341731 | H4: =_xlfn.T.TEST(B4:B28, C4:C28, 2,2) -> 0.00021943314 | I4: =_xlfn.T.TEST(B4:B28,C4:C28, 2,3) -> 0.00024747479 | J4: =AVERAGE(B4:B28)-AVERAGE(C4:C28) -> 0.081723968 | K4: =AVERAGE(B4:B28) -> 0.72379591 | L4: =AVERAGE(C4:C28) -> 0.64207194
A5: 2 | B5: 0.68095868 | C5: 0.67785078
A6: 3 | B6: 0.7714667 | C6: 0.67795229
A7: 4 | B7: 0.74680366 | C7: 0.66135317
A8: 5 | B8: 0.73798076 | C8: 0.59399104
A9: 6 | B9: 0.69925919 | C9: 0.6086453
A10: 7 | B10: 0.73513908 | C10: 0.57481882
A11: 8 | B11: 0.69432538 | C11: 0.52225005
A12: 9 | B12: 0.75495398 | C12: 0.76343563
A13: 10 | B13: 0.78013162 | C13: 0.6903629
A14: 11 | B14: 0.74137141 | C14: 0.66961631
A15: 12 | B15: 0.75243055 | C15: 0.75051558
A16: 13 | B16: 0.65869741 | C16: 0.70922297
... A28: 25 | B28: 0.71620656 | C28: 0.62965658
A32: General
A34: Turn | B34: ac15p | C34: hybrid | D34: hybsem | E34: ac15 | F34: control | H34: ANOVA - Single Factor
A35: 1 | B35: 0.78294334 | C35: 0.79629877 | D35: 0.80285811 | E35: 0.77257697 | F35: 0.82062035 | H35: Alpha | I35: 0.05
A36: 2 | B36: 0.72616788 | C36: 0.73955855 | D36: 0.72383072 | E36: 0.68095868 | F36: 0.67785078
A37: 3 | B37: 0.76238484 | C37: 0.7395449 | D37: 0.72009692 | E37: 0.7714667 | F37: 0.67795229 | H37: Groups | I37: Count | J37: Sum | K37: Mean | L37: Variance
A38: 4 | B38: 0.70329396 | C38: 0.74302939 | D38: 0.74456365 | E38: 0.74680366 | F38: 0.66135317 | H38: Column 1 | I38: =COUNT(inter_system_stats!$B$34:$B$59) -> 25 | J38: =SUM(inter_system_stats!$B$34:$B$59) -> 18.362259 | K38: =AVERAGE(inter_system_stats!$B$34:$B$59) -> 0.73449037 | L38: =VAR(inter_system_stats!$B$34:$B$59) -> 0.0034118332
A39: 5 | B39: 0.7296907 | C39: 0.72550205 | D39: 0.67114667 | E39: 0.73798076 | F39: 0.59399104 | H39: Column 2 | I39: =COUNT(inter_system_stats!$C$34:$C$59) -> 25 | J39: =SUM(inter_system_stats!$C$34:$C$59) -> 18.19339 | K39: =AVERAGE(inter_system_stats!$C$34:$C$59) -> 0.72773559 | L39: =VAR(inter_system_stats!$C$34:$C$59) -> 0.0041595685
A40: 6 | B40: 0.75207613 | C40: 0.74855685 | D40: 0.74069871 | E40: 0.69925919 | F40: 0.6086453 | H40: Column 3 | I40: =COUNT(inter_system_stats!$D$34:$D$59) -> 25 | J40: =SUM(inter_system_stats!$D$34:$D$59) -> 18.464777 | K40: =AVERAGE(inter_system_stats!$D$34:$D$59) -> 0.73859107 | L40: =VAR(inter_system_stats!$D$34:$D$59) -> 0.0029744307
A41: 7 | B41: 0.81177256 | C41: 0.73413847 | D41: 0.77377244 | E41: 0.73513908 | F41: 0.57481882 | H41: Column 4 | I41: =COUNT(inter_system_stats!$E$34:$E$59) -> 25 | J41: =SUM(inter_system_stats!$E$34:$E$59) -> 18.094898 | K41: =AVERAGE(inter_system_stats!$E$34:$E$59) -> 0.72379591 | L41: =VAR(inter_system_stats!$E$34:$E$59) -> 0.0034157774
A42: 8 | B42: 0.71832924 | C42: 0.66870134 | D42: 0.66913129 | E42: 0.69432538 | F42: 0.52225005 | H42: Column 5 | I42: =COUNT(inter_system_stats!$F$34:$F$59) -> 25 | J42: =SUM(inter_system_stats!$F$34:$F$59) -> 16.051799 | K42: =AVERAGE(inter_system_stats!$F$34:$F$59) -> 0.64207194 | L42: =VAR(inter_system_stats!$F$34:$F$59) -> 0.0070305804
A43: 9 | B43: 0.75089851 | C43: 0.78688004 | D43: 0.76936358 | E43: 0.75495398 | F43: 0.76343563
A44: 10 | B44: 0.71233537 | C44: 0.80994866 | D44: 0.7953936 | E44: 0.78013162 | F44: 0.6903629 | H44: Source of Variation | I44: SS | J44: df | K44: MS | L44: F | M44: P-value | N44: F critical
A45: 11 | B45: 0.77617003 | C45: 0.69017189 | D45: 0.75028001 | E45: 0.74137141 | F45: 0.66961631 | H45: Between Groups | I45: =SUMPRODUCT(inter_system_stats!$J$38:$J$42,inter_system_stats!$K$38:$K$42)-SUM(inter_system_stats!$J$38:$J$42)^2/SUM(inter_system_stats!$I$38:$I$42) -> 0.16201626 | J45: =COUNT(inter_system_stats!$J$38:$J$42)-1 -> 4 | K45: =inter_system_stats!$I$45 / inter_system_stats!$J$45 -> 0.040504065 | L45: =inter_system_stats!$K$45 / inter_system_stats!$K$46 -> 9.6474128 | M45: =FDIST(inter_system_stats!$L$45, inter_system_stats!$J$45, inter_system_stats!$J$46) -> 8.4625931e-07 | N45: =FINV(inter_system_stats!$I$35, inter_system_stats!$J$45, inter_system_stats!$J$46) -> 2.4472365
A46: 12 | B46: 0.77041801 | C46: 0.74912535 | D46: 0.79111205 | E46: 0.75243055 | F46: 0.75051558 | H46: Within Groups | I46: =SUM(DEVSQ(inter_system_stats!$B$34:$B$59),DEVSQ(inter_system_stats!$C$34:$C$59),DEVSQ(inter_system_stats!$D$34:$D$59),DEVSQ(inter_system_stats!$E$34:$E$59),DEVSQ(inter_system_stats!$F$34:$F$59)) -> 0.50381256 | J46: =SUM(inter_system_stats!$I$38:$I$42)-COUNT(inter_system_stats!$I$38:$I$42) -> 120 | K46: =inter_system_stats!$I$46 / inter_system_stats!$J$46 -> 0.004198438
A47: 13 | B47: 0.68718184 | C47: 0.67748078 | D47: 0.68490072 | E47: 0.65869741 | F47: 0.70922297 | H47: Total | I47: =DEVSQ(inter_system_stats!$B$34:$B$59,inter_system_stats!$C$34:$C$59,inter_system_stats!$D$34:$D$59,inter_system_stats!$E$34:$E$59,inter_system_stats!$F$34:$F$59) -> 0.66582882 | J47: =SUM(inter_system_stats!$I$38:$I$42) - 1 -> 124
A48: 14 | B48: 0.81381365 | C48: 0.79291905 | D48: 0.81196411 | E48: 0.81359318 | F48: 0.52610751
A49: 15 | B49: 0.78154173 | C49: 0.80088441 | D49: 0.79331545 | E49: 0.75883989 | F49: 0.56860664
A50: 16 | B50: 0.67997326 | C50: 0.64539917 | D50: 0.67762274 | E50: 0.64864237 | F50: 0.49501171
A51: 17 | B51: 0.80453974 | C51: 0.77301622 | D51: 0.77509055 | E51: 0.77983743 | F51: 0.67299501
A52: 18 | B52: 0.57578838 | C52: 0.58304544 | D52: 0.6089102 | E52: 0.57208918 | F52: 0.63783224
A53: 19 | B53: 0.80829344 | C53: 0.7954812 | D53: 0.81633901 | E53: 0.76396894 | F53: 0.67734808
A54: 20 | B54: 0.6310987 | C54: 0.65250777 | D54: 0.67591292 | E54: 0.6243046 | F54: 0.67594723
A55: 21 | B55: 0.72352146 | C55: 0.6134279 | D55: 0.74812573 | E55: 0.65989322 | F55: 0.61094333
A56: 22 | B56: 0.66763609 | C56: 0.65699942 | D56: 0.66618629 | E56: 0.6890459 | F56: 0.75009119
...

Sheet delta sims
B3: ac15p | C3: hybrid | D3: hybsem | E3: ac15
B4: 0.78294334 | C4: 0.79629877 | D4: 0.80285811 | E4: 0.77257697
B5: 0.72616788 | C5: 0.73955855 | D5: 0.72383072 | E5: 0.68095868
B6: 0.76238484 | C6: 0.7395449 | D6: 0.72009692 | E6: 0.7714667
B7: 0.70329396 | C7: 0.74302939 | D7: 0.74456365 | E7: 0.74680366
B8: 0.7296907 | C8: 0.72550205 | D8: 0.67114667 | E8: 0.73798076
B9: 0.75207613 | C9: 0.74855685 | D9: 0.74069871 | E9: 0.69925919
B10: 0.81177256 | C10: 0.73413847 | D10: 0.77377244 | E10: 0.73513908
B11: 0.71832924 | C11: 0.66870134 | D11: 0.66913129 | E11: 0.69432538
B12: 0.75089851 | C12: 0.78688004 | D12: 0.76936358 | E12: 0.75495398
B13: 0.71233537 | C13: 0.80994866 | D13: 0.7953936 | E13: 0.78013162
B14: 0.77617003 | C14: 0.69017189 | D14: 0.75028001 | E14: 0.74137141
B15: 0.77041801 | C15: 0.74912535 | D15: 0.79111205 | E15: 0.75243055
... B28: 0.69433576 | C28: 0.69566442 | D28: 0.74873273 | E28: 0.71620656
A31: deltas: | G31: stdev
B32: ac15p | C32: hybrid | D32: hybsem | E32: ac15 | G32: ac15p | H32: hybrid | I32: hybsem | J32: ac15
B33: =B5-B4 -> -0.056775466 | C33: =C5-C4 -> -0.056740219 | D33: =D5-D4 -> -0.079027383 | E33: =E5-E4 -> -0.091618281 | G33: =_xlfn.STDEV.S(B33:B56) -> 0.10173747 | H33: =_xlfn.STDEV.S(C33:C56) -> 0.099952935 | I33: =_xlfn.STDEV.S(D33:D56) -> 0.094351237 | J33: =_xlfn.STDEV.S(E33:E56) -> 0.094708375
B34: =B6-B5 -> 0.036216968 | C34: =C6-C5 -> -1.3652223e-05 | D34: =D6-D5 -> -0.0037337989 | E34: =E6-E5 -> 0.090508016
B35: =B7-B6 -> -0.05909088 | C35: =C7-C6 -> 0.0034844938 | D35: =D7-D6 -> 0.024466721 | E35: =E7-E6 -> -0.024663039
B36: =B8-B7 -> 0.02639674 | C36: =C8-C7 -> -0.017527345 | D36: =D8-D7 -> -0.073416973 | E36: =E8-E7 -> -0.008822899
B37: =B9-B8 -> 0.022385425 | C37: =C9-C8 -> 0.023054805 | D37: =D9-D8 -> 0.069552035 | E37: =E9-E8 -> -0.038721575
B38: =B10-B9 -> 0.059696432 | C38: =C10-C9 -> -0.014418384 | D38: =D10-D9 -> 0.03307373 | E38: =E10-E9 -> 0.035879894
B39: =B11-B10 -> -0.093443315 | C39: =C11-C10 -> -0.065437126 | D39: =D11-D10 -> -0.10464115 | E39: =E11-E10 -> -0.040813701
B40: =B12-B11 -> 0.032569264 | C40: =C12-C11 -> 0.1181787 | D40: =D12-D11 -> 0.10023229 | E40: =E12-E11 -> 0.060628606
B41: =B13-B12 -> -0.03856314 | C41: =C13-C12 -> 0.023068622 | D41: =D13-D12 -> 0.026030023 | E41: =E13-E12 -> 0.02517764
B42: =B14-B13 -> 0.063834662 | C42: =C14-C13 -> -0.11977677 | D42: =D14-D13 -> -0.045113591 | E42: =E14-E13 -> -0.038760214
B43: =B15-B14 -> -0.005752022 | C43: =C15-C14 -> 0.058953456 | D43: =D15-D14 -> 0.040832042 | E43: =E15-E14 -> 0.011059135
B44: =B16-B15 -> -0.083236172 | C44: =C16-C15 -> -0.071644565 | D44: =D16-D15 -> -0.10621133 | E44: =E16-E15 -> -0.093733132
B45: =B17-B16 -> 0.12663181 | C45: =C17-C16 -> 0.11543827 | D45: =D17-D16 -> 0.12706339 | E45: =E17-E16 -> 0.15489576
... B56: =B28-B27 -> -0.07457383 | C56: =C28-C27 -> -0.10000801 | D56: =D28-D27 -> 0.00051507137 | E56: =E28-E27 -> -0.079495847
