Workbook

Sheet scen2_ac15
A1: turnId | B1: user_id | C1: assistant_id | D1: projectName | E1: sessionName | F1: seq | G1: anchorName | H1: weight | I1: promptSim | J1: responseSim | K1: activation delta | L1: prompt_to_response | N1: Average activation/turn | O1: average conversation activation | P1: count | Q1: correlation weights / activation delta | R1: p
A3: ff6ef636-b021-4a05-94dc-76edced40e73 | B3: cmja7ntys00i5zc4ends3iomi | C3: cmja7ova500imzc4e50vzek16 | D3: test_ac15 | E3: Scenario_2_v3 | F3: 1 | G3: practicality_and_feasibility | H3: 0.2058 | I3: 0.3033785 | J3: 0.38700011 | K3: =J3-I3 -> 0.08362161 | L3: 0.82022841 | N3: =AVERAGE(K3:K8) -> 0.096093869 | O3: =AVERAGE(K3:K141) -> 0.06608221 | P3: =COUNT(K3:K141) -> 139 | Q3: =CORREL(H3:H141,K3:K141) -> 0.16559238 | R3: 0.088
A4: ff6ef636-b021-4a05-94dc-76edced40e73 | B4: cmja7ntys00i5zc4ends3iomi | C4: cmja7ova500imzc4e50vzek16 | D4: test_ac15 | E4: Scenario_2_v3 | F4: 1 | G4: temporal_dynamics | H4: 0.1919 | I4: 0.28284332 | J4: 0.38817383 | K4: =J4-I4 -> 0.10533051 | L4: 0.82022841
A5: ff6ef636-b021-4a05-94dc-76edced40e73 | B5: cmja7ntys00i5zc4ends3iomi | C5: cmja7ova500imzc4e50vzek16 | D5: test_ac15 | E5: Scenario_2_v3 | F5: 1 | G5: mathematics_computer_science_engineering | H5: 0.182 | I5: 0.26834766 | J5: 0.35983603 | K5: =J5-I5 -> 0.091488371 | L5: 0.82022841
A6: ff6ef636-b021-4a05-94dc-76edced40e73 | B6: cmja7ntys00i5zc4ends3iomi | C6: cmja7ova500imzc4e50vzek16 | D6: test_ac15 | E6: Scenario_2_v3 | F6: 1 | G6: affective_interface | H6: 0.1602 | I6: 0.23617811 | J6: 0.32420733 | K6: =J6-I6 -> 0.088029222 | L6: 0.82022841
A7: ff6ef636-b021-4a05-94dc-76edced40e73 | B7: cmja7ntys00i5zc4ends3iomi | C7: cmja7ova500imzc4e50vzek16 | D7: test_ac15 | E7: Scenario_2_v3 | F7: 1 | G7: imagination_and_possibility | H7: 0.1601 | I7: 0.23608419 | J7: 0.3278449 | K7: =J7-I7 -> 0.091760706 | L7: 0.82022841
A8: ff6ef636-b021-4a05-94dc-76edced40e73 | B8: cmja7ntys00i5zc4ends3iomi | C8: cmja7ova500imzc4e50vzek16 | D8: test_ac15 | E8: Scenario_2_v3 | F8: 1 | G8: truth_and_fact | H8: 0.1 | I8: 0.12244252 | J8: 0.23877532 | K8: =J8-I8 -> 0.1163328 | L8: 0.82022841
A9: 0d240f00-4508-4047-aeca-047390fb69a8 | B9: cmja7qae200iqzc4ew0sy3lwo | C9: cmja7rchl00j7zc4euomo3uvl | D9: test_ac15 | E9: Scenario_2_v3 | F9: 3 | G9: practicality_and_feasibility | H9: 0.1939 | I9: 0.29185102 | J9: 0.39081759 | K9: =J9-I9 -> 0.098966563 | L9: 0.76459215 | N9: =AVERAGE(K9:K14) -> 0.092919337
A10: 0d240f00-4508-4047-aeca-047390fb69a8 | B10: cmja7qae200iqzc4ew0sy3lwo | C10: cmja7rchl00j7zc4euomo3uvl | D10: test_ac15 | E10: Scenario_2_v3 | F10: 3 | G10: temporal_dynamics | H10: 0.1889 | I10: 0.28444744 | J10: 0.36488515 | K10: =J10-I10 -> 0.080437707 | L10: 0.76459215
A11: 0d240f00-4508-4047-aeca-047390fb69a8 | B11: cmja7qae200iqzc4ew0sy3lwo | C11: cmja7rchl00j7zc4euomo3uvl | D11: test_ac15 | E11: Scenario_2_v3 | F11: 3 | G11: mathematics_computer_science_engineering | H11: 0.1848 | I11: 0.27814284 | J11: 0.37235356 | K11: =J11-I11 -> 0.09421072 | L11: 0.76459215
A12: 0d240f00-4508-4047-aeca-047390fb69a8 | B12: cmja7qae200iqzc4ew0sy3lwo | C12: cmja7rchl00j7zc4euomo3uvl | D12: test_ac15 | E12: Scenario_2_v3 | F12: 3 | G12: sovereignty | H12: 0.1733 | I12: 0.26090257 | J12: 0.31973055 | K12: =J12-I12 -> 0.058827983 | L12: 0.76459215
A13: 0d240f00-4508-4047-aeca-047390fb69a8 | B13: cmja7qae200iqzc4ew0sy3lwo | C13: cmja7rchl00j7zc4euomo3uvl | D13: test_ac15 | E13: Scenario_2_v3 | F13: 3 | G13: affective_interface | H13: 0.1591 | I13: 0.23953965 | J13: 0.35578605 | K13: =J13-I13 -> 0.1162464 | L13: 0.76459215
A14: 0d240f00-4508-4047-aeca-047390fb69a8 | B14: cmja7qae200iqzc4ew0sy3lwo | C14: cmja7rchl00j7zc4euomo3uvl | D14: test_ac15 | E14: Scenario_2_v3 | F14: 3 | G14: truth_and_fact | H14: 0.1 | I14: 0.17049908 | J14: 0.27932572 | K14: =J14-I14 -> 0.10882665 | L14: 0.76459215
A15: 1e00989b-8ba5-4412-a0ae-4469a1cd26c1 | B15: cmja7t05a00jbzc4e2nb0abl1 | C15: cmja7tojr00jszc4estitmwv5 | D15: test_ac15 | E15: Scenario_2_v3 | F15: 5 | G15: practicality_and_feasibility | H15: 0.1939 | I15: 0.35833567 | J15: 0.41726913 | K15: =J15-I15 -> 0.058933461 | L15: 0.72301136 | N15: =AVERAGE(K15:K20) -> 0.045096375
A16: 1e00989b-8ba5-4412-a0ae-4469a1cd26c1 | B16: cmja7t05a00jbzc4e2nb0abl1 | C16: cmja7tojr00jszc4estitmwv5 | D16: test_ac15 | E16: Scenario_2_v3 | F16: 5 | G16: temporal_dynamics | H16: 0.1901 | I16: 0.35125102 | J16: 0.39150162 | K16: =J16-I16 -> 0.0402506 | L16: 0.72301136
A17: 1e00989b-8ba5-4412-a0ae-4469a1cd26c1 | B17: cmja7t05a00jbzc4e2nb0abl1 | C17: cmja7tojr00jszc4estitmwv5 | D17: test_ac15 | E17: Scenario_2_v3 | F17: 5 | G17: mathematics_computer_science_engineering | H17: 0.1834 | I17: 0.33878726 | J17: 0.39699814 | K17: =J17-I17 -> 0.058210887 | L17: 0.72301136
A18: 1e00989b-8ba5-4412-a0ae-4469a1cd26c1 | B18: cmja7t05a00jbzc4e2nb0abl1 | C18: cmja7tojr00jszc4estitmwv5 | D18: test_ac15 | E18: Scenario_2_v3 | F18: 5 | G18: affective_interface | H18: 0.1777 | I18: 0.32839301 | J18: 0.36192687 | K18: =J18-I18 -> 0.033533862 | L18: 0.72301136
A19: 1e00989b-8ba5-4412-a0ae-4469a1cd26c1 | B19: cmja7t05a00jbzc4e2nb0abl1 | C19: cmja7tojr00jszc4estitmwv5 | D19: test_ac15 | E19: Scenario_2_v3 | F19: 5 | G19: science | H19: 0.1549 | I19: 0.28620055 | J19: 0.32592775 | K19: =J19-I19 -> 0.039727203 | L19: 0.72301136
A20: 1e00989b-8ba5-4412-a0ae-4469a1cd26c1 | B20: cmja7t05a00jbzc4e2nb0abl1 | C20: cmja7tojr00jszc4estitmwv5 | D20: test_ac15 | E20: Scenario_2_v3 | F20: 5 | G20: truth_and_fact | H20: 0.1 | I20: 0.2032307 | J20: 0.24315293 | K20: =J20-I20 -> 0.039922237 | L20: 0.72301136
A21: fa9c1b06-b05c-413d-b833-abca412700af | B21: cmja7vdp100jwzc4ehwy2mydu | C21: cmja7vz2100kdzc4exo90gnds | D21: test_ac15 | E21: Scenario_2_v3 | F21: 7 | G21: temporal_dynamics | H21: 0.2088 | I21: 0.32813141 | J21: 0.3352545 | K21: =J21-I21 -> 0.0071230905 | L21: 0.75642044 | N21: =AVERAGE(K21:K26) -> 0.052580262
A22: fa9c1b06-b05c-413d-b833-abca412700af | B22: cmja7vdp100jwzc4ehwy2mydu | C22: cmja7vz2100kdzc4exo90gnds | D22: test_ac15 | E22: Scenario_2_v3 | F22: 7 | G22: practicality_and_feasibility | H22: 0.1939 | I22: 0.30463705 | J22: 0.37884847 | K22: =J22-I22 -> 0.07421142 | L22: 0.75642044
A23: fa9c1b06-b05c-413d-b833-abca412700af | B23: cmja7vdp100jwzc4ehwy2mydu | C23: cmja7vz2100kdzc4exo90gnds | D23: test_ac15 | E23: Scenario_2_v3 | F23: 7 | G23: mathematics_computer_science_engineering | H23: 0.1743 | I23: 0.2738652 | J23: 0.34134469 | K23: =J23-I23 -> 0.067479493 | L23: 0.75642044
A24: fa9c1b06-b05c-413d-b833-abca412700af | B24: cmja7vdp100jwzc4ehwy2mydu | C24: cmja7vz2100kdzc4exo90gnds | D24: test_ac15 | E24: Scenario_2_v3 | F24: 7 | G24: imagination_and_possibility | H24: 0.1635 | I24: 0.25691842 | J24: 0.30583589 | K24: =J24-I24 -> 0.048917472 | L24: 0.75642044
A25: fa9c1b06-b05c-413d-b833-abca412700af | B25: cmja7vdp100jwzc4ehwy2mydu | C25: cmja7vz2100kdzc4exo90gnds | D25: test_ac15 | E25: Scenario_2_v3 | F25: 7 | G25: context_dependent_expression | H25: 0.1595 | I25: 0.25061048 | J25: 0.26441787 | K25: =J25-I25 -> 0.013807398 | L25: 0.75642044
A26: fa9c1b06-b05c-413d-b833-abca412700af | B26: cmja7vdp100jwzc4ehwy2mydu | C26: cmja7vz2100kdzc4exo90gnds | D26: test_ac15 | E26: Scenario_2_v3 | F26: 7 | G26: truth_and_fact | H26: 0.1 | I26: 0.14990223 | J26: 0.25384494 | K26: =J26-I26 -> 0.1039427 | L26: 0.75642044
A27: 648500d2-4c59-4a0d-81e6-00a10821f3c3 | B27: cmja7x49y00khzc4eryu1vt7s | C27: cmja7xwnn00kyzc4ee1ce55tn | D27: test_ac15 | E27: Scenario_2_v3 | F27: 9 | G27: practicality_and_feasibility | H27: 0.1979 | I27: 0.30217863 | J27: 0.38098 | K27: =J27-I27 -> 0.078801374 | L27: 0.62046218 | N27: =AVERAGE(K27:K32) -> 0.078793483
A28: 648500d2-4c59-4a0d-81e6-00a10821f3c3 | B28: cmja7x49y00khzc4eryu1vt7s | C28: cmja7xwnn00kyzc4ee1ce55tn | D28: test_ac15 | E28: Scenario_2_v3 | F28: 9 | G28: temporal_dynamics | H28: 0.1907 | I28: 0.29110324 | J28: 0.35169146 | K28: =J28-I28 -> 0.060588222 | L28: 0.62046218
A29: 648500d2-4c59-4a0d-81e6-00a10821f3c3 | B29: cmja7x49y00khzc4eryu1vt7s | C29: cmja7xwnn00kyzc4ee1ce55tn | D29: test_ac15 | E29: Scenario_2_v3 | F29: 9 | G29: sovereignty | H29: 0.1757 | I29: 0.26819993 | J29: 0.31463535 | K29: =J29-I29 -> 0.046435417 | L29: 0.62046218
A30: 648500d2-4c59-4a0d-81e6-00a10821f3c3 | B30: cmja7x49y00khzc4eryu1vt7s | C30: cmja7xwnn00kyzc4ee1ce55tn | D30: test_ac15 | E30: Scenario_2_v3 | F30: 9 | G30: affective_interface | H30: 0.1723 | I30: 0.26309495 | J30: 0.33218556 | K30: =J30-I30 -> 0.069090612 | L30: 0.62046218
A31: 648500d2-4c59-4a0d-81e6-00a10821f3c3 | B31: cmja7x49y00khzc4eryu1vt7s | C31: cmja7xwnn00kyzc4ee1ce55tn | D31: test_ac15 | E31: Scenario_2_v3 | F31: 9 | G31: mathematics_computer_science_engineering | H31: 0.1634 | I31: 0.24951848 | J31: 0.37266003 | K31: =J31-I31 -> 0.12314155 | L31: 0.62046218
A32: 648500d2-4c59-4a0d-81e6-00a10821f3c3 | B32: cmja7x49y00khzc4eryu1vt7s | C32: cmja7xwnn00kyzc4ee1ce55tn | D32: test_ac15 | E32: Scenario_2_v3 | F32: 9 | G32: truth_and_fact | H32: 0.1 | I32: 0.1889232 | J32: 0.28362691 | K32: =J32-I32 -> 0.094703716 | L32: 0.62046218
A33: fd036cb9-f09f-4656-a8c0-d2620210c5e3 | B33: cmja7zjod00l2zc4e4ehcsf1d | C33: cmja80ksn00ljzc4ew6crt6c2 | D33: test_ac15 | E33: Scenario_2_v3 | F33: 11 | G33: practicality_and_feasibility | H33: 0.3091 | I33: 0.2637185 | J33: 0.36767005 | K33: =J33-I33 -> 0.10395154 | L33: 0.798549 | N33: =AVERAGE(K33:K36) -> 0.092602588
A34: fd036cb9-f09f-4656-a8c0-d2620210c5e3 | B34: cmja7zjod00l2zc4e4ehcsf1d | C34: cmja80ksn00ljzc4ew6crt6c2 | D34: test_ac15 | E34: Scenario_2_v3 | F34: 11 | G34: temporal_dynamics | H34: 0.3023 | I34: 0.25788128 | J34: 0.34945593 | K34: =J34-I34 -> 0.091574656 | L34: 0.798549
A35: fd036cb9-f09f-4656-a8c0-d2620210c5e3 | B35: cmja7zjod00l2zc4e4ehcsf1d | C35: cmja80ksn00ljzc4ew6crt6c2 | D35: test_ac15 | E35: Scenario_2_v3 | F35: 11 | G35: mathematics_computer_science_engineering | H35: 0.2886 | I35: 0.24624592 | J35: 0.33690631 | K35: =J35-I35 -> 0.090660385 | L35: 0.798549
A36: fd036cb9-f09f-4656-a8c0-d2620210c5e3 | B36: cmja7zjod00l2zc4e4ehcsf1d | C36: cmja80ksn00ljzc4ew6crt6c2 | D36: test_ac15 | E36: Scenario_2_v3 | F36: 11 | G36: truth_and_fact | H36: 0.1 | I36: 0.15195909 | J36: 0.23618285 | K36: =J36-I36 -> 0.084223767 | L36: 0.798549
A37: 4547fea3-1318-4582-85e4-048adcfac381 | B37: cmja8222100lnzc4edmcsvl6c | C37: cmja82of700m4zc4ecssmiz4k | D37: test_ac15 | E37: Scenario_2_v3 | F37: 13 | G37: practicality_and_feasibility | H37: 0.2042 | I37: 0.26607846 | J37: 0.34001096 | K37: =J37-I37 -> 0.073932501 | L37: 0.75460376 | N37: =AVERAGE(K37:K42) -> 0.10184661
A38: 4547fea3-1318-4582-85e4-048adcfac381 | B38: cmja8222100lnzc4edmcsvl6c | C38: cmja82of700m4zc4ecssmiz4k | D38: test_ac15 | E38: Scenario_2_v3 | F38: 13 | G38: mathematics_computer_science_engineering | H38: 0.1944 | I38: 0.25340395 | J38: 0.34169139 | K38: =J38-I38 -> 0.088287442 | L38: 0.75460376
A39: 4547fea3-1318-4582-85e4-048adcfac381 | B39: cmja8222100lnzc4edmcsvl6c | C39: cmja82of700m4zc4ecssmiz4k | D39: test_ac15 | E39: Scenario_2_v3 | F39: 13 | G39: temporal_dynamics | H39: 0.1911 | I39: 0.24908622 | J39: 0.31987593 | K39: =J39-I39 -> 0.070789714 | L39: 0.75460376
A40: 4547fea3-1318-4582-85e4-048adcfac381 | B40: cmja8222100lnzc4edmcsvl6c | C40: cmja82of700m4zc4ecssmiz4k | D40: test_ac15 | E40: Scenario_2_v3 | F40: 13 | G40: affective_interface | H40: 0.1553 | I40: 0.20244794 | J40: 0.33099298 | K40: =J40-I40 -> 0.12854504 | L40: 0.75460376
A41: 4547fea3-1318-4582-85e4-048adcfac381 | B41: cmja8222100lnzc4edmcsvl6c | C41: cmja82of700m4zc4ecssmiz4k | D41: test_ac15 | E41: Scenario_2_v3 | F41: 13 | G41: sovereignty | H41: 0.1549 | I41: 0.20189747 | J41: 0.34493507 | K41: =J41-I41 -> 0.1430376 | L41: 0.75460376
...

Sheet notes
A1: p calculation
A3: 1. count | B3: =scen2_ac15!P3 -> 139
A4: 2. t statistic | B4: =B10*SQRT((B3-2)/(1-B10^2)) -> 1.9653421
A5: 3. p | B5: =_xlfn.T.DIST.2T(ABS(B4),B3-2) -> 0.051397368
A9: count | B9: correlation weights / activation delta
A10: =B3 -> 139 | B10: =scen2_ac15!Q3 -> 0.16559238

Sheet actdel_prompt_response
B1: prompt_to_response | C1: Average activation/turn | H1: Correlation | I1: count | J1: T-statistic | K1: p
A2: Turn
A3: 1 | B3: 0.82022841 | C3: 0.096093869 | H3: =CORREL(B3:B27,C3:C27) -> 0.14143322 | I3: =COUNT(C3:C27) -> 25 | J3: =H3*SQRT((I3-2)/(1-H3^2)) -> 0.68517743 | K3: =_xlfn.T.DIST.2T(ABS(J3),I3-2) -> 0.50007979
A4: 2 | B4: 0.76459215 | C4: 0.092919337
A5: 3 | B5: 0.72301136 | C5: 0.045096375
A6: 4 | B6: 0.75642044 | C6: 0.052580262
A7: 5 | B7: 0.62046218 | C7: 0.078793483
A8: 6 | B8: 0.798549 | C8: 0.092602588
A9: 7 | B9: 0.75460376 | C9: 0.10184661
A10: 8 | B10: 0.78612837 | C10: 0.098795332
A11: 9 | B11: 0.75325744 | C11: 0.024083629
A12: 10 | B12: 0.80784383 | C12: 0.058489624
A13: 11 | B13: 0.77810084 | C13: 0.10713842
A14: 12 | B14: 0.76245246 | C14: 0.11586751
A15: 13 | B15: 0.72002227 | C15: 0.10683628
... A27: 25 | B27: 0.73057748 | C27: 0.068263477

Sheet inter_system_stats
B2: Prompt-response
A3: turns | B3: ac15 | C3: control | E3: std. Ac15 | F3: std. Control | G3: F. test | H3: T. Test equal variances | I3: T.Test unequal | J3: Mean difference | K3: average scenario | L3: average control
A4: 1 | B4: 0.82022841 | C4: 0.81423911 | E4: =_xlfn.STDEV.S(B4:B28) -> 0.046176143 | F4: =_xlfn.STDEV.S(C4:C28) -> 0.11577762 | G4: =_xlfn.F.TEST(B4:B28,C4:C28) -> 2.7403314e-05 | H4: =_xlfn.T.TEST(B4:B28, C4:C28, 2,2) -> 2.8150938e-11 | I4: =_xlfn.T.TEST(B4:B28,C4:C28, 2,3) -> 9.2678175e-10 | J4: =AVERAGE(B4:B28)-AVERAGE(C4:C28) -> 0.21427897 | K4: =AVERAGE(B4:B28) -> 0.75129303 | L4: =AVERAGE(C4:C28) -> 0.53701406
A5: 2 | B5: 0.76459215 | C5: 0.49037431
A6: 3 | B6: 0.72301136 | C6: 0.51102033
A7: 4 | B7: 0.75642044 | C7: 0.73212747
A8: 5 | B8: 0.62046218 | C8: 0.5045879
A9: 6 | B9: 0.798549 | C9: 0.62221695
A10: 7 | B10: 0.75460376 | C10: 0.5682134
A11: 8 | B11: 0.78612837 | C11: 0.41336821
A12: 9 | B12: 0.75325744 | C12: 0.4696191
A13: 10 | B13: 0.80784383 | C13: 0.70259754
A14: 11 | B14: 0.77810084 | C14: 0.53574689
A15: 12 | B15: 0.76245246 | C15: 0.61680633
A16: 13 | B16: 0.72002227 | C16: 0.52630891
... A28: 25 | B28: 0.73057748 | C28: 0.36540877
B33: Prompt-response
A35: turns | B35: ac15 | C35: hybrid | D35: ac15p | E35: hybsem | G35: ANOVA - Single Factor
A36: 1 | B36: 0.82022841 | C36: 0.82558738 | D36: 0.84283713 | E36: 0.82646574 | G36: Alpha | H36: 0.05
A37: 2 | B37: 0.76459215 | C37: 0.7843254 | D37: 0.75574435 | E37: 0.76029579
A38: 3 | B38: 0.72301136 | C38: 0.74701543 | D38: 0.75246139 | E38: 0.7455131 | G38: Groups | H38: Count | I38: Sum | J38: Mean | K38: Variance
A39: 4 | B39: 0.75642044 | C39: 0.74257299 | D39: 0.75523994 | E39: 0.74023798 | G39: Column 1 | H39: =COUNT(inter_system_stats!$B$35:$B$60) -> 25 | I39: =SUM(inter_system_stats!$B$35:$B$60) -> 18.782326 | J39: =AVERAGE(inter_system_stats!$B$35:$B$60) -> 0.75129303 | K39: =VAR(inter_system_stats!$B$35:$B$60) -> 0.0021322361
A40: 5 | B40: 0.62046218 | C40: 0.6382916 | D40: 0.68196907 | E40: 0.70141781 | G40: Column 2 | H40: =COUNT(inter_system_stats!$C$35:$C$60) -> 25 | I40: =SUM(inter_system_stats!$C$35:$C$60) -> 18.811104 | J40: =AVERAGE(inter_system_stats!$C$35:$C$60) -> 0.75244418 | K40: =VAR(inter_system_stats!$C$35:$C$60) -> 0.0023181036
A41: 6 | B41: 0.798549 | C41: 0.77002186 | D41: 0.80509458 | E41: 0.76441227 | G41: Column 3 | H41: =COUNT(inter_system_stats!$D$35:$D$60) -> 25 | I41: =SUM(inter_system_stats!$D$35:$D$60) -> 18.805159 | J41: =AVERAGE(inter_system_stats!$D$35:$D$60) -> 0.75220636 | K41: =VAR(inter_system_stats!$D$35:$D$60) -> 0.0020240087
A42: 7 | B42: 0.75460376 | C42: 0.77670818 | D42: 0.7314491 | E42: 0.70462919 | G42: Column 4 | H42: =COUNT(inter_system_stats!$E$35:$E$60) -> 25 | I42: =SUM(inter_system_stats!$E$35:$E$60) -> 18.726659 | J42: =AVERAGE(inter_system_stats!$E$35:$E$60) -> 0.74906635 | K42: =VAR(inter_system_stats!$E$35:$E$60) -> 0.0020364168
A43: 8 | B43: 0.78612837 | C43: 0.76689514 | D43: 0.7986994 | E43: 0.77201186
A44: 9 | B44: 0.75325744 | C44: 0.72686528 | D44: 0.75118107 | E44: 0.72188408 | G44: Source of Variation | H44: SS | I44: df | J44: MS | K44: F | L44: P-value | M44: F critical
A45: 10 | B45: 0.80784383 | C45: 0.76670386 | D45: 0.78031701 | E45: 0.80179909 | G45: Between Groups | H45: =SUMPRODUCT(inter_system_stats!$I$39:$I$42,inter_system_stats!$J$39:$J$42)-SUM(inter_system_stats!$I$39:$I$42)^2/SUM(inter_system_stats!$H$39:$H$42) -> 0.00017777105 | I45: =COUNT(inter_system_stats!$I$39:$I$42)-1 -> 3 | J45: =inter_system_stats!$H$45 / inter_system_stats!$I$45 -> 5.9257017e-05 | K45: =inter_system_stats!$J$45 / inter_system_stats!$J$46 -> 0.027850383 | L45: =FDIST(inter_system_stats!$K$45, inter_system_stats!$I$45, inter_system_stats!$I$46) -> 0.99369156 | M45: =FINV(inter_system_stats!$H$36, inter_system_stats!$I$45, inter_system_stats!$I$46) -> 2.6993926
A46: 11 | B46: 0.77810084 | C46: 0.82651214 | D46: 0.78896492 | E46: 0.82639187 | G46: Within Groups | H46: =SUM(DEVSQ(inter_system_stats!$B$35:$B$60),DEVSQ(inter_system_stats!$C$35:$C$60),DEVSQ(inter_system_stats!$D$35:$D$60),DEVSQ(inter_system_stats!$E$35:$E$60)) -> 0.20425837 | I46: =SUM(inter_system_stats!$H$39:$H$42)-COUNT(inter_system_stats!$H$39:$H$42) -> 96 | J46: =inter_system_stats!$H$46 / inter_system_stats!$I$46 -> 0.0021276913
A47: 12 | B47: 0.76245246 | C47: 0.76273614 | D47: 0.74442966 | E47: 0.74557662 | G47: Total | H47: =DEVSQ(inter_system_stats!$B$35:$B$60,inter_system_stats!$C$35:$C$60,inter_system_stats!$D$35:$D$60,inter_system_stats!$E$35:$E$60) -> 0.20443614 | I47: =SUM(inter_system_stats!$H$39:$H$42) - 1 -> 99
A48: 13 | B48: 0.72002227 | C48: 0.7101601 | D48: 0.76434794 | E48: 0.73930479
A49: 14 | B49: 0.73869436 | C49: 0.73437638 | D49: 0.71664792 | E49: 0.71677589
A50: 15 | B50: 0.74342183 | C50: 0.75654224 | D50: 0.76192925 | E50: 0.7233547
A51: 16 | B51: 0.76347969 | C51: 0.77373202 | D51: 0.74274873 | E51: 0.7414815
A52: 17 | B52: 0.74466799 | C52: 0.81269061 | D52: 0.76420987 | E52: 0.78281323
A53: 18 | B53: 0.69508995 | C53: 0.72648885 | D53: 0.70079627 | E53: 0.68392473
A54: 19 | B54: 0.71974841 | C54: 0.76330056 | D54: 0.71628406 | E54: 0.74186163
A55: 20 | B55: 0.85011013 | C55: 0.81653813 | D55: 0.83902354 | E55: 0.86129103
A56: 21 | B56: 0.73465848 | C56: 0.64339143 | D56: 0.70402483 | E56: 0.72699778
A57: 22 | B57: 0.7022056 | C57: 0.76925587 | D57: 0.68499859 | E57: 0.66522196
...

Sheet std delta(sim)-delta(sim-1)
B2: ac15 | C2: hybrid | D2: ac15p | E2: hybsem
B3: 0.82022841 | C3: 0.82558738 | D3: 0.84283713 | E3: 0.82646574
B4: 0.76459215 | C4: 0.7843254 | D4: 0.75574435 | E4: 0.76029579
B5: 0.72301136 | C5: 0.74701543 | D5: 0.75246139 | E5: 0.7455131
B6: 0.75642044 | C6: 0.74257299 | D6: 0.75523994 | E6: 0.74023798
B7: 0.62046218 | C7: 0.6382916 | D7: 0.68196907 | E7: 0.70141781
B8: 0.798549 | C8: 0.77002186 | D8: 0.80509458 | E8: 0.76441227
B9: 0.75460376 | C9: 0.77670818 | D9: 0.7314491 | E9: 0.70462919
B10: 0.78612837 | C10: 0.76689514 | D10: 0.7986994 | E10: 0.77201186
B11: 0.75325744 | C11: 0.72686528 | D11: 0.75118107 | E11: 0.72188408
B12: 0.80784383 | C12: 0.76670386 | D12: 0.78031701 | E12: 0.80179909
B13: 0.77810084 | C13: 0.82651214 | D13: 0.78896492 | E13: 0.82639187
B14: 0.76245246 | C14: 0.76273614 | D14: 0.74442966 | E14: 0.74557662
... B27: 0.73057748 | C27: 0.72723041 | D27: 0.71511197 | E27: 0.72503242
A29: deltas: | G29: stdev:
B30: ac15 | C30: hybrid | D30: ac15p | E30: hybsem | G30: ac15 | H30: hybrid | I30: ac15p | J30: hybsem
A31: 2 | B31: =B4-B3 -> -0.055636266 | C31: =C4-C3 -> -0.041261982 | D31: =D4-D3 -> -0.087092785 | E31: =E4-E3 -> -0.066169952 | G31: =_xlfn.STDEV.S(B31:B54) -> 0.069153109 | H31: =_xlfn.STDEV.S(C31:C54) -> 0.071806546 | I31: =_xlfn.STDEV.S(D31:D54) -> 0.06849765 | J31: =_xlfn.STDEV.S(E31:E54) -> 0.06450649
A32: 3 | B32: =B5-B4 -> -0.041580783 | C32: =C5-C4 -> -0.037309967 | D32: =D5-D4 -> -0.0032829615 | E32: =E5-E4 -> -0.014782687
A33: 4 | B33: =B6-B5 -> 0.033409078 | C33: =C6-C5 -> -0.0044424464 | D33: =D6-D5 -> 0.0027785522 | E33: =E6-E5 -> -0.0052751272
A34: 5 | B34: =B7-B6 -> -0.13595827 | C34: =C7-C6 -> -0.10428138 | D34: =D7-D6 -> -0.073270871 | E34: =E7-E6 -> -0.03882017
A35: 6 | B35: =B8-B7 -> 0.17808683 | C35: =C8-C7 -> 0.13173026 | D35: =D8-D7 -> 0.12312552 | E35: =E8-E7 -> 0.062994462
A36: 7 | B36: =B9-B8 -> -0.043945241 | C36: =C9-C8 -> 0.006686316 | D36: =D9-D8 -> -0.073645486 | E36: =E9-E8 -> -0.059783081
A37: 8 | B37: =B10-B9 -> 0.031524604 | C37: =C10-C9 -> -0.009813041 | D37: =D10-D9 -> 0.0672503 | E37: =E10-E9 -> 0.067382675
A38: 9 | B38: =B11-B10 -> -0.032870931 | C38: =C11-C10 -> -0.040029853 | D38: =D11-D10 -> -0.047518331 | E38: =E11-E10 -> -0.050127785
A39: 10 | B39: =B12-B11 -> 0.054586397 | C39: =C12-C11 -> 0.039838577 | D39: =D12-D11 -> 0.029135945 | E39: =E12-E11 -> 0.079915016
A40: 11 | B40: =B13-B12 -> -0.02974299 | C40: =C13-C12 -> 0.059808283 | D40: =D13-D12 -> 0.0086479082 | E40: =E13-E12 -> 0.024592776
A41: 12 | B41: =B14-B13 -> -0.015648384 | C41: =C14-C13 -> -0.063776003 | D41: =D14-D13 -> -0.044535263 | E41: =E14-E13 -> -0.080815247
A42: 13 | B42: =B15-B14 -> -0.042430185 | C42: =C15-C14 -> -0.052576036 | D42: =D15-D14 -> 0.019918284 | E42: =E15-E14 -> -0.0062718313
A43: 14 | B43: =B16-B15 -> 0.018672086 | C43: =C16-C15 -> 0.024216281 | D43: =D16-D15 -> -0.047700018 | E43: =E16-E15 -> -0.022528901
... A54: 25 | B54: =B27-B26 -> -0.060400574 | C54: =C27-C26 -> -0.031261473 | D54: =D27-D26 -> -0.094724639 | E54: =E27-E26 -> -0.021184373
