Workbook

Sheet scen7_ac15
A1: turnId | B1: user_id | C1: assistant_id | D1: projectName | E1: sessionName | F1: seq | G1: anchorName | H1: weight | I1: promptSim | J1: responseSim | K1: activation delta | L1: prompt_to_response | P1: count | Q1: activation delta average | R1: correlation weights / activation delta | S1: p
P2: =COUNT(K3:K137) -> 135 | Q2: =AVERAGE(K3:K137) -> 0.046204621 | R2: =CORREL(H3:H137,K3:K137) -> 0.10836359 | S2: 0.211
A3: 82aafe6a-83d2-4d83-8442-754e3cc88971 | B3: cmjjwxxuc01o1zceelpy270qm | C3: cmjjwz1pn01oizceepc6qdson | D3: test_ac15 | E3: Scenario_7 | F3: 0 | G3: temporal_dynamics | H3: 0.3244 | I3: 0.25375928 | J3: 0.32841478 | K3: =J3-I3 -> 0.074655504 | L3: 0.72607266
A4: 82aafe6a-83d2-4d83-8442-754e3cc88971 | B4: cmjjwxxuc01o1zceelpy270qm | C4: cmjjwz1pn01oizceepc6qdson | D4: test_ac15 | E4: Scenario_7 | F4: 0 | G4: imagination_and_possibility | H4: 0.2993 | I4: 0.23417292 | J4: 0.31660555 | K4: =J4-I4 -> 0.082432628 | L4: 0.72607266
A5: 82aafe6a-83d2-4d83-8442-754e3cc88971 | B5: cmjjwxxuc01o1zceelpy270qm | C5: cmjjwz1pn01oizceepc6qdson | D5: test_ac15 | E5: Scenario_7 | F5: 0 | G5: practicality_and_feasibility | H5: 0.2763 | I5: 0.21612778 | J5: 0.34607448 | K5: =J5-I5 -> 0.12994669 | L5: 0.72607266
A6: 82aafe6a-83d2-4d83-8442-754e3cc88971 | B6: cmjjwxxuc01o1zceelpy270qm | C6: cmjjwz1pn01oizceepc6qdson | D6: test_ac15 | E6: Scenario_7 | F6: 0 | G6: truth_and_fact | H6: 0.1 | I6: 0.14119919 | J6: 0.2282501 | K6: =J6-I6 -> 0.08705091 | L6: 0.72607266
A7: 302fc833-817b-4338-9e9e-bff9f1fe197c | B7: cmjjwz7uz01omzceevwgt8qgi | C7: cmjjwztil01p3zceeenggruhc | D7: test_ac15 | E7: Scenario_7 | F7: 2 | G7: imagination_and_possibility | H7: 0.2074 | I7: 0.26472206 | J7: 0.37615662 | K7: =J7-I7 -> 0.11143455 | L7: 0.6826637
A8: 302fc833-817b-4338-9e9e-bff9f1fe197c | B8: cmjjwz7uz01omzceevwgt8qgi | C8: cmjjwztil01p3zceeenggruhc | D8: test_ac15 | E8: Scenario_7 | F8: 2 | G8: temporal_dynamics | H8: 0.1944 | I8: 0.24810124 | J8: 0.35074161 | K8: =J8-I8 -> 0.10264038 | L8: 0.6826637
A9: 302fc833-817b-4338-9e9e-bff9f1fe197c | B9: cmjjwz7uz01omzceevwgt8qgi | C9: cmjjwztil01p3zceeenggruhc | D9: test_ac15 | E9: Scenario_7 | F9: 2 | G9: electricity | H9: 0.1699 | I9: 0.21684254 | J9: 0.2853309 | K9: =J9-I9 -> 0.06848836 | L9: 0.6826637
A10: 302fc833-817b-4338-9e9e-bff9f1fe197c | B10: cmjjwz7uz01omzceevwgt8qgi | C10: cmjjwztil01p3zceeenggruhc | D10: test_ac15 | E10: Scenario_7 | F10: 2 | G10: practicality_and_feasibility | H10: 0.1653 | I10: 0.21100146 | J10: 0.3201305 | K10: =J10-I10 -> 0.10912904 | L10: 0.6826637
A11: 302fc833-817b-4338-9e9e-bff9f1fe197c | B11: cmjjwz7uz01omzceevwgt8qgi | C11: cmjjwztil01p3zceeenggruhc | D11: test_ac15 | E11: Scenario_7 | F11: 2 | G11: freedom_and_limitations | H11: 0.163 | I11: 0.20801841 | J11: 0.33901398 | K11: =J11-I11 -> 0.13099557 | L11: 0.6826637
A12: 302fc833-817b-4338-9e9e-bff9f1fe197c | B12: cmjjwz7uz01omzceevwgt8qgi | C12: cmjjwztil01p3zceeenggruhc | D12: test_ac15 | E12: Scenario_7 | F12: 2 | G12: truth_and_fact | H12: 0.1 | I12: 0.15437749 | J12: 0.27565811 | K12: =J12-I12 -> 0.12128062 | L12: 0.6826637
A13: 7e3010f0-6cf5-4cba-950e-71f4db2f81f8 | B13: cmjjx024y01p7zceedzv6ikuw | C13: cmjjx0mni01pozceej6qar53q | D13: test_ac15 | E13: Scenario_7 | F13: 4 | G13: imagination_and_possibility | H13: 0.9 | I13: 0.22739828 | J13: 0.32008454 | K13: =J13-I13 -> 0.092686252 | L13: 0.61522445
A14: 7e3010f0-6cf5-4cba-950e-71f4db2f81f8 | B14: cmjjx024y01p7zceedzv6ikuw | C14: cmjjx0mni01pozceej6qar53q | D14: test_ac15 | E14: Scenario_7 | F14: 4 | G14: truth_and_fact | H14: 0.1 | I14: 0.14959753 | J14: 0.25518047 | K14: =J14-I14 -> 0.10558295 | L14: 0.61522445
... A137: b113521f-8ef5-4b66-945f-d048bce6a3f6 | B137: cmjjxkgi90221zceepgy0uiuy | C137: cmjjxl07d022izceemto36uqw | D137: test_ac15 | E137: Scenario_7 | F137: 48 | G137: truth_and_fact | H137: 0.1 | I137: 0.28160293 | J137: 0.2482603 | K137: =J137-I137 -> -0.033342626 | L137: 0.74520686

Sheet Notes
A1: p calculation
A3: 1. count | B3: =scen7_ac15!P2 -> 135
A4: 2. t statistic | B4: =B10*SQRT((B3-2)/(1-B10^2)) -> 1.2571126
A5: 3. p | B5: =_xlfn.T.DIST.2T(ABS(B4),B3-2) -> 0.21091599
A9: count | B9: correlation weights / activation delta
A10: =B3 -> 135 | B10: =scen7_ac15!R2 -> 0.10836359

Sheet actdel_prompt_response
A1: Prompt-response
A2: Turn | B2: ac15
A3: 1 | B3: 0.72607266
A4: 2 | B4: 0.6826637
A5: 3 | B5: 0.61522445
A6: 4 | B6: 0.72861828
A7: 5 | B7: 0.68860406
A8: 6 | B8: 0.66907489
A9: 7 | B9: 0.7593725
A10: 8 | B10: 0.6958285
A11: 9 | B11: 0.77989957
A12: 10 | B12: 0.6325723
A13: 11 | B13: 0.73306421
A14: 12 | B14: 0.69302754
... A27: 25 | B27: 0.74520686

Sheet inter_system_stats
A1: Prompt-response
A2: Turn | B2: ac15 | C2: control | D2: activation delta | E2: Choose` | F2: std. Ac15 | G2: std. Control | H2: F. test | I2: T. Test equal variances | J2: T.Test unequal | K2: Mean difference | L2: mean AC15 | M2: Mean control
A3: 1 | B3: 0.72607266 | C3: 0.78035784 | D3: =B3-C3 -> -0.054285187 | F3: =_xlfn.STDEV.S(B3:B27) -> 0.057280753 | G3: =_xlfn.STDEV.S(C3:C27) -> 0.10899113 | H3: =_xlfn.F.TEST(B3:B27,C3:C27) -> 0.0025165239 | I3: =_xlfn.T.TEST(B3:B27, C3:C27, 2,2) -> 3.7967274e-07 | J3: =_xlfn.T.TEST(B3:B27,C3:C27, 2,3) -> 9.689303e-07 | K3: =AVERAGE(B3:B27)-AVERAGE(C3:C27) -> 0.14484285 | L3: =AVERAGE(B3:B27) -> 0.71309316 | M3: =AVERAGE(C3:C27) -> 0.56825031
A4: 2 | B4: 0.6826637 | C4: 0.41620709 | D4: =B4-C4 -> 0.2664566 | E4: x
A5: 3 | B5: 0.61522445 | C5: 0.44069473 | D5: =B5-C5 -> 0.17452972 | E5: x
A6: 4 | B6: 0.72861828 | C6: 0.50298343 | D6: =B6-C6 -> 0.22563485 | E6: x
A7: 5 | B7: 0.68860406 | C7: 0.64837824 | D7: =B7-C7 -> 0.040225819
A8: 6 | B8: 0.66907489 | C8: 0.55690541 | D8: =B8-C8 -> 0.11216948
A9: 7 | B9: 0.7593725 | C9: 0.67658778 | D9: =B9-C9 -> 0.082784723
A10: 8 | B10: 0.6958285 | C10: 0.53755699 | D10: =B10-C10 -> 0.15827152
A11: 9 | B11: 0.77989957 | C11: 0.54745066 | D11: =B11-C11 -> 0.23244892 | E11: x
A12: 10 | B12: 0.6325723 | C12: 0.40447571 | D12: =B12-C12 -> 0.22809659 | E12: x
A13: 11 | B13: 0.73306421 | C13: 0.57351245 | D13: =B13-C13 -> 0.15955176
A14: 12 | B14: 0.69302754 | C14: 0.68842639 | D14: =B14-C14 -> 0.0046011524
A15: 13 | B15: 0.70443832 | C15: 0.53673254 | D15: =B15-C15 -> 0.16770578
A16: 14 | B16: 0.8229238 | C16: 0.70690542 | D16: =B16-C16 -> 0.11601838
A17: 15 | B17: 0.59885683 | C17: 0.55927598 | D17: =B17-C17 -> 0.039580846
A18: 16 | B18: 0.74588549 | C18: 0.6966876 | D18: =B18-C18 -> 0.049197892
A19: 17 | B19: 0.62741304 | C19: 0.48999145 | D19: =B19-C19 -> 0.13742159
A20: 18 | B20: 0.76472415 | C20: 0.70377733 | D20: =B20-C20 -> 0.060946825
A21: 19 | B21: 0.66544272 | C21: 0.53831183 | D21: =B21-C21 -> 0.12713089
A22: 20 | B22: 0.73912001 | C22: 0.65861958 | D22: =B22-C22 -> 0.080500433
A23: 21 | B23: 0.74085559 | C23: 0.40765354 | D23: =B23-C23 -> 0.33320205 | E23: x
A24: 22 | B24: 0.72498603 | C24: 0.51587679 | D24: =B24-C24 -> 0.20910924
A25: 23 | B25: 0.73254807 | C25: 0.47404366 | D25: =B25-C25 -> 0.25850441 | E25: x
A26: 24 | B26: 0.81090533 | C26: 0.69013711 | D26: =B26-C26 -> 0.12076822
A27: 25 | B27: 0.74520686 | C27: 0.4547081 | D27: =B27-C27 -> 0.29049875 | E27: x
A29: General
A31: Turn | B31: ac15p | C31: Hybrid | D31: Hybsem | E31: ac15 | F31: control | H31: ANOVA - Single Factor
A32: 1 | B32: 0.72660445 | C32: 0.74561822 | D32: 0.72409953 | E32: 0.72607266 | F32: 0.78035784 | H32: Alpha | I32: 0.05
A33: 2 | B33: 0.70895983 | C33: 0.73196562 | D33: 0.69040579 | E33: 0.6826637 | F33: 0.41620709
A34: 3 | B34: 0.65625079 | C34: 0.55634941 | D34: 0.66442409 | E34: 0.61522445 | F34: 0.44069473 | H34: Groups | I34: Count | J34: Sum | K34: Mean | L34: Variance
A35: 4 | B35: 0.68248006 | C35: 0.74696128 | D35: 0.73787209 | E35: 0.72861828 | F35: 0.50298343 | H35: Column 1 | I35: =COUNT(inter_system_stats!$B$31:$B$56) -> 25 | J35: =SUM(inter_system_stats!$B$31:$B$56) -> 17.785397 | K35: =AVERAGE(inter_system_stats!$B$31:$B$56) -> 0.71141589 | L35: =VAR(inter_system_stats!$B$31:$B$56) -> 0.0022639834
A36: 5 | B36: 0.75066609 | C36: 0.73630313 | D36: 0.73166495 | E36: 0.68860406 | F36: 0.64837824 | H36: Column 2 | I36: =COUNT(inter_system_stats!$C$31:$C$56) -> 25 | J36: =SUM(inter_system_stats!$C$31:$C$56) -> 18.057281 | K36: =AVERAGE(inter_system_stats!$C$31:$C$56) -> 0.72229125 | L36: =VAR(inter_system_stats!$C$31:$C$56) -> 0.0025385628
A37: 6 | B37: 0.69003761 | C37: 0.69306052 | D37: 0.72767432 | E37: 0.66907489 | F37: 0.55690541 | H37: Column 3 | I37: =COUNT(inter_system_stats!$D$31:$D$56) -> 25 | J37: =SUM(inter_system_stats!$D$31:$D$56) -> 18.015458 | K37: =AVERAGE(inter_system_stats!$D$31:$D$56) -> 0.72061831 | L37: =VAR(inter_system_stats!$D$31:$D$56) -> 0.0024899574
A38: 7 | B38: 0.70889799 | C38: 0.74859756 | D38: 0.78515917 | E38: 0.7593725 | F38: 0.67658778 | H38: Column 4 | I38: =COUNT(inter_system_stats!$E$31:$E$56) -> 25 | J38: =SUM(inter_system_stats!$E$31:$E$56) -> 17.827329 | K38: =AVERAGE(inter_system_stats!$E$31:$E$56) -> 0.71309316 | L38: =VAR(inter_system_stats!$E$31:$E$56) -> 0.0032810847
A39: 8 | B39: 0.68554662 | C39: 0.70516594 | D39: 0.69936593 | E39: 0.6958285 | F39: 0.53755699
A40: 9 | B40: 0.72762952 | C40: 0.75036872 | D40: 0.74686473 | E40: 0.77989957 | F40: 0.54745066 | H40: Source of Variation | I40: SS | J40: df | K40: MS | L40: F | M40: P-value | N40: F critical
A41: 10 | B41: 0.63748551 | C41: 0.682433 | D41: 0.68571667 | E41: 0.6325723 | F41: 0.40447571 | H41: Between Groups | I41: =SUMPRODUCT(inter_system_stats!$J$35:$J$38,inter_system_stats!$K$35:$K$38)-SUM(inter_system_stats!$J$35:$J$38)^2/SUM(inter_system_stats!$I$35:$I$38) -> 0.0021862684 | J41: =COUNT(inter_system_stats!$J$35:$J$38)-1 -> 3 | K41: =inter_system_stats!$I$41 / inter_system_stats!$J$41 -> 0.00072875612 | L41: =inter_system_stats!$K$41 / inter_system_stats!$K$42 -> 0.27568924 | M41: =FDIST(inter_system_stats!$L$41, inter_system_stats!$J$41, inter_system_stats!$J$42) -> 0.84280843 | N41: =FINV(inter_system_stats!$I$32, inter_system_stats!$J$41, inter_system_stats!$J$42) -> 2.6993926
A42: 11 | B42: 0.71798946 | C42: 0.72387381 | D42: 0.76511491 | E42: 0.73306421 | F42: 0.57351245 | H42: Within Groups | I42: =SUM(DEVSQ(inter_system_stats!$B$31:$B$56),DEVSQ(inter_system_stats!$C$31:$C$56),DEVSQ(inter_system_stats!$D$31:$D$56),DEVSQ(inter_system_stats!$E$31:$E$56)) -> 0.25376612 | J42: =SUM(inter_system_stats!$I$35:$I$38)-COUNT(inter_system_stats!$I$35:$I$38) -> 96 | K42: =inter_system_stats!$I$42 / inter_system_stats!$J$42 -> 0.0026433971
...

Sheet simst
B2: Turn | C2: ac15p | D2: Hybrid | E2: Hybsem | F2: ac15
B3: 1 | C3: 0.72660445 | D3: 0.74561822 | E3: 0.72409953 | F3: 0.72607266
B4: 2 | C4: 0.70895983 | D4: 0.73196562 | E4: 0.69040579 | F4: 0.6826637
B5: 3 | C5: 0.65625079 | D5: 0.55634941 | E5: 0.66442409 | F5: 0.61522445
B6: 4 | C6: 0.68248006 | D6: 0.74696128 | E6: 0.73787209 | F6: 0.72861828
B7: 5 | C7: 0.75066609 | D7: 0.73630313 | E7: 0.73166495 | F7: 0.68860406
B8: 6 | C8: 0.69003761 | D8: 0.69306052 | E8: 0.72767432 | F8: 0.66907489
B9: 7 | C9: 0.70889799 | D9: 0.74859756 | E9: 0.78515917 | F9: 0.7593725
B10: 8 | C10: 0.68554662 | D10: 0.70516594 | E10: 0.69936593 | F10: 0.6958285
B11: 9 | C11: 0.72762952 | D11: 0.75036872 | E11: 0.74686473 | F11: 0.77989957
B12: 10 | C12: 0.63748551 | D12: 0.682433 | E12: 0.68571667 | F12: 0.6325723
B13: 11 | C13: 0.71798946 | D13: 0.72387381 | E13: 0.76511491 | F13: 0.73306421
B14: 12 | C14: 0.77090629 | D14: 0.66770176 | E14: 0.73664424 | F14: 0.69302754
... B27: 25 | C27: 0.76958641 | D27: 0.727724 | E27: 0.76225457 | F27: 0.74520686
H30: stdev
A31: deltas
C32: ac15p | D32: Hybrid | E32: Hybsem | F32: ac15 | H32: ac15p | I32: Hybrid | J32: Hybsem | K32: ac15
C33: =C4-C3 -> -0.017644618 | D33: =D4-D3 -> -0.0136526 | E33: =E4-E3 -> -0.033693747 | F33: =F4-F3 -> -0.043408957 | H33: =_xlfn.STDEV.S(C33:C56) -> 0.079537002 | I33: =_xlfn.STDEV.S(D33:D56) -> 0.083647598 | J33: =_xlfn.STDEV.S(E33:E56) -> 0.085757231 | K33: =_xlfn.STDEV.S(F33:F56) -> 0.097548204
C34: =C5-C4 -> -0.052709038 | D34: =D5-D4 -> -0.17561621 | E34: =E5-E4 -> -0.025981695 | F34: =F5-F4 -> -0.067439244
C35: =C6-C5 -> 0.026229273 | D35: =D6-D5 -> 0.19061187 | E35: =E6-E5 -> 0.073447997 | F35: =F6-F5 -> 0.11339382
C36: =C7-C6 -> 0.068186025 | D36: =D7-D6 -> -0.010658149 | E36: =E7-E6 -> -0.0062071368 | F36: =F7-F6 -> -0.040014219
C37: =C8-C7 -> -0.060628475 | D37: =D8-D7 -> -0.043242609 | E37: =E8-E7 -> -0.0039906345 | F37: =F8-F7 -> -0.019529163
C38: =C9-C8 -> 0.018860377 | D38: =D9-D8 -> 0.055537043 | E38: =E9-E8 -> 0.057484856 | F38: =F9-F8 -> 0.090297611
C39: =C10-C9 -> -0.02335137 | D39: =D10-D9 -> -0.043431626 | E39: =E10-E9 -> -0.08579324 | F39: =F10-F9 -> -0.063544
C40: =C11-C10 -> 0.042082895 | D40: =D11-D10 -> 0.045202778 | E40: =E11-E10 -> 0.047498799 | F40: =F11-F10 -> 0.084071069
C41: =C12-C11 -> -0.090144 | D41: =D12-D11 -> -0.06793572 | E41: =E12-E11 -> -0.061148062 | F41: =F12-F11 -> -0.14732727
C42: =C13-C12 -> 0.080503942 | D42: =D13-D12 -> 0.041440818 | E42: =E13-E12 -> 0.079398239 | F42: =F13-F12 -> 0.10049191
C43: =C14-C13 -> 0.052916836 | D43: =D14-D13 -> -0.056172051 | E43: =E14-E13 -> -0.028470673 | F43: =F14-F13 -> -0.040036671
C44: =C15-C14 -> -0.061078393 | D44: =D15-D14 -> 0.062250917 | E44: =E15-E14 -> -0.057977725 | F44: =F15-F14 -> 0.011410775
C45: =C16-C15 -> 0.1149481 | D45: =D16-D15 -> 0.065216875 | E45: =E16-E15 -> 0.12148214 | F45: =F16-F15 -> 0.11848548
... C56: =C27-C26 -> -0.0012997055 | D56: =D27-D26 -> -0.082441165 | E56: =E27-E26 -> -0.031072726 | F56: =F27-F26 -> -0.065698473
