Workbook

Sheet scen5_ac15
A1: turnId | B1: user_id | C1: assistant_id | D1: projectName | E1: sessionName | F1: seq | G1: anchorName | H1: weight | I1: promptSim | J1: responseSim | K1: activation delta | L1: prompt_to_response | P1: count | Q1: activation delta average | R1: correlation weights / activation delta | S1: p
P2: =COUNT(K3:K152) -> 150 | Q2: =AVERAGE(K3:K152) -> 0.032479658 | R2: =CORREL(H3:H152,K3:K152) -> -0.20083069 | S2: =Notes!B5 -> 0.013730116
A3: ba2aab4f-3cf5-4c85-b248-dd8b6e05b5d2 | B3: cmjfe08pa00h2zca6bnu9qeal | C3: cmjfe15o200hjzca6fagnpsd7 | D3: test_ac15 | E3: scenario_5 | F3: 1 | G3: temporal_dynamics | H3: 0.1911 | I3: 0.3984358 | J3: 0.45096623 | K3: =J3-I3 -> 0.052530429 | L3: 0.75408939
A4: ba2aab4f-3cf5-4c85-b248-dd8b6e05b5d2 | B4: cmjfe08pa00h2zca6bnu9qeal | C4: cmjfe15o200hjzca6fagnpsd7 | D4: test_ac15 | E4: scenario_5 | F4: 1 | G4: practicality_and_feasibility | H4: 0.1811 | I4: 0.3776332 | J4: 0.42432583 | K4: =J4-I4 -> 0.046692636 | L4: 0.75408939
A5: ba2aab4f-3cf5-4c85-b248-dd8b6e05b5d2 | B5: cmjfe08pa00h2zca6bnu9qeal | C5: cmjfe15o200hjzca6fagnpsd7 | D5: test_ac15 | E5: scenario_5 | F5: 1 | G5: mathematics_computer_science_engineering | H5: 0.1801 | I5: 0.37552564 | J5: 0.41587638 | K5: =J5-I5 -> 0.040350741 | L5: 0.75408939
A6: ba2aab4f-3cf5-4c85-b248-dd8b6e05b5d2 | B6: cmjfe08pa00h2zca6bnu9qeal | C6: cmjfe15o200hjzca6fagnpsd7 | D6: test_ac15 | E6: scenario_5 | F6: 1 | G6: affective_interface | H6: 0.1745 | I6: 0.36389509 | J6: 0.40472094 | K6: =J6-I6 -> 0.040825848 | L6: 0.75408939
A7: ba2aab4f-3cf5-4c85-b248-dd8b6e05b5d2 | B7: cmjfe08pa00h2zca6bnu9qeal | C7: cmjfe15o200hjzca6fagnpsd7 | D7: test_ac15 | E7: scenario_5 | F7: 1 | G7: imagination_and_possibility | H7: 0.1731 | I7: 0.36099453 | J7: 0.41208367 | K7: =J7-I7 -> 0.051089133 | L7: 0.75408939
A8: ba2aab4f-3cf5-4c85-b248-dd8b6e05b5d2 | B8: cmjfe08pa00h2zca6bnu9qeal | C8: cmjfe15o200hjzca6fagnpsd7 | D8: test_ac15 | E8: scenario_5 | F8: 1 | G8: truth_and_fact | H8: 0.1 | I8: 0.23857066 | J8: 0.31346576 | K8: =J8-I8 -> 0.074895096 | L8: 0.75408939
A9: a96bd5ea-0e56-4596-b4d2-2549e7ae1afc | B9: cmjfe26z800hnzca6wcmb4lmr | C9: cmjfe2pj700i4zca6tdewdpzs | D9: test_ac15 | E9: scenario_5 | F9: 3 | G9: temporal_dynamics | H9: 0.2161 | I9: 0.45778433 | J9: 0.4841141 | K9: =J9-I9 -> 0.026329776 | L9: 0.77669571
A10: a96bd5ea-0e56-4596-b4d2-2549e7ae1afc | B10: cmjfe26z800hnzca6wcmb4lmr | C10: cmjfe2pj700i4zca6tdewdpzs | D10: test_ac15 | E10: scenario_5 | F10: 3 | G10: imagination_and_possibility | H10: 0.173 | I10: 0.36647495 | J10: 0.41448103 | K10: =J10-I10 -> 0.048006081 | L10: 0.77669571
A11: a96bd5ea-0e56-4596-b4d2-2549e7ae1afc | B11: cmjfe26z800hnzca6wcmb4lmr | C11: cmjfe2pj700i4zca6tdewdpzs | D11: test_ac15 | E11: scenario_5 | F11: 3 | G11: mathematics_computer_science_engineering | H11: 0.1723 | I11: 0.36509346 | J11: 0.43405 | K11: =J11-I11 -> 0.068956544 | L11: 0.77669571
A12: a96bd5ea-0e56-4596-b4d2-2549e7ae1afc | B12: cmjfe26z800hnzca6wcmb4lmr | C12: cmjfe2pj700i4zca6tdewdpzs | D12: test_ac15 | E12: scenario_5 | F12: 3 | G12: freedom_and_limitations | H12: 0.1703 | I12: 0.36070714 | J12: 0.39607582 | K12: =J12-I12 -> 0.035368678 | L12: 0.77669571
A13: a96bd5ea-0e56-4596-b4d2-2549e7ae1afc | B13: cmjfe26z800hnzca6wcmb4lmr | C13: cmjfe2pj700i4zca6tdewdpzs | D13: test_ac15 | E13: scenario_5 | F13: 3 | G13: practicality_and_feasibility | H13: 0.1684 | I13: 0.35667678 | J13: 0.40953162 | K13: =J13-I13 -> 0.052854844 | L13: 0.77669571
A14: a96bd5ea-0e56-4596-b4d2-2549e7ae1afc | B14: cmjfe26z800hnzca6wcmb4lmr | C14: cmjfe2pj700i4zca6tdewdpzs | D14: test_ac15 | E14: scenario_5 | F14: 3 | G14: truth_and_fact | H14: 0.1 | I14: 0.28937789 | J14: 0.38750407 | K14: =J14-I14 -> 0.09812618 | L14: 0.77669571
... A152: 78e66274-d201-49f0-9f1c-b639e0d402fb | B152: cmjffcazh00v2zca6scrlkp3g | C152: cmjffcnpa00vjzca6dkgmvadp | D152: test_ac15 | E152: scenario_5 | F152: 49 | G152: truth_and_fact | H152: 0.152 | I152: 0.32390368 | J152: 0.34426515 | K152: =J152-I152 -> 0.020361471 | L152: 0.66737839

Sheet Notes
A1: p calculation
A3: 1. count | B3: =scen5_ac15!P2 -> 150
A4: 2. t statistic | B4: =B10*SQRT((B3-2)/(1-B10^2)) -> -2.4940241
A5: 3. p | B5: =_xlfn.T.DIST.2T(ABS(B4),B3-2) -> 0.013730116
A9: count | B9: correlation weights / activation delta
A10: =B3 -> 150 | B10: =scen5_ac15!R2 -> -0.20083069

Sheet actdel_prompt_response
A2: Prompt-response
A3: Turn | B3: ac15
A4: 1 | B4: 0.75408939
A5: 2 | B5: 0.77669571
A6: 3 | B6: 0.73998988
A7: 4 | B7: 0.74224592
A8: 5 | B8: 0.80763856
A9: 6 | B9: 0.7401628
A10: 7 | B10: 0.78103755
A11: 8 | B11: 0.69641748
A12: 9 | B12: 0.7422517
A13: 10 | B13: 0.82422175
A14: 11 | B14: 0.70611649
A15: 12 | B15: 0.77994707
... A28: 25 | B28: 0.66737839

Sheet inter_system_stats
A2: Prompt-response
A3: Turn | B3: ac15 | C3: control | D3: delta | E3: choose | F3: std. Ac15 | G3: std. Control | H3: F. test | I3: T. Test equal variances | J3: T.Test unequal | K3: Mean difference | L3: Average scen | M3: Average control
A4: 1 | B4: 0.75408939 | C4: 0.75451957 | D4: =B4-C4 -> -0.00043017169 | F4: =_xlfn.STDEV.S(B4:B28) -> 0.042716379 | G4: =_xlfn.STDEV.S(C4:C28) -> 0.070588432 | H4: =_xlfn.F.TEST(B4:B28,C4:C28) -> 0.016976398 | I4: =_xlfn.T.TEST(B4:B28, C4:C28, 2,2) -> 1.3266703e-07 | J4: =_xlfn.T.TEST(B4:B28,C4:C28, 2,3) -> 2.7641179e-07 | K4: =AVERAGE(B4:B28)-AVERAGE(C4:C28) -> 0.10199219 | L4: =AVERAGE(B4:B28) -> 0.73704774 | M4: =AVERAGE(C4:C28) -> 0.63505555
A5: 2 | B5: 0.77669571 | C5: 0.58315782 | D5: =B5-C5 -> 0.19353789 | E5: x
A6: 3 | B6: 0.73998988 | C6: 0.61890492 | D6: =B6-C6 -> 0.12108496
A7: 4 | B7: 0.74224592 | C7: 0.74737712 | D7: =B7-C7 -> -0.0051312065
A8: 5 | B8: 0.80763856 | C8: 0.54898023 | D8: =B8-C8 -> 0.25865833 | E8: x ok
A9: 6 | B9: 0.7401628 | C9: 0.63269023 | D9: =B9-C9 -> 0.10747258
A10: 7 | B10: 0.78103755 | C10: 0.70178677 | D10: =B10-C10 -> 0.079250784
A11: 8 | B11: 0.69641748 | C11: 0.58456232 | D11: =B11-C11 -> 0.11185516
A12: 9 | B12: 0.7422517 | C12: 0.63553024 | D12: =B12-C12 -> 0.10672146
A13: 10 | B13: 0.82422175 | C13: 0.69186078 | D13: =B13-C13 -> 0.13236097 | E13: X – no
A14: 11 | B14: 0.70611649 | C14: 0.74687441 | D14: =B14-C14 -> -0.040757919
A15: 12 | B15: 0.77994707 | C15: 0.64610334 | D15: =B15-C15 -> 0.13384372 | E15: x
A16: 13 | B16: 0.70737027 | C16: 0.71426745 | D16: =B16-C16 -> -0.0068971826
A17: 14 | B17: 0.682205 | C17: 0.64598849 | D17: =B17-C17 -> 0.03621651
A18: 15 | B18: 0.66668527 | C18: 0.55912558 | D18: =B18-C18 -> 0.10755969
A19: 16 | B19: 0.74885321 | C19: 0.66444414 | D19: =B19-C19 -> 0.084409063
A20: 17 | B20: 0.74296531 | C20: 0.68292872 | D20: =B20-C20 -> 0.060036595
A21: 18 | B21: 0.7285887 | C21: 0.60902978 | D21: =B21-C21 -> 0.11955892
A22: 19 | B22: 0.74125096 | C22: 0.62513635 | D22: =B22-C22 -> 0.1161146
A23: 20 | B23: 0.72225143 | C23: 0.62889699 | D23: =B23-C23 -> 0.093354434
A24: 21 | B24: 0.8032107 | C24: 0.49049501 | D24: =B24-C24 -> 0.31271568 | E24: x ok
A25: 22 | B25: 0.67321428 | C25: 0.55121839 | D25: =B25-C25 -> 0.12199589
A26: 23 | B26: 0.72384088 | C26: 0.64465959 | D26: =B26-C26 -> 0.079181294
A27: 24 | B27: 0.72756478 | C27: 0.65498089 | D27: =B27-C27 -> 0.072583892
A28: 25 | B28: 0.66737839 | C28: 0.51286959 | D28: =B28-C28 -> 0.1545088 | E28: x ok
A32: General
A34: Turn | B34: ac15p | C34: hybrid | D34: hybsem | E34: ac15 | F34: control
A35: 1 | B35: 0.77595367 | C35: 0.74885829 | D35: 0.76068069 | E35: 0.75408939 | F35: 0.75451957 | H35: ANOVA - Single Factor
A36: 2 | B36: 0.74238116 | C36: 0.75950632 | D36: 0.7151545 | E36: 0.77669571 | F36: 0.58315782 | H36: Alpha | I36: 0.05
A37: 3 | B37: 0.71959451 | C37: 0.71541388 | D37: 0.72734735 | E37: 0.73998988 | F37: 0.61890492
A38: 4 | B38: 0.74468578 | C38: 0.75834839 | D38: 0.7330552 | E38: 0.74224592 | F38: 0.74737712 | H38: Groups | I38: Count | J38: Sum | K38: Mean | L38: Variance
A39: 5 | B39: 0.81047209 | C39: 0.81056506 | D39: 0.80006557 | E39: 0.80763856 | F39: 0.54898023 | H39: Column 1 | I39: =COUNT(inter_system_stats!$B$34:$B$59) -> 25 | J39: =SUM(inter_system_stats!$B$34:$B$59) -> 18.309276 | K39: =AVERAGE(inter_system_stats!$B$34:$B$59) -> 0.73237105 | L39: =VAR(inter_system_stats!$B$34:$B$59) -> 0.0021075812
A40: 6 | B40: 0.72631626 | C40: 0.74228911 | D40: 0.7090712 | E40: 0.7401628 | F40: 0.63269023 | H40: Column 2 | I40: =COUNT(inter_system_stats!$C$34:$C$59) -> 25 | J40: =SUM(inter_system_stats!$C$34:$C$59) -> 18.309431 | K40: =AVERAGE(inter_system_stats!$C$34:$C$59) -> 0.73237725 | L40: =VAR(inter_system_stats!$C$34:$C$59) -> 0.0015741888
A41: 7 | B41: 0.79321544 | C41: 0.76425064 | D41: 0.7749469 | E41: 0.78103755 | F41: 0.70178677 | H41: Column 3 | I41: =COUNT(inter_system_stats!$D$34:$D$59) -> 25 | J41: =SUM(inter_system_stats!$D$34:$D$59) -> 18.277814 | K41: =AVERAGE(inter_system_stats!$D$34:$D$59) -> 0.73111256 | L41: =VAR(inter_system_stats!$D$34:$D$59) -> 0.0012492374
A42: 8 | B42: 0.70459928 | C42: 0.69857772 | D42: 0.75158773 | E42: 0.69641748 | F42: 0.58456232 | H42: Column 4 | I42: =COUNT(inter_system_stats!$E$34:$E$59) -> 25 | J42: =SUM(inter_system_stats!$E$34:$E$59) -> 18.426193 | K42: =AVERAGE(inter_system_stats!$E$34:$E$59) -> 0.73704774 | L42: =VAR(inter_system_stats!$E$34:$E$59) -> 0.0018246891
A43: 9 | B43: 0.75323189 | C43: 0.76611524 | D43: 0.71546563 | E43: 0.7422517 | F43: 0.63553024
A44: 10 | B44: 0.78691806 | C44: 0.7779242 | D44: 0.79344326 | E44: 0.82422175 | F44: 0.69186078 | H44: Source of Variation | I44: SS | J44: df | K44: MS | L44: F | M44: P-value | N44: F critical
A45: 11 | B45: 0.75773765 | C45: 0.73133786 | D45: 0.7308636 | E45: 0.70611649 | F45: 0.74687441 | H45: Between Groups | I45: =SUMPRODUCT(inter_system_stats!$J$39:$J$42,inter_system_stats!$K$39:$K$42)-SUM(inter_system_stats!$J$39:$J$42)^2/SUM(inter_system_stats!$I$39:$I$42) -> 0.00051309066 | J45: =COUNT(inter_system_stats!$J$39:$J$42)-1 -> 3 | K45: =inter_system_stats!$I$45 / inter_system_stats!$J$45 -> 0.00017103022 | L45: =inter_system_stats!$K$45 / inter_system_stats!$K$46 -> 0.10126578 | M45: =FDIST(inter_system_stats!$L$45, inter_system_stats!$J$45, inter_system_stats!$J$46) -> 0.95910616 | N45: =FINV(inter_system_stats!$I$36, inter_system_stats!$J$45, inter_system_stats!$J$46) -> 2.6993926
...

Sheet sims
B2: ac15p | C2: hybrid | D2: hybsem | E2: ac15
B3: 0.77595367 | C3: 0.74885829 | D3: 0.76068069 | E3: 0.75408939
B4: 0.74238116 | C4: 0.75950632 | D4: 0.7151545 | E4: 0.77669571
B5: 0.71959451 | C5: 0.71541388 | D5: 0.72734735 | E5: 0.73998988
B6: 0.74468578 | C6: 0.75834839 | D6: 0.7330552 | E6: 0.74224592
B7: 0.81047209 | C7: 0.81056506 | D7: 0.80006557 | E7: 0.80763856
B8: 0.72631626 | C8: 0.74228911 | D8: 0.7090712 | E8: 0.7401628
B9: 0.79321544 | C9: 0.76425064 | D9: 0.7749469 | E9: 0.78103755
B10: 0.70459928 | C10: 0.69857772 | D10: 0.75158773 | E10: 0.69641748
B11: 0.75323189 | C11: 0.76611524 | D11: 0.71546563 | E11: 0.7422517
B12: 0.78691806 | C12: 0.7779242 | D12: 0.79344326 | E12: 0.82422175
B13: 0.75773765 | C13: 0.73133786 | D13: 0.7308636 | E13: 0.70611649
B14: 0.79048878 | C14: 0.76164459 | D14: 0.78662473 | E14: 0.77994707
... B27: 0.66558311 | C27: 0.68787927 | D27: 0.70142641 | E27: 0.66737839
A29: deltas | G29: stdev
B30: ac15p | C30: hybrid | D30: hybsem | E30: ac15 | G30: ac15p | H30: hybrid | I30: hybsem | J30: ac15
B31: =B4-B3 -> -0.033572517 | C31: =C4-C3 -> 0.010648032 | D31: =D4-D3 -> -0.045526198 | E31: =E4-E3 -> 0.022606314 | G31: =_xlfn.STDEV.S(B31:B54) -> 0.055048154 | H31: =_xlfn.STDEV.S(C31:C54) -> 0.056023237 | I31: =_xlfn.STDEV.S(D31:D54) -> 0.054679968 | J31: =_xlfn.STDEV.S(E31:E54) -> 0.062810582
B32: =B5-B4 -> -0.022786642 | C32: =C5-C4 -> -0.04409244 | D32: =D5-D4 -> 0.012192859 | E32: =E5-E4 -> -0.036705828
B33: =B6-B5 -> 0.025091265 | C33: =C6-C5 -> 0.042934514 | D33: =D6-D5 -> 0.0057078489 | E33: =E6-E5 -> 0.0022560385
B34: =B7-B6 -> 0.065786309 | C34: =C7-C6 -> 0.052216672 | D34: =D7-D6 -> 0.067010371 | E34: =E7-E6 -> 0.065392638
B35: =B8-B7 -> -0.084155828 | C35: =C8-C7 -> -0.06827595 | D35: =D8-D7 -> -0.090994379 | E35: =E8-E7 -> -0.067475752
B36: =B9-B8 -> 0.066899179 | C36: =C9-C8 -> 0.021961529 | D36: =D9-D8 -> 0.065875707 | E36: =E9-E8 -> 0.040874749
B37: =B10-B9 -> -0.088616161 | C37: =C10-C9 -> -0.065672921 | D37: =D10-D9 -> -0.023359169 | E37: =E10-E9 -> -0.084620069
B38: =B11-B10 -> 0.048632609 | C38: =C11-C10 -> 0.067537518 | D38: =D11-D10 -> -0.036122107 | E38: =E11-E10 -> 0.045834217
B39: =B12-B11 -> 0.033686176 | C39: =C12-C11 -> 0.011808961 | D39: =D12-D11 -> 0.077977637 | E39: =E12-E11 -> 0.081970053
B40: =B13-B12 -> -0.029180415 | C40: =C13-C12 -> -0.046586335 | D40: =D13-D12 -> -0.062579668 | E40: =E13-E12 -> -0.11810526
B41: =B14-B13 -> 0.032751136 | C41: =C14-C13 -> 0.03030673 | D41: =D14-D13 -> 0.055761132 | E41: =E14-E13 -> 0.073830575
B42: =B15-B14 -> -0.098301047 | C42: =C15-C14 -> -0.042215229 | D42: =D15-D14 -> -0.099808385 | E42: =E15-E14 -> -0.072576798
B43: =B16-B15 -> -0.0028078686 | C43: =C16-C15 -> -0.040783851 | D43: =D16-D15 -> 0.031594018 | E43: =E16-E15 -> -0.025165265
... B54: =B27-B26 -> -0.056193262 | C54: =C27-C26 -> -0.034532658 | D54: =D27-D26 -> -0.04584203 | E54: =E27-E26 -> -0.060186388
