Workbook

Sheet scen8_ac15
A1: turnId | B1: user_id | C1: assistant_id | D1: projectName | E1: sessionName | F1: seq | G1: anchorName | H1: weight | I1: promptSim | J1: responseSim | K1: Activation Delta | L1: prompt_to_response | P1: count | Q1: Activation delta average | R1: correlation weights / activation delta | S1: p
P2: =COUNT(K3:K140) -> 138 | Q2: =AVERAGE(K3:K140) -> 0.070899373 | R2: =CORREL(H3:H140,K3:K140) -> 0.10466153 | S2: 0.22
A3: f529882d-6070-41e1-8e5d-01378280daff | B3: cmjl5i8sh01nazccmlq92hvbe | C3: cmjl5ixkc01nrzccmerglbxaw | D3: test_ac15 | E3: Scenario_8 | F3: 0 | G3: truth_and_fact | H3: 0.1 | I3: 0.15447021 | J3: 0.31002827 | K3: =J3-I3 -> 0.15555805 | L3: 0.74784302
A4: 87d594cd-af8a-4fed-b24e-b0c89858daf4 | B4: cmjl5lsxs01nvzccmavnk3xs0 | C4: cmjl5mbs401oczccmgvbvdln2 | D4: test_ac15 | E4: Scenario_8 | F4: 2 | G4: identity | H4: 0.4733 | I4: 0.23385786 | J4: 0.30416648 | K4: =J4-I4 -> 0.070308611 | L4: 0.74810416
A5: 87d594cd-af8a-4fed-b24e-b0c89858daf4 | B5: cmjl5lsxs01nvzccmavnk3xs0 | C5: cmjl5mbs401oczccmgvbvdln2 | D5: test_ac15 | E5: Scenario_8 | F5: 2 | G5: affective_interface | H5: 0.4267 | I5: 0.21081408 | J5: 0.32794679 | K5: =J5-I5 -> 0.11713271 | L5: 0.74810416
A6: 87d594cd-af8a-4fed-b24e-b0c89858daf4 | B6: cmjl5lsxs01nvzccmavnk3xs0 | C6: cmjl5mbs401oczccmgvbvdln2 | D6: test_ac15 | E6: Scenario_8 | F6: 2 | G6: truth_and_fact | H6: 0.1 | I6: 0.1847486 | J6: 0.27031836 | K6: =J6-I6 -> 0.085569758 | L6: 0.74810416
A7: 88b7d41e-e094-40d6-9628-808ac6e55c6c | B7: cmjl5mmlq01ogzccmsteo9q2i | C7: cmjl5mygx01oxzccmwl7g9mt7 | D7: test_ac15 | E7: Scenario_8 | F7: 4 | G7: identity | H7: 0.4562 | I7: 0.22156158 | J7: 0.35775491 | K7: =J7-I7 -> 0.13619333 | L7: 0.71984401
A8: 88b7d41e-e094-40d6-9628-808ac6e55c6c | B8: cmjl5mmlq01ogzccmsteo9q2i | C8: cmjl5mygx01oxzccmwl7g9mt7 | D8: test_ac15 | E8: Scenario_8 | F8: 4 | G8: affective_interface | H8: 0.4438 | I8: 0.21554443 | J8: 0.38075828 | K8: =J8-I8 -> 0.16521385 | L8: 0.71984401
A9: 88b7d41e-e094-40d6-9628-808ac6e55c6c | B9: cmjl5mmlq01ogzccmsteo9q2i | C9: cmjl5mygx01oxzccmwl7g9mt7 | D9: test_ac15 | E9: Scenario_8 | F9: 4 | G9: truth_and_fact | H9: 0.1 | I9: 0.16708569 | J9: 0.31262853 | K9: =J9-I9 -> 0.14554284 | L9: 0.71984401
A10: 76354c3c-7bf6-4d4a-98ea-1b79a54d8a4d | B10: cmjl5n89901p1zccmokw66d6c | C10: cmjl5npee01pizccm7p2mbe81 | D10: test_ac15 | E10: Scenario_8 | F10: 6 | G10: affective_interface | H10: 0.1868 | I10: 0.26673512 | J10: 0.3852368 | K10: =J10-I10 -> 0.11850168 | L10: 0.71608665
A11: 76354c3c-7bf6-4d4a-98ea-1b79a54d8a4d | B11: cmjl5n89901p1zccmokw66d6c | C11: cmjl5npee01pizccm7p2mbe81 | D11: test_ac15 | E11: Scenario_8 | F11: 6 | G11: imagination_and_possibility | H11: 0.1781 | I11: 0.2543329 | J11: 0.39655938 | K11: =J11-I11 -> 0.14222648 | L11: 0.71608665
A12: 76354c3c-7bf6-4d4a-98ea-1b79a54d8a4d | B12: cmjl5n89901p1zccmokw66d6c | C12: cmjl5npee01pizccm7p2mbe81 | D12: test_ac15 | E12: Scenario_8 | F12: 6 | G12: truth_and_fact | H12: 0.1671 | I12: 0.23871069 | J12: 0.38044888 | K12: =J12-I12 -> 0.14173819 | L12: 0.71608665
A13: 76354c3c-7bf6-4d4a-98ea-1b79a54d8a4d | B13: cmjl5n89901p1zccmokw66d6c | C13: cmjl5npee01pizccm7p2mbe81 | D13: test_ac15 | E13: Scenario_8 | F13: 6 | G13: identity | H13: 0.1658 | I13: 0.23686131 | J13: 0.40771749 | K13: =J13-I13 -> 0.17085618 | L13: 0.71608665
A14: 76354c3c-7bf6-4d4a-98ea-1b79a54d8a4d | B14: cmjl5n89901p1zccmokw66d6c | C14: cmjl5npee01pizccm7p2mbe81 | D14: test_ac15 | E14: Scenario_8 | F14: 6 | G14: science | H14: 0.1588 | I14: 0.22675659 | J14: 0.39245036 | K14: =J14-I14 -> 0.16569376 | L14: 0.71608665
... A140: 829e7c92-9c34-45cc-997a-44c3d381e9d1 | B140: cmjl62qj0021azccmsbevv092 | C140: cmjl6357e021rzccmkvvzz76m | D140: test_ac15 | E140: Scenario_8 | F140: 48 | G140: truth_and_fact | H140: 0.1 | I140: 0.29362308 | J140: 0.26475669 | K140: =J140-I140 -> -0.028866394 | L140: 0.69394021

Sheet Notes
A1: p calculation
A3: 1. count | B3: =scen8_ac15!P2 -> 138
A4: 2. t statistic | B4: =B10*SQRT((B3-2)/(1-B10^2)) -> 1.2272931
A5: 3. p | B5: =_xlfn.T.DIST.2T(ABS(B4),B3-2) -> 0.22183265
A9: count | B9: correlation weights / activation delta
A10: =B3 -> 138 | B10: =scen8_ac15!R2 -> 0.10466153

Sheet actdel_prompt_response
A1: Prompt-response
A2: Turn | B2: ac15
A3: 1 | B3: 0.74784302
A4: 2 | B4: 0.74810416
A5: 3 | B5: 0.71984401
A6: 4 | B6: 0.71608665
A7: 5 | B7: 0.76249307
A8: 6 | B8: 0.65351959
A9: 7 | B9: 0.71975014
A10: 8 | B10: 0.77831813
A11: 9 | B11: 0.74239741
A12: 10 | B12: 0.83322558
A13: 11 | B13: 0.71752562
A14: 12 | B14: 0.75083214
... A27: 25 | B27: 0.69394021

Sheet inter_system_stats
A1: Prompt-response
A2: Turn | B2: ac15 | C2: control | E2: std. Ac15 | F2: std. Control | G2: F. test | H2: T. Test equal variances | I2: T.Test unequal | J2: Mean difference | K2: Mean ac15 | L2: Mean control
A3: 1 | B3: 0.74784302 | C3: 0.77181473 | E3: =_xlfn.STDEV.S(B3:B27) -> 0.040164993 | F3: =_xlfn.STDEV.S(C3:C27) -> 0.077480319 | G3: =_xlfn.F.TEST(B3:B27,C3:C27) -> 0.0020569455 | H3: =_xlfn.T.TEST(B3:B27, C3:C27, 2,2) -> 8.2539835e-07 | I3: =_xlfn.T.TEST(B3:B27,C3:C27, 2,3) -> 1.9737004e-06 | J3: =AVERAGE(B3:B27)-AVERAGE(C3:C27) -> 0.098792304 | K3: =AVERAGE(B3:B27) -> 0.74057302 | L3: =AVERAGE(C3:C27) -> 0.64178072
A4: 2 | B4: 0.74810416 | C4: 0.58574872
A5: 3 | B5: 0.71984401 | C5: 0.59442253
A6: 4 | B6: 0.71608665 | C6: 0.60678637
A7: 5 | B7: 0.76249307 | C7: 0.69941561
A8: 6 | B8: 0.65351959 | C8: 0.58498361
A9: 7 | B9: 0.71975014 | C9: 0.5234345
A10: 8 | B10: 0.77831813 | C10: 0.73317738
A11: 9 | B11: 0.74239741 | C11: 0.62302935
A12: 10 | B12: 0.83322558 | C12: 0.56912644
A13: 11 | B13: 0.71752562 | C13: 0.71261685
A14: 12 | B14: 0.75083214 | C14: 0.62399467
A15: 13 | B15: 0.77358788 | C15: 0.70817517
... A27: 25 | B27: 0.69394021 | C27: 0.63735102
A31: General
A33: Turn | B33: ac15p | C33: hybrid | D33: hybsem | E33: ac15 | F33: control | H33: ANOVA - Single Factor
A34: 1 | B34: 0.74689963 | C34: 0.7534273 | D34: 0.72612266 | E34: 0.74784302 | F34: 0.77181473 | H34: Alpha | I34: 0.05
A35: 2 | B35: 0.76044077 | C35: 0.76537158 | D35: 0.74438797 | E35: 0.74810416 | F35: 0.58574872
A36: 3 | B36: 0.7454261 | C36: 0.75306867 | D36: 0.72244326 | E36: 0.71984401 | F36: 0.59442253 | H36: Groups | I36: Count | J36: Sum | K36: Mean | L36: Variance
A37: 4 | B37: 0.75451829 | C37: 0.73318408 | D37: 0.70607009 | E37: 0.71608665 | F37: 0.60678637 | H37: Column 1 | I37: =COUNT(inter_system_stats!$B$33:$B$58) -> 25 | J37: =SUM(inter_system_stats!$B$33:$B$58) -> 18.551522 | K37: =AVERAGE(inter_system_stats!$B$33:$B$58) -> 0.74206089 | L37: =VAR(inter_system_stats!$B$33:$B$58) -> 0.0023570201
A38: 5 | B38: 0.81871695 | C38: 0.83979766 | D38: 0.83046527 | E38: 0.76249307 | F38: 0.69941561 | H38: Column 2 | I38: =COUNT(inter_system_stats!$C$33:$C$58) -> 25 | J38: =SUM(inter_system_stats!$C$33:$C$58) -> 18.601632 | K38: =AVERAGE(inter_system_stats!$C$33:$C$58) -> 0.7440653 | L38: =VAR(inter_system_stats!$C$33:$C$58) -> 0.0024830668
A39: 6 | B39: 0.66147537 | C39: 0.62076408 | D39: 0.63935057 | E39: 0.65351959 | F39: 0.58498361 | H39: Column 3 | I39: =COUNT(inter_system_stats!$D$33:$D$58) -> 25 | J39: =SUM(inter_system_stats!$D$33:$D$58) -> 18.458602 | K39: =AVERAGE(inter_system_stats!$D$33:$D$58) -> 0.73834409 | L39: =VAR(inter_system_stats!$D$33:$D$58) -> 0.0016596641
A40: 7 | B40: 0.70483109 | C40: 0.70824915 | D40: 0.74569214 | E40: 0.71975014 | F40: 0.5234345 | H40: Column 4 | I40: =COUNT(inter_system_stats!$E$33:$E$58) -> 25 | J40: =SUM(inter_system_stats!$E$33:$E$58) -> 18.514326 | K40: =AVERAGE(inter_system_stats!$E$33:$E$58) -> 0.74057302 | L40: =VAR(inter_system_stats!$E$33:$E$58) -> 0.0016132267
A41: 8 | B41: 0.77544567 | C41: 0.81183171 | D41: 0.7775837 | E41: 0.77831813 | F41: 0.73317738
A42: 9 | B42: 0.73492259 | C42: 0.71788979 | D42: 0.71622198 | E42: 0.74239741 | F42: 0.62302935 | H42: Source of Variation | I42: SS | J42: df | K42: MS | L42: F | M42: P-value | N42: F critical
A43: 10 | B43: 0.80955347 | C43: 0.82670674 | D43: 0.78949018 | E43: 0.83322558 | F43: 0.56912644 | H43: Between Groups | I43: =SUMPRODUCT(inter_system_stats!$J$37:$J$40,inter_system_stats!$K$37:$K$40)-SUM(inter_system_stats!$J$37:$J$40)^2/SUM(inter_system_stats!$I$37:$I$40) -> 0.00043713959 | J43: =COUNT(inter_system_stats!$J$37:$J$40)-1 -> 3 | K43: =inter_system_stats!$I$43 / inter_system_stats!$J$43 -> 0.0001457132 | L43: =inter_system_stats!$K$43 / inter_system_stats!$K$44 -> 0.071842031 | M43: =FDIST(inter_system_stats!$L$43, inter_system_stats!$J$43, inter_system_stats!$J$44) -> 0.97489922 | N43: =FINV(inter_system_stats!$I$34, inter_system_stats!$J$43, inter_system_stats!$J$44) -> 2.6993926
A44: 11 | B44: 0.73619363 | C44: 0.7515872 | D44: 0.73775481 | E44: 0.71752562 | F44: 0.71261685 | H44: Within Groups | I44: =SUM(DEVSQ(inter_system_stats!$B$33:$B$58),DEVSQ(inter_system_stats!$C$33:$C$58),DEVSQ(inter_system_stats!$D$33:$D$58),DEVSQ(inter_system_stats!$E$33:$E$58)) -> 0.19471146 | J44: =SUM(inter_system_stats!$I$37:$I$40)-COUNT(inter_system_stats!$I$37:$I$40) -> 96 | K44: =inter_system_stats!$I$44 / inter_system_stats!$J$44 -> 0.0020282444
A45: 12 | B45: 0.76045069 | C45: 0.76757629 | D45: 0.74693269 | E45: 0.75083214 | F45: 0.62399467 | H45: Total | I45: =DEVSQ(inter_system_stats!$B$33:$B$58,inter_system_stats!$C$33:$C$58,inter_system_stats!$D$33:$D$58,inter_system_stats!$E$33:$E$58) -> 0.1951486 | J45: =SUM(inter_system_stats!$I$37:$I$40) - 1 -> 99
A46: 13 | B46: 0.78341715 | C46: 0.7747223 | D46: 0.7432118 | E46: 0.77358788 | F46: 0.70817517
A47: 14 | B47: 0.73635141 | C47: 0.714364 | D47: 0.75356616 | E47: 0.74640132 | F47: 0.59884737
A48: 15 | B48: 0.69516465 | C48: 0.71442988 | D48: 0.67957361 | E48: 0.67489988 | F48: 0.59844888 | H48: ANOVA - Single Factor
A49: 16 | B49: 0.75366371 | C49: 0.73057533 | D49: 0.73260677 | E49: 0.7493482 | F49: 0.68611268 | H49: Alpha | I49: 0.05
A50: 17 | B50: 0.75925493 | C50: 0.73176737 | D50: 0.75054669 | E50: 0.78450743 | F50: 0.65645249
A51: 18 | B51: 0.74400179 | C51: 0.71592458 | D51: 0.73764676 | E51: 0.72412595 | F51: 0.70859012 | H51: Groups | I51: Count | J51: Sum | K51: Mean | L51: Variance
A52: 19 | B52: 0.77774572 | C52: 0.78193272 | D52: 0.77078688 | E52: 0.74985544 | F52: 0.65625023 | H52: Column 1 | I52: =COUNT(inter_system_stats!$B$33:$B$58) -> 25 | J52: =SUM(inter_system_stats!$B$33:$B$58) -> 18.551522 | K52: =AVERAGE(inter_system_stats!$B$33:$B$58) -> 0.74206089 | L52: =VAR(inter_system_stats!$B$33:$B$58) -> 0.0023570201
A53: 20 | B53: 0.78440488 | C53: 0.77021152 | D53: 0.74933745 | E53: 0.77672939 | F53: 0.7661441 | H53: Column 2 | I53: =COUNT(inter_system_stats!$C$33:$C$58) -> 25 | J53: =SUM(inter_system_stats!$C$33:$C$58) -> 18.601632 | K53: =AVERAGE(inter_system_stats!$C$33:$C$58) -> 0.7440653 | L53: =VAR(inter_system_stats!$C$33:$C$58) -> 0.0024830668
A54: 21 | B54: 0.6465587 | C54: 0.6564293 | D54: 0.67660499 | E54: 0.67663643 | F54: 0.61167392 | H54: Column 3 | I54: =COUNT(inter_system_stats!$D$33:$D$58) -> 25 | J54: =SUM(inter_system_stats!$D$33:$D$58) -> 18.458602 | K54: =AVERAGE(inter_system_stats!$D$33:$D$58) -> 0.73834409 | L54: =VAR(inter_system_stats!$D$33:$D$58) -> 0.0016596641
A55: 22 | B55: 0.64627244 | C55: 0.69967526 | D55: 0.69004986 | E55: 0.72066032 | F55: 0.57321384 | H55: Column 4 | I55: =COUNT(inter_system_stats!$E$33:$E$58) -> 25 | J55: =SUM(inter_system_stats!$E$33:$E$58) -> 18.514326 | K55: =AVERAGE(inter_system_stats!$E$33:$E$58) -> 0.74057302 | L55: =VAR(inter_system_stats!$E$33:$E$58) -> 0.0016132267
...

Sheet simst
B2: ac15p | C2: hybrid | D2: hybsem | E2: ac15
B3: 0.74689963 | C3: 0.7534273 | D3: 0.72612266 | E3: 0.74784302
B4: 0.76044077 | C4: 0.76537158 | D4: 0.74438797 | E4: 0.74810416
B5: 0.7454261 | C5: 0.75306867 | D5: 0.72244326 | E5: 0.71984401
B6: 0.75451829 | C6: 0.73318408 | D6: 0.70607009 | E6: 0.71608665
B7: 0.81871695 | C7: 0.83979766 | D7: 0.83046527 | E7: 0.76249307
B8: 0.66147537 | C8: 0.62076408 | D8: 0.63935057 | E8: 0.65351959
B9: 0.70483109 | C9: 0.70824915 | D9: 0.74569214 | E9: 0.71975014
B10: 0.77544567 | C10: 0.81183171 | D10: 0.7775837 | E10: 0.77831813
B11: 0.73492259 | C11: 0.71788979 | D11: 0.71622198 | E11: 0.74239741
B12: 0.80955347 | C12: 0.82670674 | D12: 0.78949018 | E12: 0.83322558
B13: 0.73619363 | C13: 0.7515872 | D13: 0.73775481 | E13: 0.71752562
B14: 0.76045069 | C14: 0.76757629 | D14: 0.74693269 | E14: 0.75083214
... B27: 0.67270335 | C27: 0.71750131 | D27: 0.73470637 | E27: 0.69394021
A29: deltas | G29: stdev
B30: ac15p | C30: hybrid | D30: hybsem | E30: ac15 | G30: ac15p | H30: hybrid | I30: hybsem | J30: ac15
B31: =B4-B3 -> 0.013541138 | C31: =C4-C3 -> 0.011944281 | D31: =D4-D3 -> 0.018265302 | E31: =E4-E3 -> 0.00026113597 | G31: =_xlfn.STDEV.S(B31:B54) -> 0.069877231 | H31: =_xlfn.STDEV.S(C31:C54) -> 0.078908934 | I31: =_xlfn.STDEV.S(D31:D54) -> 0.067132644 | J31: =_xlfn.STDEV.S(E31:E54) -> 0.061534308
B32: =B5-B4 -> -0.01501467 | C32: =C5-C4 -> -0.012302914 | D32: =D5-D4 -> -0.021944703 | E32: =E5-E4 -> -0.02826015
B33: =B6-B5 -> 0.0090921849 | C33: =C6-C5 -> -0.019884591 | D33: =D6-D5 -> -0.016373173 | E33: =E6-E5 -> -0.0037573615
B34: =B7-B6 -> 0.06419866 | C34: =C7-C6 -> 0.10661358 | D34: =D7-D6 -> 0.12439518 | E34: =E7-E6 -> 0.046406423
B35: =B8-B7 -> -0.15724158 | C35: =C8-C7 -> -0.21903358 | D35: =D8-D7 -> -0.19111471 | E35: =E8-E7 -> -0.10897348
B36: =B9-B8 -> 0.043355723 | C36: =C9-C8 -> 0.087485068 | D36: =D9-D8 -> 0.10634157 | E36: =E9-E8 -> 0.066230545
B37: =B10-B9 -> 0.070614575 | C37: =C10-C9 -> 0.10358256 | D37: =D10-D9 -> 0.031891557 | E37: =E10-E9 -> 0.058567993
B38: =B11-B10 -> -0.040523077 | C38: =C11-C10 -> -0.093941922 | D38: =D11-D10 -> -0.061361717 | E38: =E11-E10 -> -0.035920722
B39: =B12-B11 -> 0.074630877 | C39: =C12-C11 -> 0.10881695 | D39: =D12-D11 -> 0.073268194 | E39: =E12-E11 -> 0.090828176
B40: =B13-B12 -> -0.073359835 | C40: =C13-C12 -> -0.075119541 | D40: =D13-D12 -> -0.051735369 | E40: =E13-E12 -> -0.11569997
B41: =B14-B13 -> 0.024257054 | C41: =C14-C13 -> 0.015989084 | D41: =D14-D13 -> 0.0091778856 | E41: =E14-E13 -> 0.033306528
B42: =B15-B14 -> 0.022966457 | C42: =C15-C14 -> 0.0071460116 | D42: =D15-D14 -> -0.0037208881 | E42: =E15-E14 -> 0.022755738
B43: =B16-B15 -> -0.047065739 | C43: =C16-C15 -> -0.060358299 | D43: =D16-D15 -> 0.010354359 | E43: =E16-E15 -> -0.027186561
... B54: =B27-B26 -> -0.1430224 | C54: =C27-C26 -> -0.090802938 | D54: =D27-D26 -> -0.064128763 | E54: =E27-E26 -> -0.087297793
