Workbook

Sheet scen1_ac15
A1: turnId | B1: user_id | C1: assistant_id | D1: projectName | E1: sessionName | F1: seq | G1: anchorName | H1: weight | I1: promptSim | J1: responseSim | K1: activation delta | L1: prompt_to_response | N1: Average activation/turn | O1: average conversation activation | P1: count | Q1: correlation weights / activation delta | R1: p
A3: 65bad581-5200-42d2-86f4-742e3d34452d | B3: cmj8h17rv0025zcr34r4o7q6h | C3: cmj8h2bsc002mzcr39vcv85cs | D3: test_ac15 | E3: Scenario_1_v2_lights | F3: 1 | G3: temporal_dynamics | H3: 0.1958 | I3: 0.31495854 | J3: 0.35236559 | K3: =J3-I3 -> 0.037407052 | L3: 0.82952135 | N3: =AVERAGE(K3:K8) -> 0.066168011 | O3: =AVERAGE(K3:K152) -> 0.03780378 | P3: =COUNT(K3:K152) -> 150 | Q3: =CORREL(H3:H152,K3:K152) -> -0.11797192
A4: 65bad581-5200-42d2-86f4-742e3d34452d | B4: cmj8h17rv0025zcr34r4o7q6h | C4: cmj8h2bsc002mzcr39vcv85cs | D4: test_ac15 | E4: Scenario_1_v2_lights | F4: 1 | G4: practicality_and_feasibility | H4: 0.1952 | I4: 0.31402213 | J4: 0.38777257 | K4: =J4-I4 -> 0.073750438 | L4: 0.82952135
A5: 65bad581-5200-42d2-86f4-742e3d34452d | B5: cmj8h17rv0025zcr34r4o7q6h | C5: cmj8h2bsc002mzcr39vcv85cs | D5: test_ac15 | E5: Scenario_1_v2_lights | F5: 1 | G5: mathematics_computer_science_engineering | H5: 0.1901 | I5: 0.30594307 | J5: 0.37459667 | K5: =J5-I5 -> 0.0686536 | L5: 0.82952135
A6: 65bad581-5200-42d2-86f4-742e3d34452d | B6: cmj8h17rv0025zcr34r4o7q6h | C6: cmj8h2bsc002mzcr39vcv85cs | D6: test_ac15 | E6: Scenario_1_v2_lights | F6: 1 | G6: sovereignty | H6: 0.1611 | I6: 0.25923992 | J6: 0.34164358 | K6: =J6-I6 -> 0.082403657 | L6: 0.82952135
A7: 65bad581-5200-42d2-86f4-742e3d34452d | B7: cmj8h17rv0025zcr34r4o7q6h | C7: cmj8h2bsc002mzcr39vcv85cs | D7: test_ac15 | E7: Scenario_1_v2_lights | F7: 1 | G7: affective_interface | H7: 0.1578 | I7: 0.25390468 | J7: 0.31205688 | K7: =J7-I7 -> 0.058152194 | L7: 0.82952135
A8: 65bad581-5200-42d2-86f4-742e3d34452d | B8: cmj8h17rv0025zcr34r4o7q6h | C8: cmj8h2bsc002mzcr39vcv85cs | D8: test_ac15 | E8: Scenario_1_v2_lights | F8: 1 | G8: truth_and_fact | H8: 0.1 | I8: 0.17671737 | J8: 0.2533585 | K8: =J8-I8 -> 0.076641127 | L8: 0.82952135
A9: 55e9b8cd-c347-48ea-9ccd-4993ba3051b2 | B9: cmj8h3lsn002qzcr31179k8dp | C9: cmj8h4eeu0037zcr39em5jsjw | D9: test_ac15 | E9: Scenario_1_v2_lights | F9: 3 | G9: practicality_and_feasibility | H9: 0.2047 | I9: 0.33013713 | J9: 0.38571109 | K9: =J9-I9 -> 0.055573962 | L9: 0.73519371 | N9: =AVERAGE(K9:K14) -> 0.060061241
A10: 55e9b8cd-c347-48ea-9ccd-4993ba3051b2 | B10: cmj8h3lsn002qzcr31179k8dp | C10: cmj8h4eeu0037zcr39em5jsjw | D10: test_ac15 | E10: Scenario_1_v2_lights | F10: 3 | G10: temporal_dynamics | H10: 0.1852 | I10: 0.29865044 | J10: 0.37164631 | K10: =J10-I10 -> 0.07299587 | L10: 0.73519371
A11: 55e9b8cd-c347-48ea-9ccd-4993ba3051b2 | B11: cmj8h3lsn002qzcr31179k8dp | C11: cmj8h4eeu0037zcr39em5jsjw | D11: test_ac15 | E11: Scenario_1_v2_lights | F11: 3 | G11: mathematics_computer_science_engineering | H11: 0.1832 | I11: 0.29540862 | J11: 0.37460286 | K11: =J11-I11 -> 0.079194237 | L11: 0.73519371
A12: 55e9b8cd-c347-48ea-9ccd-4993ba3051b2 | B12: cmj8h3lsn002qzcr31179k8dp | C12: cmj8h4eeu0037zcr39em5jsjw | D12: test_ac15 | E12: Scenario_1_v2_lights | F12: 3 | G12: sovereignty | H12: 0.1775 | I12: 0.28624896 | J12: 0.33415133 | K12: =J12-I12 -> 0.047902365 | L12: 0.73519371
A13: 55e9b8cd-c347-48ea-9ccd-4993ba3051b2 | B13: cmj8h3lsn002qzcr31179k8dp | C13: cmj8h4eeu0037zcr39em5jsjw | D13: test_ac15 | E13: Scenario_1_v2_lights | F13: 3 | G13: electricity | H13: 0.1493 | I13: 0.24073171 | J13: 0.27359383 | K13: =J13-I13 -> 0.032862119 | L13: 0.73519371
A14: 55e9b8cd-c347-48ea-9ccd-4993ba3051b2 | B14: cmj8h3lsn002qzcr31179k8dp | C14: cmj8h4eeu0037zcr39em5jsjw | D14: test_ac15 | E14: Scenario_1_v2_lights | F14: 3 | G14: truth_and_fact | H14: 0.1 | I14: 0.19711159 | J14: 0.26895048 | K14: =J14-I14 -> 0.07183889 | L14: 0.73519371
A15: 4bb4e535-4ab4-4e28-9f49-910520f84cb1 | B15: cmj8h63ss003bzcr3qf6un6j2 | C15: cmj8h6kyj003szcr3ab4p0og1 | D15: test_ac15 | E15: Scenario_1_v2_lights | F15: 5 | G15: temporal_dynamics | H15: 0.2024 | I15: 0.37825801 | J15: 0.37770835 | K15: =J15-I15 -> -0.00054966361 | L15: 0.73805452 | N15: =AVERAGE(K15:K20) -> 0.035609304
A16: 4bb4e535-4ab4-4e28-9f49-910520f84cb1 | B16: cmj8h63ss003bzcr3qf6un6j2 | C16: cmj8h6kyj003szcr3ab4p0og1 | D16: test_ac15 | E16: Scenario_1_v2_lights | F16: 5 | G16: practicality_and_feasibility | H16: 0.2014 | I16: 0.37646948 | J16: 0.42281154 | K16: =J16-I16 -> 0.046342062 | L16: 0.73805452
A17: 4bb4e535-4ab4-4e28-9f49-910520f84cb1 | B17: cmj8h63ss003bzcr3qf6un6j2 | C17: cmj8h6kyj003szcr3ab4p0og1 | D17: test_ac15 | E17: Scenario_1_v2_lights | F17: 5 | G17: mathematics_computer_science_engineering | H17: 0.1805 | I17: 0.33745747 | J17: 0.39922497 | K17: =J17-I17 -> 0.061767495 | L17: 0.73805452
A18: 4bb4e535-4ab4-4e28-9f49-910520f84cb1 | B18: cmj8h63ss003bzcr3qf6un6j2 | C18: cmj8h6kyj003szcr3ab4p0og1 | D18: test_ac15 | E18: Scenario_1_v2_lights | F18: 5 | G18: sovereignty | H18: 0.1599 | I18: 0.29887494 | J18: 0.33194286 | K18: =J18-I18 -> 0.033067916 | L18: 0.73805452
A19: 4bb4e535-4ab4-4e28-9f49-910520f84cb1 | B19: cmj8h63ss003bzcr3qf6un6j2 | C19: cmj8h6kyj003szcr3ab4p0og1 | D19: test_ac15 | E19: Scenario_1_v2_lights | F19: 5 | G19: metaphorical_scaffolding | H19: 0.1558 | I19: 0.29112796 | J19: 0.3248227 | K19: =J19-I19 -> 0.033694739 | L19: 0.73805452
A20: 4bb4e535-4ab4-4e28-9f49-910520f84cb1 | B20: cmj8h63ss003bzcr3qf6un6j2 | C20: cmj8h6kyj003szcr3ab4p0og1 | D20: test_ac15 | E20: Scenario_1_v2_lights | F20: 5 | G20: truth_and_fact | H20: 0.1 | I20: 0.24263973 | J20: 0.28197301 | K20: =J20-I20 -> 0.039333277 | L20: 0.73805452
A21: e5f31daf-8d1a-43f4-a640-d42a5ac4224c | B21: cmj8h7lrs003wzcr3k7vgx4j8 | C21: cmj8h88bl004dzcr3ynwjng2i | D21: test_ac15 | E21: Scenario_1_v2_lights | F21: 7 | G21: practicality_and_feasibility | H21: 0.214 | I21: 0.36914606 | J21: 0.42405176 | K21: =J21-I21 -> 0.054905697 | L21: 0.63946145 | N21: =AVERAGE(K21:K26) -> 0.046881592
A22: e5f31daf-8d1a-43f4-a640-d42a5ac4224c | B22: cmj8h7lrs003wzcr3k7vgx4j8 | C22: cmj8h88bl004dzcr3ynwjng2i | D22: test_ac15 | E22: Scenario_1_v2_lights | F22: 7 | G22: temporal_dynamics | H22: 0.198 | I22: 0.34155907 | J22: 0.36410105 | K22: =J22-I22 -> 0.022541981 | L22: 0.63946145
A23: e5f31daf-8d1a-43f4-a640-d42a5ac4224c | B23: cmj8h7lrs003wzcr3k7vgx4j8 | C23: cmj8h88bl004dzcr3ynwjng2i | D23: test_ac15 | E23: Scenario_1_v2_lights | F23: 7 | G23: mathematics_computer_science_engineering | H23: 0.1784 | I23: 0.30779553 | J23: 0.38784834 | K23: =J23-I23 -> 0.080052807 | L23: 0.63946145
A24: e5f31daf-8d1a-43f4-a640-d42a5ac4224c | B24: cmj8h7lrs003wzcr3k7vgx4j8 | C24: cmj8h88bl004dzcr3ynwjng2i | D24: test_ac15 | E24: Scenario_1_v2_lights | F24: 7 | G24: sovereignty | H24: 0.1675 | I24: 0.28899496 | J24: 0.31719836 | K24: =J24-I24 -> 0.028203404 | L24: 0.63946145
A25: e5f31daf-8d1a-43f4-a640-d42a5ac4224c | B25: cmj8h7lrs003wzcr3k7vgx4j8 | C25: cmj8h88bl004dzcr3ynwjng2i | D25: test_ac15 | E25: Scenario_1_v2_lights | F25: 7 | G25: imagination_and_possibility | H25: 0.142 | I25: 0.24485588 | J25: 0.27442221 | K25: =J25-I25 -> 0.029566327 | L25: 0.63946145
A26: e5f31daf-8d1a-43f4-a640-d42a5ac4224c | B26: cmj8h7lrs003wzcr3k7vgx4j8 | C26: cmj8h88bl004dzcr3ynwjng2i | D26: test_ac15 | E26: Scenario_1_v2_lights | F26: 7 | G26: truth_and_fact | H26: 0.1 | I26: 0.20802883 | J26: 0.27404817 | K26: =J26-I26 -> 0.066019336 | L26: 0.63946145
A27: e8159a62-8cd7-4176-a2c4-87698c1a592d | B27: cmj8h98aa004hzcr3xdn4mwvv | C27: cmj8h9wqh004yzcr3r5q75k6e | D27: test_ac15 | E27: Scenario_1_v2_lights | F27: 9 | G27: practicality_and_feasibility | H27: 0.2171 | I27: 0.42031574 | J27: 0.39317307 | K27: =J27-I27 -> -0.027142674 | L27: 0.6011484 | N27: =AVERAGE(K27:K32) -> 0.0054283418
A28: e8159a62-8cd7-4176-a2c4-87698c1a592d | B28: cmj8h98aa004hzcr3xdn4mwvv | C28: cmj8h9wqh004yzcr3r5q75k6e | D28: test_ac15 | E28: Scenario_1_v2_lights | F28: 9 | G28: mathematics_computer_science_engineering | H28: 0.1836 | I28: 0.35541435 | J28: 0.36981048 | K28: =J28-I28 -> 0.014396129 | L28: 0.6011484
A29: e8159a62-8cd7-4176-a2c4-87698c1a592d | B29: cmj8h98aa004hzcr3xdn4mwvv | C29: cmj8h9wqh004yzcr3r5q75k6e | D29: test_ac15 | E29: Scenario_1_v2_lights | F29: 9 | G29: temporal_dynamics | H29: 0.1759 | I29: 0.34061355 | J29: 0.35731561 | K29: =J29-I29 -> 0.016702058 | L29: 0.6011484
A30: e8159a62-8cd7-4176-a2c4-87698c1a592d | B30: cmj8h98aa004hzcr3xdn4mwvv | C30: cmj8h9wqh004yzcr3r5q75k6e | D30: test_ac15 | E30: Scenario_1_v2_lights | F30: 9 | G30: affective_interface | H30: 0.1646 | I30: 0.31871873 | J30: 0.29542059 | K30: =J30-I30 -> -0.023298136 | L30: 0.6011484
A31: e8159a62-8cd7-4176-a2c4-87698c1a592d | B31: cmj8h98aa004hzcr3xdn4mwvv | C31: cmj8h9wqh004yzcr3r5q75k6e | D31: test_ac15 | E31: Scenario_1_v2_lights | F31: 9 | G31: sovereignty | H31: 0.1587 | I31: 0.30726339 | J31: 0.34162107 | K31: =J31-I31 -> 0.034357679 | L31: 0.6011484
A32: e8159a62-8cd7-4176-a2c4-87698c1a592d | B32: cmj8h98aa004hzcr3xdn4mwvv | C32: cmj8h9wqh004yzcr3r5q75k6e | D32: test_ac15 | E32: Scenario_1_v2_lights | F32: 9 | G32: truth_and_fact | H32: 0.1 | I32: 0.25424075 | J32: 0.27179574 | K32: =J32-I32 -> 0.017554996 | L32: 0.6011484
A33: 0193987a-9522-4c92-a38b-8be38f11be07 | B33: cmj8hazkj0052zcr3jml7f11a | C33: cmj8hc3c6005jzcr3vla9m4sb | D33: test_ac15 | E33: Scenario_1_v2_lights | F33: 11 | G33: practicality_and_feasibility | H33: 0.218 | I33: 0.36471402 | J33: 0.36540835 | K33: =J33-I33 -> 0.00069433153 | L33: 0.77349923 | N33: =AVERAGE(K33:K38) -> 0.014697263
A34: 0193987a-9522-4c92-a38b-8be38f11be07 | B34: cmj8hazkj0052zcr3jml7f11a | C34: cmj8hc3c6005jzcr3vla9m4sb | D34: test_ac15 | E34: Scenario_1_v2_lights | F34: 11 | G34: mathematics_computer_science_engineering | H34: 0.1915 | I34: 0.32044345 | J34: 0.32503899 | K34: =J34-I34 -> 0.0045955322 | L34: 0.77349923
A35: 0193987a-9522-4c92-a38b-8be38f11be07 | B35: cmj8hazkj0052zcr3jml7f11a | C35: cmj8hc3c6005jzcr3vla9m4sb | D35: test_ac15 | E35: Scenario_1_v2_lights | F35: 11 | G35: temporal_dynamics | H35: 0.1837 | I35: 0.30742916 | J35: 0.34338522 | K35: =J35-I35 -> 0.035956062 | L35: 0.77349923
A36: 0193987a-9522-4c92-a38b-8be38f11be07 | B36: cmj8hazkj0052zcr3jml7f11a | C36: cmj8hc3c6005jzcr3vla9m4sb | D36: test_ac15 | E36: Scenario_1_v2_lights | F36: 11 | G36: sovereignty | H36: 0.1605 | I36: 0.26855493 | J36: 0.26954665 | K36: =J36-I36 -> 0.00099172109 | L36: 0.77349923
A37: 0193987a-9522-4c92-a38b-8be38f11be07 | B37: cmj8hazkj0052zcr3jml7f11a | C37: cmj8hc3c6005jzcr3vla9m4sb | D37: test_ac15 | E37: Scenario_1_v2_lights | F37: 11 | G37: imagination_and_possibility | H37: 0.1463 | I37: 0.2447951 | J37: 0.26121296 | K37: =J37-I37 -> 0.016417865 | L37: 0.77349923
A38: 0193987a-9522-4c92-a38b-8be38f11be07 | B38: cmj8hazkj0052zcr3jml7f11a | C38: cmj8hc3c6005jzcr3vla9m4sb | D38: test_ac15 | E38: Scenario_1_v2_lights | F38: 11 | G38: truth_and_fact | H38: 0.1 | I38: 0.19432181 | J38: 0.22384987 | K38: =J38-I38 -> 0.029528066 | L38: 0.77349923
A39: c7acf8b6-981f-4875-81d3-88079abc3e0b | B39: cmj8heq8u005nzcr3n2y7g0ly | C39: cmj8hfv630064zcr3x020wbm0 | D39: test_ac15 | E39: Scenario_1_v2_lights | F39: 13 | G39: practicality_and_feasibility | H39: 0.2194 | I39: 0.34082691 | J39: 0.40558723 | K39: =J39-I39 -> 0.06476032 | L39: 0.65742523 | N39: =AVERAGE(K39:K44) -> 0.082909871
A40: c7acf8b6-981f-4875-81d3-88079abc3e0b | B40: cmj8heq8u005nzcr3n2y7g0ly | C40: cmj8hfv630064zcr3x020wbm0 | D40: test_ac15 | E40: Scenario_1_v2_lights | F40: 13 | G40: temporal_dynamics | H40: 0.1943 | I40: 0.30177996 | J40: 0.37602165 | K40: =J40-I40 -> 0.074241687 | L40: 0.65742523
A41: c7acf8b6-981f-4875-81d3-88079abc3e0b | B41: cmj8heq8u005nzcr3n2y7g0ly | C41: cmj8hfv630064zcr3x020wbm0 | D41: test_ac15 | E41: Scenario_1_v2_lights | F41: 13 | G41: mathematics_computer_science_engineering | H41: 0.1937 | I41: 0.30089205 | J41: 0.38247574 | K41: =J41-I41 -> 0.081583688 | L41: 0.65742523
...

Sheet notes
A1: p calculation
A3: 1. count | B3: =COUNT(scen1_ac15!K3:K152) -> 150
A4: 2. t statistic | B4: =scen1_ac15!Q3*SQRT((B3-2)/(1-scen1_ac15!Q3^2)) -> -1.4452829
A5: 3. p | B5: =_xlfn.T.DIST.2T(ABS(B4),B3-2) -> 0.15049252

Sheet actdel_prompt_response
A2: turn | B2: prompt_to_response | C2: Average activation/turn | H2: Correlation | I2: count | J2: T-statistic | K2: p
A4: 1 | B4: 0.82952135 | C4: 0.066168011 | H4: =CORREL(B4:B28,C4:C28) -> 0.24396669 | I4: =COUNT(C4:C28) -> 25 | J4: =H4*SQRT((I4-2)/(1-H4^2)) -> 1.2064786 | K4: =_xlfn.T.DIST.2T(ABS(J4),I4-2) -> 0.23989661
A5: 2 | B5: 0.73519371 | C5: 0.060061241
A6: 3 | B6: 0.73805452 | C6: 0.035609304
A7: 4 | B7: 0.63946145 | C7: 0.046881592
A8: 5 | B8: 0.6011484 | C8: 0.0054283418
A9: 6 | B9: 0.77349923 | C9: 0.014697263
A10: 7 | B10: 0.65742523 | C10: 0.082909871
A11: 8 | B11: 0.71261314 | C11: -0.0058417364
A12: 9 | B12: 0.69508286 | C12: -0.04011499
A13: 10 | B13: 0.70158644 | C13: 0.040890779
A14: 11 | B14: 0.69702804 | C14: 0.0598247
A15: 12 | B15: 0.78055884 | C15: 0.082711045
A16: 13 | B16: 0.72081439 | C16: 0.097198497
... A28: 25 | B28: 0.68313654 | C28: 0.045313309

Sheet inter-system stats
B4: ac15 | C4: control | D4: delta activation | E4: choose | F4: std. Ac15 | G4: std. Control | H4: F. test | I4: T. Test equal variances | J4: T.Test unequal | K4: Mean difference
A5: 1 | B5: 0.82952135 | C5: 0.84316826 | D5: =B5-C5 -> -0.013646912 | F5: =_xlfn.STDEV.S(B5:B29) -> 0.06078154 | G5: =_xlfn.STDEV.S(C5:C29) -> 0.11788306 | H5: =_xlfn.F.TEST(B5:B29,C5:C29) -> 0.0018992762 | I5: =_xlfn.T.TEST(B5:B29, C5:C29, 2,2) -> 4.6958715e-07 | J5: =_xlfn.T.TEST(B5:B29,C5:C29, 2,3) -> 1.2140351e-06 | K5: =AVERAGE(B5:B29)-AVERAGE(C5:C29) -> 0.154415
A6: 2 | B6: 0.73519371 | C6: 0.41048157 | D6: =B6-C6 -> 0.32471214 | E6: x
A7: 3 | B7: 0.73805452 | C7: 0.55797537 | D7: =B7-C7 -> 0.18007915 | E7: x
A8: 4 | B8: 0.63946145 | C8: 0.61915827 | D8: =B8-C8 -> 0.020303183
A9: 5 | B9: 0.6011484 | C9: 0.40396308 | D9: =B9-C9 -> 0.19718532 | E9: x
A10: 6 | B10: 0.77349923 | C10: 0.57074388 | D10: =B10-C10 -> 0.20275534 | E10: x
A11: 7 | B11: 0.65742523 | C11: 0.61160895 | D11: =B11-C11 -> 0.045816281
A12: 8 | B12: 0.71261314 | C12: 0.51665839 | D12: =B12-C12 -> 0.19595475 | E12: x
A13: 9 | B13: 0.69508286 | C13: 0.51910728 | D13: =B13-C13 -> 0.17597558 | E13: x
A14: 10 | B14: 0.70158644 | C14: 0.68124246 | D14: =B14-C14 -> 0.020343985
A15: 11 | B15: 0.69702804 | C15: 0.66509925 | D15: =B15-C15 -> 0.031928796
A16: 12 | B16: 0.78055884 | C16: 0.68559512 | D16: =B16-C16 -> 0.094963724
A17: 13 | B17: 0.72081439 | C17: 0.65114377 | D17: =B17-C17 -> 0.069670623
A18: 14 | B18: 0.74029899 | C18: 0.60348677 | D18: =B18-C18 -> 0.13681222
A19: 15 | B19: 0.70744158 | C19: 0.49806868 | D19: =B19-C19 -> 0.2093729 | E19: x
A20: 16 | B20: 0.71912587 | C20: 0.63037797 | D20: =B20-C20 -> 0.088747897
A21: 17 | B21: 0.71888938 | C21: 0.65792717 | D21: =B21-C21 -> 0.060962216
A22: 18 | B22: 0.73502249 | C22: 0.56086051 | D22: =B22-C22 -> 0.17416198 | E22: x
A23: 19 | B23: 0.58170038 | C23: 0.50207793 | D23: =B23-C23 -> 0.07962245
A24: 20 | B24: 0.84942539 | C24: 0.47716849 | D24: =B24-C24 -> 0.3722569 | E24: x
A25: 21 | B25: 0.78210709 | C25: 0.49071258 | D25: =B25-C25 -> 0.2913945 | E25: x
A26: 22 | B26: 0.67793147 | C26: 0.37364723 | D26: =B26-C26 -> 0.30428424 | E26: x
A27: 23 | B27: 0.72213492 | C27: 0.656355 | D27: =B27-C27 -> 0.065779927
A28: 24 | B28: 0.72781041 | C28: 0.57973183 | D28: =B28-C28 -> 0.14807859 | E28: x
A29: 25 | B29: 0.68313654 | C29: 0.30027741 | D29: =B29-C29 -> 0.38285913 | E29: x
A33: General
B34: Hybsem | C34: Hybrid | D34: ac15p | E34: ac15 | G34: ANOVA - Single Factor
B35: 0.82908352 | C35: 0.83430834 | D35: 0.82032979 | E35: 0.82952135 | G35: Alpha | H35: 0.05
B36: 0.7664449 | C36: 0.78737809 | D36: 0.76020895 | E36: 0.73519371
B37: 0.82081493 | C37: 0.82347011 | D37: 0.77935892 | E37: 0.73805452 | G37: Groups | H37: Count | I37: Sum | J37: Mean | K37: Variance
B38: 0.58934068 | C38: 0.64138219 | D38: 0.65547417 | E38: 0.63946145 | G38: Column 1 | H38: =COUNT('inter-system stats'!$B$34:$B$59) -> 25 | I38: =SUM('inter-system stats'!$B$34:$B$59) -> 18.326035 | J38: =AVERAGE('inter-system stats'!$B$34:$B$59) -> 0.73304139 | K38: =VAR('inter-system stats'!$B$34:$B$59) -> 0.0042880587
B39: 0.54993991 | C39: 0.64856074 | D39: 0.60148827 | E39: 0.6011484 | G39: Column 2 | H39: =COUNT('inter-system stats'!$C$34:$C$59) -> 25 | I39: =SUM('inter-system stats'!$C$34:$C$59) -> 18.263774 | J39: =AVERAGE('inter-system stats'!$C$34:$C$59) -> 0.73055098 | K39: =VAR('inter-system stats'!$C$34:$C$59) -> 0.0032014709
B40: 0.8063013 | C40: 0.73754073 | D40: 0.80260511 | E40: 0.77349923 | G40: Column 3 | H40: =COUNT('inter-system stats'!$D$34:$D$59) -> 25 | I40: =SUM('inter-system stats'!$D$34:$D$59) -> 18.268163 | J40: =AVERAGE('inter-system stats'!$D$34:$D$59) -> 0.73072651 | K40: =VAR('inter-system stats'!$D$34:$D$59) -> 0.004609989
B41: 0.65442075 | C41: 0.63496808 | D41: 0.64887842 | E41: 0.65742523 | G41: Column 4 | H41: =COUNT('inter-system stats'!$E$34:$E$59) -> 25 | I41: =SUM('inter-system stats'!$E$34:$E$59) -> 17.927012 | J41: =AVERAGE('inter-system stats'!$E$34:$E$59) -> 0.71708049 | K41: =VAR('inter-system stats'!$E$34:$E$59) -> 0.0036943957
B42: 0.74745701 | C42: 0.74640085 | D42: 0.75255045 | E42: 0.71261314
B43: 0.76315444 | C43: 0.68880534 | D43: 0.72599844 | E43: 0.69508286 | G43: Source of Variation | H43: SS | I43: df | J43: MS | K43: F | L43: P-value | M43: F critical
B44: 0.74529883 | C44: 0.74363979 | D44: 0.70681936 | E44: 0.70158644 | G44: Between Groups | H44: =SUMPRODUCT('inter-system stats'!$I$38:$I$41,'inter-system stats'!$J$38:$J$41)-SUM('inter-system stats'!$I$38:$I$41)^2/SUM('inter-system stats'!$H$38:$H$41) -> 0.0039625637 | I44: =COUNT('inter-system stats'!$I$38:$I$41)-1 -> 3 | J44: ='inter-system stats'!$H$44 / 'inter-system stats'!$I$44 -> 0.0013208546 | K44: ='inter-system stats'!$J$44 / 'inter-system stats'!$J$45 -> 0.33452241 | L44: =FDIST('inter-system stats'!$K$44, 'inter-system stats'!$I$44, 'inter-system stats'!$I$45) -> 0.80039762 | M44: =FINV('inter-system stats'!$H$35, 'inter-system stats'!$I$44, 'inter-system stats'!$I$45) -> 2.6993926
B45: 0.70359943 | C45: 0.71319147 | D45: 0.66388414 | E45: 0.69702804 | G45: Within Groups | H45: =SUM(DEVSQ('inter-system stats'!$B$34:$B$59),DEVSQ('inter-system stats'!$C$34:$C$59),DEVSQ('inter-system stats'!$D$34:$D$59),DEVSQ('inter-system stats'!$E$34:$E$59)) -> 0.37905394 | I45: =SUM('inter-system stats'!$H$38:$H$41)-COUNT('inter-system stats'!$H$38:$H$41) -> 96 | J45: ='inter-system stats'!$H$45 / 'inter-system stats'!$I$45 -> 0.0039484785
B46: 0.79229112 | C46: 0.76713896 | D46: 0.80868052 | E46: 0.78055884 | G46: Total | H46: =DEVSQ('inter-system stats'!$B$34:$B$59,'inter-system stats'!$C$34:$C$59,'inter-system stats'!$D$34:$D$59,'inter-system stats'!$E$34:$E$59) -> 0.3830165 | I46: =SUM('inter-system stats'!$H$38:$H$41) - 1 -> 99
...

Sheet std delta(sim)-delta(sim-1)
A2: General
B3: Hybsem | C3: Hybrid | D3: ac15p | E3: ac15
B4: 0.82908352 | C4: 0.83430834 | D4: 0.82032979 | E4: 0.82952135
B5: 0.7664449 | C5: 0.78737809 | D5: 0.76020895 | E5: 0.73519371
B6: 0.82081493 | C6: 0.82347011 | D6: 0.77935892 | E6: 0.73805452
B7: 0.58934068 | C7: 0.64138219 | D7: 0.65547417 | E7: 0.63946145
B8: 0.54993991 | C8: 0.64856074 | D8: 0.60148827 | E8: 0.6011484
B9: 0.8063013 | C9: 0.73754073 | D9: 0.80260511 | E9: 0.77349923
B10: 0.65442075 | C10: 0.63496808 | D10: 0.64887842 | E10: 0.65742523
B11: 0.74745701 | C11: 0.74640085 | D11: 0.75255045 | E11: 0.71261314
B12: 0.76315444 | C12: 0.68880534 | D12: 0.72599844 | E12: 0.69508286
B13: 0.74529883 | C13: 0.74363979 | D13: 0.70681936 | E13: 0.70158644
B14: 0.70359943 | C14: 0.71319147 | D14: 0.66388414 | E14: 0.69702804
B15: 0.79229112 | C15: 0.76713896 | D15: 0.80868052 | E15: 0.78055884
... B28: 0.71866241 | C28: 0.70629147 | D28: 0.69002391 | E28: 0.68313654
A31: sim(t)-sim(t-1) | G31: STDEV:
B32: Hybsem | C32: Hybrid | D32: ac15p | E32: ac15 | G32: Hybsem | H32: Hybrid | I32: ac15p | J32: ac15
A33: 2 | B33: =B5-B4 -> -0.062638614 | C33: =C5-C4 -> -0.046930248 | D33: =D5-D4 -> -0.060120837 | E33: =E5-E4 -> -0.094327639 | G33: =_xlfn.STDEV.S(B33:B56) -> 0.092058482 | H33: =_xlfn.STDEV.S(C33:C56) -> 0.079958501 | I33: =_xlfn.STDEV.S(D33:D56) -> 0.10509626 | J33: =_xlfn.STDEV.S(E33:E56) -> 0.091544494
A34: 3 | B34: =B6-B5 -> 0.054370024 | C34: =C6-C5 -> 0.036092019 | D34: =D6-D5 -> 0.019149966 | E34: =E6-E5 -> 0.002860809
A35: 4 | B35: =B7-B6 -> -0.23147425 | C35: =C7-C6 -> -0.18208792 | D35: =D7-D6 -> -0.12388475 | E35: =E7-E6 -> -0.098593069
A36: 5 | B36: =B8-B7 -> -0.03940077 | C36: =C8-C7 -> 0.0071785549 | D36: =D8-D7 -> -0.053985898 | E36: =E8-E7 -> -0.038313049
A37: 6 | B37: =B9-B8 -> 0.25636139 | C37: =C9-C8 -> 0.088979984 | D37: =D9-D8 -> 0.20111684 | E37: =E9-E8 -> 0.17235082
A38: 7 | B38: =B10-B9 -> -0.15188055 | C38: =C10-C9 -> -0.10257264 | D38: =D10-D9 -> -0.1537267 | E38: =E10-E9 -> -0.11607399
A39: 8 | B39: =B11-B10 -> 0.093036259 | C39: =C11-C10 -> 0.11143277 | D39: =D11-D10 -> 0.10367203 | E39: =E11-E10 -> 0.055187904
A40: 9 | B40: =B12-B11 -> 0.01569743 | C40: =C12-C11 -> -0.057595511 | D40: =D12-D11 -> -0.026552011 | E40: =E12-E11 -> -0.017530281
A41: 10 | B41: =B13-B12 -> -0.01785561 | C41: =C13-C12 -> 0.054834451 | D41: =D13-D12 -> -0.019179085 | E41: =E13-E12 -> 0.0065035839
A42: 11 | B42: =B14-B13 -> -0.041699399 | C42: =C14-C13 -> -0.030448329 | D42: =D14-D13 -> -0.04293522 | E42: =E14-E13 -> -0.0045583963
A43: 12 | B43: =B15-B14 -> 0.088691692 | C43: =C15-C14 -> 0.053947491 | D43: =D15-D14 -> 0.14479638 | E43: =E15-E14 -> 0.083530797
A44: 13 | B44: =B16-B15 -> -0.049542275 | C44: =C16-C15 -> -0.041449688 | D44: =D16-D15 -> -0.11089073 | E44: =E16-E15 -> -0.059744446
A45: 14 | B45: =B17-B16 -> -0.012009811 | C45: =C17-C16 -> -0.041937885 | D45: =D17-D16 -> 0.051860108 | E45: =E17-E16 -> 0.019484597
... A56: 25 | B56: =B28-B27 -> -0.035959773 | C56: =C28-C27 -> -0.00043619663 | D56: =D28-D27 -> -0.093554885 | E56: =E28-E27 -> -0.044673875
