Workbook

Sheet scen3_ac15
A1: turnId | B1: user_id | C1: assistant_id | D1: projectName | E1: sessionName | F1: seq | G1: anchorName | H1: weight | I1: promptSim | J1: responseSim | K1: activation delta | L1: prompt_to_response | O1: average conversation activation | P1: count | Q1: correlation weights / activation delta | R1: p
O2: =AVERAGE(K3:K152) -> 0.056810471 | P2: =COUNT(K3:K152) -> 150 | Q2: =CORREL(H3:H152,K3:K152) -> -0.047014511 | R2: 0.56779157
B3: e864a2c3-fa36-4505-bbfc-3f0075b26c80 | C3: cmjbbv7uv0003zc7qerw712p5 | D3: test_ac15 | E3: scenario_3 | F3: 0 | G3: practicality_and_feasibility | H3: 0.1989 | I3: 0.34332465 | J3: 0.43996816 | K3: =J3-I3 -> 0.096643515 | L3: 0.81564959
B4: e864a2c3-fa36-4505-bbfc-3f0075b26c80 | C4: cmjbbv7uv0003zc7qerw712p5 | D4: test_ac15 | E4: scenario_3 | F4: 0 | G4: mathematics_computer_science_engineering | H4: 0.1977 | I4: 0.34121155 | J4: 0.40415836 | K4: =J4-I4 -> 0.062946805 | L4: 0.81564959
B5: e864a2c3-fa36-4505-bbfc-3f0075b26c80 | C5: cmjbbv7uv0003zc7qerw712p5 | D5: test_ac15 | E5: scenario_3 | F5: 0 | G5: temporal_dynamics | H5: 0.1803 | I5: 0.31129079 | J5: 0.36317849 | K5: =J5-I5 -> 0.051887703 | L5: 0.81564959
B6: e864a2c3-fa36-4505-bbfc-3f0075b26c80 | C6: cmjbbv7uv0003zc7qerw712p5 | D6: test_ac15 | E6: scenario_3 | F6: 0 | G6: imagination_and_possibility | H6: 0.1617 | I6: 0.279136 | J6: 0.37606086 | K6: =J6-I6 -> 0.096924862 | L6: 0.81564959
B7: e864a2c3-fa36-4505-bbfc-3f0075b26c80 | C7: cmjbbv7uv0003zc7qerw712p5 | D7: test_ac15 | E7: scenario_3 | F7: 0 | G7: affective_interface | H7: 0.1614 | I7: 0.27863807 | J7: 0.37189912 | K7: =J7-I7 -> 0.093261056 | L7: 0.81564959
B8: e864a2c3-fa36-4505-bbfc-3f0075b26c80 | C8: cmjbbv7uv0003zc7qerw712p5 | D8: test_ac15 | E8: scenario_3 | F8: 0 | G8: truth_and_fact | H8: 0.1 | I8: 0.23870068 | J8: 0.36340304 | K8: =J8-I8 -> 0.12470236 | L8: 0.81564959
A9: 2751a2fc-17a6-4393-b628-1bce6b19ceb6 | B9: cmjbby05o000ozc7qr3wea0sq | C9: cmjbbyy2e0015zc7qlof75kam | D9: test_ac15 | E9: scenario_3 | F9: 2 | G9: practicality_and_feasibility | H9: 0.2127 | I9: 0.40865935 | J9: 0.4470209 | K9: =J9-I9 -> 0.038361545 | L9: 0.67540263
A10: 2751a2fc-17a6-4393-b628-1bce6b19ceb6 | B10: cmjbby05o000ozc7qr3wea0sq | C10: cmjbbyy2e0015zc7qlof75kam | D10: test_ac15 | E10: scenario_3 | F10: 2 | G10: mathematics_computer_science_engineering | H10: 0.2017 | I10: 0.3874418 | J10: 0.4333179 | K10: =J10-I10 -> 0.045876091 | L10: 0.67540263
A11: 2751a2fc-17a6-4393-b628-1bce6b19ceb6 | B11: cmjbby05o000ozc7qr3wea0sq | C11: cmjbbyy2e0015zc7qlof75kam | D11: test_ac15 | E11: scenario_3 | F11: 2 | G11: science | H11: 0.1723 | I11: 0.33104871 | J11: 0.43569495 | K11: =J11-I11 -> 0.10464624 | L11: 0.67540263
A12: 2751a2fc-17a6-4393-b628-1bce6b19ceb6 | B12: cmjbby05o000ozc7qr3wea0sq | C12: cmjbbyy2e0015zc7qlof75kam | D12: test_ac15 | E12: scenario_3 | F12: 2 | G12: metaphorical_scaffolding | H12: 0.1583 | I12: 0.30407037 | J12: 0.3773701 | K12: =J12-I12 -> 0.073299728 | L12: 0.67540263
A13: 2751a2fc-17a6-4393-b628-1bce6b19ceb6 | B13: cmjbby05o000ozc7qr3wea0sq | C13: cmjbbyy2e0015zc7qlof75kam | D13: test_ac15 | E13: scenario_3 | F13: 2 | G13: temporal_dynamics | H13: 0.1551 | I13: 0.29790893 | J13: 0.3294284 | K13: =J13-I13 -> 0.031519468 | L13: 0.67540263
A14: 2751a2fc-17a6-4393-b628-1bce6b19ceb6 | B14: cmjbby05o000ozc7qr3wea0sq | C14: cmjbbyy2e0015zc7qlof75kam | D14: test_ac15 | E14: scenario_3 | F14: 2 | G14: truth_and_fact | H14: 0.1 | I14: 0.28634047 | J14: 0.37430172 | K14: =J14-I14 -> 0.087961252 | L14: 0.67540263
A15: 259e10f8-4c48-486b-ae01-fa07996fea30 | B15: cmjbc0ns70019zc7q3rw3sxut | C15: cmjbc1hkw001qzc7qk967aan4 | D15: test_ac15 | E15: scenario_3 | F15: 4 | G15: practicality_and_feasibility | H15: 0.1924 | I15: 0.33872077 | J15: 0.39052534 | K15: =J15-I15 -> 0.05180457 | L15: 0.65794906
A16: 259e10f8-4c48-486b-ae01-fa07996fea30 | B16: cmjbc0ns70019zc7q3rw3sxut | C16: cmjbc1hkw001qzc7qk967aan4 | D16: test_ac15 | E16: scenario_3 | F16: 4 | G16: metaphorical_scaffolding | H16: 0.1674 | I16: 0.29462855 | J16: 0.33314534 | K16: =J16-I16 -> 0.038516788 | L16: 0.65794906
A17: 259e10f8-4c48-486b-ae01-fa07996fea30 | B17: cmjbc0ns70019zc7q3rw3sxut | C17: cmjbc1hkw001qzc7qk967aan4 | D17: test_ac15 | E17: scenario_3 | F17: 4 | G17: mathematics_computer_science_engineering | H17: 0.1664 | I17: 0.29295903 | J17: 0.36811863 | K17: =J17-I17 -> 0.075159603 | L17: 0.65794906
A18: 259e10f8-4c48-486b-ae01-fa07996fea30 | B18: cmjbc0ns70019zc7q3rw3sxut | C18: cmjbc1hkw001qzc7qk967aan4 | D18: test_ac15 | E18: scenario_3 | F18: 4 | G18: science | H18: 0.1664 | I18: 0.29300966 | J18: 0.31432025 | K18: =J18-I18 -> 0.021310587 | L18: 0.65794906
A19: 259e10f8-4c48-486b-ae01-fa07996fea30 | B19: cmjbc0ns70019zc7q3rw3sxut | C19: cmjbc1hkw001qzc7qk967aan4 | D19: test_ac15 | E19: scenario_3 | F19: 4 | G19: truth_and_fact | H19: 0.156 | I19: 0.27471426 | J19: 0.2580817 | K19: =J19-I19 -> -0.016632566 | L19: 0.65794906
A20: 259e10f8-4c48-486b-ae01-fa07996fea30 | B20: cmjbc0ns70019zc7q3rw3sxut | C20: cmjbc1hkw001qzc7qk967aan4 | D20: test_ac15 | E20: scenario_3 | F20: 4 | G20: imagination_and_possibility | H20: 0.1514 | I20: 0.26651328 | J20: 0.30757919 | K20: =J20-I20 -> 0.041065912 | L20: 0.65794906
... A152: fb474895-4d08-4190-9f42-312d96c02e14 | B152: cmjbcsxz500e3zc7q24kn3s2a | C152: cmjbctdi200ekzc7qfelm64b8 | D152: test_ac15 | E152: scenario_3 | F152: 48 | G152: truth_and_fact | H152: 0.1 | I152: 0.2255603 | J152: 0.23357641 | K152: =J152-I152 -> 0.0080161043 | L152: 0.73243468

Sheet Notes
A1: p calculation
A3: 1. count | B3: =scen3_ac15!P2 -> 150
A4: 2. t statistic | B4: =B10*SQRT((B3-2)/(1-B10^2)) -> -0.57258938
A5: 3. p | B5: =_xlfn.T.DIST.2T(ABS(B4),B3-2) -> 0.56779157
A9: count | B9: correlation weights / activation delta
A10: =B3 -> 150 | B10: =scen3_ac15!Q2 -> -0.047014511

Sheet actdel_prompt_response
B2: Prompt-response
A3: Turn | B3: ac15
A4: 1 | B4: 0.81564959
A5: 2 | B5: 0.67540263
A6: 3 | B6: 0.65794906
A7: 4 | B7: 0.59515296
A8: 5 | B8: 0.54127803
A9: 6 | B9: 0.69456049
A10: 7 | B10: 0.82120974
A11: 8 | B11: 0.8272465
A12: 9 | B12: 0.67669431
A13: 10 | B13: 0.61131327
A14: 11 | B14: 0.74656093
A15: 12 | B15: 0.70879684
... A28: 25 | B28: 0.73243468

Sheet inter_system_stats
B2: prompt_to_response
A3: Turn | B3: ac15 | C3: control | E3: std.ac15 | F3: std. Control | G3: F. test | H3: T. Test equal variances | I3: T.Test unequal | J3: Mean difference | K3: average scenario | L3: average control
A4: 1 | B4: 0.81564959 | C4: 0.81237587 | E4: =_xlfn.STDEV.S(B4:B28) -> 0.073504161 | F4: =_xlfn.STDEV.S(C4:C28) -> 0.089932626 | G4: =_xlfn.F.TEST(B4:B28,C4:C28) -> 0.32969555 | H4: =_xlfn.T.TEST(B4:B28, C4:C28, 2,2) -> 2.908573e-06 | I4: =_xlfn.T.TEST(B4:B28,C4:C28, 2,3) -> 3.1924321e-06 | J4: =AVERAGE(B4:B28)-AVERAGE(C4:C28) -> 0.12305516 | K4: =AVERAGE(B4:B28) -> 0.71536169 | L4: =AVERAGE(C4:C28) -> 0.59230653
A5: 2 | B5: 0.67540263 | C5: 0.62132605
A6: 3 | B6: 0.65794906 | C6: 0.68189933
A7: 4 | B7: 0.59515296 | C7: 0.67477184
A8: 5 | B8: 0.54127803 | C8: 0.51803751
A9: 6 | B9: 0.69456049 | C9: 0.60625362
A10: 7 | B10: 0.82120974 | C10: 0.60279121
A11: 8 | B11: 0.8272465 | C11: 0.5426037
A12: 9 | B12: 0.67669431 | C12: 0.65241954
A13: 10 | B13: 0.61131327 | C13: 0.4509056
A14: 11 | B14: 0.74656093 | C14: 0.54613378
A15: 12 | B15: 0.70879684 | C15: 0.66577803
A16: 13 | B16: 0.72827882 | C16: 0.57017868
... A28: 25 | B28: 0.73243468 | C28: 0.40886576
A32: General
B33: ac15p | C33: hybrid | D33: hybsem | E33: ac15 | G33: ANOVA - Single Factor
A34: 1 | B34: 0.81661277 | C34: 0.81577203 | D34: 0.8076297 | E34: 0.81564959 | G34: Alpha | H34: 0.05
A35: 2 | B35: 0.68560399 | C35: 0.69017898 | D35: 0.73890843 | E35: 0.67540263
A36: 3 | B36: 0.692193 | C36: 0.6782366 | D36: 0.66648251 | E36: 0.65794906 | G36: Groups | H36: Count | I36: Sum | J36: Mean | K36: Variance
A37: 4 | B37: 0.63109017 | C37: 0.59975321 | D37: 0.6172328 | E37: 0.59515296 | G37: Column 1 | H37: =COUNT(inter_system_stats!$B$33:$B$57) -> 24 | I37: =SUM(inter_system_stats!$B$33:$B$57) -> 17.564842 | J37: =AVERAGE(inter_system_stats!$B$33:$B$57) -> 0.73186842 | K37: =VAR(inter_system_stats!$B$33:$B$57) -> 0.0049204956
A38: 5 | B38: 0.59460889 | C38: 0.57141073 | D38: 0.61042546 | E38: 0.54127803 | G38: Column 2 | H38: =COUNT(inter_system_stats!$C$33:$C$57) -> 24 | I38: =SUM(inter_system_stats!$C$33:$C$57) -> 17.327131 | J38: =AVERAGE(inter_system_stats!$C$33:$C$57) -> 0.72196379 | K38: =VAR(inter_system_stats!$C$33:$C$57) -> 0.0054482895
A39: 6 | B39: 0.67289207 | C39: 0.66533199 | D39: 0.70330399 | E39: 0.69456049 | G39: Column 3 | H39: =COUNT(inter_system_stats!$D$33:$D$57) -> 24 | I39: =SUM(inter_system_stats!$D$33:$D$57) -> 17.359952 | J39: =AVERAGE(inter_system_stats!$D$33:$D$57) -> 0.72333134 | K39: =VAR(inter_system_stats!$D$33:$D$57) -> 0.0043705973
A40: 7 | B40: 0.81547187 | C40: 0.83458196 | D40: 0.81769202 | E40: 0.82120974 | G40: Column 4 | H40: =COUNT(inter_system_stats!$E$33:$E$57) -> 24 | I40: =SUM(inter_system_stats!$E$33:$E$57) -> 17.151608 | J40: =AVERAGE(inter_system_stats!$E$33:$E$57) -> 0.71465031 | K40: =VAR(inter_system_stats!$E$33:$E$57) -> 0.0056245673
A41: 8 | B41: 0.77736126 | C41: 0.72719155 | D41: 0.7620195 | E41: 0.8272465
A42: 9 | B42: 0.69224629 | C42: 0.69768145 | D42: 0.64235421 | E42: 0.67669431 | G42: Source of Variation | H42: SS | I42: df | J42: MS | K42: F | L42: P-value | M42: F critical
A43: 10 | B43: 0.61584135 | C43: 0.61958009 | D43: 0.62291306 | E43: 0.61131327 | G43: Between Groups | H43: =SUMPRODUCT(inter_system_stats!$I$37:$I$40,inter_system_stats!$J$37:$J$40)-SUM(inter_system_stats!$I$37:$I$40)^2/SUM(inter_system_stats!$H$37:$H$40) -> 0.0035889823 | I43: =COUNT(inter_system_stats!$I$37:$I$40)-1 -> 3 | J43: =inter_system_stats!$H$43 / inter_system_stats!$I$43 -> 0.0011963274 | K43: =inter_system_stats!$J$43 / inter_system_stats!$J$44 -> 0.23498927 | L43: =FDIST(inter_system_stats!$K$43, inter_system_stats!$I$43, inter_system_stats!$I$44) -> 0.8717735 | M43: =FINV(inter_system_stats!$H$34, inter_system_stats!$I$43, inter_system_stats!$I$44) -> 2.703594
A44: 11 | B44: 0.77530249 | C44: 0.77492118 | D44: 0.77112756 | E44: 0.74656093 | G44: Within Groups | H44: =SUM(DEVSQ(inter_system_stats!$B$33:$B$57),DEVSQ(inter_system_stats!$C$33:$C$57),DEVSQ(inter_system_stats!$D$33:$D$57),DEVSQ(inter_system_stats!$E$33:$E$57)) -> 0.46837084 | I44: =SUM(inter_system_stats!$H$37:$H$40)-COUNT(inter_system_stats!$H$37:$H$40) -> 92 | J44: =inter_system_stats!$H$44 / inter_system_stats!$I$44 -> 0.0050909874
A45: 12 | B45: 0.74554982 | C45: 0.75355371 | D45: 0.75570049 | E45: 0.70879684 | G45: Total | H45: =DEVSQ(inter_system_stats!$B$33:$B$57,inter_system_stats!$C$33:$C$57,inter_system_stats!$D$33:$D$57,inter_system_stats!$E$33:$E$57) -> 0.47195983 | I45: =SUM(inter_system_stats!$H$37:$H$40) - 1 -> 95
A46: 13 | B46: 0.67593648 | C46: 0.67256393 | D46: 0.65220649 | E46: 0.72827882
A47: 14 | B47: 0.79745535 | C47: 0.79342845 | D47: 0.77420332 | E47: 0.76551888
A48: 15 | B48: 0.83168375 | C48: 0.82221564 | D48: 0.80993905 | E48: 0.814181
A49: 16 | B49: 0.66591506 | C49: 0.63533272 | D49: 0.65013163 | E49: 0.71176218
A50: 17 | B50: 0.80846503 | C50: 0.79359465 | D50: 0.79718908 | E50: 0.76658995
A51: 18 | B51: 0.70292333 | C51: 0.70487145 | D51: 0.72918538 | E51: 0.74497397
A52: 19 | B52: 0.83384929 | C52: 0.80738013 | D52: 0.81431744 | E52: 0.80774842
A53: 20 | B53: 0.79062425 | C53: 0.68583989 | D53: 0.72621087 | E53: 0.66966014
A54: 21 | B54: 0.73061736 | C54: 0.74453294 | D54: 0.72902821 | E54: 0.64644513
A55: 22 | B55: 0.76520806 | C55: 0.79344048 | D55: 0.72636055 | E55: 0.69084564
...

Sheet std delta(sim)-delta(sim-1)
C2: ac15p | D2: hybrid | E2: hybsem | F2: ac15
B3: 1 | C3: 0.81661277 | D3: 0.81577203 | E3: 0.8076297 | F3: 0.81564959
B4: 2 | C4: 0.68560399 | D4: 0.69017898 | E4: 0.73890843 | F4: 0.67540263
B5: 3 | C5: 0.692193 | D5: 0.6782366 | E5: 0.66648251 | F5: 0.65794906
B6: 4 | C6: 0.63109017 | D6: 0.59975321 | E6: 0.6172328 | F6: 0.59515296
B7: 5 | C7: 0.59460889 | D7: 0.57141073 | E7: 0.61042546 | F7: 0.54127803
B8: 6 | C8: 0.67289207 | D8: 0.66533199 | E8: 0.70330399 | F8: 0.69456049
B9: 7 | C9: 0.81547187 | D9: 0.83458196 | E9: 0.81769202 | F9: 0.82120974
B10: 8 | C10: 0.77736126 | D10: 0.72719155 | E10: 0.7620195 | F10: 0.8272465
B11: 9 | C11: 0.69224629 | D11: 0.69768145 | E11: 0.64235421 | F11: 0.67669431
B12: 10 | C12: 0.61584135 | D12: 0.61958009 | E12: 0.62291306 | F12: 0.61131327
B13: 11 | C13: 0.77530249 | D13: 0.77492118 | E13: 0.77112756 | F13: 0.74656093
B14: 12 | C14: 0.74554982 | D14: 0.75355371 | E14: 0.75570049 | F14: 0.70879684
... B26: 24 | C26: 0.7303546 | D26: 0.73783554 | E26: 0.73739705 | F26: 0.72779628
A29: deltas:
H30: stdev
C31: ac15p | D31: hybrid | E31: hybsem | F31: ac15 | H31: ac15p | I31: hybrid | J31: hybsem | K31: ac15
B32: 2 | C32: =C5-C4 -> 0.0065890098 | D32: =D5-D4 -> -0.011942386 | E32: =E5-E4 -> -0.072425918 | F32: =F5-F4 -> -0.017453569 | H32: =_xlfn.STDEV.S(C32:C53) -> 0.092156815 | I32: =_xlfn.STDEV.S(D32:D53) -> 0.10158971 | J32: =_xlfn.STDEV.S(E32:E53) -> 0.088767686 | K32: =_xlfn.STDEV.S(F32:F53) -> 0.080940275
B33: 3 | C33: =C6-C5 -> -0.061102833 | D33: =D6-D5 -> -0.078483385 | E33: =E6-E5 -> -0.049249719 | F33: =F6-F5 -> -0.062796103
B34: 4 | C34: =C7-C6 -> -0.036481277 | D34: =D7-D6 -> -0.028342479 | E34: =E7-E6 -> -0.0068073402 | F34: =F7-F6 -> -0.053874933
B35: 5 | C35: =C8-C7 -> 0.078283185 | D35: =D8-D7 -> 0.093921265 | E35: =E8-E7 -> 0.092878535 | F35: =F8-F7 -> 0.15328247
B36: 6 | C36: =C9-C8 -> 0.1425798 | D36: =D9-D8 -> 0.16924996 | E36: =E9-E8 -> 0.11438803 | F36: =F9-F8 -> 0.12664925
B37: 7 | C37: =C10-C9 -> -0.038110613 | D37: =D10-D9 -> -0.1073904 | E37: =E10-E9 -> -0.055672522 | F37: =F10-F9 -> 0.0060367632
B38: 8 | C38: =C11-C10 -> -0.08511497 | D38: =D11-D10 -> -0.029510103 | E38: =E11-E10 -> -0.11966528 | F38: =F11-F10 -> -0.15055219
B39: 9 | C39: =C12-C11 -> -0.076404942 | D39: =D12-D11 -> -0.078101357 | E39: =E12-E11 -> -0.019441152 | F39: =F12-F11 -> -0.065381041
B40: 10 | C40: =C13-C12 -> 0.15946114 | D40: =D13-D12 -> 0.15534108 | E40: =E13-E12 -> 0.1482145 | F40: =F13-F12 -> 0.13524766
B41: 11 | C41: =C14-C13 -> -0.029752672 | D41: =D14-D13 -> -0.021367468 | E41: =E14-E13 -> -0.015427064 | F41: =F14-F13 -> -0.037764093
B42: 12 | C42: =C15-C14 -> -0.069613345 | D42: =D15-D14 -> -0.08098978 | E42: =E15-E14 -> -0.103494 | F42: =F15-F14 -> 0.019481977
B43: 13 | C43: =C16-C15 -> 0.12151887 | D43: =D16-D15 -> 0.12086452 | E43: =E16-E15 -> 0.12199682 | F43: =F16-F15 -> 0.037240061
B44: 14 | C44: =C17-C16 -> 0.034228401 | D44: =D17-D16 -> 0.028787199 | E44: =E17-E16 -> 0.03573573 | F44: =F17-F16 -> 0.048662118
... B53: 23 | C53: =C26-C25 -> 0.013319168 | D53: =D26-D25 -> 0.02993393 | E53: =E26-E25 -> 0.039403639 | F53: =F26-F25 -> 0.021803563
