Workbook

Sheet scen6_ac15
A1: turnId | B1: user_id | C1: assistant_id | D1: projectName | E1: sessionName | F1: seq | G1: anchorName | H1: weight | I1: promptSim | J1: responseSim | K1: activation delta | L1: prompt_to_response | P1: count | Q1: activation delta average | R1: correlation weights / activation delta | S1: p
P2: =COUNT(K3:K128) -> 126 | Q2: =AVERAGE(K3:K128) -> 0.037829613 | R2: =CORREL(H3:H128,K3:K128) -> 0.29933771 | S2: 0.00066165904
A3: 3b71e762-df73-4e98-bc34-0b56e323fa20 | B3: cmjhai3wa00v4zcx2fq9tzz0q | C3: cmjhaj97b00vlzcx2dlux6ngg | D3: test_ac15 | E3: Scenario_6 | F3: 0 | G3: truth_and_fact | H3: 0.1 | I3: 0.11889934 | J3: 0.18155795 | K3: =J3-I3 -> 0.062658618 | L3: 0.82327274
A4: a9bd27ae-9789-4088-ba9d-b981224b09df | B4: cmjhakr1u00vpzcx29lcpygjc | C4: cmjhala4900w6zcx29m3eaj8z | D4: test_ac15 | E4: Scenario_6 | F4: 2 | G4: truth_and_fact | H4: 0.1 | I4: 0.13328355 | J4: 0.23129946 | K4: =J4-I4 -> 0.09801591 | L4: 0.64219932
A5: a21fca21-697f-43f3-9d22-bc5a826dabc4 | B5: cmjhaqbyl00wazcx2gehz0nor | C5: cmjhar28s00wrzcx2a7r3mido | D5: test_ac15 | E5: Scenario_6 | F5: 4 | G5: temporal_dynamics | H5: 0.1911 | I5: 0.26319333 | J5: 0.26753619 | K5: =J5-I5 -> 0.0043428594 | L5: 0.72456003
A6: a21fca21-697f-43f3-9d22-bc5a826dabc4 | B6: cmjhaqbyl00wazcx2gehz0nor | C6: cmjhar28s00wrzcx2a7r3mido | D6: test_ac15 | E6: Scenario_6 | F6: 4 | G6: practicality_and_feasibility | H6: 0.1903 | I6: 0.26210365 | J6: 0.26659469 | K6: =J6-I6 -> 0.0044910422 | L6: 0.72456003
A7: a21fca21-697f-43f3-9d22-bc5a826dabc4 | B7: cmjhaqbyl00wazcx2gehz0nor | C7: cmjhar28s00wrzcx2a7r3mido | D7: test_ac15 | E7: Scenario_6 | F7: 4 | G7: freedom_and_limitations | H7: 0.1751 | I7: 0.24112215 | J7: 0.24219632 | K7: =J7-I7 -> 0.0010741645 | L7: 0.72456003
A8: a21fca21-697f-43f3-9d22-bc5a826dabc4 | B8: cmjhaqbyl00wazcx2gehz0nor | C8: cmjhar28s00wrzcx2a7r3mido | D8: test_ac15 | E8: Scenario_6 | F8: 4 | G8: sovereignty | H8: 0.1741 | I8: 0.23979675 | J8: 0.26107539 | K8: =J8-I8 -> 0.021278642 | L8: 0.72456003
A9: a21fca21-697f-43f3-9d22-bc5a826dabc4 | B9: cmjhaqbyl00wazcx2gehz0nor | C9: cmjhar28s00wrzcx2a7r3mido | D9: test_ac15 | E9: Scenario_6 | F9: 4 | G9: identity | H9: 0.1694 | I9: 0.23333242 | J9: 0.23639553 | K9: =J9-I9 -> 0.003063119 | L9: 0.72456003
A10: a21fca21-697f-43f3-9d22-bc5a826dabc4 | B10: cmjhaqbyl00wazcx2gehz0nor | C10: cmjhar28s00wrzcx2a7r3mido | D10: test_ac15 | E10: Scenario_6 | F10: 4 | G10: truth_and_fact | H10: 0.1 | I10: 0.18214194 | J10: 0.19760614 | K10: =J10-I10 -> 0.015464206 | L10: 0.72456003
A11: 5b1ea5a0-8e5f-48af-a1f4-2cff29537db5 | B11: cmjhatv6100wvzcx2ez64j3wo | C11: cmjhauf4r00xczcx2s8ykaita | D11: test_ac15 | E11: Scenario_6 | F11: 6 | G11: sovereignty | H11: 0.456 | I11: 0.20689921 | J11: 0.31470853 | K11: =J11-I11 -> 0.10780933 | L11: 0.70833619
A12: 5b1ea5a0-8e5f-48af-a1f4-2cff29537db5 | B12: cmjhatv6100wvzcx2ez64j3wo | C12: cmjhauf4r00xczcx2s8ykaita | D12: test_ac15 | E12: Scenario_6 | F12: 6 | G12: practicality_and_feasibility | H12: 0.444 | I12: 0.20146387 | J12: 0.35682206 | K12: =J12-I12 -> 0.1553582 | L12: 0.70833619
A13: 5b1ea5a0-8e5f-48af-a1f4-2cff29537db5 | B13: cmjhatv6100wvzcx2ez64j3wo | C13: cmjhauf4r00xczcx2s8ykaita | D13: test_ac15 | E13: Scenario_6 | F13: 6 | G13: truth_and_fact | H13: 0.1 | I13: 0.16035842 | J13: 0.23637827 | K13: =J13-I13 -> 0.076019848 | L13: 0.70833619
A14: 748623ac-9737-4f73-a4ae-925b6ebc2a95 | B14: cmjhauwgr00xgzcx2z95vhr4x | C14: cmjhaw1bl00xxzcx2zttcqfac | D14: test_ac15 | E14: Scenario_6 | F14: 8 | G14: practicality_and_feasibility | H14: 0.2088 | I14: 0.34983171 | J14: 0.31339674 | K14: =J14-I14 -> -0.036434971 | L14: 0.69762049
... A128: 3f8b6a8a-6587-4337-9885-3eb744176744 | B128: cmjhbe3ue0194zcx2vj5pvw8q | C128: cmjhbek34019lzcx27a657a6c | D128: test_ac15 | E128: Scenario_6 | F128: 48 | G128: truth_and_fact | H128: 0.1 | I128: 0.22074993 | J128: 0.28092173 | K128: =J128-I128 -> 0.060171797 | L128: 0.75603222

Sheet notes
A1: p calculation
A3: 1. count | B3: =scen6_ac15!P2 -> 126
A4: 2. t statistic | B4: =B10*SQRT((B3-2)/(1-B10^2)) -> 3.4934689
A5: 3. p | B5: =_xlfn.T.DIST.2T(ABS(B4),B3-2) -> 0.00066165904
A9: count | B9: correlation weights / activation delta
A10: =B3 -> 126 | B10: =scen6_ac15!R2 -> 0.29933771

Sheet actdel_prompt_response
A2: Prompt-response
A3: Turn | B3: ac15
A4: 1 | B4: 0.82327274
A5: 2 | B5: 0.64219932
A6: 3 | B6: 0.72456003
A7: 4 | B7: 0.70833619
A8: 5 | B8: 0.69762049
A9: 6 | B9: 0.75727629
A10: 7 | B10: 0.7584497
A11: 8 | B11: 0.70527533
A12: 9 | B12: 0.63811046
A13: 10 | B13: 0.71891692
A14: 11 | B14: 0.76091064
A15: 12 | B15: 0.8127806
... A28: 25 | B28: 0.75603222

Sheet inter_system_stats
A2: Prompt-response
A3: Turn | B3: ac15 | C3: control | D3: delta activation | E3: choose | F3: std. Hybsem | G3: std. Control | H3: F. test | I3: T. Test equal variances | J3: T.Test unequal | K3: Mean difference | L3: Mean ac15 | M3: Mean control
A4: 1 | B4: 0.82327274 | C4: 0.8205306 | D4: =B4-C4 -> 0.00274214 | F4: =_xlfn.STDEV.S(B4:B28) -> 0.052085231 | G4: =_xlfn.STDEV.S(C4:C28) -> 0.1102969 | H4: =_xlfn.F.TEST(B4:B28,C4:C28) -> 0.00048795879 | I4: =_xlfn.T.TEST(B4:B28, C4:C28, 2,2) -> 3.2633921e-08 | J4: =_xlfn.T.TEST(B4:B28,C4:C28, 2,3) -> 1.5026764e-07 | K4: =AVERAGE(B4:B28)-AVERAGE(C4:C28) -> 0.16047544 | L4: =AVERAGE(B4:B28) -> 0.72482238 | M4: =AVERAGE(C4:C28) -> 0.56434695
A5: 2 | B5: 0.64219932 | C5: 0.4077777 | D5: =B5-C5 -> 0.23442162 | E5: x
A6: 3 | B6: 0.72456003 | C6: 0.64741534 | D6: =B6-C6 -> 0.077144695
A7: 4 | B7: 0.70833619 | C7: 0.4921473 | D7: =B7-C7 -> 0.21618889 | E7: x
A8: 5 | B8: 0.69762049 | C8: 0.53686287 | D8: =B8-C8 -> 0.16075762 | E8: x
A9: 6 | B9: 0.75727629 | C9: 0.63772449 | D9: =B9-C9 -> 0.1195518
A10: 7 | B10: 0.7584497 | C10: 0.61665661 | D10: =B10-C10 -> 0.1417931
A11: 8 | B11: 0.70527533 | C11: 0.62659257 | D11: =B11-C11 -> 0.078682753
A12: 9 | B12: 0.63811046 | C12: 0.64803425 | D12: =B12-C12 -> -0.0099237935
A13: 10 | B13: 0.71891692 | C13: 0.50632365 | D13: =B13-C13 -> 0.21259327 | E13: x
A14: 11 | B14: 0.76091064 | C14: 0.58561227 | D14: =B14-C14 -> 0.17529837 | E14: x
A15: 12 | B15: 0.8127806 | C15: 0.52267553 | D15: =B15-C15 -> 0.29010508 | E15: x
A16: 13 | B16: 0.72140757 | C16: 0.59336895 | D16: =B16-C16 -> 0.12803862
A17: 14 | B17: 0.76471606 | C17: 0.71201019 | D17: =B17-C17 -> 0.052705864
A18: 15 | B18: 0.71175796 | C18: 0.38959043 | D18: =B18-C18 -> 0.32216753 | E18: x
A19: 16 | B19: 0.63640913 | C19: 0.53846119 | D19: =B19-C19 -> 0.097947944
A20: 17 | B20: 0.76068461 | C20: 0.56235223 | D20: =B20-C20 -> 0.19833238 | E20: x
A21: 18 | B21: 0.68944451 | C21: 0.44901918 | D21: =B21-C21 -> 0.24042533 | E21: x
A22: 19 | B22: 0.69990755 | C22: 0.54704697 | D22: =B22-C22 -> 0.15286059
A23: 20 | B23: 0.72147067 | C23: 0.5661061 | D23: =B23-C23 -> 0.15536457
A24: 21 | B24: 0.69401911 | C24: 0.40458195 | D24: =B24-C24 -> 0.28943716 | E24: x
A25: 22 | B25: 0.75579758 | C25: 0.66244443 | D25: =B25-C25 -> 0.093353157
A26: 23 | B26: 0.65088531 | C26: 0.4215713 | D26: =B26-C26 -> 0.22931401 | E26: x
A27: 24 | B27: 0.81031859 | C27: 0.7443393 | D27: =B27-C27 -> 0.065979289
A28: 25 | B28: 0.75603222 | C28: 0.46942826 | D28: =B28-C28 -> 0.28660396 | E28: x
A32: General
A34: Turn | B34: ac15p | C34: hybrid | D34: hybsem | E34: ac15 | F34: control | H34: ANOVA - Single Factor
A35: 1 | B35: 0.79000575 | C35: 0.8189473 | D35: 0.78516876 | E35: 0.82327274 | F35: 0.8205306 | H35: Alpha | I35: 0.05
A36: 2 | B36: 0.6817351 | C36: 0.72667505 | D36: 0.70344439 | E36: 0.64219932 | F36: 0.4077777
A37: 3 | B37: 0.73659154 | C37: 0.75382376 | D37: 0.73539986 | E37: 0.72456003 | F37: 0.64741534 | H37: Groups | I37: Count | J37: Sum | K37: Mean | L37: Variance
A38: 4 | B38: 0.65821229 | C38: 0.69468916 | D38: 0.69729745 | E38: 0.70833619 | F38: 0.4921473 | H38: Column 1 | I38: =COUNT(inter_system_stats!$B$34:$B$59) -> 25 | J38: =SUM(inter_system_stats!$B$34:$B$59) -> 18.201412 | K38: =AVERAGE(inter_system_stats!$B$34:$B$59) -> 0.72805647 | L38: =VAR(inter_system_stats!$B$34:$B$59) -> 0.0037347451
A39: 5 | B39: 0.74318489 | C39: 0.75031898 | D39: 0.71322313 | E39: 0.69762049 | F39: 0.53686287 | H39: Column 2 | I39: =COUNT(inter_system_stats!$C$34:$C$59) -> 25 | J39: =SUM(inter_system_stats!$C$34:$C$59) -> 18.400771 | K39: =AVERAGE(inter_system_stats!$C$34:$C$59) -> 0.73603082 | L39: =VAR(inter_system_stats!$C$34:$C$59) -> 0.0029897442
A40: 6 | B40: 0.7383633 | C40: 0.79289751 | D40: 0.76734743 | E40: 0.75727629 | F40: 0.63772449 | H40: Column 3 | I40: =COUNT(inter_system_stats!$D$34:$D$59) -> 25 | J40: =SUM(inter_system_stats!$D$34:$D$59) -> 18.007959 | K40: =AVERAGE(inter_system_stats!$D$34:$D$59) -> 0.72031836 | L40: =VAR(inter_system_stats!$D$34:$D$59) -> 0.0032534829
A41: 7 | B41: 0.80270938 | C41: 0.74071706 | D41: 0.74121447 | E41: 0.7584497 | F41: 0.61665661 | H41: Column 4 | I41: =COUNT(inter_system_stats!$E$34:$E$59) -> 25 | J41: =SUM(inter_system_stats!$E$34:$E$59) -> 18.12056 | K41: =AVERAGE(inter_system_stats!$E$34:$E$59) -> 0.72482238 | L41: =VAR(inter_system_stats!$E$34:$E$59) -> 0.0027128713
A42: 8 | B42: 0.76713782 | C42: 0.70151887 | D42: 0.7026918 | E42: 0.70527533 | F42: 0.62659257
A43: 9 | B43: 0.65520384 | C43: 0.67940884 | D43: 0.67641093 | E43: 0.63811046 | F43: 0.64803425 | H43: Source of Variation | I43: SS | J43: df | K43: MS | L43: F | M43: P-value | N43: F critical
A44: 10 | B44: 0.70090518 | C44: 0.69382834 | D44: 0.71515554 | E44: 0.71891692 | F44: 0.50632365 | H44: Between Groups | I44: =SUMPRODUCT(inter_system_stats!$J$38:$J$41,inter_system_stats!$K$38:$K$41)-SUM(inter_system_stats!$J$38:$J$41)^2/SUM(inter_system_stats!$I$38:$I$41) -> 0.0032920291 | J44: =COUNT(inter_system_stats!$J$38:$J$41)-1 -> 3 | K44: =inter_system_stats!$I$44 / inter_system_stats!$J$44 -> 0.001097343 | L44: =inter_system_stats!$K$44 / inter_system_stats!$K$45 -> 0.34586922 | M44: =FDIST(inter_system_stats!$L$44, inter_system_stats!$J$44, inter_system_stats!$J$45) -> 0.79220631 | N44: =FINV(inter_system_stats!$I$35, inter_system_stats!$J$44, inter_system_stats!$J$45) -> 2.6993926
A45: 11 | B45: 0.71962924 | C45: 0.71401509 | D45: 0.72491699 | E45: 0.76091064 | F45: 0.58561227 | H45: Within Groups | I45: =SUM(DEVSQ(inter_system_stats!$B$34:$B$59),DEVSQ(inter_system_stats!$C$34:$C$59),DEVSQ(inter_system_stats!$D$34:$D$59),DEVSQ(inter_system_stats!$E$34:$E$59)) -> 0.30458024 | J45: =SUM(inter_system_stats!$I$38:$I$41)-COUNT(inter_system_stats!$I$38:$I$41) -> 96 | K45: =inter_system_stats!$I$45 / inter_system_stats!$J$45 -> 0.0031727109
...

Sheet sims
A2: Turn | B2: ac15p | C2: hybrid | D2: hybsem | E2: ac15
A3: 1 | B3: 0.79000575 | C3: 0.8189473 | D3: 0.78516876 | E3: 0.82327274
A4: 2 | B4: 0.6817351 | C4: 0.72667505 | D4: 0.70344439 | E4: 0.64219932
A5: 3 | B5: 0.73659154 | C5: 0.75382376 | D5: 0.73539986 | E5: 0.72456003
A6: 4 | B6: 0.65821229 | C6: 0.69468916 | D6: 0.69729745 | E6: 0.70833619
A7: 5 | B7: 0.74318489 | C7: 0.75031898 | D7: 0.71322313 | E7: 0.69762049
A8: 6 | B8: 0.7383633 | C8: 0.79289751 | D8: 0.76734743 | E8: 0.75727629
A9: 7 | B9: 0.80270938 | C9: 0.74071706 | D9: 0.74121447 | E9: 0.7584497
A10: 8 | B10: 0.76713782 | C10: 0.70151887 | D10: 0.7026918 | E10: 0.70527533
A11: 9 | B11: 0.65520384 | C11: 0.67940884 | D11: 0.67641093 | E11: 0.63811046
A12: 10 | B12: 0.70090518 | C12: 0.69382834 | D12: 0.71515554 | E12: 0.71891692
A13: 11 | B13: 0.71962924 | C13: 0.71401509 | D13: 0.72491699 | E13: 0.76091064
A14: 12 | B14: 0.83162141 | C14: 0.82935334 | D14: 0.84477335 | E14: 0.8127806
... A27: 25 | B27: 0.72794547 | C27: 0.7362928 | D27: 0.69720151 | E27: 0.75603222
A31: deltas | G31: stdev
B32: ac15p | C32: hybrid | D32: hybsem | E32: ac15 | G32: ac15p | H32: hybrid | I32: hybsem | J32: ac15
B33: =B4-B3 -> -0.10827065 | C33: =C4-C3 -> -0.092272244 | D33: =D4-D3 -> -0.081724374 | E33: =E4-E3 -> -0.18107343 | G33: =STDEV(B33:B56) -> 0.092675031 | H33: =STDEV(C33:C56) -> 0.082535014 | I33: =STDEV(D33:D56) -> 0.088965255 | J33: =STDEV(E33:E56) -> 0.079505643
B34: =B5-B4 -> 0.054856443 | C34: =C5-C4 -> 0.027148709 | D34: =D5-D4 -> 0.031955468 | E34: =E5-E4 -> 0.082360713
B35: =B6-B5 -> -0.078379249 | C35: =C6-C5 -> -0.059134602 | D35: =D6-D5 -> -0.038102402 | E35: =E6-E5 -> -0.016223843
B36: =B7-B6 -> 0.0849726 | C36: =C7-C6 -> 0.055629814 | D36: =D7-D6 -> 0.015925673 | E36: =E7-E6 -> -0.0107157
B37: =B8-B7 -> -0.0048215929 | C37: =C8-C7 -> 0.042578531 | D37: =D8-D7 -> 0.054124302 | E37: =E8-E7 -> 0.059655804
B38: =B9-B8 -> 0.064346081 | C38: =C9-C8 -> -0.052180443 | D38: =D9-D8 -> -0.026132955 | E38: =E9-E8 -> 0.0011734108
B39: =B10-B9 -> -0.03557156 | C39: =C10-C9 -> -0.039198197 | D39: =D10-D9 -> -0.03852267 | E39: =E10-E9 -> -0.053174376
B40: =B11-B10 -> -0.11193398 | C40: =C11-C10 -> -0.022110028 | D40: =D11-D10 -> -0.026280879 | E40: =E11-E10 -> -0.067164868
B41: =B12-B11 -> 0.045701341 | C41: =C12-C11 -> 0.014419501 | D41: =D12-D11 -> 0.038744614 | E41: =E12-E11 -> 0.080806462
B42: =B13-B12 -> 0.018724052 | C42: =C13-C12 -> 0.020186755 | D42: =D13-D12 -> 0.0097614552 | E42: =E13-E12 -> 0.041993725
B43: =B14-B13 -> 0.11199218 | C43: =C14-C13 -> 0.11533824 | D43: =D14-D13 -> 0.11985636 | E43: =E14-E13 -> 0.051869959
B44: =B15-B14 -> -0.12210191 | C44: =C15-C14 -> -0.088018221 | D44: =D15-D14 -> -0.17400207 | E44: =E15-E14 -> -0.091373032
B45: =B16-B15 -> 0.043068537 | C45: =C16-C15 -> 0.036223577 | D45: =D16-D15 -> 0.078428059 | E45: =E16-E15 -> 0.043308487
... B56: =B27-B26 -> -0.12506681 | C56: =C27-C26 -> -0.11027655 | D56: =D27-D26 -> -0.12385221 | E56: =E27-E26 -> -0.054286367
