Workbook

Sheet initial sheet
C2: average conversation activation | D2: correlation weights / activation delta | E2: P
A3: Scenario 1
B4: ac15p | C4: 0.040727738 | D4: -0.20986674 | E4: 0.0099
B5: hybrid | C5: 0.03949068 | D5: -0.04055391 | E5: 0.62696517
B6: hybsem | C6: 0.03944214 | D6: -0.0096862162 | E6: 0.90762425
B7: ac15 | C7: 0.03780378 | D7: -0.11797192 | E7: 0.151
A9: Scenario 2
B10: ac15p | C10: 0.079908646 | D10: 0.088676395 | E10: 0.29
B11: hybrid | C11: 0.061242462 | D11: 0.19163293 | E11: 0.02833034
B12: hybsem | C12: 0.057053659 | D12: 0.12685514 | E12: 0.1367
B13: ac15 | C13: 0.06608221 | D13: 0.16559238 | E13: 0.088
A15: Scenario 3
B16: ac15p | C16: 0.048767418 | D16: 0.037229909 | E16: 0.653
B17: hybrid | C17: 0.051082083 | D17: -0.16612815 | E17: 0.046589407
B18: hybsem | C18: 0.049157864 | D18: -0.13952101 | E18: 0.088601631
B19: ac15 | C19: 0.056810471 | D19: -0.047014511 | E19: 0.56779157
A21: Scenario 4
B22: ac15p | C22: 0.052228295 | D22: -0.059158262 | E22: 0.472
B23: hybrid | C23: 0.054236474 | D23: 0.041393677 | E23: 0.621
B24: hybsem | C24: 0.048938143 | D24: -0.0044933836 | E24: 0.96
B25: ac15 | C25: 0.055958911 | D25: 0.034070544 | E25: 0.68
A27: Scenario 5
B28: ac15p | C28: 0.027098527 | D28: -0.25383926 | E28: 0.0017221861
B29: hybrid | C29: 0.037631878 | D29: -0.20998728 | E29: 0.00990535
B30: hybsem | C30: 0.030045283 | D30: -0.34078016 | E30: 1.9793024e-05
B31: ac15 | C31: 0.032479658 | D31: -0.20083069 | E31: 0.013730116
A33: Scenario 6
B34: ac15p | C34: 0.04570281 | D34: 0.25777242 | E34: 0.0038478417
B35: hybrid | C35: 0.044551994 | D35: 0.035675108 | E35: 0.708
B36: hybsem | C36: 0.043140099 | D36: -0.013730456 | E36: 0.88
B37: ac15 | C37: 0.037829613 | D37: 0.29933771 | E37: 0.00066165904
A39: Scenario 7
B40: ac15p | C40: 0.046128744 | D40: 0.18510111 | E40: 0.033
B41: hybrid | C41: 0.045117016 | D41: 0.14440781 | E41: 0.1053
B42: hybsem | C42: 0.033631002 | D42: 0.14885737 | E42: 0.078
B43: ac15 | C43: 0.046204621 | D43: 0.10836359 | E43: 0.211
A45: Scenario 8
B46: ac15p | C46: 0.0575252 | D46: 0.11436986 | E46: 0.19
B47: hybrid | C47: 0.070469109 | D47: 0.35334384 | E47: 5.2998013e-05
B48: hybsem | C48: 0.065233247 | D48: 0.36240036 | E48: 1.9534765e-05
...

Sheet control vs. scenario-prompt.res
A3: Scenario 1 | C3: std. Scenario | D3: std. Control | E3: F. test | F3: T. Test equal variances | G3: T.Test unequal | H3: Mean difference | I3: Mean scenario | J3: mean control
B4: ac15p | C4: 0.067896899 | D4: 0.11788306 | E4: 0.0090042231 | F4: 1.3447401e-07 | G4: 3.1421376e-07 | H4: 0.16806102 | I4: 0.73072651 | J4: 0.56266549
B5: hybrid | C5: 0.056581542 | D5: 0.11788306 | E5: 0.00063255311 | F5: 5.7118842e-08 | G5: 2.3132071e-07 | H5: 0.16788549 | I5: 0.73055098 | J5: 0.56266549
B6: hybsem | C6: 0.06548327 | D6: 0.11788306 | E6: 0.0055234552 | F6: 8.1996229e-08 | G6: 2.2046054e-07 | H6: 0.1703759 | I6: =AVERAGE('[1]inter_system stats'!$B$3:$B$28) -> 0.73304139 | J6: =AVERAGE('[1]inter_system stats'!$C$3:$C$28) -> 0.56266549
B7: ac15 | C7: 0.06078154 | D7: 0.11788306 | E7: 0.0018992762 | F7: 4.6958715e-07 | G7: 1.2140351e-06 | H7: 0.154415 | I7: 0.717 | J7: =AVERAGE('[1]inter_system stats'!$C$3:$C$28) -> 0.56266549
A9: Scenario 2
C10: std. Scenario | D10: std. Control | E10: F. test | F10: T. Test equal variances | G10: T.Test unequal | H10: Mean difference | I10: Mean scenario | J10: mean control
B11: ac15p | C11: 0.044988984 | D11: 0.11577762 | E11: 1.7096385e-05 | F11: 2.2389505e-11 | G11: 8.5891805e-10 | H11: 0.2151923 | I11: =AVERAGE([2]inter_system_stats!$B$3:$B$28) -> 0.75220636 | J11: =AVERAGE([2]inter_system_stats!$C$3:$C$28) -> 0.53701406
B12: hybrid | C12: 0.048146689 | D12: 0.11577762 | E12: 5.7570479e-05 | F12: 2.8643042e-11 | G12: 7.9981665e-10 | H12: 0.21543012 | I12: 0.75244418 | J12: 0.53701406
B13: hybsem | C13: 0.045126675 | D13: 0.11577762 | E13: 1.8075799e-05 | F13: 3.4939752e-11 | G13: 1.1871252e-09 | H13: 0.21205229 | I13: 0.74906635 | J13: 0.53701406
B14: ac15 | C14: 0.046176143 | D14: 0.11577762 | E14: 2.7403314e-05 | F14: 2.8150938e-11 | G14: 9.2678175e-10 | H14: 0.21427897 | I14: 0.75129303 | J14: 0.53701406
A16: Scenario 3
C17: std. Scenario | D17: std. Control | E17: F. test | F17: T. Test equal variances | G17: T.Test unequal | H17: Mean difference | I17: Mean scenario | J17: mean control
B18: ac15p | C18: 0.068942724 | D18: 0.089932626 | E18: 0.20012458 | F18: 1.1881327e-07 | G18: 1.5154255e-07 | H18: 0.14078866 | I18: 0.73309519 | J18: 0.59230653
B19: hybrid | C19: 0.073812529 | D19: 0.083159468 | E19: 0.57209129 | F19: 2.4666853e-06 | G19: 2.5557022e-06 | H19: 0.12201389 | I19: 0.72196379 | J19: 0.5999499
B20: hybsem | C20: 0.066110493 | D20: 0.083159468 | E20: 0.27847032 | F20: 8.4312901e-07 | G20: 9.7782892e-07 | H20: 0.12338145 | I20: 0.72333134 | J20: 0.5999499
B21: ac15 | C21: 0.073504161 | D21: 0.089932626 | E21: 0.32969555 | F21: 2.908573e-06 | G21: 3.1924321e-06 | H21: 0.12305516 | I21: 0.71536169 | J21: 0.59230653
A23: Scenario 4
C24: std. Scenario | D24: std. Control | E24: F. test | F24: T. Test equal variances | G24: T.Test unequal | H24: Mean difference | I24: Mean scenario | J24: mean control
B25: ac15p | C25: 0.0584109 | D25: 0.083848556 | E25: 0.08285923 | F25: 4.0180702e-05 | G25: 4.7869225e-05 | H25: 0.092418433 | I25: 0.73449 | J25: 0.642072
B26: hybrid | C26: 0.064494717 | D26: 0.083848556 | E26: 0.20579936 | F26: 0.00018662898 | G26: 0.00020003225 | H26: 0.085663653 | I26: 0.727736 | J26: 0.642072
B27: hybsem | C27: 0.054538342 | D27: 0.083848556 | E27: 0.039906432 | F27: 1.4604213e-05 | G27: 1.9464309e-05 | H27: 0.096519133 | I27: 0.738591 | J27: 0.642072
B28: ac15 | C28: 0.058444652 | D28: 0.083848556 | E28: 0.083341731 | F28: 0.00021943314 | G28: 0.00024747479 | H28: 0.081723968 | I28: 0.723796 | J28: 0.642072
A30: Scenario 5
C31: std. Scenario | D31: std. Control | E31: F. test | F31: T. Test equal variances | G31: T.Test unequal | H31: Mean difference | I31: Mean scenario | J31: mean control
B32: ac15p | C32: 0.0459084 | D32: 0.070588432 | E32: 0.039857183 | F32: 5.4533914e-07 | G32: 8.778905e-07 | H32: 0.097315497 | I32: 0.73237105 | J32: 0.63505555
B33: hybrid | C33: 0.039676048 | D33: 0.070588432 | E33: 0.0064899184 | F33: 2.4259587e-07 | G33: 5.6411108e-07 | H33: 0.097321697 | I33: 0.73237725 | J33: 0.63505555
B34: hybsem | C34: 0.035344552 | D34: 0.070588432 | E34: 0.001221091 | F34: 1.8660508e-07 | G34: 5.7771037e-07 | H34: 0.096057016 | I34: 0.73111256 | J34: 0.63505555
B35: ac15 | C35: 0.042716379 | D35: 0.070588432 | E35: 0.016976398 | F35: 1.3266703e-07 | G35: 2.7641179e-07 | H35: 0.10199219 | I35: 0.73704774 | J35: 0.63505555
A37: Scenario 6
C38: std. Scenario | D38: std. Control | E38: F. test | F38: T. Test equal variances | G38: T.Test unequal | H38: Mean difference | I38: Mean scenario | J38: mean control
B39: ac15p | C39: 0.061112561 | D39: 0.1102969 | E39: 0.0053317721 | F39: 4.4322352e-08 | G39: 1.287107e-07 | H39: 0.16370952 | I39: 0.72805647 | J39: 0.56434695
B40: hybrid | C40: 0.054678553 | D40: 0.1102969 | E40: 0.0010477438 | F40: 8.0884894e-09 | G40: 4.0618641e-08 | H40: 0.17168388 | I40: 0.73603082 | J40: 0.56434695
B41: hybsem | C41: 0.05703931 | D41: 0.1102969 | E41: 0.0019849337 | F41: 9.3374879e-08 | G41: 2.9439777e-07 | H41: 0.15597142 | I41: 0.72031836 | J41: 0.56434695
B42: ac15 | C42: 0.052085231 | D42: 0.1102969 | E42: 0.00048795879 | F42: 3.2633921e-08 | G42: 1.5026764e-07 | H42: 0.16047544 | I42: 0.72482238 | J42: 0.56434695
A44: Scenario 7
C45: std. Scenario | D45: std. Control | E45: F. test | F45: T. Test equal variances | G45: T.Test unequal | H45: Mean difference | I45: Mean scenario | J45: mean control
B46: ac15p | C46: 0.047581334 | D46: 0.10899113 | E46: 0.00013326183 | F46: 2.3438272e-07 | G46: 9.3037077e-07 | H46: 0.14316558 | I46: 0.71141589 | J46: 0.56825031
B47: hybrid | C47: 0.050384152 | D47: 0.10899113 | E47: 0.00034575751 | F47: 5.8179761e-08 | G47: 2.5702888e-07 | H47: 0.15404094 | I47: 0.72229125 | J47: 0.56825031
B48: hybsem | C48: 0.049899473 | D48: 0.10899113 | E48: 0.00029515491 | F48: 7.1638658e-08 | G48: 3.1286987e-07 | H48: 0.15236801 | I48: 0.72061831 | J48: 0.56825031
...

Sheet Anova-prompt-response
A2: Scenario 1
B3: ANOVA - Single Factor
B4: Alpha | C4: 0.05
B6: Groups | C6: Count | D6: Sum | E6: Mean | F6: Variance
A7: ac15p | B7: Column 1 | C7: =COUNT('[3]inter-system stats'!$B$34:$B$59) -> 25 | D7: =SUM('[3]inter-system stats'!$B$34:$B$59) -> 18.326035 | E7: =AVERAGE('[3]inter-system stats'!$B$34:$B$59) -> 0.73304139 | F7: =VAR('[3]inter-system stats'!$B$34:$B$59) -> 0.0042880587
A8: hybrid | B8: Column 2 | C8: =COUNT('[3]inter-system stats'!$C$34:$C$59) -> 25 | D8: =SUM('[3]inter-system stats'!$C$34:$C$59) -> 18.263774 | E8: =AVERAGE('[3]inter-system stats'!$C$34:$C$59) -> 0.73055098 | F8: =VAR('[3]inter-system stats'!$C$34:$C$59) -> 0.0032014709
A9: hybsem | B9: Column 3 | C9: =COUNT('[3]inter-system stats'!$D$34:$D$59) -> 25 | D9: =SUM('[3]inter-system stats'!$D$34:$D$59) -> 18.268163 | E9: =AVERAGE('[3]inter-system stats'!$D$34:$D$59) -> 0.73072651 | F9: =VAR('[3]inter-system stats'!$D$34:$D$59) -> 0.004609989
A10: ac15 | B10: Column 4 | C10: =COUNT('[3]inter-system stats'!$E$34:$E$59) -> 25 | D10: =SUM('[3]inter-system stats'!$E$34:$E$59) -> 17.927012 | E10: =AVERAGE('[3]inter-system stats'!$E$34:$E$59) -> 0.71708049 | F10: =VAR('[3]inter-system stats'!$E$34:$E$59) -> 0.0036943957
B12: Source of Variation | C12: SS | D12: df | E12: MS | F12: F | G12: P-value | H12: F critical
B13: Between Groups | C13: =SUMPRODUCT('Anova-prompt-response'!$D$7:$D$10,'Anova-prompt-response'!$E$7:$E$10)-SUM('Anova-prompt-response'!$D$7:$D$10)^2/SUM('Anova-prompt-response'!$C$7:$C$10) -> 0.0039625637 | D13: =COUNT('Anova-prompt-response'!$D$7:$D$10)-1 -> 3 | E13: ='Anova-prompt-response'!$C$13 / 'Anova-prompt-response'!$D$13 -> 0.0013208546 | F13: ='Anova-prompt-response'!$E$13 / 'Anova-prompt-response'!$E$14 -> 0.33452241 | G13: =FDIST('Anova-prompt-response'!$F$13, 'Anova-prompt-response'!$D$13, 'Anova-prompt-response'!$D$14) -> 0.80039762 | H13: =FINV('Anova-prompt-response'!$C$4, 'Anova-prompt-response'!$D$13, 'Anova-prompt-response'!$D$14) -> 2.6993926
B14: Within Groups | C14: =SUM(DEVSQ('[3]inter-system stats'!$B$34:$B$59),DEVSQ('[3]inter-system stats'!$C$34:$C$59),DEVSQ('[3]inter-system stats'!$D$34:$D$59),DEVSQ('[3]inter-system stats'!$E$34:$E$59)) -> 0.37905394 | D14: =SUM('Anova-prompt-response'!$C$7:$C$10)-COUNT('Anova-prompt-response'!$C$7:$C$10) -> 96 | E14: ='Anova-prompt-response'!$C$14 / 'Anova-prompt-response'!$D$14 -> 0.0039484785
B15: Total | C15: =DEVSQ('[3]inter-system stats'!$B$34:$B$59,'[3]inter-system stats'!$C$34:$C$59,'[3]inter-system stats'!$D$34:$D$59,'[3]inter-system stats'!$E$34:$E$59) -> 0.3830165 | D15: =SUM('Anova-prompt-response'!$C$7:$C$10) - 1 -> 99
B16: ANOVA - Single Factor
A25: Scenario 2
B27: ANOVA - Single Factor
B28: Alpha | C28: 0.05
B30: Groups | C30: Count | D30: Sum | E30: Mean | F30: Variance
A31: ac15p | B31: Column 1 | C31: =COUNT([4]inter_system_stats!$B$35:$B$60) -> 25 | D31: =SUM([4]inter_system_stats!$B$35:$B$60) -> 18.782326 | E31: =AVERAGE([4]inter_system_stats!$B$35:$B$60) -> 0.75129303 | F31: =VAR([4]inter_system_stats!$B$35:$B$60) -> 0.0021322361
A32: hybrid | B32: Column 2 | C32: =COUNT([4]inter_system_stats!$C$35:$C$60) -> 25 | D32: =SUM([4]inter_system_stats!$C$35:$C$60) -> 18.811104 | E32: =AVERAGE([4]inter_system_stats!$C$35:$C$60) -> 0.75244418 | F32: =VAR([4]inter_system_stats!$C$35:$C$60) -> 0.0023181036
A33: hybsem | B33: Column 3 | C33: =COUNT([4]inter_system_stats!$D$35:$D$60) -> 25 | D33: =SUM([4]inter_system_stats!$D$35:$D$60) -> 18.805159 | E33: =AVERAGE([4]inter_system_stats!$D$35:$D$60) -> 0.75220636 | F33: =VAR([4]inter_system_stats!$D$35:$D$60) -> 0.0020240087
A34: ac15 | B34: Column 4 | C34: =COUNT([4]inter_system_stats!$E$35:$E$60) -> 25 | D34: =SUM([4]inter_system_stats!$E$35:$E$60) -> 18.726659 | E34: =AVERAGE([4]inter_system_stats!$E$35:$E$60) -> 0.74906635 | F34: =VAR([4]inter_system_stats!$E$35:$E$60) -> 0.0020364168
B36: Source of Variation | C36: SS | D36: df | E36: MS | F36: F | G36: P-value | H36: F critical
B37: Between Groups | C37: =SUMPRODUCT('Anova-prompt-response'!$D$31:$D$34,'Anova-prompt-response'!$E$31:$E$34)-SUM('Anova-prompt-response'!$D$31:$D$34)^2/SUM('Anova-prompt-response'!$C$31:$C$34) -> 0.00017777105 | D37: =COUNT('Anova-prompt-response'!$D$31:$D$34)-1 -> 3 | E37: ='Anova-prompt-response'!$C$37 / 'Anova-prompt-response'!$D$37 -> 5.9257017e-05 | F37: ='Anova-prompt-response'!$E$37 / 'Anova-prompt-response'!$E$38 -> 0.027850383 | G37: =FDIST('Anova-prompt-response'!$F$37, 'Anova-prompt-response'!$D$37, 'Anova-prompt-response'!$D$38) -> 0.99369156 | H37: =FINV('Anova-prompt-response'!$C$28, 'Anova-prompt-response'!$D$37, 'Anova-prompt-response'!$D$38) -> 2.6993926
B38: Within Groups | C38: =SUM(DEVSQ([4]inter_system_stats!$B$35:$B$60),DEVSQ([4]inter_system_stats!$C$35:$C$60),DEVSQ([4]inter_system_stats!$D$35:$D$60),DEVSQ([4]inter_system_stats!$E$35:$E$60)) -> 0.20425837 | D38: =SUM('Anova-prompt-response'!$C$31:$C$34)-COUNT('Anova-prompt-response'!$C$31:$C$34) -> 96 | E38: ='Anova-prompt-response'!$C$38 / 'Anova-prompt-response'!$D$38 -> 0.0021276913
B39: Total | C39: =DEVSQ([4]inter_system_stats!$B$35:$B$60,[4]inter_system_stats!$C$35:$C$60,[4]inter_system_stats!$D$35:$D$60,[4]inter_system_stats!$E$35:$E$60) -> 0.20443614 | D39: =SUM('Anova-prompt-response'!$C$31:$C$34) - 1 -> 99
A48: Scenario 3
B49: ANOVA - Single Factor
B50: Alpha | C50: 0.05
B52: Groups | C52: Count | D52: Sum | E52: Mean | F52: Variance
A53: ac15p | B53: Column 1 | C53: =COUNT([5]inter_system_stats!$B$33:$B$57) -> 24 | D53: =SUM([5]inter_system_stats!$B$33:$B$57) -> 17.564842 | E53: =AVERAGE([5]inter_system_stats!$B$33:$B$57) -> 0.73186842 | F53: =VAR([5]inter_system_stats!$B$33:$B$57) -> 0.0049204956
A54: hybrid | B54: Column 2 | C54: =COUNT([5]inter_system_stats!$C$33:$C$57) -> 24 | D54: =SUM([5]inter_system_stats!$C$33:$C$57) -> 17.327131 | E54: =AVERAGE([5]inter_system_stats!$C$33:$C$57) -> 0.72196379 | F54: =VAR([5]inter_system_stats!$C$33:$C$57) -> 0.0054482895
A55: hybsem | B55: Column 3 | C55: =COUNT([5]inter_system_stats!$D$33:$D$57) -> 24 | D55: =SUM([5]inter_system_stats!$D$33:$D$57) -> 17.359952 | E55: =AVERAGE([5]inter_system_stats!$D$33:$D$57) -> 0.72333134 | F55: =VAR([5]inter_system_stats!$D$33:$D$57) -> 0.0043705973
A56: ac15 | B56: Column 4 | C56: =COUNT([5]inter_system_stats!$E$33:$E$57) -> 24 | D56: =SUM([5]inter_system_stats!$E$33:$E$57) -> 17.151608 | E56: =AVERAGE([5]inter_system_stats!$E$33:$E$57) -> 0.71465031 | F56: =VAR([5]inter_system_stats!$E$33:$E$57) -> 0.0056245673
B58: Source of Variation | C58: SS | D58: df | E58: MS | F58: F | G58: P-value | H58: F critical
B59: Between Groups | C59: =SUMPRODUCT('Anova-prompt-response'!$D$53:$D$56,'Anova-prompt-response'!$E$53:$E$56)-SUM('Anova-prompt-response'!$D$53:$D$56)^2/SUM('Anova-prompt-response'!$C$53:$C$56) -> 0.0035889823 | D59: =COUNT('Anova-prompt-response'!$D$53:$D$56)-1 -> 3 | E59: ='Anova-prompt-response'!$C$59 / 'Anova-prompt-response'!$D$59 -> 0.0011963274 | F59: ='Anova-prompt-response'!$E$59 / 'Anova-prompt-response'!$E$60 -> 0.23498927 | G59: =FDIST('Anova-prompt-response'!$F$59, 'Anova-prompt-response'!$D$59, 'Anova-prompt-response'!$D$60) -> 0.8717735 | H59: =FINV('Anova-prompt-response'!$C$50, 'Anova-prompt-response'!$D$59, 'Anova-prompt-response'!$D$60) -> 2.703594
B60: Within Groups | C60: =SUM(DEVSQ([5]inter_system_stats!$B$33:$B$57),DEVSQ([5]inter_system_stats!$C$33:$C$57),DEVSQ([5]inter_system_stats!$D$33:$D$57),DEVSQ([5]inter_system_stats!$E$33:$E$57)) -> 0.46837084 | D60: =SUM('Anova-prompt-response'!$C$53:$C$56)-COUNT('Anova-prompt-response'!$C$53:$C$56) -> 92 | E60: ='Anova-prompt-response'!$C$60 / 'Anova-prompt-response'!$D$60 -> 0.0050909874
B61: Total | C61: =DEVSQ([5]inter_system_stats!$B$33:$B$57,[5]inter_system_stats!$C$33:$C$57,[5]inter_system_stats!$D$33:$D$57,[5]inter_system_stats!$E$33:$E$57) -> 0.47195983 | D61: =SUM('Anova-prompt-response'!$C$53:$C$56) - 1 -> 95
A69: Scenario 4
B70: ANOVA - Single Factor
B71: Alpha | C71: 0.05
...

Sheet Compasrison of critical turns
A1: * For ABS(response-prompt)>=0.05
A4: Scenario 1
A6: Turn | B6: comparison | C6: delta | E6: Count - delta | F6: comparison | G6: Scenario 1
A7: 5 | B7: hybrid-hybsem | C7: 0.098620831 | E7: Turn | F7: ac15 hybrid | G7: ac15 hybsem | H7: ac15-ac15p | I7: hybrid-ac15p | J7: hybrid-hybsem | K7: hybsem ac15p | L7: Total Result
A8: 9 | B8: hybrid-hybsem | C8: 0.074349093 | E8: 2 | F8: 1 | L8: 1
A9: 6 | B9: hybrid-hybsem | C9: 0.068760577 | E9: 3 | F9: 1 | G9: 1 | L9: 2
A10: 17 | B10: hybrid-hybsem | C10: 0.052987223 | E10: 4 | G10: 1 | J10: 1 | K10: 1 | L10: 3
A11: 19 | B11: hybrid-hybsem | C11: 0.052745357 | E11: 5 | G11: 1 | J11: 1 | K11: 1 | L11: 3
A12: 4 | B12: hybrid-hybsem | C12: 0.052041506 | E12: 6 | I12: 1 | J12: 1 | L12: 2
A13: 15 | B13: hybrid-hybsem | C13: 0.051309121 | E13: 9 | G13: 1 | J13: 1 | L13: 2
A14: 22 | B14: ac15-ac15p | C14: 0.079287974 | E14: 14 | F14: 1 | I14: 1 | L14: 2
A15: 24 | B15: ac15-ac15p | C15: 0.055768384 | E15: 15 | F15: 1 | J15: 1 | L15: 2
A16: 19 | B16: hybrid-ac15p | C16: 0.079800639 | E16: 16 | K16: 1 | L16: 1
A17: 24 | B17: hybrid-ac15p | C17: 0.076851129 | E17: 17 | F17: 1 | I17: 1 | J17: 1 | L17: 3
A18: 22 | B18: hybrid-ac15p | C18: 0.067913393 | E18: 19 | F18: 1 | G18: 1 | I18: 1 | J18: 1 | K18: 1 | L18: 5
A19: 14 | B19: hybrid-ac15p | C19: 0.06589851 | E19: 20 | K19: 1 | L19: 1
A20: 6 | B20: hybrid-ac15p | C20: 0.065064386 | E20: 22 | H20: 1 | I20: 1 | K20: 1 | L20: 3
A21: 17 | B21: hybrid-ac15p | C21: 0.050035675 | E21: 24 | H21: 1 | I21: 1 | L21: 2
A22: 19 | B22: hybsem ac15p | C22: 0.132546 | E22: Total Result | F22: 6 | G22: 5 | H22: 2 | I22: 6 | J22: 7 | K22: 6 | L22: 32
A23: 16 | B23: hybsem ac15p | C23: 0.071984492
A24: 4 | B24: hybsem ac15p | C24: 0.066133487
A25: 20 | B25: hybsem ac15p | C25: 0.052261883
A26: 5 | B26: hybsem ac15p | C26: 0.051548359
A27: 22 | B27: hybsem ac15p | C27: 0.050206798
A28: 3 | B28: ac15 hybrid | C28: 0.085415588
A29: 19 | B29: ac15 hybrid | C29: 0.072330129
A30: 15 | B30: ac15 hybrid | C30: 0.071369072
A31: 14 | B31: ac15 hybrid | C31: 0.056547607
A32: 17 | B32: ac15 hybrid | C32: 0.053647376
A33: 2 | B33: ac15 hybrid | C33: 0.052184378
A34: 19 | B34: ac15 hybsem | C34: 0.12507549
... A38: 4 | B38: ac15 hybsem | C38: 0.05012077
A41: Scenario 2
A43: turns | B43: comparison | C43: abs delta | E43: Count - abs delta | F43: comparison | G43: Scenario 2
A44: 22 | B44: Hybesm-hybrid | C44: 0.10403392 | E44: turns | F44: ac15-ac15p | G44: Hybesm-hybrid | H44: Hybrid-ac15 | I44: Hybrid-ac15p | J44: Hybsem-ac15 | K44: Hybsem-ac15p | L44: Total Result
A45: 21 | B45: Hybrid-ac15 | C45: 0.091267052 | E45: 5 | F45: 1 | G45: 1 | J45: 1 | L45: 3
A46: 22 | B46: Hybrid-ac15p | C46: 0.084257278 | E46: 7 | G46: 1 | L46: 1
A47: 21 | B47: Hybesm-hybrid | C47: 0.08360635 | E47: 13 | I47: 1 | L47: 1
A48: 5 | B48: Hybsem-ac15 | C48: 0.080955631 | E48: 17 | H48: 1 | L48: 1
A49: 23 | B49: Hybesm-hybrid | C49: 0.077076384 | E49: 21 | G49: 1 | H49: 1 | I49: 1 | L49: 3
...

Sheet Anchors_raw_information
A2: Scenario 1:
B3: Scenario 1 | D3: Project | J3: Test of Independence (Chi-Square)
B4: Anchors | C4: Data | D4: ac15-plain | E4: hybrid_v3_5 | F4: hybrid_v3_5_semantic | G4: test_ac15 | H4: Total Result | J4: Alpha | K4: 0.05
B5: affective_interface | C5: Count - weights | D5: 11 | E5: 3 | F5: 10 | G5: 10 | H5: 34 | J5: df | K5: =(COLUMNS([11]anchors_raw_information!$G$261:$J$271) - 1) * (ROWS([11]anchors_raw_information!$G$261:$J$271) - 1) -> 30
C6: Average - weights | D6: 0.15725455 | E6: 0.16406667 | F6: 0.16736 | G6: 0.1613 | H6: 0.16201765 | J6: P-value | K6: =CHITEST([11]anchors_raw_information!$G$261:$J$271, MMULT(MMULT([11]anchors_raw_information!$G$261:$J$271,TRANSPOSE(IF(COLUMN([11]anchors_raw_information!$G$261:$J$271),TRUE()))),MMULT(TRANSPOSE(IF(ROW([11]anchors_raw_information!$G$261:$J$271),TRUE())),[11]anchors_raw_information!$G$261:$J$271)) / SUM([11]anchors_raw_information!$G$261:$J$271)) -> 0.010693264
B7: electricity | C7: Count - weights | D7: 10 | E7: 7 | F7: 8 | G7: 6 | H7: 31 | J7: Test Statistic | K7: =CHIINV(Anchors_raw_information!$K$6, Anchors_raw_information!$K$5) -> 50.615989
C8: Average - weights | D8: 0.16259 | E8: 0.16622857 | F8: 0.1677625 | G8: 0.16023333 | H8: 0.16429032 | J8: Critical Value | K8: =CHIINV(Anchors_raw_information!$K$4, Anchors_raw_information!$K$5) -> 43.772972
B9: freedom_and_limitations | C9: Count - weights | D9: 2 | E9: 5 | F9: 1 | H9: 8
C10: Average - weights | D10: 0.1569 | E10: 0.15472 | F10: 0.1453 | H10: 0.1540875 | J10: Test of Independence (Chi-Square) – freedom
B11: imagination_and_possibility | C11: Count - weights | E11: 19 | F11: 15 | G11: 6 | H11: 40 | J11: Alpha | K11: 0.05
C12: Average - weights | E12: 0.16626842 | F12: 0.16717333 | G12: 0.15548333 | H12: 0.16499 | J12: df | K12: =(COLUMNS([11]anchors_raw_information!$G$282:$J$290) - 1) * (ROWS([11]anchors_raw_information!$G$282:$J$290) - 1) -> 24
B13: mathematics_computer_science_engineering | C13: Count - weights | D13: 23 | E13: 24 | F13: 20 | G13: 25 | H13: 92 | J13: P-value | K13: =CHITEST([11]anchors_raw_information!$G$282:$J$290, MMULT(MMULT([11]anchors_raw_information!$G$282:$J$290,TRANSPOSE(IF(COLUMN([11]anchors_raw_information!$G$282:$J$290),TRUE()))),MMULT(TRANSPOSE(IF(ROW([11]anchors_raw_information!$G$282:$J$290),TRUE())),[11]anchors_raw_information!$G$282:$J$290)) / SUM([11]anchors_raw_information!$G$282:$J$290)) -> 0.037399629
C14: Average - weights | D14: 0.17606087 | E14: 0.17728333 | F14: 0.17726 | G14: 0.180072 | H14: 0.17773043 | J14: Test Statistic | K14: =CHIINV(Anchors_raw_information!$K$13, Anchors_raw_information!$K$12) -> 37.677586
B15: metaphorical_scaffolding | C15: Count - weights | D15: 3 | F15: 4 | G15: 3 | H15: 10 | J15: Critical Value | K15: =CHIINV(Anchors_raw_information!$K$11, Anchors_raw_information!$K$12) -> 36.415029
C16: Average - weights | D16: 0.15276667 | F16: 0.16345 | G16: 0.15366667 | H16: 0.15731
B17: practicality_and_feasibility | C17: Count - weights | D17: 25 | E17: 25 | F17: 25 | G17: 25 | H17: 100
C18: Average - weights | D18: 0.196308 | E18: 0.214124 | F18: 0.218356 | G18: 0.204948 | H18: 0.208434 | J18: Chi square test – science-truth – freedom
B19: science | C19: Count - weights | D19: 1 | G19: 3 | H19: 4 | J19: Alpha | K19: 0.05
C20: Average - weights | D20: 0.1509 | G20: 0.15926667 | H20: 0.157175 | J20: df | K20: =(COLUMNS([11]anchors_raw_information!$G$301:$J$308) - 1) * (ROWS([11]anchors_raw_information!$G$301:$J$308) - 1) -> 21
B21: sovereignty | C21: Count - weights | D21: 25 | E21: 15 | F21: 13 | G21: 22 | H21: 75 | J21: P-value | K21: =CHITEST([11]anchors_raw_information!$G$301:$J$308, MMULT(MMULT([11]anchors_raw_information!$G$301:$J$308,TRANSPOSE(IF(COLUMN([11]anchors_raw_information!$G$301:$J$308),TRUE()))),MMULT(TRANSPOSE(IF(ROW([11]anchors_raw_information!$G$301:$J$308),TRUE())),[11]anchors_raw_information!$G$301:$J$308)) / SUM([11]anchors_raw_information!$G$301:$J$308)) -> 0.014017188
C22: Average - weights | D22: 0.173296 | E22: 0.16872 | F22: 0.18175385 | G22: 0.16459545 | H22: 0.17129467 | J22: Test Statistic | K22: =CHIINV(Anchors_raw_information!$K$21, Anchors_raw_information!$K$20) -> 37.687871
B23: temporal_dynamics | C23: Count - weights | D23: 25 | E23: 23 | F23: 25 | G23: 25 | H23: 98 | J23: Critical Value | K23: =CHIINV(Anchors_raw_information!$K$19, Anchors_raw_information!$K$20) -> 32.670573
C24: Average - weights | D24: 0.18282 | E24: 0.2056 | F24: 0.192444 | G24: 0.188348 | H24: 0.19203163
B25: truth_and_fact | C25: Count - weights | D25: 25 | E25: 25 | F25: 25 | G25: 25 | H25: 100
C26: Average - weights | D26: 0.114436 | E26: 0.10174 | F26: 0.1 | G26: 0.103932 | H26: 0.105027
B27: Total Count - weights | D27: 150 | E27: 146 | F27: 146 | G27: 150 | H27: 592
B28: Total Average - weights | D28: 0.166664 | E28: 0.17122945 | F28: 0.17123562 | G28: 0.16666467 | H28: 0.16891757
A33: Scenario 2:
B34: Scenario 2 | D34: projectName | J34: Test of Independence (Chi-Square)
B35: anchorName | C35: Data | D35: ac15-plain | E35: hybrid_v3_5 | F35: hysem | G35: test_ac15 | H35: Total Result | J35: Alpha | K35: 0.05
B36: affective_interface | C36: Count - weight | D36: 20 | E36: 18 | F36: 24 | G36: 17 | H36: 79 | J36: df | K36: =(COLUMNS([12]anchors_raw_information!$H$81:$K$91) - 1) * (ROWS([12]anchors_raw_information!$H$81:$K$91) - 1) -> 30
C37: Average - weight* | D37: 0.175175 | E37: 0.18772222 | F37: 0.2031875 | G37: 0.17807059 | H37: 0.18716709 | J37: P-value | K37: =CHITEST([12]anchors_raw_information!$H$81:$K$91, MMULT(MMULT([12]anchors_raw_information!$H$81:$K$91,TRANSPOSE(IF(COLUMN([12]anchors_raw_information!$H$81:$K$91),TRUE()))),MMULT(TRANSPOSE(IF(ROW([12]anchors_raw_information!$H$81:$K$91),TRUE())),[12]anchors_raw_information!$H$81:$K$91)) / SUM([12]anchors_raw_information!$H$81:$K$91)) -> 0.015316595
B38: context_dependent_expression | C38: Count - weight | D38: 1 | E38: 1 | G38: 2 | H38: 4 | J38: Test Statistic | K38: =CHIINV(Anchors_raw_information!$K$37, Anchors_raw_information!$K$36) -> 49.110096
C39: Average - weight* | D39: 0.1711 | E39: 0.2002 | G39: 0.16385 | H39: 0.17475 | J39: Critical Value | K39: =CHIINV(Anchors_raw_information!$K$35, Anchors_raw_information!$K$36) -> 43.772972
B40: freedom_and_limitations | C40: Count - weight | E40: 1 | F40: 2 | H40: 3
C41: Average - weight* | E41: 0.1772 | F41: 0.15575 | H41: 0.1629 | J41: Chi Square - context – freedom – truth
B42: imagination_and_possibility | C42: Count - weight | D42: 6 | E42: 18 | F42: 19 | G42: 10 | H42: 53 | J42: Alpha | K42: 0.05
C43: Average - weight* | D43: 0.15935 | E43: 0.17331667 | F43: 0.16609474 | G43: 0.16556 | H43: 0.16768302 | J43: df | K43: =(COLUMNS([12]anchors_raw_information!$H$105:$L$112) - 1) * (ROWS([12]anchors_raw_information!$H$105:$L$112) - 1) -> 28
B44: mathematics_computer_science_engineering | C44: Count - weight | D44: 21 | E44: 16 | F44: 16 | G44: 24 | H44: 77 | J44: P-value | K44: =CHITEST([12]anchors_raw_information!$H$105:$L$112, MMULT(MMULT([12]anchors_raw_information!$H$105:$L$112,TRANSPOSE(IF(COLUMN([12]anchors_raw_information!$H$105:$L$112),TRUE()))),MMULT(TRANSPOSE(IF(ROW([12]anchors_raw_information!$H$105:$L$112),TRUE())),[12]anchors_raw_information!$H$105:$L$112)) / SUM([12]anchors_raw_information!$H$105:$L$112)) -> 0.033796699
C45: Average - weight* | D45: 0.17064762 | E45: 0.16456875 | F45: 0.1561375 | G45: 0.197875 | H45: 0.17485584 | J45: Test Statistic | K45: =CHIINV(Anchors_raw_information!$K$44, Anchors_raw_information!$K$43) -> 43.13192
...

Sheet delta (t)= sim(t)-sim(t-1)
A2: std(delta(t)=sim(t)-sim(t-1))
G4: stdev
B5: Hybsem | C5: Hybrid | D5: ac15p | E5: ac15 | G5: Hybsem | H5: Hybrid | I5: ac15p | J5: ac15
A6: Scenario 1 | B6: 0.092058482 | C6: 0.079958501 | D6: 0.10509626 | E6: 0.091544494 | G6: =STDEV(B6:B13) -> 0.015055547 | H6: =STDEV(C6:C13) -> 0.014644247 | I6: =STDEV(D6:D13) -> 0.017698054 | J6: =STDEV(E6:E13) -> 0.014203348
A7: Scenario 2 | B7: 0.06450649 | C7: 0.071806546 | D7: 0.06849765 | E7: 0.069153109
A8: Scenario 3 | B8: 0.088767686 | C8: 0.10158971 | D8: 0.092156815 | E8: 0.080940275
A9: Scenario 4 | B9: 0.094351 | C9: 0.099953 | D9: 0.101737 | E9: 0.094708
A10: Scenario 5 | B10: 0.054679968 | C10: 0.056023237 | D10: 0.055048154 | E10: 0.062810582
A11: Scenario 6 | B11: 0.088965255 | C11: 0.082535014 | D11: 0.092675031 | E11: 0.079505643
A12: Scenario 7 | B12: 0.085757231 | C12: 0.083647598 | D12: 0.079537002 | E12: 0.097548204
A13: Scenario 8 | B13: 0.067132644 | C13: 0.078908934 | D13: 0.069877231 | E13: 0.061534308
