Workbook

Sheet scen7_hybsem
A1: turnId | B1: user_id | C1: assistant_id | D1: projectName | E1: sessionName | F1: seq | G1: anchorName | H1: weight | I1: promptSim | J1: responseSim | K1: activation delta | L1: prompt_to_response | P1: count | Q1: activation delta average | R1: correlation weights / activation delta | S1: p
P2: =COUNT(K3:K143) -> 141 | Q2: =AVERAGE(K3:K143) -> 0.033631002 | R2: =CORREL(H3:H143,K3:K143) -> 0.14885737 | S2: 0.078
A3: 6d440638-5838-44a7-a15b-ff7336dab415 | B3: cmjjw7ztj019ezceepd87zo3e | C3: cmjjw946g019vzceem0b3p17w | D3: hybrid_v3_5_semantic | E3: Scenario_7 | F3: 0 | G3: imagination_and_possibility | H3: 0.3145 | I3: 0.22006742 | J3: 0.29048783 | K3: =J3-I3 -> 0.070420412 | L3: 0.72409953
A4: 6d440638-5838-44a7-a15b-ff7336dab415 | B4: cmjjw7ztj019ezceepd87zo3e | C4: cmjjw946g019vzceem0b3p17w | D4: hybrid_v3_5_semantic | E4: Scenario_7 | F4: 0 | G4: temporal_dynamics | H4: 0.298 | I4: 0.20850097 | J4: 0.27579563 | K4: =J4-I4 -> 0.067294669 | L4: 0.72409953
A5: 6d440638-5838-44a7-a15b-ff7336dab415 | B5: cmjjw7ztj019ezceepd87zo3e | C5: cmjjw946g019vzceem0b3p17w | D5: hybrid_v3_5_semantic | E5: Scenario_7 | F5: 0 | G5: affective_interface | H5: 0.2876 | I5: 0.20123296 | J5: 0.31881151 | K5: =J5-I5 -> 0.11757855 | L5: 0.72409953
A6: 6d440638-5838-44a7-a15b-ff7336dab415 | B6: cmjjw7ztj019ezceepd87zo3e | C6: cmjjw946g019vzceem0b3p17w | D6: hybrid_v3_5_semantic | E6: Scenario_7 | F6: 0 | G6: truth_and_fact | H6: 0.1 | I6: 0.14597014 | J6: 0.23127769 | K6: =J6-I6 -> 0.085307552 | L6: 0.72409953
A7: 204abaec-f79e-4bbb-bfdd-b30d74b81de8 | B7: cmjjw9ghj019zzceertc0ziao | C7: cmjjwa02h01agzceeu4m9wsle | D7: hybrid_v3_5_semantic | E7: Scenario_7 | F7: 2 | G7: imagination_and_possibility | H7: 0.1879 | I7: 0.22988725 | J7: 0.31169478 | K7: =J7-I7 -> 0.081807528 | L7: 0.69040579
A8: 204abaec-f79e-4bbb-bfdd-b30d74b81de8 | B8: cmjjw9ghj019zzceertc0ziao | C8: cmjjwa02h01agzceeu4m9wsle | D8: hybrid_v3_5_semantic | E8: Scenario_7 | F8: 2 | G8: practicality_and_feasibility | H8: 0.1866 | I8: 0.22821858 | J8: 0.29402017 | K8: =J8-I8 -> 0.065801587 | L8: 0.69040579
A9: 204abaec-f79e-4bbb-bfdd-b30d74b81de8 | B9: cmjjw9ghj019zzceertc0ziao | C9: cmjjwa02h01agzceeu4m9wsle | D9: hybrid_v3_5_semantic | E9: Scenario_7 | F9: 2 | G9: affective_interface | H9: 0.1796 | I9: 0.21968733 | J9: 0.36062377 | K9: =J9-I9 -> 0.14093644 | L9: 0.69040579
A10: 204abaec-f79e-4bbb-bfdd-b30d74b81de8 | B10: cmjjw9ghj019zzceertc0ziao | C10: cmjjwa02h01agzceeu4m9wsle | D10: hybrid_v3_5_semantic | E10: Scenario_7 | F10: 2 | G10: temporal_dynamics | H10: 0.1746 | I10: 0.21361579 | J10: 0.2727824 | K10: =J10-I10 -> 0.059166603 | L10: 0.69040579
A11: 204abaec-f79e-4bbb-bfdd-b30d74b81de8 | B11: cmjjw9ghj019zzceertc0ziao | C11: cmjjwa02h01agzceeu4m9wsle | D11: hybrid_v3_5_semantic | E11: Scenario_7 | F11: 2 | G11: context_dependent_expression | H11: 0.1712 | I11: 0.20942433 | J11: 0.27553718 | K11: =J11-I11 -> 0.066112851 | L11: 0.69040579
A12: 204abaec-f79e-4bbb-bfdd-b30d74b81de8 | B12: cmjjw9ghj019zzceertc0ziao | C12: cmjjwa02h01agzceeu4m9wsle | D12: hybrid_v3_5_semantic | E12: Scenario_7 | F12: 2 | G12: truth_and_fact | H12: 0.1 | I12: 0.17857288 | J12: 0.25470432 | K12: =J12-I12 -> 0.076131449 | L12: 0.69040579
A13: 60087b4a-96f5-47e4-9873-a2fbf02673f2 | B13: cmjjwaayw01akzceeob9l0x1u | C13: cmjjwathf01b1zceeqbkjmmta | D13: hybrid_v3_5_semantic | E13: Scenario_7 | F13: 4 | G13: identity | H13: 0.1957 | I13: 0.24846454 | J13: 0.23039573 | K13: =J13-I13 -> -0.018068818 | L13: 0.66442409
A14: 60087b4a-96f5-47e4-9873-a2fbf02673f2 | B14: cmjjwaayw01akzceeob9l0x1u | C14: cmjjwathf01b1zceeqbkjmmta | D14: hybrid_v3_5_semantic | E14: Scenario_7 | F14: 4 | G14: affective_interface | H14: 0.1933 | I14: 0.24540064 | J14: 0.30995023 | K14: =J14-I14 -> 0.064549593 | L14: 0.66442409
... A143: 3d63dee1-3f8c-43ed-95fc-443c46ed0733 | B143: cmjjwviwg01nezceep7s4bt7x | C143: cmjjww34501nvzceewtxy7zxg | D143: hybrid_v3_5_semantic | E143: Scenario_7 | F143: 48 | G143: truth_and_fact | H143: 0.1 | I143: 0.23936121 | J143: 0.2338736 | K143: =J143-I143 -> -0.0054876104 | L143: 0.76225457

Sheet Notes
A1: p calculation
A3: 1. count | B3: =scen7_hybsem!P2 -> 141
A4: 2. t statistic | B4: =B10*SQRT((B3-2)/(1-B10^2)) -> 1.7747758
A5: 3. p | B5: =_xlfn.T.DIST.2T(ABS(B4),B3-2) -> 0.078123775
A9: count | B9: correlation weights / activation delta
A10: =B3 -> 141 | B10: =scen7_hybsem!R2 -> 0.14885737

Sheet actdel_prompt_response
A1: Prompt-response
A2: Turn | B2: Hybsem
A3: 1 | B3: 0.72409953
A4: 2 | B4: 0.69040579
A5: 3 | B5: 0.66442409
A6: 4 | B6: 0.73787209
A7: 5 | B7: 0.73166495
A8: 6 | B8: 0.72767432
A9: 7 | B9: 0.78515917
A10: 8 | B10: 0.69936593
A11: 9 | B11: 0.74686473
A12: 10 | B12: 0.68571667
A13: 11 | B13: 0.76511491
A14: 12 | B14: 0.73664424
... A27: 25 | B27: 0.76225457

Sheet inter_system_stats
A1: Prompt-response
A2: Turn | B2: Hybsem | C2: control | E2: std. Hybsem | F2: std. Control | G2: F. test | H2: T. Test equal variances | I2: T.Test unequal | J2: Mean difference | K2: Mean Hybsem | L2: Mean control
A3: 1 | B3: 0.72409953 | C3: 0.78035784 | E3: =_xlfn.STDEV.S(B3:B27) -> 0.049899473 | F3: =_xlfn.STDEV.S(C3:C27) -> 0.10899113 | G3: =_xlfn.F.TEST(B3:B27,C3:C27) -> 0.00029515491 | H3: =_xlfn.T.TEST(B3:B27, C3:C27, 2,2) -> 7.1638658e-08 | I3: =_xlfn.T.TEST(B3:B27,C3:C27, 2,3) -> 3.1286987e-07 | J3: =AVERAGE(B3:B27)-AVERAGE(C3:C27) -> 0.15236801 | K3: =AVERAGE(B3:B27) -> 0.72061831 | L3: =AVERAGE(C3:C27) -> 0.56825031
A4: 2 | B4: 0.69040579 | C4: 0.41620709
A5: 3 | B5: 0.66442409 | C5: 0.44069473
A6: 4 | B6: 0.73787209 | C6: 0.50298343
A7: 5 | B7: 0.73166495 | C7: 0.64837824
A8: 6 | B8: 0.72767432 | C8: 0.55690541
A9: 7 | B9: 0.78515917 | C9: 0.67658778
A10: 8 | B10: 0.69936593 | C10: 0.53755699
A11: 9 | B11: 0.74686473 | C11: 0.54745066
A12: 10 | B12: 0.68571667 | C12: 0.40447571
A13: 11 | B13: 0.76511491 | C13: 0.57351245
A14: 12 | B14: 0.73664424 | C14: 0.68842639
A15: 13 | B15: 0.67866651 | C15: 0.53673254
... A27: 25 | B27: 0.76225457 | C27: 0.4547081
A29: General
A31: Turn | B31: ac15p | C31: Hybrid | D31: Hybsem | F31: ANOVA - Single Factor
A32: 1 | B32: 0.72660445 | C32: 0.74561822 | D32: 0.72409953 | F32: Alpha | G32: 0.05
A33: 2 | B33: 0.70895983 | C33: 0.73196562 | D33: 0.69040579
A34: 3 | B34: 0.65625079 | C34: 0.55634941 | D34: 0.66442409 | F34: Groups | G34: Count | H34: Sum | I34: Mean | J34: Variance
A35: 4 | B35: 0.68248006 | C35: 0.74696128 | D35: 0.73787209 | F35: Column 1 | G35: =COUNT(inter_system_stats!$B$31:$B$56) -> 25 | H35: =SUM(inter_system_stats!$B$31:$B$56) -> 17.785397 | I35: =AVERAGE(inter_system_stats!$B$31:$B$56) -> 0.71141589 | J35: =VAR(inter_system_stats!$B$31:$B$56) -> 0.0022639834
A36: 5 | B36: 0.75066609 | C36: 0.73630313 | D36: 0.73166495 | F36: Column 2 | G36: =COUNT(inter_system_stats!$C$31:$C$56) -> 25 | H36: =SUM(inter_system_stats!$C$31:$C$56) -> 18.057281 | I36: =AVERAGE(inter_system_stats!$C$31:$C$56) -> 0.72229125 | J36: =VAR(inter_system_stats!$C$31:$C$56) -> 0.0025385628
A37: 6 | B37: 0.69003761 | C37: 0.69306052 | D37: 0.72767432 | F37: Column 3 | G37: =COUNT(inter_system_stats!$D$31:$D$56) -> 25 | H37: =SUM(inter_system_stats!$D$31:$D$56) -> 18.015458 | I37: =AVERAGE(inter_system_stats!$D$31:$D$56) -> 0.72061831 | J37: =VAR(inter_system_stats!$D$31:$D$56) -> 0.0024899574
A38: 7 | B38: 0.70889799 | C38: 0.74859756 | D38: 0.78515917
A39: 8 | B39: 0.68554662 | C39: 0.70516594 | D39: 0.69936593 | F39: Source of Variation | G39: SS | H39: df | I39: MS | J39: F | K39: P-value | L39: F critical
A40: 9 | B40: 0.72762952 | C40: 0.75036872 | D40: 0.74686473 | F40: Between Groups | G40: =SUMPRODUCT(inter_system_stats!$H$35:$H$37,inter_system_stats!$I$35:$I$37)-SUM(inter_system_stats!$H$35:$H$37)^2/SUM(inter_system_stats!$G$35:$G$37) -> 0.0017146397 | H40: =COUNT(inter_system_stats!$H$35:$H$37)-1 -> 2 | I40: =inter_system_stats!$G$40 / inter_system_stats!$H$40 -> 0.00085731987 | J40: =inter_system_stats!$I$40 / inter_system_stats!$I$41 -> 0.35268541 | K40: =FDIST(inter_system_stats!$J$40, inter_system_stats!$H$40, inter_system_stats!$H$41) -> 0.70400557 | L40: =FINV(inter_system_stats!$G$32, inter_system_stats!$H$40, inter_system_stats!$H$41) -> 3.1239074
A41: 10 | B41: 0.63748551 | C41: 0.682433 | D41: 0.68571667 | F41: Within Groups | G41: =SUM(DEVSQ(inter_system_stats!$B$31:$B$56),DEVSQ(inter_system_stats!$C$31:$C$56),DEVSQ(inter_system_stats!$D$31:$D$56)) -> 0.17502009 | H41: =SUM(inter_system_stats!$G$35:$G$37)-COUNT(inter_system_stats!$G$35:$G$37) -> 72 | I41: =inter_system_stats!$G$41 / inter_system_stats!$H$41 -> 0.0024308345
A42: 11 | B42: 0.71798946 | C42: 0.72387381 | D42: 0.76511491 | F42: Total | G42: =DEVSQ(inter_system_stats!$B$31:$B$56,inter_system_stats!$C$31:$C$56,inter_system_stats!$D$31:$D$56) -> 0.17673473 | H42: =SUM(inter_system_stats!$G$35:$G$37) - 1 -> 74
A43: 12 | B43: 0.77090629 | C43: 0.66770176 | D43: 0.73664424
A44: 13 | B44: 0.7098279 | C44: 0.72995268 | D44: 0.67866651
A45: 14 | B45: 0.824776 | C45: 0.79516956 | D45: 0.80014865
A46: 15 | B46: 0.6113315 | C46: 0.64136105 | D46: 0.61365644
A47: 16 | B47: 0.74347337 | C47: 0.75855012 | D47: 0.70191453
A48: 17 | B48: 0.6577691 | C48: 0.69417603 | D48: 0.69604098
A49: 18 | B49: 0.73366789 | C49: 0.75354741 | D49: 0.76411137
A50: 19 | B50: 0.66476983 | C50: 0.71847314 | D50: 0.61294959
A51: 20 | B51: 0.73551176 | C51: 0.75453899 | D51: 0.76123446
A52: 21 | B52: 0.71546661 | C52: 0.71601755 | D52: 0.70854575
A53: 22 | B53: 0.7090201 | C53: 0.75187651 | D53: 0.75606945
...
