Workbook

Sheet scen6_hybsem
A1: turnId | B1: user_id | C1: assistant_id | D1: projectName | E1: sessionName | F1: seq | G1: anchorName | H1: weight | I1: promptSim | J1: responseSim | K1: activation delta | L1: prompt_to_response | P1: count | Q1: Activation delta average | R1: correlation weights / activation delta | S1: p
P2: =COUNT(F3:F117) -> 115 | Q2: =AVERAGE(K3:K117) -> 0.043140099 | R2: =CORREL(H3:H117,K3:K117) -> -0.013730456 | S2: 0.88
A3: 9408e536-8de1-496b-95d0-3ddfb84fec4a | B3: cmjh7ushb00eqzcx2pnk1sf7g | C3: cmjh7vx5r00f7zcx2f5va5erf | D3: hybrid_v3_5_semantic | E3: Scenario_6 | F3: 0 | G3: truth_and_fact | H3: 0.1 | I3: 0.13491773 | J3: 0.22076022 | K3: =J3-I3 -> 0.085842485 | L3: 0.78516876
A4: b74c727f-c0ca-4522-930f-656f1d669a30 | B4: cmjh7wt1g00fbzcx2ngcarogp | C4: cmjh7xbpq00fszcx2lf5t0qpi | D4: hybrid_v3_5_semantic | E4: Scenario_6 | F4: 2 | G4: practicality_and_feasibility | H4: 0.3369 | I4: 0.24282597 | J4: 0.34618307 | K4: =J4-I4 -> 0.1033571 | L4: 0.70344439
A5: b74c727f-c0ca-4522-930f-656f1d669a30 | B5: cmjh7wt1g00fbzcx2ngcarogp | C5: cmjh7xbpq00fszcx2lf5t0qpi | D5: hybrid_v3_5_semantic | E5: Scenario_6 | F5: 2 | G5: affective_interface | H5: 0.2849 | I5: 0.20536473 | J5: 0.34942664 | K5: =J5-I5 -> 0.14406191 | L5: 0.70344439
A6: b74c727f-c0ca-4522-930f-656f1d669a30 | B6: cmjh7wt1g00fbzcx2ngcarogp | C6: cmjh7xbpq00fszcx2lf5t0qpi | D6: hybrid_v3_5_semantic | E6: Scenario_6 | F6: 2 | G6: temporal_dynamics | H6: 0.2782 | I6: 0.20051983 | J6: 0.2220046 | K6: =J6-I6 -> 0.021484774 | L6: 0.70344439
A7: b74c727f-c0ca-4522-930f-656f1d669a30 | B7: cmjh7wt1g00fbzcx2ngcarogp | C7: cmjh7xbpq00fszcx2lf5t0qpi | D7: hybrid_v3_5_semantic | E7: Scenario_6 | F7: 2 | G7: truth_and_fact | H7: 0.1 | I7: 0.15782558 | J7: 0.23137116 | K7: =J7-I7 -> 0.073545573 | L7: 0.70344439
A8: c566cb99-b456-411a-99b0-8dbb99d04df8 | B8: cmjh7zqne00fwzcx2ve2nxgih | C8: cmjh80iqu00gdzcx2njkkat4w | D8: hybrid_v3_5_semantic | E8: Scenario_6 | F8: 4 | G8: practicality_and_feasibility | H8: 0.2505 | I8: 0.24287653 | J8: 0.23262807 | K8: =J8-I8 -> -0.010248455 | L8: 0.73539986
A9: c566cb99-b456-411a-99b0-8dbb99d04df8 | B9: cmjh7zqne00fwzcx2ve2nxgih | C9: cmjh80iqu00gdzcx2njkkat4w | D9: hybrid_v3_5_semantic | E9: Scenario_6 | F9: 4 | G9: affective_interface | H9: 0.2208 | I9: 0.21401622 | J9: 0.19554088 | K9: =J9-I9 -> -0.018475341 | L9: 0.73539986
A10: c566cb99-b456-411a-99b0-8dbb99d04df8 | B10: cmjh7zqne00fwzcx2ve2nxgih | C10: cmjh80iqu00gdzcx2njkkat4w | D10: hybrid_v3_5_semantic | E10: Scenario_6 | F10: 4 | G10: sovereignty | H10: 0.2168 | I10: 0.21021038 | J10: 0.20733822 | K10: =J10-I10 -> -0.0028721567 | L10: 0.73539986
A11: c566cb99-b456-411a-99b0-8dbb99d04df8 | B11: cmjh7zqne00fwzcx2ve2nxgih | C11: cmjh80iqu00gdzcx2njkkat4w | D11: hybrid_v3_5_semantic | E11: Scenario_6 | F11: 4 | G11: context_dependent_expression | H11: 0.2119 | I11: 0.20539297 | J11: 0.18366152 | K11: =J11-I11 -> -0.021731448 | L11: 0.73539986
A12: c566cb99-b456-411a-99b0-8dbb99d04df8 | B12: cmjh7zqne00fwzcx2ve2nxgih | C12: cmjh80iqu00gdzcx2njkkat4w | D12: hybrid_v3_5_semantic | E12: Scenario_6 | F12: 4 | G12: truth_and_fact | H12: 0.1 | I12: 0.1803739 | J12: 0.18329278 | K12: =J12-I12 -> 0.0029188748 | L12: 0.73539986
A13: 02829bdf-eb6a-4143-bcb9-2ab38f44f559 | B13: cmjh810r700ghzcx23ca73hny | C13: cmjh81klu00gyzcx2w2lmbhgm | D13: hybrid_v3_5_semantic | E13: Scenario_6 | F13: 6 | G13: truth_and_fact | H13: 0.1 | I13: 0.13623931 | J13: 0.22363976 | K13: =J13-I13 -> 0.087400446 | L13: 0.69729745
A14: f6dcef14-6472-4af8-ae10-251ff2d97bb6 | B14: cmjh82eji00h2zcx2ado4q1qo | C14: cmjh83lin00hjzcx2vio8aq6i | D14: hybrid_v3_5_semantic | E14: Scenario_6 | F14: 8 | G14: practicality_and_feasibility | H14: 0.2105 | I14: 0.29546287 | J14: 0.32499677 | K14: =J14-I14 -> 0.029533905 | L14: 0.71322313
... A117: edc86d51-f990-431a-9dbb-0b33174c23d3 | B117: cmjh9r8fc00sqzcx2jltnr7u8 | C117: cmjh9rp1000t7zcx235vjpklz | D117: hybrid_v3_5_semantic | E117: Scenario_6 | F117: 48 | G117: truth_and_fact | H117: 0.1 | I117: 0.18098435 | J117: 0.28637343 | K117: =J117-I117 -> 0.10538908 | L117: 0.69720151

Sheet Notes
A1: p calculation
A3: 1. count | B3: =scen6_hybsem!P2 -> 115
A4: 2. t statistic | B4: =B10*SQRT((B3-2)/(1-B10^2)) -> -0.14597051
A5: 3. p | B5: =_xlfn.T.DIST.2T(ABS(B4),B3-2) -> 0.88420475
A9: count | B9: correlation weights / activation delta
A10: =B3 -> 115 | B10: =scen6_hybsem!R2 -> -0.013730456

Sheet actdel_prompt_response
A2: Prompt-response
A3: Turn | B3: hybsem
A4: 1 | B4: 0.78516876
A5: 2 | B5: 0.70344439
A6: 3 | B6: 0.73539986
A7: 4 | B7: 0.69729745
A8: 5 | B8: 0.71322313
A9: 6 | B9: 0.76734743
A10: 7 | B10: 0.74121447
A11: 8 | B11: 0.7026918
A12: 9 | B12: 0.67641093
A13: 10 | B13: 0.71515554
A14: 11 | B14: 0.72491699
A15: 12 | B15: 0.84477335
... A28: 25 | B28: 0.69720151

Sheet inter_system_stats
A2: Prompt-response
A3: Turn | B3: hybsem | C3: control | E3: std. Hybsem | F3: std. Control | G3: F. test | H3: T. Test equal variances | I3: T.Test unequal | J3: Mean difference | K3: Mean scen | L3: Mean control
A4: 1 | B4: 0.78516876 | C4: 0.8205306 | E4: =_xlfn.STDEV.S(B4:B28) -> 0.05703931 | F4: =_xlfn.STDEV.S(C4:C28) -> 0.1102969 | G4: =_xlfn.F.TEST(B4:B28,C4:C28) -> 0.0019849337 | H4: =_xlfn.T.TEST(B4:B28, C4:C28, 2,2) -> 9.3374879e-08 | I4: =_xlfn.T.TEST(B4:B28,C4:C28, 2,3) -> 2.9439777e-07 | J4: =AVERAGE(B4:B28)-AVERAGE(C4:C28) -> 0.15597142 | K4: =AVERAGE(B4:B28) -> 0.72031836 | L4: =AVERAGE(C4:C28) -> 0.56434695
A5: 2 | B5: 0.70344439 | C5: 0.4077777
A6: 3 | B6: 0.73539986 | C6: 0.64741534
A7: 4 | B7: 0.69729745 | C7: 0.4921473
A8: 5 | B8: 0.71322313 | C8: 0.53686287
A9: 6 | B9: 0.76734743 | C9: 0.63772449
A10: 7 | B10: 0.74121447 | C10: 0.61665661
A11: 8 | B11: 0.7026918 | C11: 0.62659257
A12: 9 | B12: 0.67641093 | C12: 0.64803425
A13: 10 | B13: 0.71515554 | C13: 0.50632365
A14: 11 | B14: 0.72491699 | C14: 0.58561227
A15: 12 | B15: 0.84477335 | C15: 0.52267553
A16: 13 | B16: 0.67077129 | C16: 0.59336895
... A28: 25 | B28: 0.69720151 | C28: 0.46942826
A32: General
A34: Turn | B34: ac15p | C34: hybrid | D34: hybsem | F34: ANOVA - Single Factor
A35: 1 | B35: 0.79000575 | C35: 0.8189473 | D35: 0.78516876 | F35: Alpha | G35: 0.05
A36: 2 | B36: 0.6817351 | C36: 0.72667505 | D36: 0.70344439
A37: 3 | B37: 0.73659154 | C37: 0.75382376 | D37: 0.73539986 | F37: Groups | G37: Count | H37: Sum | I37: Mean | J37: Variance
A38: 4 | B38: 0.65821229 | C38: 0.69468916 | D38: 0.69729745 | F38: Column 1 | G38: =COUNT(inter_system_stats!$B$34:$B$59) -> 25 | H38: =SUM(inter_system_stats!$B$34:$B$59) -> 18.201412 | I38: =AVERAGE(inter_system_stats!$B$34:$B$59) -> 0.72805647 | J38: =VAR(inter_system_stats!$B$34:$B$59) -> 0.0037347451
A39: 5 | B39: 0.74318489 | C39: 0.75031898 | D39: 0.71322313 | F39: Column 2 | G39: =COUNT(inter_system_stats!$C$34:$C$59) -> 25 | H39: =SUM(inter_system_stats!$C$34:$C$59) -> 18.400771 | I39: =AVERAGE(inter_system_stats!$C$34:$C$59) -> 0.73603082 | J39: =VAR(inter_system_stats!$C$34:$C$59) -> 0.0029897442
A40: 6 | B40: 0.7383633 | C40: 0.79289751 | D40: 0.76734743 | F40: Column 3 | G40: =COUNT(inter_system_stats!$D$34:$D$59) -> 25 | H40: =SUM(inter_system_stats!$D$34:$D$59) -> 18.007959 | I40: =AVERAGE(inter_system_stats!$D$34:$D$59) -> 0.72031836 | J40: =VAR(inter_system_stats!$D$34:$D$59) -> 0.0032534829
A41: 7 | B41: 0.80270938 | C41: 0.74071706 | D41: 0.74121447
A42: 8 | B42: 0.76713782 | C42: 0.70151887 | D42: 0.7026918 | F42: Source of Variation | G42: SS | H42: df | I42: MS | J42: F | K42: P-value | L42: F critical
A43: 9 | B43: 0.65520384 | C43: 0.67940884 | D43: 0.67641093 | F43: Between Groups | G43: =SUMPRODUCT(inter_system_stats!$H$38:$H$40,inter_system_stats!$I$38:$I$40)-SUM(inter_system_stats!$H$38:$H$40)^2/SUM(inter_system_stats!$G$38:$G$40) -> 0.0030862501 | H43: =COUNT(inter_system_stats!$H$38:$H$40)-1 -> 2 | I43: =inter_system_stats!$G$43 / inter_system_stats!$H$43 -> 0.001543125 | J43: =inter_system_stats!$I$43 / inter_system_stats!$I$44 -> 0.46395952 | K43: =FDIST(inter_system_stats!$J$43, inter_system_stats!$H$43, inter_system_stats!$H$44) -> 0.63065567 | L43: =FINV(inter_system_stats!$G$35, inter_system_stats!$H$43, inter_system_stats!$H$44) -> 3.1239074
A44: 10 | B44: 0.70090518 | C44: 0.69382834 | D44: 0.71515554 | F44: Within Groups | G44: =SUM(DEVSQ(inter_system_stats!$B$34:$B$59),DEVSQ(inter_system_stats!$C$34:$C$59),DEVSQ(inter_system_stats!$D$34:$D$59)) -> 0.23947133 | H44: =SUM(inter_system_stats!$G$38:$G$40)-COUNT(inter_system_stats!$G$38:$G$40) -> 72 | I44: =inter_system_stats!$G$44 / inter_system_stats!$H$44 -> 0.0033259907
A45: 11 | B45: 0.71962924 | C45: 0.71401509 | D45: 0.72491699 | F45: Total | G45: =DEVSQ(inter_system_stats!$B$34:$B$59,inter_system_stats!$C$34:$C$59,inter_system_stats!$D$34:$D$59) -> 0.24255758 | H45: =SUM(inter_system_stats!$G$38:$G$40) - 1 -> 74
A46: 12 | B46: 0.83162141 | C46: 0.82935334 | D46: 0.84477335
A47: 13 | B47: 0.7095195 | C47: 0.74133511 | D47: 0.67077129
A48: 14 | B48: 0.75258804 | C48: 0.77755869 | D48: 0.74919935
A49: 15 | B49: 0.74255587 | C49: 0.76965524 | D49: 0.7103344
A50: 16 | B50: 0.62660019 | C50: 0.69268523 | D50: 0.65823366
A51: 17 | B51: 0.81814248 | C51: 0.80578727 | D51: 0.82153301
A52: 18 | B52: 0.64796342 | C52: 0.63109379 | D52: 0.65400156
A53: 19 | B53: 0.64384174 | C53: 0.69026916 | D53: 0.59076887
A54: 20 | B54: 0.65454773 | C54: 0.69704907 | D54: 0.71658496
A55: 21 | B55: 0.73727979 | C55: 0.69517695 | D55: 0.66973956
A56: 22 | B56: 0.741791 | C56: 0.7579538 | D56: 0.73555551
...
