Workbook

Sheet scen1_hybsem
A1: turnId | B1: user_id | C1: assistant_id | D1: projectName | E1: sessionName | F1: seq | G1: anchorName | H1: weight | I1: promptSim | J1: responseSim | K1: activation delta | L1: prompt_to_response | N1: Average activation/turn | O1: average conversation activation | P1: count | Q1: correlation weights / activation delta | R1: p
A3: e2a1c274-8538-4b11-a127-f1551496f014 | B3: cmj8klijk00h9zcr30j55eyq5 | C3: cmj8kmhpy00hqzcr3q19ccfs0 | D3: hybrid_v3_5_semantic | E3: scenario_1_v2 | F3: 1 | G3: practicality_and_feasibility | H3: 0.2068 | I3: 0.29784571 | J3: 0.37091866 | K3: =J3-I3 -> 0.07307295 | L3: 0.82908352 | N3: =AVERAGE(K3:K8) -> 0.055445341 | O3: =AVERAGE(K3:K148) -> 0.03944214 | P3: =COUNT(K3:K148) -> 146 | Q3: =CORREL(H3:H148,K3:K148) -> -0.0096862162 | R3: 0.90762425
A4: e2a1c274-8538-4b11-a127-f1551496f014 | B4: cmj8klijk00h9zcr30j55eyq5 | C4: cmj8kmhpy00hqzcr3q19ccfs0 | D4: hybrid_v3_5_semantic | E4: scenario_1_v2 | F4: 1 | G4: temporal_dynamics | H4: 0.1966 | I4: 0.28309069 | J4: 0.31266664 | K4: =J4-I4 -> 0.029575959 | L4: 0.82908352
A5: e2a1c274-8538-4b11-a127-f1551496f014 | B5: cmj8klijk00h9zcr30j55eyq5 | C5: cmj8kmhpy00hqzcr3q19ccfs0 | D5: hybrid_v3_5_semantic | E5: scenario_1_v2 | F5: 1 | G5: mathematics_computer_science_engineering | H5: 0.1723 | I5: 0.24813442 | J5: 0.28698161 | K5: =J5-I5 -> 0.038847192 | L5: 0.82908352
A6: e2a1c274-8538-4b11-a127-f1551496f014 | B6: cmj8klijk00h9zcr30j55eyq5 | C6: cmj8kmhpy00hqzcr3q19ccfs0 | D6: hybrid_v3_5_semantic | E6: scenario_1_v2 | F6: 1 | G6: affective_interface | H6: 0.1636 | I6: 0.23564305 | J6: 0.29150164 | K6: =J6-I6 -> 0.055858596 | L6: 0.82908352
A7: e2a1c274-8538-4b11-a127-f1551496f014 | B7: cmj8klijk00h9zcr30j55eyq5 | C7: cmj8kmhpy00hqzcr3q19ccfs0 | D7: hybrid_v3_5_semantic | E7: scenario_1_v2 | F7: 1 | G7: sovereignty | H7: 0.1606 | I7: 0.23121629 | J7: 0.30043158 | K7: =J7-I7 -> 0.069215288 | L7: 0.82908352
A8: e2a1c274-8538-4b11-a127-f1551496f014 | B8: cmj8klijk00h9zcr30j55eyq5 | C8: cmj8kmhpy00hqzcr3q19ccfs0 | D8: hybrid_v3_5_semantic | E8: scenario_1_v2 | F8: 1 | G8: truth_and_fact | H8: 0.1 | I8: 0.15658745 | J8: 0.22268951 | K8: =J8-I8 -> 0.066102062 | L8: 0.82908352
A9: 5a32769e-087b-4227-b432-8a9ab7848ca9 | B9: cmj8kox5w00huzcr3r41ck1az | C9: cmj8kq1dt00ibzcr38k7zaod2 | D9: hybrid_v3_5_semantic | E9: scenario_1_v2 | F9: 3 | G9: practicality_and_feasibility | H9: 0.2204 | I9: 0.29563304 | J9: 0.36255665 | K9: =J9-I9 -> 0.066923611 | L9: 0.7664449 | N9: =AVERAGE(K9:K14) -> 0.070299443
A10: 5a32769e-087b-4227-b432-8a9ab7848ca9 | B10: cmj8kox5w00huzcr3r41ck1az | C10: cmj8kq1dt00ibzcr38k7zaod2 | D10: hybrid_v3_5_semantic | E10: scenario_1_v2 | F10: 3 | G10: sovereignty | H10: 0.1964 | I10: 0.26347984 | J10: 0.32060591 | K10: =J10-I10 -> 0.057126071 | L10: 0.7664449
A11: 5a32769e-087b-4227-b432-8a9ab7848ca9 | B11: cmj8kox5w00huzcr3r41ck1az | C11: cmj8kq1dt00ibzcr38k7zaod2 | D11: hybrid_v3_5_semantic | E11: scenario_1_v2 | F11: 3 | G11: temporal_dynamics | H11: 0.1738 | I11: 0.23307247 | J11: 0.29605503 | K11: =J11-I11 -> 0.062982563 | L11: 0.7664449
A12: 5a32769e-087b-4227-b432-8a9ab7848ca9 | B12: cmj8kox5w00huzcr3r41ck1az | C12: cmj8kq1dt00ibzcr38k7zaod2 | D12: hybrid_v3_5_semantic | E12: scenario_1_v2 | F12: 3 | G12: imagination_and_possibility | H12: 0.1584 | I12: 0.21250842 | J12: 0.28661759 | K12: =J12-I12 -> 0.074109169 | L12: 0.7664449
A13: 5a32769e-087b-4227-b432-8a9ab7848ca9 | B13: cmj8kox5w00huzcr3r41ck1az | C13: cmj8kq1dt00ibzcr38k7zaod2 | D13: hybrid_v3_5_semantic | E13: scenario_1_v2 | F13: 3 | G13: electricity | H13: 0.1509 | I13: 0.20243004 | J13: 0.26204665 | K13: =J13-I13 -> 0.059616607 | L13: 0.7664449
A14: 5a32769e-087b-4227-b432-8a9ab7848ca9 | B14: cmj8kox5w00huzcr3r41ck1az | C14: cmj8kq1dt00ibzcr38k7zaod2 | D14: hybrid_v3_5_semantic | E14: scenario_1_v2 | F14: 3 | G14: truth_and_fact | H14: 0.1 | I14: 0.13299836 | J14: 0.234037 | K14: =J14-I14 -> 0.10103864 | L14: 0.7664449
A15: a1ef12bb-1e19-4fca-a1c4-67be27eb97d4 | B15: cmj8kwd6200ifzcr3cna6z7cp | C15: cmj8kwv3w00iwzcr3r2cs3jj4 | D15: hybrid_v3_5_semantic | E15: scenario_1_v2 | F15: 5 | G15: practicality_and_feasibility | H15: 0.2176 | I15: 0.36079952 | J15: 0.39471692 | K15: =J15-I15 -> 0.033917391 | L15: 0.82081493 | N15: =AVERAGE(K15:K20) -> 0.045535564
A16: a1ef12bb-1e19-4fca-a1c4-67be27eb97d4 | B16: cmj8kwd6200ifzcr3cna6z7cp | C16: cmj8kwv3w00iwzcr3r2cs3jj4 | D16: hybrid_v3_5_semantic | E16: scenario_1_v2 | F16: 5 | G16: temporal_dynamics | H16: 0.1759 | I16: 0.29160197 | J16: 0.34930089 | K16: =J16-I16 -> 0.057698918 | L16: 0.82081493
A17: a1ef12bb-1e19-4fca-a1c4-67be27eb97d4 | B17: cmj8kwd6200ifzcr3cna6z7cp | C17: cmj8kwv3w00iwzcr3r2cs3jj4 | D17: hybrid_v3_5_semantic | E17: scenario_1_v2 | F17: 5 | G17: sovereignty | H17: 0.1699 | I17: 0.28172224 | J17: 0.30752137 | K17: =J17-I17 -> 0.025799132 | L17: 0.82081493
A18: a1ef12bb-1e19-4fca-a1c4-67be27eb97d4 | B18: cmj8kwd6200ifzcr3cna6z7cp | C18: cmj8kwv3w00iwzcr3r2cs3jj4 | D18: hybrid_v3_5_semantic | E18: scenario_1_v2 | F18: 5 | G18: imagination_and_possibility | H18: 0.1684 | I18: 0.27916975 | J18: 0.30850718 | K18: =J18-I18 -> 0.029337428 | L18: 0.82081493
A19: a1ef12bb-1e19-4fca-a1c4-67be27eb97d4 | B19: cmj8kwd6200ifzcr3cna6z7cp | C19: cmj8kwv3w00iwzcr3r2cs3jj4 | D19: hybrid_v3_5_semantic | E19: scenario_1_v2 | F19: 5 | G19: mathematics_computer_science_engineering | H19: 0.1681 | I19: 0.27876425 | J19: 0.33561095 | K19: =J19-I19 -> 0.056846703 | L19: 0.82081493
A20: a1ef12bb-1e19-4fca-a1c4-67be27eb97d4 | B20: cmj8kwd6200ifzcr3cna6z7cp | C20: cmj8kwv3w00iwzcr3r2cs3jj4 | D20: hybrid_v3_5_semantic | E20: scenario_1_v2 | F20: 5 | G20: truth_and_fact | H20: 0.1 | I20: 0.18672779 | J20: 0.2563416 | K20: =J20-I20 -> 0.069613813 | L20: 0.82081493
A21: 46e9fb75-2e4e-4c23-988a-eceecb0bed1e | B21: cmj8kylgx00j0zcr3q1hngl6u | C21: cmj8kzf5v00jhzcr3vepu6u4i | D21: hybrid_v3_5_semantic | E21: scenario_1_v2 | F21: 7 | G21: practicality_and_feasibility | H21: 0.2192 | I21: 0.37000057 | J21: 0.3755955 | K21: =J21-I21 -> 0.0055949277 | L21: 0.58934068 | N21: =AVERAGE(K21:K26) -> 0.016619078
A22: 46e9fb75-2e4e-4c23-988a-eceecb0bed1e | B22: cmj8kylgx00j0zcr3q1hngl6u | C22: cmj8kzf5v00jhzcr3vepu6u4i | D22: hybrid_v3_5_semantic | E22: scenario_1_v2 | F22: 7 | G22: temporal_dynamics | H22: 0.1921 | I22: 0.32435166 | J22: 0.34174416 | K22: =J22-I22 -> 0.017392505 | L22: 0.58934068
A23: 46e9fb75-2e4e-4c23-988a-eceecb0bed1e | B23: cmj8kylgx00j0zcr3q1hngl6u | C23: cmj8kzf5v00jhzcr3vepu6u4i | D23: hybrid_v3_5_semantic | E23: scenario_1_v2 | F23: 7 | G23: mathematics_computer_science_engineering | H23: 0.1849 | I23: 0.31207133 | J23: 0.30860916 | K23: =J23-I23 -> -0.0034621657 | L23: 0.58934068
A24: 46e9fb75-2e4e-4c23-988a-eceecb0bed1e | B24: cmj8kylgx00j0zcr3q1hngl6u | C24: cmj8kzf5v00jhzcr3vepu6u4i | D24: hybrid_v3_5_semantic | E24: scenario_1_v2 | F24: 7 | G24: sovereignty | H24: 0.1522 | I24: 0.25695272 | J24: 0.26539775 | K24: =J24-I24 -> 0.0084450247 | L24: 0.58934068
A25: 46e9fb75-2e4e-4c23-988a-eceecb0bed1e | B25: cmj8kylgx00j0zcr3q1hngl6u | C25: cmj8kzf5v00jhzcr3vepu6u4i | D25: hybrid_v3_5_semantic | E25: scenario_1_v2 | F25: 7 | G25: electricity | H25: 0.1516 | I25: 0.25588908 | J25: 0.27218055 | K25: =J25-I25 -> 0.016291473 | L25: 0.58934068
A26: 46e9fb75-2e4e-4c23-988a-eceecb0bed1e | B26: cmj8kylgx00j0zcr3q1hngl6u | C26: cmj8kzf5v00jhzcr3vepu6u4i | D26: hybrid_v3_5_semantic | E26: scenario_1_v2 | F26: 7 | G26: truth_and_fact | H26: 0.1 | I26: 0.20075843 | J26: 0.25621113 | K26: =J26-I26 -> 0.055452702 | L26: 0.58934068
A27: 8d220410-522e-4b50-adee-9f2f07d35025 | B27: cmj8l2r0z00jlzcr3xmhaqxb1 | C27: cmj8l3jed00k2zcr399oism5x | D27: hybrid_v3_5_semantic | E27: scenario_1_v2 | F27: 9 | G27: practicality_and_feasibility | H27: 0.209 | I27: 0.32617558 | J27: 0.38132347 | K27: =J27-I27 -> 0.055147891 | L27: 0.54993991 | N27: =AVERAGE(K27:K32) -> 0.04436839
A28: 8d220410-522e-4b50-adee-9f2f07d35025 | B28: cmj8l2r0z00jlzcr3xmhaqxb1 | C28: cmj8l3jed00k2zcr399oism5x | D28: hybrid_v3_5_semantic | E28: scenario_1_v2 | F28: 9 | G28: temporal_dynamics | H28: 0.1927 | I28: 0.30071229 | J28: 0.31963397 | K28: =J28-I28 -> 0.018921682 | L28: 0.54993991
A29: 8d220410-522e-4b50-adee-9f2f07d35025 | B29: cmj8l2r0z00jlzcr3xmhaqxb1 | C29: cmj8l3jed00k2zcr399oism5x | D29: hybrid_v3_5_semantic | E29: scenario_1_v2 | F29: 9 | G29: affective_interface | H29: 0.1748 | I29: 0.2727731 | J29: 0.29400422 | K29: =J29-I29 -> 0.021231124 | L29: 0.54993991
A30: 8d220410-522e-4b50-adee-9f2f07d35025 | B30: cmj8l2r0z00jlzcr3xmhaqxb1 | C30: cmj8l3jed00k2zcr399oism5x | D30: hybrid_v3_5_semantic | E30: scenario_1_v2 | F30: 9 | G30: mathematics_computer_science_engineering | H30: 0.1648 | I30: 0.25727022 | J30: 0.3106754 | K30: =J30-I30 -> 0.053405184 | L30: 0.54993991
A31: 8d220410-522e-4b50-adee-9f2f07d35025 | B31: cmj8l2r0z00jlzcr3xmhaqxb1 | C31: cmj8l3jed00k2zcr399oism5x | D31: hybrid_v3_5_semantic | E31: scenario_1_v2 | F31: 9 | G31: electricity | H31: 0.1588 | I31: 0.24782867 | J31: 0.30005961 | K31: =J31-I31 -> 0.05223094 | L31: 0.54993991
A32: 8d220410-522e-4b50-adee-9f2f07d35025 | B32: cmj8l2r0z00jlzcr3xmhaqxb1 | C32: cmj8l3jed00k2zcr399oism5x | D32: hybrid_v3_5_semantic | E32: scenario_1_v2 | F32: 9 | G32: truth_and_fact | H32: 0.1 | I32: 0.18491283 | J32: 0.25018635 | K32: =J32-I32 -> 0.065273516 | L32: 0.54993991
A33: f620b784-04dc-4b50-a8ff-43b61165203d | B33: cmj8l6qyy00k6zcr3995erl9t | C33: cmj8l7ovp00knzcr3qbyjw292 | D33: hybrid_v3_5_semantic | E33: scenario_1_v2 | F33: 11 | G33: practicality_and_feasibility | H33: 0.2241 | I33: 0.34350994 | J33: 0.32163656 | K33: =J33-I33 -> -0.021873378 | L33: 0.8063013 | N33: =AVERAGE(K33:K38) -> -0.0019804665
A34: f620b784-04dc-4b50-a8ff-43b61165203d | B34: cmj8l6qyy00k6zcr3995erl9t | C34: cmj8l7ovp00knzcr3qbyjw292 | D34: hybrid_v3_5_semantic | E34: scenario_1_v2 | F34: 11 | G34: temporal_dynamics | H34: 0.1866 | I34: 0.28611848 | J34: 0.28570075 | K34: =J34-I34 -> -0.00041773728 | L34: 0.8063013
A35: f620b784-04dc-4b50-a8ff-43b61165203d | B35: cmj8l6qyy00k6zcr3995erl9t | C35: cmj8l7ovp00knzcr3qbyjw292 | D35: hybrid_v3_5_semantic | E35: scenario_1_v2 | F35: 11 | G35: imagination_and_possibility | H35: 0.1721 | I35: 0.26385813 | J35: 0.23586656 | K35: =J35-I35 -> -0.027991571 | L35: 0.8063013
A36: f620b784-04dc-4b50-a8ff-43b61165203d | B36: cmj8l6qyy00k6zcr3995erl9t | C36: cmj8l7ovp00knzcr3qbyjw292 | D36: hybrid_v3_5_semantic | E36: scenario_1_v2 | F36: 11 | G36: mathematics_computer_science_engineering | H36: 0.1719 | I36: 0.26354424 | J36: 0.27369251 | K36: =J36-I36 -> 0.010148263 | L36: 0.8063013
A37: f620b784-04dc-4b50-a8ff-43b61165203d | B37: cmj8l6qyy00k6zcr3995erl9t | C37: cmj8l7ovp00knzcr3qbyjw292 | D37: hybrid_v3_5_semantic | E37: scenario_1_v2 | F37: 11 | G37: freedom_and_limitations | H37: 0.1453 | I37: 0.2227416 | J37: 0.23199125 | K37: =J37-I37 -> 0.0092496443 | L37: 0.8063013
A38: f620b784-04dc-4b50-a8ff-43b61165203d | B38: cmj8l6qyy00k6zcr3995erl9t | C38: cmj8l7ovp00knzcr3qbyjw292 | D38: hybrid_v3_5_semantic | E38: scenario_1_v2 | F38: 11 | G38: truth_and_fact | H38: 0.1 | I38: 0.17068518 | J38: 0.18968716 | K38: =J38-I38 -> 0.01900198 | L38: 0.8063013
A39: f2eb5bcb-3344-4411-93d1-c12c61b69949 | B39: cmj8ldajt00krzcr3cfmdlq71 | C39: cmj8lebqf00l8zcr3ri13obo4 | D39: hybrid_v3_5_semantic | E39: scenario_1_v2 | F39: 13 | G39: practicality_and_feasibility | H39: 0.2492 | I39: 0.2574249 | J39: 0.38215269 | K39: =J39-I39 -> 0.12472778 | L39: 0.65442075 | N39: =AVERAGE(K39:K43) -> 0.081941456
A40: f2eb5bcb-3344-4411-93d1-c12c61b69949 | B40: cmj8ldajt00krzcr3cfmdlq71 | C40: cmj8lebqf00l8zcr3ri13obo4 | D40: hybrid_v3_5_semantic | E40: scenario_1_v2 | F40: 13 | G40: temporal_dynamics | H40: 0.2474 | I40: 0.25554578 | J40: 0.33943453 | K40: =J40-I40 -> 0.083888753 | L40: 0.65442075
A41: f2eb5bcb-3344-4411-93d1-c12c61b69949 | B41: cmj8ldajt00krzcr3cfmdlq71 | C41: cmj8lebqf00l8zcr3ri13obo4 | D41: hybrid_v3_5_semantic | E41: scenario_1_v2 | F41: 13 | G41: mathematics_computer_science_engineering | H41: 0.2095 | I41: 0.21643966 | J41: 0.29863656 | K41: =J41-I41 -> 0.082196903 | L41: 0.65442075
...

Sheet notes
A1: p calculation
A3: 1. count | B3: =COUNT(scen1_hybsem!K3:K148) -> 146 | C3: activation delta
A4: 2. t statistic | B4: =scen1_hybsem!Q3*SQRT((B3-2)/(1-scen1_hybsem!Q3^2)) -> -0.11624005
A5: 3. p | B5: =_xlfn.T.DIST.2T(ABS(B4),B3-2) -> 0.90762425

Sheet actdel_prompt_response
A2: turn | B2: prompt_to_response | C2: Average activation/turn | H2: Correlation | I2: count | J2: T-statistic | K2: p
A4: 1 | B4: 0.82908352 | C4: 0.055445341 | H4: =CORREL(B4:B28,C4:C28) -> 0.056860464 | I4: =COUNT(C4:C28) -> 25 | J4: =H4*SQRT((I4-2)/(1-H4^2)) -> 0.2731351 | K4: =_xlfn.T.DIST.2T(ABS(J4),I4-2) -> 0.78718692
A5: 2 | B5: 0.7664449 | C5: 0.070299443
A6: 3 | B6: 0.82081493 | C6: 0.045535564
A7: 4 | B7: 0.58934068 | C7: 0.016619078
A8: 5 | B8: 0.54993991 | C8: 0.04436839
A9: 6 | B9: 0.8063013 | C9: -0.0019804665
A10: 7 | B10: 0.65442075 | C10: 0.081941456
A11: 8 | B11: 0.74745701 | C11: 0.044518113
A12: 9 | B12: 0.76315444 | C12: -0.0012153879
A13: 10 | B13: 0.74529883 | C13: 0.036960441
A14: 11 | B14: 0.70359943 | C14: 0.034937913
A15: 12 | B15: 0.79229112 | C15: 0.04105536
A16: 13 | B16: 0.74274884 | C16: 0.10756364
... A28: 25 | B28: 0.71866241 | C28: 0.03183744

Sheet inter_system stats
H2: Tests
B3: hybsem | C3: control | E3: std. Hybrid | F3: std. Control | G3: F. test | H3: T. Test equal variances | I3: T.Test unequal | J3: Mean difference | L3: Paired t-test
A4: 1 | B4: 0.82908352 | C4: 0.84316826 | E4: =_xlfn.STDEV.S(B4:B28) -> 0.06548327 | F4: =_xlfn.STDEV.S(C4:C28) -> 0.11788306 | G4: =_xlfn.F.TEST(B4:B28,C4:C28) -> 0.0055234552 | H4: =_xlfn.T.TEST(B4:B28, C4:C28, 2,2) -> 8.1996229e-08 | I4: =_xlfn.T.TEST(B4:B28,C4:C28, 2,3) -> 2.2046054e-07 | J4: =AVERAGE(B4:B28)-AVERAGE(C4:C28) -> 0.1703759 | L4: Alpha | M4: 0.05
A5: 2 | B5: 0.7664449 | C5: 0.41048157 | L5: Hypothesized Mean Difference | M5: 0
A6: 3 | B6: 0.82081493 | C6: 0.55797537 | M6: Variable 1 | N6: Variable 2
A7: 4 | B7: 0.58934068 | C7: 0.61915827 | L7: Mean | M7: =AVERAGE('inter_system stats'!$B$3:$B$28) -> 0.73304139 | N7: =AVERAGE('inter_system stats'!$C$3:$C$28) -> 0.56266549
A8: 5 | B8: 0.54993991 | C8: 0.40396308 | L8: Variance | M8: =VAR('inter_system stats'!$B$3:$B$28) -> 0.0042880587 | N8: =VAR('inter_system stats'!$C$3:$C$28) -> 0.013896415
A9: 6 | B9: 0.8063013 | C9: 0.57074388 | L9: Observations | M9: =COUNT('inter_system stats'!$B$3:$B$28) -> 25 | N9: =COUNT('inter_system stats'!$C$3:$C$28) -> 25
A10: 7 | B10: 0.65442075 | C10: 0.61160895 | L10: Pearson Correlation | M10: =CORREL('inter_system stats'!$B$3:$B$28,'inter_system stats'!$C$3:$C$28) -> 0.23279543
A11: 8 | B11: 0.74745701 | C11: 0.51665839 | L11: Observed Mean Difference | M11: {=AVERAGE(IF(ISODD(IF(ISNUMBER('inter_system stats'!$B$3:$B$28), 1, 0) * IF(ISNUMBER('inter_system stats'!$C$3:$C$28), 1, 0)), 'inter_system stats'!$B$3:$B$28 - 'inter_system stats'!$C$3:$C$28, "NA"))} -> 0.1703759
A12: 9 | B12: 0.76315444 | C12: 0.51910728 | L12: Variance of the Differences | M12: {=VAR(IF(ISODD(IF(ISNUMBER('inter_system stats'!$B$3:$B$28), 1, 0) * IF(ISNUMBER('inter_system stats'!$C$3:$C$28), 1, 0)), 'inter_system stats'!$B$3:$B$28 - 'inter_system stats'!$C$3:$C$28, "NA"))} -> 0.014590406
A13: 10 | B13: 0.74529883 | C13: 0.68124246 | L13: df | M13: {=SUM(IF(ISNUMBER('inter_system stats'!$B$3:$B$28), 1, 0) * IF(ISNUMBER('inter_system stats'!$C$3:$C$28), 1, 0)) - 1} -> 24
A14: 11 | B14: 0.70359943 | C14: 0.66509925 | L14: t Stat | M14: =('inter_system stats'!$M$11 - 'inter_system stats'!$M$5) / ('inter_system stats'!$M$12 / ( 'inter_system stats'!$M$13 + 1)) ^ 0.5 -> 7.0525224
A15: 12 | B15: 0.79229112 | C15: 0.68559512 | L15: P (T<=t) one-tail | M15: =TDIST(ABS('inter_system stats'!$M$14), 'inter_system stats'!$M$13, 1) -> 1.3623057e-07
A16: 13 | B16: 0.74274884 | C16: 0.65114377 | L16: t Critical one-tail | M16: =TINV(2*'inter_system stats'!$M$4, 'inter_system stats'!$M$13) -> 1.7108821
A17: 14 | B17: 0.73073903 | C17: 0.60348677 | L17: P (T<=t) two-tail | M17: =TDIST(ABS('inter_system stats'!$M$14), 'inter_system stats'!$M$13, 2) -> 2.7246115e-07
A18: 15 | B18: 0.72750153 | C18: 0.49806868 | L18: t Critical two-tail | M18: =TINV('inter_system stats'!$M$4, 'inter_system stats'!$M$13) -> 2.0638986
A19: 16 | B19: 0.69212024 | C19: 0.63037797
A20: 17 | B20: 0.71954954 | C20: 0.65792717
A21: 18 | B21: 0.70854009 | C21: 0.56086051
A22: 19 | B22: 0.70677586 | C22: 0.50207793
A23: 20 | B23: 0.81055278 | C23: 0.47716849
A24: 21 | B24: 0.77965151 | C24: 0.49071258
A25: 22 | B25: 0.70701265 | C25: 0.37364723
A26: 23 | B26: 0.7594112 | C26: 0.656355
A27: 24 | B27: 0.75462219 | C27: 0.57973183
A28: 25 | B28: 0.71866241 | C28: 0.30027741
A32: General
B33: Hybsem | C33: Hybrid | D33: ac15p | F33: ANOVA - Single Factor
B34: 0.82908352 | C34: 0.83430834 | D34: 0.82032979 | F34: Alpha | G34: 0.05
B35: 0.7664449 | C35: 0.78737809 | D35: 0.76020895
B36: 0.82081493 | C36: 0.82347011 | D36: 0.77935892 | F36: Groups | G36: Count | H36: Sum | I36: Mean | J36: Variance
B37: 0.58934068 | C37: 0.64138219 | D37: 0.65547417 | F37: Column 1 | G37: =COUNT('inter_system stats'!$B$33:$B$58) -> 25 | H37: =SUM('inter_system stats'!$B$33:$B$58) -> 18.326035 | I37: =AVERAGE('inter_system stats'!$B$33:$B$58) -> 0.73304139 | J37: =VAR('inter_system stats'!$B$33:$B$58) -> 0.0042880587
B38: 0.54993991 | C38: 0.64856074 | D38: 0.60148827 | F38: Column 2 | G38: =COUNT('inter_system stats'!$C$33:$C$58) -> 25 | H38: =SUM('inter_system stats'!$C$33:$C$58) -> 18.263774 | I38: =AVERAGE('inter_system stats'!$C$33:$C$58) -> 0.73055098 | J38: =VAR('inter_system stats'!$C$33:$C$58) -> 0.0032014709
B39: 0.8063013 | C39: 0.73754073 | D39: 0.80260511 | F39: Column 3 | G39: =COUNT('inter_system stats'!$D$33:$D$58) -> 25 | H39: =SUM('inter_system stats'!$D$33:$D$58) -> 18.268163 | I39: =AVERAGE('inter_system stats'!$D$33:$D$58) -> 0.73072651 | J39: =VAR('inter_system stats'!$D$33:$D$58) -> 0.004609989
B40: 0.65442075 | C40: 0.63496808 | D40: 0.64887842
B41: 0.74745701 | C41: 0.74640085 | D41: 0.75255045 | F41: Source of Variation | G41: SS | H41: df | I41: MS | J41: F | K41: P-value | L41: F critical
B42: 0.76315444 | C42: 0.68880534 | D42: 0.72599844 | F42: Between Groups | G42: =SUMPRODUCT('inter_system stats'!$H$37:$H$39,'inter_system stats'!$I$37:$I$39)-SUM('inter_system stats'!$H$37:$H$39)^2/SUM('inter_system stats'!$G$37:$G$39) -> 9.6596749e-05 | H42: =COUNT('inter_system stats'!$H$37:$H$39)-1 -> 2 | I42: ='inter_system stats'!$G$42 / 'inter_system stats'!$H$42 -> 4.8298375e-05 | J42: ='inter_system stats'!$I$42 / 'inter_system stats'!$I$43 -> 0.01197528 | K42: =FDIST('inter_system stats'!$J$42, 'inter_system stats'!$H$42, 'inter_system stats'!$H$43) -> 0.98809811 | L42: =FINV('inter_system stats'!$G$34, 'inter_system stats'!$H$42, 'inter_system stats'!$H$43) -> 3.1239074
B43: 0.74529883 | C43: 0.74363979 | D43: 0.70681936 | F43: Within Groups | G43: =SUM(DEVSQ('inter_system stats'!$B$33:$B$58),DEVSQ('inter_system stats'!$C$33:$C$58),DEVSQ('inter_system stats'!$D$33:$D$58)) -> 0.29038844 | H43: =SUM('inter_system stats'!$G$37:$G$39)-COUNT('inter_system stats'!$G$37:$G$39) -> 72 | I43: ='inter_system stats'!$G$43 / 'inter_system stats'!$H$43 -> 0.0040331728
B44: 0.70359943 | C44: 0.71319147 | D44: 0.66388414 | F44: Total | G44: =DEVSQ('inter_system stats'!$B$33:$B$58,'inter_system stats'!$C$33:$C$58,'inter_system stats'!$D$33:$D$58) -> 0.29048504 | H44: =SUM('inter_system stats'!$G$37:$G$39) - 1 -> 74
...
