Workbook

Sheet scen3_hybsem
A1: turnId | B1: user_id | C1: assistant_id | D1: projectName | E1: sessionName | F1: seq | G1: anchorName | H1: weight | I1: promptSim | J1: responseSim | K1: activation delta | L1: prompt_to_response | O1: average conversation activation | P1: count | Q1: correlation weights / activation delta | R1: p
A3: 02f093d3-e054-429f-bcf2-af6660c9ffbc | B3: cmjbadk2m001ozc4pwj0xyyk3 | C3: cmjbaem4r0025zc4pd3cskc6e | D3: hybrid_v3_5_semantic | E3: Scenario_3 | F3: 1 | G3: practicality_and_feasibility | H3: 0.1965 | I3: 0.30381011 | J3: 0.40229863 | K3: =J3-I3 -> 0.09848852 | L3: 0.8076297 | O3: =AVERAGE(K3:K152) -> 0.049157864 | P3: =COUNT(K3:K152) -> 150 | Q3: =CORREL(H3:H152,K3:K152) -> -0.13952101
A4: 02f093d3-e054-429f-bcf2-af6660c9ffbc | B4: cmjbadk2m001ozc4pwj0xyyk3 | C4: cmjbaem4r0025zc4pd3cskc6e | D4: hybrid_v3_5_semantic | E4: Scenario_3 | F4: 1 | G4: mathematics_computer_science_engineering | H4: 0.1927 | I4: 0.29800188 | J4: 0.36132565 | K4: =J4-I4 -> 0.063323773 | L4: 0.8076297
A5: 02f093d3-e054-429f-bcf2-af6660c9ffbc | B5: cmjbadk2m001ozc4pwj0xyyk3 | C5: cmjbaem4r0025zc4pd3cskc6e | D5: hybrid_v3_5_semantic | E5: Scenario_3 | F5: 1 | G5: affective_interface | H5: 0.1755 | I5: 0.27142395 | J5: 0.37045958 | K5: =J5-I5 -> 0.099035629 | L5: 0.8076297
A6: 02f093d3-e054-429f-bcf2-af6660c9ffbc | B6: cmjbadk2m001ozc4pwj0xyyk3 | C6: cmjbaem4r0025zc4pd3cskc6e | D6: hybrid_v3_5_semantic | E6: Scenario_3 | F6: 1 | G6: imagination_and_possibility | H6: 0.1716 | I6: 0.2653255 | J6: 0.35592643 | K6: =J6-I6 -> 0.09060093 | L6: 0.8076297
A7: 02f093d3-e054-429f-bcf2-af6660c9ffbc | B7: cmjbadk2m001ozc4pwj0xyyk3 | C7: cmjbaem4r0025zc4pd3cskc6e | D7: hybrid_v3_5_semantic | E7: Scenario_3 | F7: 1 | G7: temporal_dynamics | H7: 0.1637 | I7: 0.25312599 | J7: 0.31046614 | K7: =J7-I7 -> 0.057340149 | L7: 0.8076297
A8: 02f093d3-e054-429f-bcf2-af6660c9ffbc | B8: cmjbadk2m001ozc4pwj0xyyk3 | C8: cmjbaem4r0025zc4pd3cskc6e | D8: hybrid_v3_5_semantic | E8: Scenario_3 | F8: 1 | G8: truth_and_fact | H8: 0.1 | I8: 0.17749977 | J8: 0.27874197 | K8: =J8-I8 -> 0.1012422 | L8: 0.8076297
A9: 0c50a8c2-0bba-4b91-8553-8449c0c4b4d4 | B9: cmjbaf0a50029zc4p7h2yfeq7 | C9: cmjbafr0c002qzc4p3c963l7y | D9: hybrid_v3_5_semantic | E9: Scenario_3 | F9: 3 | G9: mathematics_computer_science_engineering | H9: 0.211 | I9: 0.37497821 | J9: 0.4131517 | K9: =J9-I9 -> 0.03817349 | L9: 0.73890843
A10: 0c50a8c2-0bba-4b91-8553-8449c0c4b4d4 | B10: cmjbaf0a50029zc4p7h2yfeq7 | C10: cmjbafr0c002qzc4p3c963l7y | D10: hybrid_v3_5_semantic | E10: Scenario_3 | F10: 3 | G10: practicality_and_feasibility | H10: 0.2021 | I10: 0.35903504 | J10: 0.4131085 | K10: =J10-I10 -> 0.054073457 | L10: 0.73890843
A11: 0c50a8c2-0bba-4b91-8553-8449c0c4b4d4 | B11: cmjbaf0a50029zc4p7h2yfeq7 | C11: cmjbafr0c002qzc4p3c963l7y | D11: hybrid_v3_5_semantic | E11: Scenario_3 | F11: 3 | G11: science | H11: 0.1661 | I11: 0.29520036 | J11: 0.37799289 | K11: =J11-I11 -> 0.082792533 | L11: 0.73890843
A12: 0c50a8c2-0bba-4b91-8553-8449c0c4b4d4 | B12: cmjbaf0a50029zc4p7h2yfeq7 | C12: cmjbafr0c002qzc4p3c963l7y | D12: hybrid_v3_5_semantic | E12: Scenario_3 | F12: 3 | G12: freedom_and_limitations | H12: 0.1607 | I12: 0.28545945 | J12: 0.35641443 | K12: =J12-I12 -> 0.070954986 | L12: 0.73890843
A13: 0c50a8c2-0bba-4b91-8553-8449c0c4b4d4 | B13: cmjbaf0a50029zc4p7h2yfeq7 | C13: cmjbafr0c002qzc4p3c963l7y | D13: hybrid_v3_5_semantic | E13: Scenario_3 | F13: 3 | G13: affective_interface | H13: 0.1601 | I13: 0.28450393 | J13: 0.37335333 | K13: =J13-I13 -> 0.088849392 | L13: 0.73890843
A14: 0c50a8c2-0bba-4b91-8553-8449c0c4b4d4 | B14: cmjbaf0a50029zc4p7h2yfeq7 | C14: cmjbafr0c002qzc4p3c963l7y | D14: hybrid_v3_5_semantic | E14: Scenario_3 | F14: 3 | G14: truth_and_fact | H14: 0.1 | I14: 0.24432002 | J14: 0.31230125 | K14: =J14-I14 -> 0.067981232 | L14: 0.73890843
A15: 78544be1-5cdb-4803-85aa-13d47cfb7824 | B15: cmjbaghid002uzc4pez74htlg | C15: cmjbahfvh003bzc4pcp8bs9nd | D15: hybrid_v3_5_semantic | E15: Scenario_3 | F15: 5 | G15: practicality_and_feasibility | H15: 0.2164 | I15: 0.34809115 | J15: 0.37356704 | K15: =J15-I15 -> 0.025475893 | L15: 0.66648251
... A152: f86eae80-95c8-40d7-ad52-26afd68f9680 | B152: cmjbbkg3q00fozc4p7hdvwwdj | C152: cmjbbkw8t00g5zc4pp4f2lmia | D152: hybrid_v3_5_semantic | E152: Scenario_3 | F152: 49 | G152: truth_and_fact | H152: 0.1 | I152: 0.16445415 | J152: 0.19121841 | K152: =J152-I152 -> 0.026764268 | L152: 0.74088392

Sheet notes
A1: p calculation
A3: 1. count | B3: =scen3_hybsem!P3 -> 150
A4: 2. t statistic | B4: =B10*SQRT((B3-2)/(1-B10^2)) -> -1.7141118
A5: 3. p | B5: =_xlfn.T.DIST.2T(ABS(B4),B3-2) -> 0.088601631
A9: count | B9: correlation weights / activation delta
A10: =B3 -> 150 | B10: =scen3_hybsem!Q3 -> -0.13952101

Sheet actdel_prompt_response
B2: prompt_to_response
A3: Turn
A4: 1 | B4: 0.8076297
A5: 2 | B5: 0.73890843
A6: 3 | B6: 0.66648251
A7: 4 | B7: 0.6172328
A8: 5 | B8: 0.61042546
A9: 6 | B9: 0.70330399
A10: 7 | B10: 0.81769202
A11: 8 | B11: 0.7620195
A12: 9 | B12: 0.64235421
A13: 10 | B13: 0.62291306
A14: 11 | B14: 0.77112756
A15: 12 | B15: 0.75570049
... A28: 25 | B28: 0.74088392

Sheet inter_system_stats
B2: prompt_to_response
A3: Turn | B3: hybsem | C3: control | E3: std. Hybsem | F3: std. Control | G3: F. test | H3: T. Test equal variances | I3: T.Test unequal | J3: Mean difference | K3: average scen | L3: average control
A4: 1 | B4: 0.8076297 | C4: 0.81237587 | E4: =_xlfn.STDEV.S(B4:B27) -> 0.066110493 | F4: =_xlfn.STDEV.S(C4:C27) -> 0.083159468 | G4: =_xlfn.F.TEST(B4:B27,C4:C27) -> 0.27847032 | H4: =_xlfn.T.TEST(B4:B27, C4:C27, 2,2) -> 8.4312901e-07 | I4: =_xlfn.T.TEST(B4:B27,C4:C27, 2,3) -> 9.7782892e-07 | J4: =AVERAGE(B4:B27)-AVERAGE(C4:C27) -> 0.12338145 | K4: =AVERAGE(B4:B27) -> 0.72333134 | L4: =AVERAGE(C4:C27) -> 0.5999499
A5: 2 | B5: 0.73890843 | C5: 0.62132605
A6: 3 | B6: 0.66648251 | C6: 0.68189933
A7: 4 | B7: 0.6172328 | C7: 0.67477184
A8: 5 | B8: 0.61042546 | C8: 0.51803751
A9: 6 | B9: 0.70330399 | C9: 0.60625362
A10: 7 | B10: 0.81769202 | C10: 0.60279121
A11: 8 | B11: 0.7620195 | C11: 0.5426037
A12: 9 | B12: 0.64235421 | C12: 0.65241954
A13: 10 | B13: 0.62291306 | C13: 0.4509056
A14: 11 | B14: 0.77112756 | C14: 0.54613378
A15: 12 | B15: 0.75570049 | C15: 0.66577803
A16: 13 | B16: 0.65220649 | C16: 0.57017868
... A27: 24 | B27: 0.73739705 | C27: 0.63175829
A31: General
B32: ac15p | C32: hybrid | D32: hybsem | F32: ANOVA - Single Factor
A33: 1 | B33: 0.81661277 | C33: 0.81577203 | D33: 0.8076297 | F33: Alpha | G33: 0.05
A34: 2 | B34: 0.68560399 | C34: 0.69017898 | D34: 0.73890843
A35: 3 | B35: 0.692193 | C35: 0.6782366 | D35: 0.66648251 | F35: Groups | G35: Count | H35: Sum | I35: Mean | J35: Variance
A36: 4 | B36: 0.63109017 | C36: 0.59975321 | D36: 0.6172328 | F36: Column 1 | G36: =COUNT(inter_system_stats!$B$32:$B$56) -> 24 | H36: =SUM(inter_system_stats!$B$32:$B$56) -> 17.564842 | I36: =AVERAGE(inter_system_stats!$B$32:$B$56) -> 0.73186842 | J36: =VAR(inter_system_stats!$B$32:$B$56) -> 0.0049204956
A37: 5 | B37: 0.59460889 | C37: 0.57141073 | D37: 0.61042546 | F37: Column 2 | G37: =COUNT(inter_system_stats!$C$32:$C$56) -> 24 | H37: =SUM(inter_system_stats!$C$32:$C$56) -> 17.327131 | I37: =AVERAGE(inter_system_stats!$C$32:$C$56) -> 0.72196379 | J37: =VAR(inter_system_stats!$C$32:$C$56) -> 0.0054482895
A38: 6 | B38: 0.67289207 | C38: 0.66533199 | D38: 0.70330399 | F38: Column 3 | G38: =COUNT(inter_system_stats!$D$32:$D$56) -> 24 | H38: =SUM(inter_system_stats!$D$32:$D$56) -> 17.359952 | I38: =AVERAGE(inter_system_stats!$D$32:$D$56) -> 0.72333134 | J38: =VAR(inter_system_stats!$D$32:$D$56) -> 0.0043705973
A39: 7 | B39: 0.81547187 | C39: 0.83458196 | D39: 0.81769202
A40: 8 | B40: 0.77736126 | C40: 0.72719155 | D40: 0.7620195 | F40: Source of Variation | G40: SS | H40: df | I40: MS | J40: F | K40: P-value | L40: F critical
A41: 9 | B41: 0.69224629 | C41: 0.69768145 | D41: 0.64235421 | F41: Between Groups | G41: =SUMPRODUCT(inter_system_stats!$H$36:$H$38,inter_system_stats!$I$36:$I$38)-SUM(inter_system_stats!$H$36:$H$38)^2/SUM(inter_system_stats!$G$36:$G$38) -> 0.0013828277 | H41: =COUNT(inter_system_stats!$H$36:$H$38)-1 -> 2 | I41: =inter_system_stats!$G$41 / inter_system_stats!$H$41 -> 0.00069141383 | J41: =inter_system_stats!$I$41 / inter_system_stats!$I$42 -> 0.14072784 | K41: =FDIST(inter_system_stats!$J$41, inter_system_stats!$H$41, inter_system_stats!$H$42) -> 0.86897441 | L41: =FINV(inter_system_stats!$G$33, inter_system_stats!$H$41, inter_system_stats!$H$42) -> 3.129644
A42: 10 | B42: 0.61584135 | C42: 0.61958009 | D42: 0.62291306 | F42: Within Groups | G42: =SUM(DEVSQ(inter_system_stats!$B$32:$B$56),DEVSQ(inter_system_stats!$C$32:$C$56),DEVSQ(inter_system_stats!$D$32:$D$56)) -> 0.3390058 | H42: =SUM(inter_system_stats!$G$36:$G$38)-COUNT(inter_system_stats!$G$36:$G$38) -> 69 | I42: =inter_system_stats!$G$42 / inter_system_stats!$H$42 -> 0.0049131275
A43: 11 | B43: 0.77530249 | C43: 0.77492118 | D43: 0.77112756 | F43: Total | G43: =DEVSQ(inter_system_stats!$B$32:$B$56,inter_system_stats!$C$32:$C$56,inter_system_stats!$D$32:$D$56) -> 0.34038862 | H43: =SUM(inter_system_stats!$G$36:$G$38) - 1 -> 71
A44: 12 | B44: 0.74554982 | C44: 0.75355371 | D44: 0.75570049
A45: 13 | B45: 0.67593648 | C45: 0.67256393 | D45: 0.65220649
A46: 14 | B46: 0.79745535 | C46: 0.79342845 | D46: 0.77420332
A47: 15 | B47: 0.83168375 | C47: 0.82221564 | D47: 0.80993905
A48: 16 | B48: 0.66591506 | C48: 0.63533272 | D48: 0.65013163
A49: 17 | B49: 0.80846503 | C49: 0.79359465 | D49: 0.79718908
A50: 18 | B50: 0.70292333 | C50: 0.70487145 | D50: 0.72918538
A51: 19 | B51: 0.83384929 | C51: 0.80738013 | D51: 0.81431744
A52: 20 | B52: 0.79062425 | C52: 0.68583989 | D52: 0.72621087
A53: 21 | B53: 0.73061736 | C53: 0.74453294 | D53: 0.72902821
A54: 22 | B54: 0.76520806 | C54: 0.79344048 | D54: 0.72636055
...
