Workbook

Sheet scen5_hybsem
A1: turnId | B1: user_id | C1: assistant_id | D1: projectName | E1: sessionName | F1: seq | G1: anchorName | H1: weight | I1: promptSim | J1: responseSim | K1: activation delta | L1: prompt_to_response | P1: count | Q1: Activation delta average | R1: correlation weights / activation delta | S1: p
P2: =COUNT(K3:K152) -> 150 | Q2: =AVERAGE(K3:K152) -> 0.030045283 | R2: =CORREL(H3:H152,K3:K152) -> -0.34078016 | S2: =notes!B5 -> 1.9793024e-05
A3: 64406fd5-e206-4f2b-acf7-3e994206acc8 | B3: cmjfcc7rc001yzca63q4fhtkq | C3: cmjfcdhfg002fzca6yotpk8ei | D3: hybrid_v3_5_semantic | E3: Scenario_5 | F3: 0 | G3: identity | H3: 0.1985 | I3: 0.38269072 | J3: 0.35952558 | K3: =J3-I3 -> -0.023165138 | L3: 0.76068069
A4: 64406fd5-e206-4f2b-acf7-3e994206acc8 | B4: cmjfcc7rc001yzca63q4fhtkq | C4: cmjfcdhfg002fzca6yotpk8ei | D4: hybrid_v3_5_semantic | E4: Scenario_5 | F4: 0 | G4: temporal_dynamics | H4: 0.1791 | I4: 0.34543646 | J4: 0.36867693 | K4: =J4-I4 -> 0.023240465 | L4: 0.76068069
A5: 64406fd5-e206-4f2b-acf7-3e994206acc8 | B5: cmjfcc7rc001yzca63q4fhtkq | C5: cmjfcdhfg002fzca6yotpk8ei | D5: hybrid_v3_5_semantic | E5: Scenario_5 | F5: 0 | G5: imagination_and_possibility | H5: 0.1776 | I5: 0.3424889 | J5: 0.38988857 | K5: =J5-I5 -> 0.047399677 | L5: 0.76068069
A6: 64406fd5-e206-4f2b-acf7-3e994206acc8 | B6: cmjfcc7rc001yzca63q4fhtkq | C6: cmjfcdhfg002fzca6yotpk8ei | D6: hybrid_v3_5_semantic | E6: Scenario_5 | F6: 0 | G6: affective_interface | H6: 0.1744 | I6: 0.33632972 | J6: 0.39349634 | K6: =J6-I6 -> 0.057166616 | L6: 0.76068069
A7: 64406fd5-e206-4f2b-acf7-3e994206acc8 | B7: cmjfcc7rc001yzca63q4fhtkq | C7: cmjfcdhfg002fzca6yotpk8ei | D7: hybrid_v3_5_semantic | E7: Scenario_5 | F7: 0 | G7: practicality_and_feasibility | H7: 0.1704 | I7: 0.3285472 | J7: 0.39606063 | K7: =J7-I7 -> 0.067513428 | L7: 0.76068069
A8: 64406fd5-e206-4f2b-acf7-3e994206acc8 | B8: cmjfcc7rc001yzca63q4fhtkq | C8: cmjfcdhfg002fzca6yotpk8ei | D8: hybrid_v3_5_semantic | E8: Scenario_5 | F8: 0 | G8: truth_and_fact | H8: 0.1 | I8: 0.21537633 | J8: 0.30463129 | K8: =J8-I8 -> 0.089254957 | L8: 0.76068069
A9: 7455051a-3913-4596-b455-5c27f289434c | B9: cmjfcept9002jzca66hlawohe | C9: cmjfcfcu80030zca6oecz16z7 | D9: hybrid_v3_5_semantic | E9: Scenario_5 | F9: 2 | G9: identity | H9: 0.1913 | I9: 0.35280545 | J9: 0.40622733 | K9: =J9-I9 -> 0.053421876 | L9: 0.7151545
A10: 7455051a-3913-4596-b455-5c27f289434c | B10: cmjfcept9002jzca66hlawohe | C10: cmjfcfcu80030zca6oecz16z7 | D10: hybrid_v3_5_semantic | E10: Scenario_5 | F10: 2 | G10: temporal_dynamics | H10: 0.1852 | I10: 0.34147864 | J10: 0.39395194 | K10: =J10-I10 -> 0.052473297 | L10: 0.7151545
A11: 7455051a-3913-4596-b455-5c27f289434c | B11: cmjfcept9002jzca66hlawohe | C11: cmjfcfcu80030zca6oecz16z7 | D11: hybrid_v3_5_semantic | E11: Scenario_5 | F11: 2 | G11: mathematics_computer_science_engineering | H11: 0.1839 | I11: 0.33908078 | J11: 0.3755855 | K11: =J11-I11 -> 0.036504715 | L11: 0.7151545
A12: 7455051a-3913-4596-b455-5c27f289434c | B12: cmjfcept9002jzca66hlawohe | C12: cmjfcfcu80030zca6oecz16z7 | D12: hybrid_v3_5_semantic | E12: Scenario_5 | F12: 2 | G12: practicality_and_feasibility | H12: 0.1709 | I12: 0.3151332 | J12: 0.39486947 | K12: =J12-I12 -> 0.079736265 | L12: 0.7151545
A13: 7455051a-3913-4596-b455-5c27f289434c | B13: cmjfcept9002jzca66hlawohe | C13: cmjfcfcu80030zca6oecz16z7 | D13: hybrid_v3_5_semantic | E13: Scenario_5 | F13: 2 | G13: metaphorical_scaffolding | H13: 0.1688 | I13: 0.31121867 | J13: 0.37799185 | K13: =J13-I13 -> 0.066773181 | L13: 0.7151545
A14: 7455051a-3913-4596-b455-5c27f289434c | B14: cmjfcept9002jzca66hlawohe | C14: cmjfcfcu80030zca6oecz16z7 | D14: hybrid_v3_5_semantic | E14: Scenario_5 | F14: 2 | G14: truth_and_fact | H14: 0.1 | I14: 0.2276052 | J14: 0.33499859 | K14: =J14-I14 -> 0.10739339 | L14: 0.7151545
... A152: 42978fac-a1a4-4b68-b28a-4786480797c5 | B152: cmjfdkjo000fyzca6jcbgnt1w | C152: cmjfdkz3i00gfzca6xstfy63b | D152: hybrid_v3_5_semantic | E152: Scenario_5 | F152: 48 | G152: metaphorical_scaffolding | H152: 0.154 | I152: 0.33791348 | J152: 0.37274832 | K152: =J152-I152 -> 0.034834838 | L152: 0.70142641

Sheet notes
A1: p calculation
A3: 1. count | B3: =scen5_hybsem!P2 -> 150
A4: 2. t statistic | B4: =B10*SQRT((B3-2)/(1-B10^2)) -> -4.4097223
A5: 3. p | B5: =_xlfn.T.DIST.2T(ABS(B4),B3-2) -> 1.9793024e-05
A9: count | B9: correlation weights / activation delta
A10: =B3 -> 150 | B10: =scen5_hybsem!R2 -> -0.34078016

Sheet actdel_prompt_response
A2: Prompt-response
A3: Turn | B3: hybsem
A4: 1 | B4: 0.76068069
A5: 2 | B5: 0.7151545
A6: 3 | B6: 0.72734735
A7: 4 | B7: 0.7330552
A8: 5 | B8: 0.80006557
A9: 6 | B9: 0.7090712
A10: 7 | B10: 0.7749469
A11: 8 | B11: 0.75158773
A12: 9 | B12: 0.71546563
A13: 10 | B13: 0.79344326
A14: 11 | B14: 0.7308636
A15: 12 | B15: 0.78662473
... A28: 25 | B28: 0.70142641

Sheet inter_system_stats
B2: prompt_to_response
A3: Turn | B3: hybsem | C3: control | E3: std.hybsem | F3: std. Control | G3: F. test | H3: T. Test equal variances | I3: T.Test unequal | J3: Mean difference | K3: Average scen | L3: Average Control
A4: 1 | B4: 0.76068069 | C4: 0.75451957 | E4: =_xlfn.STDEV.S(B4:B28) -> 0.035344552 | F4: =_xlfn.STDEV.S(C4:C28) -> 0.070588432 | G4: =_xlfn.F.TEST(B4:B28,C4:C28) -> 0.001221091 | H4: =_xlfn.T.TEST(B4:B28, C4:C28, 2,2) -> 1.8660508e-07 | I4: =_xlfn.T.TEST(B4:B28,C4:C28, 2,3) -> 5.7771037e-07 | J4: =AVERAGE(B4:B28)-AVERAGE(C4:C28) -> 0.096057016 | K4: =AVERAGE(B4:B28) -> 0.73111256 | L4: =AVERAGE(C4:C28) -> 0.63505555
A5: 2 | B5: 0.7151545 | C5: 0.58315782
A6: 3 | B6: 0.72734735 | C6: 0.61890492
A7: 4 | B7: 0.7330552 | C7: 0.74737712
A8: 5 | B8: 0.80006557 | C8: 0.54898023
A9: 6 | B9: 0.7090712 | C9: 0.63269023
A10: 7 | B10: 0.7749469 | C10: 0.70178677
A11: 8 | B11: 0.75158773 | C11: 0.58456232
A12: 9 | B12: 0.71546563 | C12: 0.63553024
A13: 10 | B13: 0.79344326 | C13: 0.69186078
A14: 11 | B14: 0.7308636 | C14: 0.74687441
A15: 12 | B15: 0.78662473 | C15: 0.64610334
A16: 13 | B16: 0.68681634 | C16: 0.71426745
... A28: 25 | B28: 0.70142641 | C28: 0.51286959
A32: General
A34: Turn | B34: ac15p | C34: hybrid | D34: hybsem | F34: ANOVA - Single Factor
A35: 1 | B35: 0.77595367 | C35: 0.74885829 | D35: 0.76068069 | F35: Alpha | G35: 0.05
A36: 2 | B36: 0.74238116 | C36: 0.75950632 | D36: 0.7151545
A37: 3 | B37: 0.71959451 | C37: 0.71541388 | D37: 0.72734735 | F37: Groups | G37: Count | H37: Sum | I37: Mean | J37: Variance
A38: 4 | B38: 0.74468578 | C38: 0.75834839 | D38: 0.7330552 | F38: Column 1 | G38: =COUNT(inter_system_stats!$B$34:$B$59) -> 25 | H38: =SUM(inter_system_stats!$B$34:$B$59) -> 18.309276 | I38: =AVERAGE(inter_system_stats!$B$34:$B$59) -> 0.73237105 | J38: =VAR(inter_system_stats!$B$34:$B$59) -> 0.0021075812
A39: 5 | B39: 0.81047209 | C39: 0.81056506 | D39: 0.80006557 | F39: Column 2 | G39: =COUNT(inter_system_stats!$C$34:$C$59) -> 25 | H39: =SUM(inter_system_stats!$C$34:$C$59) -> 18.309431 | I39: =AVERAGE(inter_system_stats!$C$34:$C$59) -> 0.73237725 | J39: =VAR(inter_system_stats!$C$34:$C$59) -> 0.0015741888
A40: 6 | B40: 0.72631626 | C40: 0.74228911 | D40: 0.7090712 | F40: Column 3 | G40: =COUNT(inter_system_stats!$D$34:$D$59) -> 25 | H40: =SUM(inter_system_stats!$D$34:$D$59) -> 18.277814 | I40: =AVERAGE(inter_system_stats!$D$34:$D$59) -> 0.73111256 | J40: =VAR(inter_system_stats!$D$34:$D$59) -> 0.0012492374
A41: 7 | B41: 0.79321544 | C41: 0.76425064 | D41: 0.7749469
A42: 8 | B42: 0.70459928 | C42: 0.69857772 | D42: 0.75158773 | F42: Source of Variation | G42: SS | H42: df | I42: MS | J42: F | K42: P-value | L42: F critical
A43: 9 | B43: 0.75323189 | C43: 0.76611524 | D43: 0.71546563 | F43: Between Groups | G43: =SUMPRODUCT(inter_system_stats!$H$38:$H$40,inter_system_stats!$I$38:$I$40)-SUM(inter_system_stats!$H$38:$H$40)^2/SUM(inter_system_stats!$G$38:$G$40) -> 2.6526922e-05 | H43: =COUNT(inter_system_stats!$H$38:$H$40)-1 -> 2 | I43: =inter_system_stats!$G$43 / inter_system_stats!$H$43 -> 1.3263461e-05 | J43: =inter_system_stats!$I$43 / inter_system_stats!$I$44 -> 0.0080694227 | K43: =FDIST(inter_system_stats!$J$43, inter_system_stats!$H$43, inter_system_stats!$H$44) -> 0.99196394 | L43: =FINV(inter_system_stats!$G$35, inter_system_stats!$H$43, inter_system_stats!$H$44) -> 3.1239074
A44: 10 | B44: 0.78691806 | C44: 0.7779242 | D44: 0.79344326 | F44: Within Groups | G44: =SUM(DEVSQ(inter_system_stats!$B$34:$B$59),DEVSQ(inter_system_stats!$C$34:$C$59),DEVSQ(inter_system_stats!$D$34:$D$59)) -> 0.11834418 | H44: =SUM(inter_system_stats!$G$38:$G$40)-COUNT(inter_system_stats!$G$38:$G$40) -> 72 | I44: =inter_system_stats!$G$44 / inter_system_stats!$H$44 -> 0.0016436691
A45: 11 | B45: 0.75773765 | C45: 0.73133786 | D45: 0.7308636 | F45: Total | G45: =DEVSQ(inter_system_stats!$B$34:$B$59,inter_system_stats!$C$34:$C$59,inter_system_stats!$D$34:$D$59) -> 0.1183707 | H45: =SUM(inter_system_stats!$G$38:$G$40) - 1 -> 74
A46: 12 | B46: 0.79048878 | C46: 0.76164459 | D46: 0.78662473
A47: 13 | B47: 0.69218774 | C47: 0.71942937 | D47: 0.68681634
A48: 14 | B48: 0.68937987 | C48: 0.67864551 | D48: 0.71841036
A49: 15 | B49: 0.76978674 | C49: 0.70496101 | D49: 0.74443367
A50: 16 | B50: 0.78421202 | C50: 0.70120829 | D50: 0.71776466
A51: 17 | B51: 0.74172531 | C51: 0.79001392 | D51: 0.73744757
A52: 18 | B52: 0.71842175 | C52: 0.717786 | D52: 0.70059154
A53: 19 | B53: 0.67659873 | C53: 0.70476772 | D53: 0.67893025
A54: 20 | B54: 0.62907881 | C54: 0.73180489 | D54: 0.69624312
A55: 21 | B55: 0.71642667 | C55: 0.76689669 | D55: 0.75149547
A56: 22 | B56: 0.67103092 | C56: 0.62802587 | D56: 0.66012396
...
