Workbook

Sheet scen4_hybsem
A1: turnId | B1: user_id | C1: assistant_id | D1: projectName | E1: sessionName | F1: seq | G1: anchorName | H1: weight | I1: promptSim | J1: responseSim | K1: activation delta | L1: prompt_to_response | P1: count | Q1: average activation delta | R1: correlation weights / activation delta | S1: p
P2: =COUNT(K3:K149) -> 147 | Q2: =AVERAGE(K3:K149) -> 0.048938143 | R2: =CORREL(H3:H149,K3:K149) -> -0.0044933836 | S2: 0.96
A3: b6424ab5-3810-4821-bb37-705e70e16d51 | B3: cmjclnfno001uzcp2y4zd603d | C3: cmjclob32002bzcp2kgfwh6r4 | D3: hybrid_v3_5_semantic | E3: Scenario_4 | F3: 0 | G3: practicality_and_feasibility | H3: 0.1996 | I3: 0.31919207 | J3: 0.39988586 | K3: =J3-I3 -> 0.080693792 | L3: 0.80285811
A4: b6424ab5-3810-4821-bb37-705e70e16d51 | B4: cmjclnfno001uzcp2y4zd603d | C4: cmjclob32002bzcp2kgfwh6r4 | D4: hybrid_v3_5_semantic | E4: Scenario_4 | F4: 0 | G4: identity | H4: 0.1924 | I4: 0.3077256 | J4: 0.34522631 | K4: =J4-I4 -> 0.037500709 | L4: 0.80285811
A5: b6424ab5-3810-4821-bb37-705e70e16d51 | B5: cmjclnfno001uzcp2y4zd603d | C5: cmjclob32002bzcp2kgfwh6r4 | D5: hybrid_v3_5_semantic | E5: Scenario_4 | F5: 0 | G5: imagination_and_possibility | H5: 0.1764 | I5: 0.28204835 | J5: 0.34245348 | K5: =J5-I5 -> 0.060405137 | L5: 0.80285811
A6: b6424ab5-3810-4821-bb37-705e70e16d51 | B6: cmjclnfno001uzcp2y4zd603d | C6: cmjclob32002bzcp2kgfwh6r4 | D6: hybrid_v3_5_semantic | E6: Scenario_4 | F6: 0 | G6: mathematics_computer_science_engineering | H6: 0.172 | I6: 0.27496751 | J6: 0.30377587 | K6: =J6-I6 -> 0.028808353 | L6: 0.80285811
A7: b6424ab5-3810-4821-bb37-705e70e16d51 | B7: cmjclnfno001uzcp2y4zd603d | C7: cmjclob32002bzcp2kgfwh6r4 | D7: hybrid_v3_5_semantic | E7: Scenario_4 | F7: 0 | G7: affective_interface | H7: 0.1596 | I7: 0.25524899 | J7: 0.3566101 | K7: =J7-I7 -> 0.10136111 | L7: 0.80285811
A8: b6424ab5-3810-4821-bb37-705e70e16d51 | B8: cmjclnfno001uzcp2y4zd603d | C8: cmjclob32002bzcp2kgfwh6r4 | D8: hybrid_v3_5_semantic | E8: Scenario_4 | F8: 0 | G8: truth_and_fact | H8: 0.1 | I8: 0.18893565 | J8: 0.23096243 | K8: =J8-I8 -> 0.042026786 | L8: 0.80285811
A9: 9c65cf22-8589-4aa1-898c-056765a7583a | B9: cmjclogln002fzcp227r5aikc | C9: cmjclp4gl002wzcp2r169mt0v | D9: hybrid_v3_5_semantic | E9: Scenario_4 | F9: 2 | G9: practicality_and_feasibility | H9: 0.2092 | I9: 0.38043295 | J9: 0.39495164 | K9: =J9-I9 -> 0.014518694 | L9: 0.72383072
A10: 9c65cf22-8589-4aa1-898c-056765a7583a | B10: cmjclogln002fzcp227r5aikc | C10: cmjclp4gl002wzcp2r169mt0v | D10: hybrid_v3_5_semantic | E10: Scenario_4 | F10: 2 | G10: identity | H10: 0.1824 | I10: 0.33162713 | J10: 0.33461714 | K10: =J10-I10 -> 0.0029900061 | L10: 0.72383072
A11: 9c65cf22-8589-4aa1-898c-056765a7583a | B11: cmjclogln002fzcp227r5aikc | C11: cmjclp4gl002wzcp2r169mt0v | D11: hybrid_v3_5_semantic | E11: Scenario_4 | F11: 2 | G11: affective_interface | H11: 0.1775 | I11: 0.3227019 | J11: 0.39458542 | K11: =J11-I11 -> 0.071883523 | L11: 0.72383072
A12: 9c65cf22-8589-4aa1-898c-056765a7583a | B12: cmjclogln002fzcp227r5aikc | C12: cmjclp4gl002wzcp2r169mt0v | D12: hybrid_v3_5_semantic | E12: Scenario_4 | F12: 2 | G12: imagination_and_possibility | H12: 0.1678 | I12: 0.30502905 | J12: 0.3426805 | K12: =J12-I12 -> 0.037651446 | L12: 0.72383072
A13: 9c65cf22-8589-4aa1-898c-056765a7583a | B13: cmjclogln002fzcp227r5aikc | C13: cmjclp4gl002wzcp2r169mt0v | D13: hybrid_v3_5_semantic | E13: Scenario_4 | F13: 2 | G13: mathematics_computer_science_engineering | H13: 0.1632 | I13: 0.29666184 | J13: 0.32512862 | K13: =J13-I13 -> 0.028466785 | L13: 0.72383072
A14: 9c65cf22-8589-4aa1-898c-056765a7583a | B14: cmjclogln002fzcp227r5aikc | C14: cmjclp4gl002wzcp2r169mt0v | D14: hybrid_v3_5_semantic | E14: Scenario_4 | F14: 2 | G14: truth_and_fact | H14: 0.1 | I14: 0.23232463 | J14: 0.30486146 | K14: =J14-I14 -> 0.072536831 | L14: 0.72383072
... A149: 0d76a0d0-8301-4ad8-b886-59fddb4a1e75 | B149: cmjcmcfzl00fuzcp2r915meev | C149: cmjcmcss800gbzcp2lw20djco | D149: hybrid_v3_5_semantic | E149: Scenario_4 | F149: 48 | G149: truth_and_fact | H149: 0.1 | I149: 0.19612342 | J149: 0.21569909 | K149: =J149-I149 -> 0.019575676 | L149: 0.74873273

Sheet notes
A1: p calculation
A3: 1. count | B3: =scen4_hybsem!P2 -> 147
A4: 2. t statistic | B4: =B10*SQRT((B3-2)/(1-B10^2)) -> -0.05410805
A5: 3. p | B5: =_xlfn.T.DIST.2T(ABS(B4),B3-2) -> 0.95692356
A9: count | B9: correlation weights / activation delta
A10: =B3 -> 147 | B10: =scen4_hybsem!R2 -> -0.0044933836

Sheet actdel_prompt_response
B2: Prompt-response
A3: Turn | B3: hybsem
A4: 1 | B4: 0.80285811
A5: 2 | B5: 0.72383072
A6: 3 | B6: 0.72009692
A7: 4 | B7: 0.74456365
A8: 5 | B8: 0.67114667
A9: 6 | B9: 0.74069871
A10: 7 | B10: 0.77377244
A11: 8 | B11: 0.66913129
A12: 9 | B12: 0.76936358
A13: 10 | B13: 0.7953936
A14: 11 | B14: 0.75028001
A15: 12 | B15: 0.79111205
... A28: 25 | B28: 0.74873273

Sheet inter_system_stats
B2: prompt_to_response
A3: Turn | B3: hybsem | C3: control | E3: std.ac15 | F3: std. Control | G3: F. test | H3: T. Test equal variances | I3: T.Test unequal | J3: Mean difference | K3: Average scenario | L3: Average control
A4: 1 | B4: 0.80285811 | C4: 0.82062035 | E4: =_xlfn.STDEV.S(B4:B28) -> 0.054538342 | F4: =_xlfn.STDEV.S(C4:C28) -> 0.083848556 | G4: =_xlfn.F.TEST(B4:B28,C4:C28) -> 0.039906432 | H4: =_xlfn.T.TEST(B4:B28, C4:C28, 2,2) -> 1.4604213e-05 | I4: =_xlfn.T.TEST(B4:B28,C4:C28, 2,3) -> 1.9464309e-05 | J4: =AVERAGE(B4:B28)-AVERAGE(C4:C28) -> 0.096519133 | K4: =AVERAGE(B4:B28) -> 0.73859107 | L4: =AVERAGE(C4:C28) -> 0.64207194
A5: 2 | B5: 0.72383072 | C5: 0.67785078
A6: 3 | B6: 0.72009692 | C6: 0.67795229
A7: 4 | B7: 0.74456365 | C7: 0.66135317
A8: 5 | B8: 0.67114667 | C8: 0.59399104
A9: 6 | B9: 0.74069871 | C9: 0.6086453
A10: 7 | B10: 0.77377244 | C10: 0.57481882
A11: 8 | B11: 0.66913129 | C11: 0.52225005
A12: 9 | B12: 0.76936358 | C12: 0.76343563
A13: 10 | B13: 0.7953936 | C13: 0.6903629
A14: 11 | B14: 0.75028001 | C14: 0.66961631
A15: 12 | B15: 0.79111205 | C15: 0.75051558
A16: 13 | B16: 0.68490072 | C16: 0.70922297
... A28: 25 | B28: 0.74873273 | C28: 0.62965658
A32: General
A34: Turn | B34: ac15p | C34: hybrid | D34: hybsem | F34: ANOVA - Single Factor
A35: 1 | B35: 0.78294334 | C35: 0.79629877 | D35: 0.80285811 | F35: Alpha | G35: 0.05
A36: 2 | B36: 0.72616788 | C36: 0.73955855 | D36: 0.72383072
A37: 3 | B37: 0.76238484 | C37: 0.7395449 | D37: 0.72009692 | F37: Groups | G37: Count | H37: Sum | I37: Mean | J37: Variance
A38: 4 | B38: 0.70329396 | C38: 0.74302939 | D38: 0.74456365 | F38: Column 1 | G38: =COUNT(inter_system_stats!$B$34:$B$59) -> 25 | H38: =SUM(inter_system_stats!$B$34:$B$59) -> 18.362259 | I38: =AVERAGE(inter_system_stats!$B$34:$B$59) -> 0.73449037 | J38: =VAR(inter_system_stats!$B$34:$B$59) -> 0.0034118332
A39: 5 | B39: 0.7296907 | C39: 0.72550205 | D39: 0.67114667 | F39: Column 2 | G39: =COUNT(inter_system_stats!$C$34:$C$59) -> 25 | H39: =SUM(inter_system_stats!$C$34:$C$59) -> 18.19339 | I39: =AVERAGE(inter_system_stats!$C$34:$C$59) -> 0.72773559 | J39: =VAR(inter_system_stats!$C$34:$C$59) -> 0.0041595685
A40: 6 | B40: 0.75207613 | C40: 0.74855685 | D40: 0.74069871 | F40: Column 3 | G40: =COUNT(inter_system_stats!$D$34:$D$59) -> 25 | H40: =SUM(inter_system_stats!$D$34:$D$59) -> 18.464777 | I40: =AVERAGE(inter_system_stats!$D$34:$D$59) -> 0.73859107 | J40: =VAR(inter_system_stats!$D$34:$D$59) -> 0.0029744307
A41: 7 | B41: 0.81177256 | C41: 0.73413847 | D41: 0.77377244
A42: 8 | B42: 0.71832924 | C42: 0.66870134 | D42: 0.66913129 | F42: Source of Variation | G42: SS | H42: df | I42: MS | J42: F | K42: P-value | L42: F critical
A43: 9 | B43: 0.75089851 | C43: 0.78688004 | D43: 0.76936358 | F43: Between Groups | G43: =SUMPRODUCT(inter_system_stats!$H$38:$H$40,inter_system_stats!$I$38:$I$40)-SUM(inter_system_stats!$H$38:$H$40)^2/SUM(inter_system_stats!$G$38:$G$40) -> 0.0015023687 | H43: =COUNT(inter_system_stats!$H$38:$H$40)-1 -> 2 | I43: =inter_system_stats!$G$43 / inter_system_stats!$H$43 -> 0.00075118433 | J43: =inter_system_stats!$I$43 / inter_system_stats!$I$44 -> 0.21369133 | K43: =FDIST(inter_system_stats!$J$43, inter_system_stats!$H$43, inter_system_stats!$H$44) -> 0.80810797 | L43: =FINV(inter_system_stats!$G$35, inter_system_stats!$H$43, inter_system_stats!$H$44) -> 3.1239074
A44: 10 | B44: 0.71233537 | C44: 0.80994866 | D44: 0.7953936 | F44: Within Groups | G44: =SUM(DEVSQ(inter_system_stats!$B$34:$B$59),DEVSQ(inter_system_stats!$C$34:$C$59),DEVSQ(inter_system_stats!$D$34:$D$59)) -> 0.25309998 | H44: =SUM(inter_system_stats!$G$38:$G$40)-COUNT(inter_system_stats!$G$38:$G$40) -> 72 | I44: =inter_system_stats!$G$44 / inter_system_stats!$H$44 -> 0.0035152775
A45: 11 | B45: 0.77617003 | C45: 0.69017189 | D45: 0.75028001 | F45: Total | G45: =DEVSQ(inter_system_stats!$B$34:$B$59,inter_system_stats!$C$34:$C$59,inter_system_stats!$D$34:$D$59) -> 0.25460235 | H45: =SUM(inter_system_stats!$G$38:$G$40) - 1 -> 74
A46: 12 | B46: 0.77041801 | C46: 0.74912535 | D46: 0.79111205
A47: 13 | B47: 0.68718184 | C47: 0.67748078 | D47: 0.68490072
A48: 14 | B48: 0.81381365 | C48: 0.79291905 | D48: 0.81196411
A49: 15 | B49: 0.78154173 | C49: 0.80088441 | D49: 0.79331545
A50: 16 | B50: 0.67997326 | C50: 0.64539917 | D50: 0.67762274
A51: 17 | B51: 0.80453974 | C51: 0.77301622 | D51: 0.77509055
A52: 18 | B52: 0.57578838 | C52: 0.58304544 | D52: 0.6089102
A53: 19 | B53: 0.80829344 | C53: 0.7954812 | D53: 0.81633901
A54: 20 | B54: 0.6310987 | C54: 0.65250777 | D54: 0.67591292
A55: 21 | B55: 0.72352146 | C55: 0.6134279 | D55: 0.74812573
A56: 22 | B56: 0.66763609 | C56: 0.65699942 | D56: 0.66618629
...
