Workbook

Sheet scen8_hybsem
A1: turnId | B1: user_id | C1: assistant_id | D1: projectName | E1: sessionName | F1: seq | G1: anchorName | H1: weight | I1: promptSim | J1: responseSim | K1: activation delta | L1: prompt_to_response | P1: count | Q1: activation delta average | R1: correlation weights / activation delta | S1: p
P2: =COUNT(K3:K134) -> 132 | Q2: =AVERAGE(K3:K134) -> 0.065233247 | R2: =CORREL(H3:H134,K3:K134) -> 0.36240036 | S2: =Notes!B5 -> 1.9534765e-05
A3: e9ed59b3-d3bd-4ee1-9668-7ff32d86e509 | B3: cmjl4tcpd018nzccmskh4l9lh | C3: cmjl4u25z0194zccmkra079u3 | D3: hybrid_v3_5_semantic | E3: Scenario_8 | F3: 0 | G3: affective_interface | H3: 0.9 | I3: 0.23708271 | J3: 0.44273425 | K3: =J3-I3 -> 0.20565154 | L3: 0.72612266
A4: e9ed59b3-d3bd-4ee1-9668-7ff32d86e509 | B4: cmjl4tcpd018nzccmskh4l9lh | C4: cmjl4u25z0194zccmkra079u3 | D4: hybrid_v3_5_semantic | E4: Scenario_8 | F4: 0 | G4: truth_and_fact | H4: 0.1 | I4: 0.15885141 | J4: 0.30435158 | K4: =J4-I4 -> 0.14550017 | L4: 0.72612266
A5: e0460eb6-7ea8-4f22-9b6d-9dc7895c8064 | B5: cmjl4udvo0198zccmb7y5fc78 | C5: cmjl4uulr019pzccmdut85twc | D5: hybrid_v3_5_semantic | E5: Scenario_8 | F5: 2 | G5: affective_interface | H5: 0.9 | I5: 0.2816758 | J5: 0.43511607 | K5: =J5-I5 -> 0.15344027 | L5: 0.74438797
A6: e0460eb6-7ea8-4f22-9b6d-9dc7895c8064 | B6: cmjl4udvo0198zccmb7y5fc78 | C6: cmjl4uulr019pzccmdut85twc | D6: hybrid_v3_5_semantic | E6: Scenario_8 | F6: 2 | G6: truth_and_fact | H6: 0.1 | I6: 0.17377922 | J6: 0.27367825 | K6: =J6-I6 -> 0.099899031 | L6: 0.74438797
A7: 7c8dcc05-cd0d-4f4f-94e2-c1a1591f94b3 | B7: cmjl4vqp5019tzccm0unwetv4 | C7: cmjl4w2np01aazccmxrxgaa7a | D7: hybrid_v3_5_semantic | E7: Scenario_8 | F7: 4 | G7: affective_interface | H7: 0.3676 | I7: 0.29836182 | J7: 0.45071666 | K7: =J7-I7 -> 0.15235485 | L7: 0.72244326
A8: 7c8dcc05-cd0d-4f4f-94e2-c1a1591f94b3 | B8: cmjl4vqp5019tzccm0unwetv4 | C8: cmjl4w2np01aazccmxrxgaa7a | D8: hybrid_v3_5_semantic | E8: Scenario_8 | F8: 4 | G8: practicality_and_feasibility | H8: 0.2716 | I8: 0.22040213 | J8: 0.33916208 | K8: =J8-I8 -> 0.11875995 | L8: 0.72244326
A9: 7c8dcc05-cd0d-4f4f-94e2-c1a1591f94b3 | B9: cmjl4vqp5019tzccm0unwetv4 | C9: cmjl4w2np01aazccmxrxgaa7a | D9: hybrid_v3_5_semantic | E9: Scenario_8 | F9: 4 | G9: imagination_and_possibility | H9: 0.2608 | I9: 0.2116209 | J9: 0.30229994 | K9: =J9-I9 -> 0.090679034 | L9: 0.72244326
A10: 7c8dcc05-cd0d-4f4f-94e2-c1a1591f94b3 | B10: cmjl4vqp5019tzccm0unwetv4 | C10: cmjl4w2np01aazccmxrxgaa7a | D10: hybrid_v3_5_semantic | E10: Scenario_8 | F10: 4 | G10: truth_and_fact | H10: 0.1 | I10: 0.18782334 | J10: 0.29874458 | K10: =J10-I10 -> 0.11092124 | L10: 0.72244326
A11: 0d44430f-2b08-4d2d-96df-0a907f71ea12 | B11: cmjl4x8wj01aezccm0f2hvk9s | C11: cmjl4xqtc01avzccmqckw3k49 | D11: hybrid_v3_5_semantic | E11: Scenario_8 | F11: 6 | G11: affective_interface | H11: 0.2671 | I11: 0.33521328 | J11: 0.43497406 | K11: =J11-I11 -> 0.099760774 | L11: 0.70607009
A12: 0d44430f-2b08-4d2d-96df-0a907f71ea12 | B12: cmjl4x8wj01aezccm0f2hvk9s | C12: cmjl4xqtc01avzccmqckw3k49 | D12: hybrid_v3_5_semantic | E12: Scenario_8 | F12: 6 | G12: practicality_and_feasibility | H12: 0.1987 | I12: 0.24932945 | J12: 0.33600421 | K12: =J12-I12 -> 0.086674759 | L12: 0.70607009
A13: 0d44430f-2b08-4d2d-96df-0a907f71ea12 | B13: cmjl4x8wj01aezccm0f2hvk9s | C13: cmjl4xqtc01avzccmqckw3k49 | D13: hybrid_v3_5_semantic | E13: Scenario_8 | F13: 6 | G13: truth_and_fact | H13: 0.1885 | I13: 0.2364885 | J13: 0.36399207 | K13: =J13-I13 -> 0.12750358 | L13: 0.70607009
A14: 0d44430f-2b08-4d2d-96df-0a907f71ea12 | B14: cmjl4x8wj01aezccm0f2hvk9s | C14: cmjl4xqtc01avzccmqckw3k49 | D14: hybrid_v3_5_semantic | E14: Scenario_8 | F14: 6 | G14: imagination_and_possibility | H14: 0.1789 | I14: 0.22444572 | J14: 0.32857789 | K14: =J14-I14 -> 0.10413217 | L14: 0.70607009
... A134: 127ef0d0-4bcf-4d65-b456-415e474a0b86 | B134: cmjl5dlsv01mnzccmwdjgi5p8 | C134: cmjl5dwxh01n4zccmv0xesvmu | D134: hybrid_v3_5_semantic | E134: Scenario_8 | F134: 48 | G134: truth_and_fact | H134: 0.1 | I134: 0.25131713 | J134: 0.31137051 | K134: =J134-I134 -> 0.060053384 | L134: 0.73470637

Sheet Notes
A1: p calculation
A3: 1. count | B3: =scen8_hybsem!P2 -> 132
A4: 2. t statistic | B4: =B10*SQRT((B3-2)/(1-B10^2)) -> 4.4333691
A5: 3. p | B5: =_xlfn.T.DIST.2T(ABS(B4),B3-2) -> 1.9534765e-05
A9: count | B9: correlation weights / activation delta
A10: =B3 -> 132 | B10: =scen8_hybsem!R2 -> 0.36240036

Sheet actdel_prompt_response
A1: Prompt-response
A2: Turn | B2: hybsem
A3: 1 | B3: 0.72612266
A4: 2 | B4: 0.74438797
A5: 3 | B5: 0.72244326
A6: 4 | B6: 0.70607009
A7: 5 | B7: 0.83046527
A8: 6 | B8: 0.63935057
A9: 7 | B9: 0.74569214
A10: 8 | B10: 0.7775837
A11: 9 | B11: 0.71622198
A12: 10 | B12: 0.78949018
A13: 11 | B13: 0.73775481
A14: 12 | B14: 0.74693269
... A27: 25 | B27: 0.73470637

Sheet inter_system_stats
A1: Prompt-response
A2: Turn | B2: hybsem | C2: control | E2: std. Hybsem | F2: std. Control | G2: F. test | H2: T. Test equal variances | I2: T.Test unequal | J2: Mean difference | K2: Mean hybsem | L2: Mean control
A3: 1 | B3: 0.72612266 | C3: 0.77181473 | E3: =_xlfn.STDEV.S(B3:B27) -> 0.040738975 | F3: =_xlfn.STDEV.S(C3:C27) -> 0.077480319 | G3: =_xlfn.F.TEST(B3:B27,C3:C27) -> 0.0025335853 | H3: =_xlfn.T.TEST(B3:B27, C3:C27, 2,2) -> 1.365526e-06 | I3: =_xlfn.T.TEST(B3:B27,C3:C27, 2,3) -> 3.0048415e-06 | J3: =AVERAGE(B3:B27)-AVERAGE(C3:C27) -> 0.096563371 | K3: =AVERAGE(B3:B27) -> 0.73834409 | L3: =AVERAGE(C3:C27) -> 0.64178072
A4: 2 | B4: 0.74438797 | C4: 0.58574872
A5: 3 | B5: 0.72244326 | C5: 0.59442253
A6: 4 | B6: 0.70607009 | C6: 0.60678637
A7: 5 | B7: 0.83046527 | C7: 0.69941561
A8: 6 | B8: 0.63935057 | C8: 0.58498361
A9: 7 | B9: 0.74569214 | C9: 0.5234345
A10: 8 | B10: 0.7775837 | C10: 0.73317738
A11: 9 | B11: 0.71622198 | C11: 0.62302935
A12: 10 | B12: 0.78949018 | C12: 0.56912644
A13: 11 | B13: 0.73775481 | C13: 0.71261685
A14: 12 | B14: 0.74693269 | C14: 0.62399467
A15: 13 | B15: 0.7432118 | C15: 0.70817517
... A27: 25 | B27: 0.73470637 | C27: 0.63735102
A30: General
A32: Turn | B32: ac15p | C32: hybrid | D32: hybsem | F32: ANOVA - Single Factor
A33: 1 | B33: 0.74689963 | C33: 0.7534273 | D33: 0.72612266 | F33: Alpha | G33: 0.05
A34: 2 | B34: 0.76044077 | C34: 0.76537158 | D34: 0.74438797
A35: 3 | B35: 0.7454261 | C35: 0.75306867 | D35: 0.72244326 | F35: Groups | G35: Count | H35: Sum | I35: Mean | J35: Variance
A36: 4 | B36: 0.75451829 | C36: 0.73318408 | D36: 0.70607009 | F36: Column 1 | G36: =COUNT(inter_system_stats!$A$32:$A$57) -> 25 | H36: =SUM(inter_system_stats!$A$32:$A$57) -> 325 | I36: =AVERAGE(inter_system_stats!$A$32:$A$57) -> 13 | J36: =VAR(inter_system_stats!$A$32:$A$57) -> 54.166667
A37: 5 | B37: 0.81871695 | C37: 0.83979766 | D37: 0.83046527 | F37: Column 2 | G37: =COUNT(inter_system_stats!$B$32:$B$57) -> 25 | H37: =SUM(inter_system_stats!$B$32:$B$57) -> 18.551522 | I37: =AVERAGE(inter_system_stats!$B$32:$B$57) -> 0.74206089 | J37: =VAR(inter_system_stats!$B$32:$B$57) -> 0.0023570201
A38: 6 | B38: 0.66147537 | C38: 0.62076408 | D38: 0.63935057 | F38: Column 3 | G38: =COUNT(inter_system_stats!$C$32:$C$57) -> 25 | H38: =SUM(inter_system_stats!$C$32:$C$57) -> 18.601632 | I38: =AVERAGE(inter_system_stats!$C$32:$C$57) -> 0.7440653 | J38: =VAR(inter_system_stats!$C$32:$C$57) -> 0.0024830668
A39: 7 | B39: 0.70483109 | C39: 0.70824915 | D39: 0.74569214 | F39: Column 4 | G39: =COUNT(inter_system_stats!$D$32:$D$57) -> 25 | H39: =SUM(inter_system_stats!$D$32:$D$57) -> 18.458602 | I39: =AVERAGE(inter_system_stats!$D$32:$D$57) -> 0.73834409 | J39: =VAR(inter_system_stats!$D$32:$D$57) -> 0.0016596641
A40: 8 | B40: 0.77544567 | C40: 0.81183171 | D40: 0.7775837
A41: 9 | B41: 0.73492259 | C41: 0.71788979 | D41: 0.71622198 | F41: Source of Variation | G41: SS | H41: df | I41: MS | J41: F | K41: P-value | L41: F critical
A42: 10 | B42: 0.80955347 | C42: 0.82670674 | D42: 0.78949018 | F42: Between Groups | G42: =SUMPRODUCT(inter_system_stats!$H$36:$H$39,inter_system_stats!$I$36:$I$39)-SUM(inter_system_stats!$H$36:$H$39)^2/SUM(inter_system_stats!$G$36:$G$39) -> 2817.5829 | H42: =COUNT(inter_system_stats!$H$36:$H$39)-1 -> 3 | I42: =inter_system_stats!$G$42 / inter_system_stats!$H$42 -> 939.1943 | J42: =inter_system_stats!$I$42 / inter_system_stats!$I$43 -> 69.347565 | K42: =FDIST(inter_system_stats!$J$42, inter_system_stats!$H$42, inter_system_stats!$H$43) -> 6.0847767e-24 | L42: =FINV(inter_system_stats!$G$33, inter_system_stats!$H$42, inter_system_stats!$H$43) -> 2.6993926
A43: 11 | B43: 0.73619363 | C43: 0.7515872 | D43: 0.73775481 | F43: Within Groups | G43: =SUM(DEVSQ(inter_system_stats!$A$32:$A$57),DEVSQ(inter_system_stats!$B$32:$B$57),DEVSQ(inter_system_stats!$C$32:$C$57),DEVSQ(inter_system_stats!$D$32:$D$57)) -> 1300.156 | H43: =SUM(inter_system_stats!$G$36:$G$39)-COUNT(inter_system_stats!$G$36:$G$39) -> 96 | I43: =inter_system_stats!$G$43 / inter_system_stats!$H$43 -> 13.543292
A44: 12 | B44: 0.76045069 | C44: 0.76757629 | D44: 0.74693269 | F44: Total | G44: =DEVSQ(inter_system_stats!$A$32:$A$57,inter_system_stats!$B$32:$B$57,inter_system_stats!$C$32:$C$57,inter_system_stats!$D$32:$D$57) -> 4117.7389 | H44: =SUM(inter_system_stats!$G$36:$G$39) - 1 -> 99
A45: 13 | B45: 0.78341715 | C45: 0.7747223 | D45: 0.7432118
A46: 14 | B46: 0.73635141 | C46: 0.714364 | D46: 0.75356616
A47: 15 | B47: 0.69516465 | C47: 0.71442988 | D47: 0.67957361
A48: 16 | B48: 0.75366371 | C48: 0.73057533 | D48: 0.73260677
A49: 17 | B49: 0.75925493 | C49: 0.73176737 | D49: 0.75054669
A50: 18 | B50: 0.74400179 | C50: 0.71592458 | D50: 0.73764676
A51: 19 | B51: 0.77774572 | C51: 0.78193272 | D51: 0.77078688
A52: 20 | B52: 0.78440488 | C52: 0.77021152 | D52: 0.74933745
A53: 21 | B53: 0.6465587 | C53: 0.6564293 | D53: 0.67660499
A54: 22 | B54: 0.64627244 | C54: 0.69967526 | D54: 0.69004986
...
