Workbook

Sheet scen2_hybsem
A1: turnId | B1: user_id | C1: assistant_id | D1: projectName | E1: sessionName | F1: seq | G1: anchorName | H1: weight | I1: promptSim | J1: responseSim | K1: activation delta | L1: prompt_to_response | N1: Average activation/turn | O1: average conversation activation | P1: count | Q1: correlation weights / activation delta | R1: p
A3: d5467efd-28d9-4c8c-9387-706193cf09bf | B3: cmja3vbwt000kzc4eu2msjdwc | C3: cmja3w8rs0011zc4e5ijfrp3u | D3: hybrid_v3_5_semantic | E3: Scenario_2_v3 | F3: 1 | G3: practicality_and_feasibility | H3: 0.2222 | I3: 0.32941288 | J3: 0.38415677 | K3: =J3-I3 -> 0.054743893 | L3: 0.82646574 | N3: =AVERAGE(K3:K8) -> 0.054643126 | O3: =AVERAGE(K3:K141) -> 0.057053659 | P3: =COUNT(K3:K141) -> 139 | Q3: =CORREL(H3:H141,K3:K141) -> 0.12685514 | R3: 0.1367
A4: d5467efd-28d9-4c8c-9387-706193cf09bf | B4: cmja3vbwt000kzc4eu2msjdwc | C4: cmja3w8rs0011zc4e5ijfrp3u | D4: hybrid_v3_5_semantic | E4: Scenario_2_v3 | F4: 1 | G4: affective_interface | H4: 0.1778 | I4: 0.2636086 | J4: 0.31499765 | K4: =J4-I4 -> 0.051389046 | L4: 0.82646574
A5: d5467efd-28d9-4c8c-9387-706193cf09bf | B5: cmja3vbwt000kzc4eu2msjdwc | C5: cmja3w8rs0011zc4e5ijfrp3u | D5: hybrid_v3_5_semantic | E5: Scenario_2_v3 | F5: 1 | G5: temporal_dynamics | H5: 0.1767 | I5: 0.26208051 | J5: 0.309427 | K5: =J5-I5 -> 0.047346493 | L5: 0.82646574
A6: d5467efd-28d9-4c8c-9387-706193cf09bf | B6: cmja3vbwt000kzc4eu2msjdwc | C6: cmja3w8rs0011zc4e5ijfrp3u | D6: hybrid_v3_5_semantic | E6: Scenario_2_v3 | F6: 1 | G6: imagination_and_possibility | H6: 0.1723 | I6: 0.25550535 | J6: 0.30110371 | K6: =J6-I6 -> 0.045598355 | L6: 0.82646574
A7: d5467efd-28d9-4c8c-9387-706193cf09bf | B7: cmja3vbwt000kzc4eu2msjdwc | C7: cmja3w8rs0011zc4e5ijfrp3u | D7: hybrid_v3_5_semantic | E7: Scenario_2_v3 | F7: 1 | G7: mathematics_computer_science_engineering | H7: 0.151 | I7: 0.22394351 | J7: 0.27295796 | K7: =J7-I7 -> 0.049014452 | L7: 0.82646574
A8: d5467efd-28d9-4c8c-9387-706193cf09bf | B8: cmja3vbwt000kzc4eu2msjdwc | C8: cmja3w8rs0011zc4e5ijfrp3u | D8: hybrid_v3_5_semantic | E8: Scenario_2_v3 | F8: 1 | G8: truth_and_fact | H8: 0.1 | I8: 0.1178327 | J8: 0.19759922 | K8: =J8-I8 -> 0.079766518 | L8: 0.82646574
A9: 78b215aa-3d91-4f01-80f0-4d26a10ac328 | B9: cmja3xbm40015zc4eqpdb9puo | C9: cmja3yldr001mzc4epu7kbfl9 | D9: hybrid_v3_5_semantic | E9: Scenario_2_v3 | F9: 3 | G9: practicality_and_feasibility | H9: 0.2342 | I9: 0.32501911 | J9: 0.40429584 | K9: =J9-I9 -> 0.079276739 | L9: 0.76029579 | N9: =AVERAGE(K9:K14) -> 0.082002902
A10: 78b215aa-3d91-4f01-80f0-4d26a10ac328 | B10: cmja3xbm40015zc4eqpdb9puo | C10: cmja3yldr001mzc4epu7kbfl9 | D10: hybrid_v3_5_semantic | E10: Scenario_2_v3 | F10: 3 | G10: temporal_dynamics | H10: 0.1886 | I10: 0.26167104 | J10: 0.30152499 | K10: =J10-I10 -> 0.039853946 | L10: 0.76029579
A11: 78b215aa-3d91-4f01-80f0-4d26a10ac328 | B11: cmja3xbm40015zc4eqpdb9puo | C11: cmja3yldr001mzc4epu7kbfl9 | D11: hybrid_v3_5_semantic | E11: Scenario_2_v3 | F11: 3 | G11: affective_interface | H11: 0.1731 | I11: 0.24023265 | J11: 0.35000473 | K11: =J11-I11 -> 0.10977208 | L11: 0.76029579
A12: 78b215aa-3d91-4f01-80f0-4d26a10ac328 | B12: cmja3xbm40015zc4eqpdb9puo | C12: cmja3yldr001mzc4epu7kbfl9 | D12: hybrid_v3_5_semantic | E12: Scenario_2_v3 | F12: 3 | G12: mathematics_computer_science_engineering | H12: 0.1535 | I12: 0.21294256 | J12: 0.28950073 | K12: =J12-I12 -> 0.076558169 | L12: 0.76029579
A13: 78b215aa-3d91-4f01-80f0-4d26a10ac328 | B13: cmja3xbm40015zc4eqpdb9puo | C13: cmja3yldr001mzc4epu7kbfl9 | D13: hybrid_v3_5_semantic | E13: Scenario_2_v3 | F13: 3 | G13: imagination_and_possibility | H13: 0.1506 | I13: 0.20904092 | J13: 0.27680546 | K13: =J13-I13 -> 0.067764532 | L13: 0.76029579
A14: 78b215aa-3d91-4f01-80f0-4d26a10ac328 | B14: cmja3xbm40015zc4eqpdb9puo | C14: cmja3yldr001mzc4epu7kbfl9 | D14: hybrid_v3_5_semantic | E14: Scenario_2_v3 | F14: 3 | G14: truth_and_fact | H14: 0.1 | I14: 0.11605782 | J14: 0.23484977 | K14: =J14-I14 -> 0.11879195 | L14: 0.76029579
A15: 5e6c3f49-1682-4f70-a5d5-50e29b1d251a | B15: cmja3ztgv001qzc4e6p1ojxtj | C15: cmja40goc0027zc4ec8dqkvdm | D15: hybrid_v3_5_semantic | E15: Scenario_2_v3 | F15: 5 | G15: practicality_and_feasibility | H15: 0.2203 | I15: 0.41180675 | J15: 0.4359075 | K15: =J15-I15 -> 0.024100744 | L15: 0.7455131 | N15: =AVERAGE(K15:K20) -> 0.050709209
A16: 5e6c3f49-1682-4f70-a5d5-50e29b1d251a | B16: cmja3ztgv001qzc4e6p1ojxtj | C16: cmja40goc0027zc4ec8dqkvdm | D16: hybrid_v3_5_semantic | E16: Scenario_2_v3 | F16: 5 | G16: temporal_dynamics | H16: 0.189 | I16: 0.35336547 | J16: 0.40886101 | K16: =J16-I16 -> 0.055495539 | L16: 0.7455131
A17: 5e6c3f49-1682-4f70-a5d5-50e29b1d251a | B17: cmja3ztgv001qzc4e6p1ojxtj | C17: cmja40goc0027zc4ec8dqkvdm | D17: hybrid_v3_5_semantic | E17: Scenario_2_v3 | F17: 5 | G17: affective_interface | H17: 0.1812 | I17: 0.33863153 | J17: 0.38842965 | K17: =J17-I17 -> 0.049798119 | L17: 0.7455131
A18: 5e6c3f49-1682-4f70-a5d5-50e29b1d251a | B18: cmja3ztgv001qzc4e6p1ojxtj | C18: cmja40goc0027zc4ec8dqkvdm | D18: hybrid_v3_5_semantic | E18: Scenario_2_v3 | F18: 5 | G18: mathematics_computer_science_engineering | H18: 0.1556 | I18: 0.29079414 | J18: 0.31568412 | K18: =J18-I18 -> 0.024889981 | L18: 0.7455131
A19: 5e6c3f49-1682-4f70-a5d5-50e29b1d251a | B19: cmja3ztgv001qzc4e6p1ojxtj | C19: cmja40goc0027zc4ec8dqkvdm | D19: hybrid_v3_5_semantic | E19: Scenario_2_v3 | F19: 5 | G19: imagination_and_possibility | H19: 0.1539 | I19: 0.28769599 | J19: 0.35870841 | K19: =J19-I19 -> 0.071012419 | L19: 0.7455131
A20: 5e6c3f49-1682-4f70-a5d5-50e29b1d251a | B20: cmja3ztgv001qzc4e6p1ojxtj | C20: cmja40goc0027zc4ec8dqkvdm | D20: hybrid_v3_5_semantic | E20: Scenario_2_v3 | F20: 5 | G20: truth_and_fact | H20: 0.1 | I20: 0.18588471 | J20: 0.26484316 | K20: =J20-I20 -> 0.078958452 | L20: 0.7455131
A21: 432a16b9-3618-4aaf-8ded-e470f745b0e1 | B21: cmja41qfw002bzc4eiega4byl | C21: cmja42b8j002szc4ee73fqo9s | D21: hybrid_v3_5_semantic | E21: Scenario_2_v3 | F21: 7 | G21: practicality_and_feasibility | H21: 0.2216 | I21: 0.36700319 | J21: 0.39461517 | K21: =J21-I21 -> 0.027611981 | L21: 0.74023798 | N21: =AVERAGE(K21:K26) -> 0.041890347
A22: 432a16b9-3618-4aaf-8ded-e470f745b0e1 | B22: cmja41qfw002bzc4eiega4byl | C22: cmja42b8j002szc4ee73fqo9s | D22: hybrid_v3_5_semantic | E22: Scenario_2_v3 | F22: 7 | G22: temporal_dynamics | H22: 0.2039 | I22: 0.33762121 | J22: 0.31170541 | K22: =J22-I22 -> -0.025915805 | L22: 0.74023798
A23: 432a16b9-3618-4aaf-8ded-e470f745b0e1 | B23: cmja41qfw002bzc4eiega4byl | C23: cmja42b8j002szc4ee73fqo9s | D23: hybrid_v3_5_semantic | E23: Scenario_2_v3 | F23: 7 | G23: affective_interface | H23: 0.1702 | I23: 0.28177854 | J23: 0.36533146 | K23: =J23-I23 -> 0.083552916 | L23: 0.74023798
A24: 432a16b9-3618-4aaf-8ded-e470f745b0e1 | B24: cmja41qfw002bzc4eiega4byl | C24: cmja42b8j002szc4ee73fqo9s | D24: hybrid_v3_5_semantic | E24: Scenario_2_v3 | F24: 7 | G24: imagination_and_possibility | H24: 0.1568 | I24: 0.25959495 | J24: 0.27986108 | K24: =J24-I24 -> 0.020266127 | L24: 0.74023798
A25: 432a16b9-3618-4aaf-8ded-e470f745b0e1 | B25: cmja41qfw002bzc4eiega4byl | C25: cmja42b8j002szc4ee73fqo9s | D25: hybrid_v3_5_semantic | E25: Scenario_2_v3 | F25: 7 | G25: mathematics_computer_science_engineering | H25: 0.1475 | I25: 0.24432024 | J25: 0.31208692 | K25: =J25-I25 -> 0.067766684 | L25: 0.74023798
A26: 432a16b9-3618-4aaf-8ded-e470f745b0e1 | B26: cmja41qfw002bzc4eiega4byl | C26: cmja42b8j002szc4ee73fqo9s | D26: hybrid_v3_5_semantic | E26: Scenario_2_v3 | F26: 7 | G26: truth_and_fact | H26: 0.1 | I26: 0.17939923 | J26: 0.25745941 | K26: =J26-I26 -> 0.078060177 | L26: 0.74023798
A27: 54dd1e03-398d-4eaa-9a7e-812574b69fa1 | B27: cmja43jjh002wzc4ed3mq4wza | C27: cmja443s4003dzc4e97urf3qe | D27: hybrid_v3_5_semantic | E27: Scenario_2_v3 | F27: 9 | G27: practicality_and_feasibility | H27: 0.2103 | I27: 0.33154777 | J27: 0.43299075 | K27: =J27-I27 -> 0.10144298 | L27: 0.70141781 | N27: =AVERAGE(K27:K32) -> 0.072899032
A28: 54dd1e03-398d-4eaa-9a7e-812574b69fa1 | B28: cmja43jjh002wzc4ed3mq4wza | C28: cmja443s4003dzc4e97urf3qe | D28: hybrid_v3_5_semantic | E28: Scenario_2_v3 | F28: 9 | G28: temporal_dynamics | H28: 0.1948 | I28: 0.30714359 | J28: 0.34157417 | K28: =J28-I28 -> 0.034430584 | L28: 0.70141781
A29: 54dd1e03-398d-4eaa-9a7e-812574b69fa1 | B29: cmja43jjh002wzc4ed3mq4wza | C29: cmja443s4003dzc4e97urf3qe | D29: hybrid_v3_5_semantic | E29: Scenario_2_v3 | F29: 9 | G29: affective_interface | H29: 0.1821 | I29: 0.28707494 | J29: 0.3613976 | K29: =J29-I29 -> 0.074322663 | L29: 0.70141781
A30: 54dd1e03-398d-4eaa-9a7e-812574b69fa1 | B30: cmja43jjh002wzc4ed3mq4wza | C30: cmja443s4003dzc4e97urf3qe | D30: hybrid_v3_5_semantic | E30: Scenario_2_v3 | F30: 9 | G30: mathematics_computer_science_engineering | H30: 0.1639 | I30: 0.25842434 | J30: 0.32468912 | K30: =J30-I30 -> 0.066264785 | L30: 0.70141781
A31: 54dd1e03-398d-4eaa-9a7e-812574b69fa1 | B31: cmja43jjh002wzc4ed3mq4wza | C31: cmja443s4003dzc4e97urf3qe | D31: hybrid_v3_5_semantic | E31: Scenario_2_v3 | F31: 9 | G31: imagination_and_possibility | H31: 0.1488 | I31: 0.23459671 | J31: 0.33525412 | K31: =J31-I31 -> 0.10065742 | L31: 0.70141781
A32: 54dd1e03-398d-4eaa-9a7e-812574b69fa1 | B32: cmja43jjh002wzc4ed3mq4wza | C32: cmja443s4003dzc4e97urf3qe | D32: hybrid_v3_5_semantic | E32: Scenario_2_v3 | F32: 9 | G32: truth_and_fact | H32: 0.1 | I32: 0.19688903 | J32: 0.2571648 | K32: =J32-I32 -> 0.060275763 | L32: 0.70141781
A33: 28e3c064-f5e1-4128-b3ee-b2c728419e53 | B33: cmja46dqm003hzc4e8eo9600x | C33: cmja47ez2003yzc4ef1gii1ye | D33: hybrid_v3_5_semantic | E33: Scenario_2_v3 | F33: 11 | G33: practicality_and_feasibility | H33: 0.2208 | I33: 0.31909553 | J33: 0.38907714 | K33: =J33-I33 -> 0.069981613 | L33: 0.76441227 | N33: =AVERAGE(K33:K38) -> 0.046802049
A34: 28e3c064-f5e1-4128-b3ee-b2c728419e53 | B34: cmja46dqm003hzc4e8eo9600x | C34: cmja47ez2003yzc4ef1gii1ye | D34: hybrid_v3_5_semantic | E34: Scenario_2_v3 | F34: 11 | G34: temporal_dynamics | H34: 0.2 | I34: 0.28897107 | J34: 0.28141823 | K34: =J34-I34 -> -0.0075528425 | L34: 0.76441227
A35: 28e3c064-f5e1-4128-b3ee-b2c728419e53 | B35: cmja46dqm003hzc4e8eo9600x | C35: cmja47ez2003yzc4ef1gii1ye | D35: hybrid_v3_5_semantic | E35: Scenario_2_v3 | F35: 11 | G35: affective_interface | H35: 0.1745 | I35: 0.25217791 | J35: 0.32692393 | K35: =J35-I35 -> 0.074746018 | L35: 0.76441227
A36: 28e3c064-f5e1-4128-b3ee-b2c728419e53 | B36: cmja46dqm003hzc4e8eo9600x | C36: cmja47ez2003yzc4ef1gii1ye | D36: hybrid_v3_5_semantic | E36: Scenario_2_v3 | F36: 11 | G36: mathematics_computer_science_engineering | H36: 0.1585 | I36: 0.22899788 | J36: 0.26525517 | K36: =J36-I36 -> 0.03625729 | L36: 0.76441227
A37: 28e3c064-f5e1-4128-b3ee-b2c728419e53 | B37: cmja46dqm003hzc4e8eo9600x | C37: cmja47ez2003yzc4ef1gii1ye | D37: hybrid_v3_5_semantic | E37: Scenario_2_v3 | F37: 11 | G37: imagination_and_possibility | H37: 0.1462 | I37: 0.21121805 | J37: 0.29054637 | K37: =J37-I37 -> 0.079328326 | L37: 0.76441227
A38: 28e3c064-f5e1-4128-b3ee-b2c728419e53 | B38: cmja46dqm003hzc4e8eo9600x | C38: cmja47ez2003yzc4ef1gii1ye | D38: hybrid_v3_5_semantic | E38: Scenario_2_v3 | F38: 11 | G38: truth_and_fact | H38: 0.1 | I38: 0.16147172 | J38: 0.18952361 | K38: =J38-I38 -> 0.028051887 | L38: 0.76441227
A39: a5e87be6-d125-4ad4-83e6-7882e3487ee9 | B39: cmja482q40042zc4eln0po4sx | C39: cmja48r2f004jzc4ec33zimak | D39: hybrid_v3_5_semantic | E39: Scenario_2_v3 | F39: 13 | G39: practicality_and_feasibility | H39: 0.2405 | I39: 0.31489127 | J39: 0.38863735 | K39: =J39-I39 -> 0.073746085 | L39: 0.70462919 | N39: =AVERAGE(K39:K44) -> 0.079766856
A40: a5e87be6-d125-4ad4-83e6-7882e3487ee9 | B40: cmja482q40042zc4eln0po4sx | C40: cmja48r2f004jzc4ec33zimak | D40: hybrid_v3_5_semantic | E40: Scenario_2_v3 | F40: 13 | G40: affective_interface | H40: 0.1784 | I40: 0.23362284 | J40: 0.35593965 | K40: =J40-I40 -> 0.12231681 | L40: 0.70462919
A41: a5e87be6-d125-4ad4-83e6-7882e3487ee9 | B41: cmja482q40042zc4eln0po4sx | C41: cmja48r2f004jzc4ec33zimak | D41: hybrid_v3_5_semantic | E41: Scenario_2_v3 | F41: 13 | G41: mathematics_computer_science_engineering | H41: 0.1686 | I41: 0.2207827 | J41: 0.26556293 | K41: =J41-I41 -> 0.044780238 | L41: 0.70462919
...

Sheet notes
A1: p calculation
A3: 1. count | B3: =scen2_hybsem!P3 -> 139
A4: 2. t statistic | B4: =B10*SQRT((B3-2)/(1-B10^2)) -> 1.4968943
A5: 3. p | B5: =_xlfn.T.DIST.2T(ABS(B4),B3-2) -> 0.13672107
A9: count | B9: correlation weights / activation delta
A10: =B3 -> 139 | B10: =scen2_hybsem!Q3 -> 0.12685514

Sheet actdel_prompt_response
B1: prompt_to_response | C1: Average activation/turn | H1: Correlation | I1: count | J1: T-statistic | K1: p
A2: Turn
A3: 1 | B3: 0.82646574 | C3: 0.054643126 | H3: =CORREL(B3:B27,C3:C27) -> -0.022568769 | I3: =COUNT(C3:C27) -> 25 | J3: =H3*SQRT((I3-2)/(1-H3^2)) -> -0.10826359 | K3: =_xlfn.T.DIST.2T(ABS(J3),I3-2) -> 0.91472555
A4: 2 | B4: 0.76029579 | C4: 0.082002902
A5: 3 | B5: 0.7455131 | C5: 0.050709209
A6: 4 | B6: 0.74023798 | C6: 0.041890347
A7: 5 | B7: 0.70141781 | C7: 0.072899032
A8: 6 | B8: 0.76441227 | C8: 0.046802049
A9: 7 | B9: 0.70462919 | C9: 0.079766856
A10: 8 | B10: 0.77201186 | C10: 0.028078518
A11: 9 | B11: 0.72188408 | C11: 0.040053029
A12: 10 | B12: 0.80179909 | C12: 0.064604803
A13: 11 | B13: 0.82639187 | C13: 0.10138798
A14: 12 | B14: 0.74557662 | C14: 0.10911979
A15: 13 | B15: 0.73930479 | C15: -0.096510018
... A27: 25 | B27: 0.72503242 | C27: 0.057386922

Sheet inter_system_stats
B2: Prompt-response
B3: hybsem | C3: control | E3: std. Hybsem | F3: std. Control | G3: F. test | H3: T. Test equal variances | I3: T.Test unequal | J3: Mean difference
A4: 1 | B4: 0.82646574 | C4: 0.81423911 | E4: =_xlfn.STDEV.S(B4:B28) -> 0.045126675 | F4: =_xlfn.STDEV.S(C4:C28) -> 0.11577762 | G4: =_xlfn.F.TEST(B4:B28,C4:C28) -> 1.8075799e-05 | H4: =_xlfn.T.TEST(B4:B28, C4:C28, 2,2) -> 3.4939752e-11 | I4: =_xlfn.T.TEST(B4:B28,C4:C28, 2,3) -> 1.1871252e-09 | J4: =AVERAGE(B4:B28)-AVERAGE(C4:C28) -> 0.21205229
A5: 2 | B5: 0.76029579 | C5: 0.49037431
A6: 3 | B6: 0.7455131 | C6: 0.51102033
A7: 4 | B7: 0.74023798 | C7: 0.73212747 | E7: Paired t-test
A8: 5 | B8: 0.70141781 | C8: 0.5045879 | E8: Alpha | F8: 0.05
A9: 6 | B9: 0.76441227 | C9: 0.62221695 | E9: Hypothesized Mean Difference | F9: 0
A10: 7 | B10: 0.70462919 | C10: 0.5682134 | F10: Variable 1 | G10: Variable 2
A11: 8 | B11: 0.77201186 | C11: 0.41336821 | E11: Mean | F11: =AVERAGE(inter_system_stats!$B$3:$B$28) -> 0.74906635 | G11: =AVERAGE(inter_system_stats!$C$3:$C$28) -> 0.53701406
A12: 9 | B12: 0.72188408 | C12: 0.4696191 | E12: Variance | F12: =VAR(inter_system_stats!$B$3:$B$28) -> 0.0020364168 | G12: =VAR(inter_system_stats!$C$3:$C$28) -> 0.013404458
A13: 10 | B13: 0.80179909 | C13: 0.70259754 | E13: Observations | F13: =COUNT(inter_system_stats!$B$3:$B$28) -> 25 | G13: =COUNT(inter_system_stats!$C$3:$C$28) -> 25
A14: 11 | B14: 0.82639187 | C14: 0.53574689 | E14: Pearson Correlation | F14: =CORREL(inter_system_stats!$B$3:$B$28,inter_system_stats!$C$3:$C$28) -> 0.30281849
A15: 12 | B15: 0.74557662 | C15: 0.61680633 | E15: Observed Mean Difference | F15: {=AVERAGE(IF(ISODD(IF(ISNUMBER(inter_system_stats!$B$3:$B$28), 1, 0) * IF(ISNUMBER(inter_system_stats!$C$3:$C$28), 1, 0)), inter_system_stats!$B$3:$B$28 - inter_system_stats!$C$3:$C$28, "NA"))} -> 0.21205229
A16: 13 | B16: 0.73930479 | C16: 0.52630891 | E16: Variance of the Differences | F16: {=VAR(IF(ISODD(IF(ISNUMBER(inter_system_stats!$B$3:$B$28), 1, 0) * IF(ISNUMBER(inter_system_stats!$C$3:$C$28), 1, 0)), inter_system_stats!$B$3:$B$28 - inter_system_stats!$C$3:$C$28, "NA"))} -> 0.012276628
A17: 14 | B17: 0.71677589 | C17: 0.42768382 | E17: df | F17: {=SUM(IF(ISNUMBER(inter_system_stats!$B$3:$B$28), 1, 0) * IF(ISNUMBER(inter_system_stats!$C$3:$C$28), 1, 0)) - 1} -> 24
A18: 15 | B18: 0.7233547 | C18: 0.57565816 | E18: t Stat | F18: =(inter_system_stats!$F$15 - inter_system_stats!$F$9) / (inter_system_stats!$F$16 / ( inter_system_stats!$F$17 + 1)) ^ 0.5 -> 9.5691514
A19: 16 | B19: 0.7414815 | C19: 0.57704588 | E19: P (T<=t) one-tail | F19: =TDIST(ABS(inter_system_stats!$F$18), inter_system_stats!$F$17, 1) -> 5.7676819e-10
A20: 17 | B20: 0.78281323 | C20: 0.65129577 | E20: t Critical one-tail | F20: =TINV(2*inter_system_stats!$F$8, inter_system_stats!$F$17) -> 1.7108821
A21: 18 | B21: 0.68392473 | C21: 0.59927589 | E21: P (T<=t) two-tail | F21: =TDIST(ABS(inter_system_stats!$F$18), inter_system_stats!$F$17, 2) -> 1.1535364e-09
A22: 19 | B22: 0.74186163 | C22: 0.50621472 | E22: t Critical two-tail | F22: =TINV(inter_system_stats!$F$8, inter_system_stats!$F$17) -> 2.0638986
A23: 20 | B23: 0.86129103 | C23: 0.47809959
A24: 21 | B24: 0.72699778 | C24: 0.38215194
A25: 22 | B25: 0.66522196 | C25: 0.42806876
A26: 23 | B26: 0.76174693 | C26: 0.34437109
A27: 24 | B27: 0.74621679 | C27: 0.58285066
A28: 25 | B28: 0.72503242 | C28: 0.36540877
B33: Prompt-response
B34: hybrid | C34: ac15p | D34: hybsem | F34: ANOVA - Single Factor
B35: 0.82558738 | C35: 0.84283713 | D35: 0.82646574 | F35: Alpha | G35: 0.05
B36: 0.7843254 | C36: 0.75574435 | D36: 0.76029579
B37: 0.74701543 | C37: 0.75246139 | D37: 0.7455131 | F37: Groups | G37: Count | H37: Sum | I37: Mean | J37: Variance
B38: 0.74257299 | C38: 0.75523994 | D38: 0.74023798 | F38: Column 1 | G38: =COUNT(inter_system_stats!$B$34:$B$59) -> 25 | H38: =SUM(inter_system_stats!$B$34:$B$59) -> 18.811104 | I38: =AVERAGE(inter_system_stats!$B$34:$B$59) -> 0.75244418 | J38: =VAR(inter_system_stats!$B$34:$B$59) -> 0.0023181036
B39: 0.6382916 | C39: 0.68196907 | D39: 0.70141781 | F39: Column 2 | G39: =COUNT(inter_system_stats!$C$34:$C$59) -> 25 | H39: =SUM(inter_system_stats!$C$34:$C$59) -> 18.805159 | I39: =AVERAGE(inter_system_stats!$C$34:$C$59) -> 0.75220636 | J39: =VAR(inter_system_stats!$C$34:$C$59) -> 0.0020240087
B40: 0.77002186 | C40: 0.80509458 | D40: 0.76441227 | F40: Column 3 | G40: =COUNT(inter_system_stats!$D$34:$D$59) -> 25 | H40: =SUM(inter_system_stats!$D$34:$D$59) -> 18.726659 | I40: =AVERAGE(inter_system_stats!$D$34:$D$59) -> 0.74906635 | J40: =VAR(inter_system_stats!$D$34:$D$59) -> 0.0020364168
B41: 0.77670818 | C41: 0.7314491 | D41: 0.70462919
B42: 0.76689514 | C42: 0.7986994 | D42: 0.77201186 | F42: Source of Variation | G42: SS | H42: df | I42: MS | J42: F | K42: P-value | L42: F critical
B43: 0.72686528 | C43: 0.75118107 | D43: 0.72188408 | F43: Between Groups | G43: =SUMPRODUCT(inter_system_stats!$H$38:$H$40,inter_system_stats!$I$38:$I$40)-SUM(inter_system_stats!$H$38:$H$40)^2/SUM(inter_system_stats!$G$38:$G$40) -> 0.00017771624 | H43: =COUNT(inter_system_stats!$H$38:$H$40)-1 -> 2 | I43: =inter_system_stats!$G$43 / inter_system_stats!$H$43 -> 8.8858118e-05 | J43: =inter_system_stats!$I$43 / inter_system_stats!$I$44 -> 0.041792449 | K43: =FDIST(inter_system_stats!$J$43, inter_system_stats!$H$43, inter_system_stats!$H$44) -> 0.95909206 | L43: =FINV(inter_system_stats!$G$35, inter_system_stats!$H$43, inter_system_stats!$H$44) -> 3.1239074
B44: 0.76670386 | C44: 0.78031701 | D44: 0.80179909 | F44: Within Groups | G44: =SUM(DEVSQ(inter_system_stats!$B$34:$B$59),DEVSQ(inter_system_stats!$C$34:$C$59),DEVSQ(inter_system_stats!$D$34:$D$59)) -> 0.1530847 | H44: =SUM(inter_system_stats!$G$38:$G$40)-COUNT(inter_system_stats!$G$38:$G$40) -> 72 | I44: =inter_system_stats!$G$44 / inter_system_stats!$H$44 -> 0.0021261764
B45: 0.82651214 | C45: 0.78896492 | D45: 0.82639187 | F45: Total | G45: =DEVSQ(inter_system_stats!$B$34:$B$59,inter_system_stats!$C$34:$C$59,inter_system_stats!$D$34:$D$59) -> 0.15326241 | H45: =SUM(inter_system_stats!$G$38:$G$40) - 1 -> 74
...
